2022-04-21T13:16:38|ERROR|ThorCamCaptureMeasure|thor_cam_capture Failed to update figure1: axis 2 is out of bounds for array of dimension 2. ['Traceback (most recent call last):\n', '  File "C:\\Users\\ZHao\\.conda\\envs\\scopefoundry\\lib\\site-packages\\ScopeFoundry\\measurement.py", line 273, in _on_display_update_timer\n    self.update_display()\n', '  File "C:\\Users\\Public\\quantum_sensing\\quantum_sensing\\fancy_microscope\\thorcam_capture.py", line 351, in update_display\n    self.imview.setImage(image, axes={\'y\':0, \'x\':1, \'c\':2}, autoLevels=True)\n', '  File "C:\\Users\\ZHao\\.conda\\envs\\scopefoundry\\lib\\site-packages\\pyqtgraph\\imageview\\ImageView.py", line 322, in setImage\n    self.updateImage(autoHistogramRange=autoHistogramRange)\n', '  File "C:\\Users\\ZHao\\.conda\\envs\\scopefoundry\\lib\\site-packages\\pyqtgraph\\imageview\\ImageView.py", line 714, in updateImage\n    image = self.getProcessedImage()\n', '  File "C:\\Users\\ZHao\\.conda\\envs\\scopefoundry\\lib\\site-packages\\pyqtgraph\\imageview\\ImageView.py", line 406, in getProcessedImage\n    self._imageLevels = self.quickMinMax(self.imageDisp)\n', '  File "C:\\Users\\ZHao\\.conda\\envs\\scopefoundry\\lib\\site-packages\\pyqtgraph\\imageview\\ImageView.py", line 648, in quickMinMax\n    float(nanmax(data.take(i, axis=cax)))) for i in range(data.shape[-1])]\n', '  File "C:\\Users\\ZHao\\.conda\\envs\\scopefoundry\\lib\\site-packages\\pyqtgraph\\imageview\\ImageView.py", line 648, in <listcomp>\n    float(nanmax(data.take(i, axis=cax)))) for i in range(data.shape[-1])]\n', 'numpy.AxisError: axis 2 is out of bounds for array of dimension 2\n']
2022-04-21T13:16:38|ERROR|ThorCamCaptureMeasure|thor_cam_capture Failed to update figure1: axis 2 is out of bounds for array of dimension 2. ['Traceback (most recent call last):\n', '  File "C:\\Users\\ZHao\\.conda\\envs\\scopefoundry\\lib\\site-packages\\ScopeFoundry\\measurement.py", line 273, in _on_display_update_timer\n    self.update_display()\n', '  File "C:\\Users\\Public\\quantum_sensing\\quantum_sensing\\fancy_microscope\\thorcam_capture.py", line 351, in update_display\n    self.imview.setImage(image, axes={\'y\':0, \'x\':1, \'c\':2}, autoLevels=True)\n', '  File "C:\\Users\\ZHao\\.conda\\envs\\scopefoundry\\lib\\site-packages\\pyqtgraph\\imageview\\ImageView.py", line 322, in setImage\n    self.updateImage(autoHistogramRange=autoHistogramRange)\n', '  File "C:\\Users\\ZHao\\.conda\\envs\\scopefoundry\\lib\\site-packages\\pyqtgraph\\imageview\\ImageView.py", line 714, in updateImage\n    image = self.getProcessedImage()\n', '  File "C:\\Users\\ZHao\\.conda\\envs\\scopefoundry\\lib\\site-packages\\pyqtgraph\\imageview\\ImageView.py", line 406, in getProcessedImage\n    self._imageLevels = self.quickMinMax(self.imageDisp)\n', '  File "C:\\Users\\ZHao\\.conda\\envs\\scopefoundry\\lib\\site-packages\\pyqtgraph\\imageview\\ImageView.py", line 648, in quickMinMax\n    float(nanmax(data.take(i, axis=cax)))) for i in range(data.shape[-1])]\n', '  File "C:\\Users\\ZHao\\.conda\\envs\\scopefoundry\\lib\\site-packages\\pyqtgraph\\imageview\\ImageView.py", line 648, in <listcomp>\n    float(nanmax(data.take(i, axis=cax)))) for i in range(data.shape[-1])]\n', 'numpy.AxisError: axis 2 is out of bounds for array of dimension 2\n']
2022-04-21T13:16:39|ERROR|ThorCamCaptureMeasure|thor_cam_capture Failed to update figure1: axis 2 is out of bounds for array of dimension 2. ['Traceback (most recent call last):\n', '  File "C:\\Users\\ZHao\\.conda\\envs\\scopefoundry\\lib\\site-packages\\ScopeFoundry\\measurement.py", line 273, in _on_display_update_timer\n    self.update_display()\n', '  File "C:\\Users\\Public\\quantum_sensing\\quantum_sensing\\fancy_microscope\\thorcam_capture.py", line 351, in update_display\n    self.imview.setImage(image, axes={\'y\':0, \'x\':1, \'c\':2}, autoLevels=True)\n', '  File "C:\\Users\\ZHao\\.conda\\envs\\scopefoundry\\lib\\site-packages\\pyqtgraph\\imageview\\ImageView.py", line 322, in setImage\n    self.updateImage(autoHistogramRange=autoHistogramRange)\n', '  File "C:\\Users\\ZHao\\.conda\\envs\\scopefoundry\\lib\\site-packages\\pyqtgraph\\imageview\\ImageView.py", line 714, in updateImage\n    image = self.getProcessedImage()\n', '  File "C:\\Users\\ZHao\\.conda\\envs\\scopefoundry\\lib\\site-packages\\pyqtgraph\\imageview\\ImageView.py", line 406, in getProcessedImage\n    self._imageLevels = self.quickMinMax(self.imageDisp)\n', '  File "C:\\Users\\ZHao\\.conda\\envs\\scopefoundry\\lib\\site-packages\\pyqtgraph\\imageview\\ImageView.py", line 648, in quickMinMax\n    float(nanmax(data.take(i, axis=cax)))) for i in range(data.shape[-1])]\n', '  File "C:\\Users\\ZHao\\.conda\\envs\\scopefoundry\\lib\\site-packages\\pyqtgraph\\imageview\\ImageView.py", line 648, in <listcomp>\n    float(nanmax(data.take(i, axis=cax)))) for i in range(data.shape[-1])]\n', 'numpy.AxisError: axis 2 is out of bounds for array of dimension 2\n']
2022-04-21T13:16:39|ERROR|ThorCamCaptureMeasure|thor_cam_capture Failed to update figure1: axis 2 is out of bounds for array of dimension 2. ['Traceback (most recent call last):\n', '  File "C:\\Users\\ZHao\\.conda\\envs\\scopefoundry\\lib\\site-packages\\ScopeFoundry\\measurement.py", line 273, in _on_display_update_timer\n    self.update_display()\n', '  File "C:\\Users\\Public\\quantum_sensing\\quantum_sensing\\fancy_microscope\\thorcam_capture.py", line 351, in update_display\n    self.imview.setImage(image, axes={\'y\':0, \'x\':1, \'c\':2}, autoLevels=True)\n', '  File "C:\\Users\\ZHao\\.conda\\envs\\scopefoundry\\lib\\site-packages\\pyqtgraph\\imageview\\ImageView.py", line 322, in setImage\n    self.updateImage(autoHistogramRange=autoHistogramRange)\n', '  File "C:\\Users\\ZHao\\.conda\\envs\\scopefoundry\\lib\\site-packages\\pyqtgraph\\imageview\\ImageView.py", line 714, in updateImage\n    image = self.getProcessedImage()\n', '  File "C:\\Users\\ZHao\\.conda\\envs\\scopefoundry\\lib\\site-packages\\pyqtgraph\\imageview\\ImageView.py", line 406, in getProcessedImage\n    self._imageLevels = self.quickMinMax(self.imageDisp)\n', '  File "C:\\Users\\ZHao\\.conda\\envs\\scopefoundry\\lib\\site-packages\\pyqtgraph\\imageview\\ImageView.py", line 648, in quickMinMax\n    float(nanmax(data.take(i, axis=cax)))) for i in range(data.shape[-1])]\n', '  File "C:\\Users\\ZHao\\.conda\\envs\\scopefoundry\\lib\\site-packages\\pyqtgraph\\imageview\\ImageView.py", line 648, in <listcomp>\n    float(nanmax(data.take(i, axis=cax)))) for i in range(data.shape[-1])]\n', 'numpy.AxisError: axis 2 is out of bounds for array of dimension 2\n']
2022-04-21T13:16:39|ERROR|ThorCamCaptureMeasure|thor_cam_capture Failed to update figure1: axis 2 is out of bounds for array of dimension 2. ['Traceback (most recent call last):\n', '  File "C:\\Users\\ZHao\\.conda\\envs\\scopefoundry\\lib\\site-packages\\ScopeFoundry\\measurement.py", line 273, in _on_display_update_timer\n    self.update_display()\n', '  File "C:\\Users\\Public\\quantum_sensing\\quantum_sensing\\fancy_microscope\\thorcam_capture.py", line 351, in update_display\n    self.imview.setImage(image, axes={\'y\':0, \'x\':1, \'c\':2}, autoLevels=True)\n', '  File "C:\\Users\\ZHao\\.conda\\envs\\scopefoundry\\lib\\site-packages\\pyqtgraph\\imageview\\ImageView.py", line 322, in setImage\n    self.updateImage(autoHistogramRange=autoHistogramRange)\n', '  File "C:\\Users\\ZHao\\.conda\\envs\\scopefoundry\\lib\\site-packages\\pyqtgraph\\imageview\\ImageView.py", line 714, in updateImage\n    image = self.getProcessedImage()\n', '  File "C:\\Users\\ZHao\\.conda\\envs\\scopefoundry\\lib\\site-packages\\pyqtgraph\\imageview\\ImageView.py", line 406, in getProcessedImage\n    self._imageLevels = self.quickMinMax(self.imageDisp)\n', '  File "C:\\Users\\ZHao\\.conda\\envs\\scopefoundry\\lib\\site-packages\\pyqtgraph\\imageview\\ImageView.py", line 648, in quickMinMax\n    float(nanmax(data.take(i, axis=cax)))) for i in range(data.shape[-1])]\n', '  File "C:\\Users\\ZHao\\.conda\\envs\\scopefoundry\\lib\\site-packages\\pyqtgraph\\imageview\\ImageView.py", line 648, in <listcomp>\n    float(nanmax(data.take(i, axis=cax)))) for i in range(data.shape[-1])]\n', 'numpy.AxisError: axis 2 is out of bounds for array of dimension 2\n']
2022-04-21T13:16:39|ERROR|ThorCamCaptureMeasure|thor_cam_capture Failed to update figure1: axis 2 is out of bounds for array of dimension 2. ['Traceback (most recent call last):\n', '  File "C:\\Users\\ZHao\\.conda\\envs\\scopefoundry\\lib\\site-packages\\ScopeFoundry\\measurement.py", line 273, in _on_display_update_timer\n    self.update_display()\n', '  File "C:\\Users\\Public\\quantum_sensing\\quantum_sensing\\fancy_microscope\\thorcam_capture.py", line 351, in update_display\n    self.imview.setImage(image, axes={\'y\':0, \'x\':1, \'c\':2}, autoLevels=True)\n', '  File "C:\\Users\\ZHao\\.conda\\envs\\scopefoundry\\lib\\site-packages\\pyqtgraph\\imageview\\ImageView.py", line 322, in setImage\n    self.updateImage(autoHistogramRange=autoHistogramRange)\n', '  File "C:\\Users\\ZHao\\.conda\\envs\\scopefoundry\\lib\\site-packages\\pyqtgraph\\imageview\\ImageView.py", line 714, in updateImage\n    image = self.getProcessedImage()\n', '  File "C:\\Users\\ZHao\\.conda\\envs\\scopefoundry\\lib\\site-packages\\pyqtgraph\\imageview\\ImageView.py", line 406, in getProcessedImage\n    self._imageLevels = self.quickMinMax(self.imageDisp)\n', '  File "C:\\Users\\ZHao\\.conda\\envs\\scopefoundry\\lib\\site-packages\\pyqtgraph\\imageview\\ImageView.py", line 648, in quickMinMax\n    float(nanmax(data.take(i, axis=cax)))) for i in range(data.shape[-1])]\n', '  File "C:\\Users\\ZHao\\.conda\\envs\\scopefoundry\\lib\\site-packages\\pyqtgraph\\imageview\\ImageView.py", line 648, in <listcomp>\n    float(nanmax(data.take(i, axis=cax)))) for i in range(data.shape[-1])]\n', 'numpy.AxisError: axis 2 is out of bounds for array of dimension 2\n']
2022-04-21T13:16:39|ERROR|ThorCamCaptureMeasure|thor_cam_capture Failed to update figure1: axis 2 is out of bounds for array of dimension 2. ['Traceback (most recent call last):\n', '  File "C:\\Users\\ZHao\\.conda\\envs\\scopefoundry\\lib\\site-packages\\ScopeFoundry\\measurement.py", line 273, in _on_display_update_timer\n    self.update_display()\n', '  File "C:\\Users\\Public\\quantum_sensing\\quantum_sensing\\fancy_microscope\\thorcam_capture.py", line 351, in update_display\n    self.imview.setImage(image, axes={\'y\':0, \'x\':1, \'c\':2}, autoLevels=True)\n', '  File "C:\\Users\\ZHao\\.conda\\envs\\scopefoundry\\lib\\site-packages\\pyqtgraph\\imageview\\ImageView.py", line 322, in setImage\n    self.updateImage(autoHistogramRange=autoHistogramRange)\n', '  File "C:\\Users\\ZHao\\.conda\\envs\\scopefoundry\\lib\\site-packages\\pyqtgraph\\imageview\\ImageView.py", line 714, in updateImage\n    image = self.getProcessedImage()\n', '  File "C:\\Users\\ZHao\\.conda\\envs\\scopefoundry\\lib\\site-packages\\pyqtgraph\\imageview\\ImageView.py", line 406, in getProcessedImage\n    self._imageLevels = self.quickMinMax(self.imageDisp)\n', '  File "C:\\Users\\ZHao\\.conda\\envs\\scopefoundry\\lib\\site-packages\\pyqtgraph\\imageview\\ImageView.py", line 648, in quickMinMax\n    float(nanmax(data.take(i, axis=cax)))) for i in range(data.shape[-1])]\n', '  File "C:\\Users\\ZHao\\.conda\\envs\\scopefoundry\\lib\\site-packages\\pyqtgraph\\imageview\\ImageView.py", line 648, in <listcomp>\n    float(nanmax(data.take(i, axis=cax)))) for i in range(data.shape[-1])]\n', 'numpy.AxisError: axis 2 is out of bounds for array of dimension 2\n']
2022-04-21T13:16:40|ERROR|ThorCamCaptureMeasure|thor_cam_capture Failed to update figure1: axis 2 is out of bounds for array of dimension 2. ['Traceback (most recent call last):\n', '  File "C:\\Users\\ZHao\\.conda\\envs\\scopefoundry\\lib\\site-packages\\ScopeFoundry\\measurement.py", line 273, in _on_display_update_timer\n    self.update_display()\n', '  File "C:\\Users\\Public\\quantum_sensing\\quantum_sensing\\fancy_microscope\\thorcam_capture.py", line 351, in update_display\n    self.imview.setImage(image, axes={\'y\':0, \'x\':1, \'c\':2}, autoLevels=True)\n', '  File "C:\\Users\\ZHao\\.conda\\envs\\scopefoundry\\lib\\site-packages\\pyqtgraph\\imageview\\ImageView.py", line 322, in setImage\n    self.updateImage(autoHistogramRange=autoHistogramRange)\n', '  File "C:\\Users\\ZHao\\.conda\\envs\\scopefoundry\\lib\\site-packages\\pyqtgraph\\imageview\\ImageView.py", line 714, in updateImage\n    image = self.getProcessedImage()\n', '  File "C:\\Users\\ZHao\\.conda\\envs\\scopefoundry\\lib\\site-packages\\pyqtgraph\\imageview\\ImageView.py", line 406, in getProcessedImage\n    self._imageLevels = self.quickMinMax(self.imageDisp)\n', '  File "C:\\Users\\ZHao\\.conda\\envs\\scopefoundry\\lib\\site-packages\\pyqtgraph\\imageview\\ImageView.py", line 648, in quickMinMax\n    float(nanmax(data.take(i, axis=cax)))) for i in range(data.shape[-1])]\n', '  File "C:\\Users\\ZHao\\.conda\\envs\\scopefoundry\\lib\\site-packages\\pyqtgraph\\imageview\\ImageView.py", line 648, in <listcomp>\n    float(nanmax(data.take(i, axis=cax)))) for i in range(data.shape[-1])]\n', 'numpy.AxisError: axis 2 is out of bounds for array of dimension 2\n']
2022-04-21T13:16:40|ERROR|ThorCamCaptureMeasure|thor_cam_capture Failed to update figure1: axis 2 is out of bounds for array of dimension 2. ['Traceback (most recent call last):\n', '  File "C:\\Users\\ZHao\\.conda\\envs\\scopefoundry\\lib\\site-packages\\ScopeFoundry\\measurement.py", line 273, in _on_display_update_timer\n    self.update_display()\n', '  File "C:\\Users\\Public\\quantum_sensing\\quantum_sensing\\fancy_microscope\\thorcam_capture.py", line 351, in update_display\n    self.imview.setImage(image, axes={\'y\':0, \'x\':1, \'c\':2}, autoLevels=True)\n', '  File "C:\\Users\\ZHao\\.conda\\envs\\scopefoundry\\lib\\site-packages\\pyqtgraph\\imageview\\ImageView.py", line 322, in setImage\n    self.updateImage(autoHistogramRange=autoHistogramRange)\n', '  File "C:\\Users\\ZHao\\.conda\\envs\\scopefoundry\\lib\\site-packages\\pyqtgraph\\imageview\\ImageView.py", line 714, in updateImage\n    image = self.getProcessedImage()\n', '  File "C:\\Users\\ZHao\\.conda\\envs\\scopefoundry\\lib\\site-packages\\pyqtgraph\\imageview\\ImageView.py", line 406, in getProcessedImage\n    self._imageLevels = self.quickMinMax(self.imageDisp)\n', '  File "C:\\Users\\ZHao\\.conda\\envs\\scopefoundry\\lib\\site-packages\\pyqtgraph\\imageview\\ImageView.py", line 648, in quickMinMax\n    float(nanmax(data.take(i, axis=cax)))) for i in range(data.shape[-1])]\n', '  File "C:\\Users\\ZHao\\.conda\\envs\\scopefoundry\\lib\\site-packages\\pyqtgraph\\imageview\\ImageView.py", line 648, in <listcomp>\n    float(nanmax(data.take(i, axis=cax)))) for i in range(data.shape[-1])]\n', 'numpy.AxisError: axis 2 is out of bounds for array of dimension 2\n']
2022-04-21T13:16:40|ERROR|ThorCamCaptureMeasure|thor_cam_capture Failed to update figure1: axis 2 is out of bounds for array of dimension 2. ['Traceback (most recent call last):\n', '  File "C:\\Users\\ZHao\\.conda\\envs\\scopefoundry\\lib\\site-packages\\ScopeFoundry\\measurement.py", line 273, in _on_display_update_timer\n    self.update_display()\n', '  File "C:\\Users\\Public\\quantum_sensing\\quantum_sensing\\fancy_microscope\\thorcam_capture.py", line 351, in update_display\n    self.imview.setImage(image, axes={\'y\':0, \'x\':1, \'c\':2}, autoLevels=True)\n', '  File "C:\\Users\\ZHao\\.conda\\envs\\scopefoundry\\lib\\site-packages\\pyqtgraph\\imageview\\ImageView.py", line 322, in setImage\n    self.updateImage(autoHistogramRange=autoHistogramRange)\n', '  File "C:\\Users\\ZHao\\.conda\\envs\\scopefoundry\\lib\\site-packages\\pyqtgraph\\imageview\\ImageView.py", line 714, in updateImage\n    image = self.getProcessedImage()\n', '  File "C:\\Users\\ZHao\\.conda\\envs\\scopefoundry\\lib\\site-packages\\pyqtgraph\\imageview\\ImageView.py", line 406, in getProcessedImage\n    self._imageLevels = self.quickMinMax(self.imageDisp)\n', '  File "C:\\Users\\ZHao\\.conda\\envs\\scopefoundry\\lib\\site-packages\\pyqtgraph\\imageview\\ImageView.py", line 648, in quickMinMax\n    float(nanmax(data.take(i, axis=cax)))) for i in range(data.shape[-1])]\n', '  File "C:\\Users\\ZHao\\.conda\\envs\\scopefoundry\\lib\\site-packages\\pyqtgraph\\imageview\\ImageView.py", line 648, in <listcomp>\n    float(nanmax(data.take(i, axis=cax)))) for i in range(data.shape[-1])]\n', 'numpy.AxisError: axis 2 is out of bounds for array of dimension 2\n']
2022-04-21T13:16:40|ERROR|ThorCamCaptureMeasure|thor_cam_capture Failed to update figure1: axis 2 is out of bounds for array of dimension 2. ['Traceback (most recent call last):\n', '  File "C:\\Users\\ZHao\\.conda\\envs\\scopefoundry\\lib\\site-packages\\ScopeFoundry\\measurement.py", line 273, in _on_display_update_timer\n    self.update_display()\n', '  File "C:\\Users\\Public\\quantum_sensing\\quantum_sensing\\fancy_microscope\\thorcam_capture.py", line 351, in update_display\n    self.imview.setImage(image, axes={\'y\':0, \'x\':1, \'c\':2}, autoLevels=True)\n', '  File "C:\\Users\\ZHao\\.conda\\envs\\scopefoundry\\lib\\site-packages\\pyqtgraph\\imageview\\ImageView.py", line 322, in setImage\n    self.updateImage(autoHistogramRange=autoHistogramRange)\n', '  File "C:\\Users\\ZHao\\.conda\\envs\\scopefoundry\\lib\\site-packages\\pyqtgraph\\imageview\\ImageView.py", line 714, in updateImage\n    image = self.getProcessedImage()\n', '  File "C:\\Users\\ZHao\\.conda\\envs\\scopefoundry\\lib\\site-packages\\pyqtgraph\\imageview\\ImageView.py", line 406, in getProcessedImage\n    self._imageLevels = self.quickMinMax(self.imageDisp)\n', '  File "C:\\Users\\ZHao\\.conda\\envs\\scopefoundry\\lib\\site-packages\\pyqtgraph\\imageview\\ImageView.py", line 648, in quickMinMax\n    float(nanmax(data.take(i, axis=cax)))) for i in range(data.shape[-1])]\n', '  File "C:\\Users\\ZHao\\.conda\\envs\\scopefoundry\\lib\\site-packages\\pyqtgraph\\imageview\\ImageView.py", line 648, in <listcomp>\n    float(nanmax(data.take(i, axis=cax)))) for i in range(data.shape[-1])]\n', 'numpy.AxisError: axis 2 is out of bounds for array of dimension 2\n']
2022-04-21T13:16:41|ERROR|ThorCamCaptureMeasure|thor_cam_capture Failed to update figure1: axis 2 is out of bounds for array of dimension 2. ['Traceback (most recent call last):\n', '  File "C:\\Users\\ZHao\\.conda\\envs\\scopefoundry\\lib\\site-packages\\ScopeFoundry\\measurement.py", line 273, in _on_display_update_timer\n    self.update_display()\n', '  File "C:\\Users\\Public\\quantum_sensing\\quantum_sensing\\fancy_microscope\\thorcam_capture.py", line 351, in update_display\n    self.imview.setImage(image, axes={\'y\':0, \'x\':1, \'c\':2}, autoLevels=True)\n', '  File "C:\\Users\\ZHao\\.conda\\envs\\scopefoundry\\lib\\site-packages\\pyqtgraph\\imageview\\ImageView.py", line 322, in setImage\n    self.updateImage(autoHistogramRange=autoHistogramRange)\n', '  File "C:\\Users\\ZHao\\.conda\\envs\\scopefoundry\\lib\\site-packages\\pyqtgraph\\imageview\\ImageView.py", line 714, in updateImage\n    image = self.getProcessedImage()\n', '  File "C:\\Users\\ZHao\\.conda\\envs\\scopefoundry\\lib\\site-packages\\pyqtgraph\\imageview\\ImageView.py", line 406, in getProcessedImage\n    self._imageLevels = self.quickMinMax(self.imageDisp)\n', '  File "C:\\Users\\ZHao\\.conda\\envs\\scopefoundry\\lib\\site-packages\\pyqtgraph\\imageview\\ImageView.py", line 648, in quickMinMax\n    float(nanmax(data.take(i, axis=cax)))) for i in range(data.shape[-1])]\n', '  File "C:\\Users\\ZHao\\.conda\\envs\\scopefoundry\\lib\\site-packages\\pyqtgraph\\imageview\\ImageView.py", line 648, in <listcomp>\n    float(nanmax(data.take(i, axis=cax)))) for i in range(data.shape[-1])]\n', 'numpy.AxisError: axis 2 is out of bounds for array of dimension 2\n']
2022-04-21T13:16:41|ERROR|ThorCamCaptureMeasure|thor_cam_capture Failed to update figure1: axis 2 is out of bounds for array of dimension 2. ['Traceback (most recent call last):\n', '  File "C:\\Users\\ZHao\\.conda\\envs\\scopefoundry\\lib\\site-packages\\ScopeFoundry\\measurement.py", line 273, in _on_display_update_timer\n    self.update_display()\n', '  File "C:\\Users\\Public\\quantum_sensing\\quantum_sensing\\fancy_microscope\\thorcam_capture.py", line 351, in update_display\n    self.imview.setImage(image, axes={\'y\':0, \'x\':1, \'c\':2}, autoLevels=True)\n', '  File "C:\\Users\\ZHao\\.conda\\envs\\scopefoundry\\lib\\site-packages\\pyqtgraph\\imageview\\ImageView.py", line 322, in setImage\n    self.updateImage(autoHistogramRange=autoHistogramRange)\n', '  File "C:\\Users\\ZHao\\.conda\\envs\\scopefoundry\\lib\\site-packages\\pyqtgraph\\imageview\\ImageView.py", line 714, in updateImage\n    image = self.getProcessedImage()\n', '  File "C:\\Users\\ZHao\\.conda\\envs\\scopefoundry\\lib\\site-packages\\pyqtgraph\\imageview\\ImageView.py", line 406, in getProcessedImage\n    self._imageLevels = self.quickMinMax(self.imageDisp)\n', '  File "C:\\Users\\ZHao\\.conda\\envs\\scopefoundry\\lib\\site-packages\\pyqtgraph\\imageview\\ImageView.py", line 648, in quickMinMax\n    float(nanmax(data.take(i, axis=cax)))) for i in range(data.shape[-1])]\n', '  File "C:\\Users\\ZHao\\.conda\\envs\\scopefoundry\\lib\\site-packages\\pyqtgraph\\imageview\\ImageView.py", line 648, in <listcomp>\n    float(nanmax(data.take(i, axis=cax)))) for i in range(data.shape[-1])]\n', 'numpy.AxisError: axis 2 is out of bounds for array of dimension 2\n']
2022-04-21T13:16:41|ERROR|ThorCamCaptureMeasure|thor_cam_capture Failed to update figure1: axis 2 is out of bounds for array of dimension 2. ['Traceback (most recent call last):\n', '  File "C:\\Users\\ZHao\\.conda\\envs\\scopefoundry\\lib\\site-packages\\ScopeFoundry\\measurement.py", line 273, in _on_display_update_timer\n    self.update_display()\n', '  File "C:\\Users\\Public\\quantum_sensing\\quantum_sensing\\fancy_microscope\\thorcam_capture.py", line 351, in update_display\n    self.imview.setImage(image, axes={\'y\':0, \'x\':1, \'c\':2}, autoLevels=True)\n', '  File "C:\\Users\\ZHao\\.conda\\envs\\scopefoundry\\lib\\site-packages\\pyqtgraph\\imageview\\ImageView.py", line 322, in setImage\n    self.updateImage(autoHistogramRange=autoHistogramRange)\n', '  File "C:\\Users\\ZHao\\.conda\\envs\\scopefoundry\\lib\\site-packages\\pyqtgraph\\imageview\\ImageView.py", line 714, in updateImage\n    image = self.getProcessedImage()\n', '  File "C:\\Users\\ZHao\\.conda\\envs\\scopefoundry\\lib\\site-packages\\pyqtgraph\\imageview\\ImageView.py", line 406, in getProcessedImage\n    self._imageLevels = self.quickMinMax(self.imageDisp)\n', '  File "C:\\Users\\ZHao\\.conda\\envs\\scopefoundry\\lib\\site-packages\\pyqtgraph\\imageview\\ImageView.py", line 648, in quickMinMax\n    float(nanmax(data.take(i, axis=cax)))) for i in range(data.shape[-1])]\n', '  File "C:\\Users\\ZHao\\.conda\\envs\\scopefoundry\\lib\\site-packages\\pyqtgraph\\imageview\\ImageView.py", line 648, in <listcomp>\n    float(nanmax(data.take(i, axis=cax)))) for i in range(data.shape[-1])]\n', 'numpy.AxisError: axis 2 is out of bounds for array of dimension 2\n']
2022-04-21T13:16:41|ERROR|ThorCamCaptureMeasure|thor_cam_capture Failed to update figure1: axis 2 is out of bounds for array of dimension 2. ['Traceback (most recent call last):\n', '  File "C:\\Users\\ZHao\\.conda\\envs\\scopefoundry\\lib\\site-packages\\ScopeFoundry\\measurement.py", line 273, in _on_display_update_timer\n    self.update_display()\n', '  File "C:\\Users\\Public\\quantum_sensing\\quantum_sensing\\fancy_microscope\\thorcam_capture.py", line 351, in update_display\n    self.imview.setImage(image, axes={\'y\':0, \'x\':1, \'c\':2}, autoLevels=True)\n', '  File "C:\\Users\\ZHao\\.conda\\envs\\scopefoundry\\lib\\site-packages\\pyqtgraph\\imageview\\ImageView.py", line 322, in setImage\n    self.updateImage(autoHistogramRange=autoHistogramRange)\n', '  File "C:\\Users\\ZHao\\.conda\\envs\\scopefoundry\\lib\\site-packages\\pyqtgraph\\imageview\\ImageView.py", line 714, in updateImage\n    image = self.getProcessedImage()\n', '  File "C:\\Users\\ZHao\\.conda\\envs\\scopefoundry\\lib\\site-packages\\pyqtgraph\\imageview\\ImageView.py", line 406, in getProcessedImage\n    self._imageLevels = self.quickMinMax(self.imageDisp)\n', '  File "C:\\Users\\ZHao\\.conda\\envs\\scopefoundry\\lib\\site-packages\\pyqtgraph\\imageview\\ImageView.py", line 648, in quickMinMax\n    float(nanmax(data.take(i, axis=cax)))) for i in range(data.shape[-1])]\n', '  File "C:\\Users\\ZHao\\.conda\\envs\\scopefoundry\\lib\\site-packages\\pyqtgraph\\imageview\\ImageView.py", line 648, in <listcomp>\n    float(nanmax(data.take(i, axis=cax)))) for i in range(data.shape[-1])]\n', 'numpy.AxisError: axis 2 is out of bounds for array of dimension 2\n']
2022-04-21T13:16:41|ERROR|ThorCamCaptureMeasure|thor_cam_capture Failed to update figure1: axis 2 is out of bounds for array of dimension 2. ['Traceback (most recent call last):\n', '  File "C:\\Users\\ZHao\\.conda\\envs\\scopefoundry\\lib\\site-packages\\ScopeFoundry\\measurement.py", line 273, in _on_display_update_timer\n    self.update_display()\n', '  File "C:\\Users\\Public\\quantum_sensing\\quantum_sensing\\fancy_microscope\\thorcam_capture.py", line 351, in update_display\n    self.imview.setImage(image, axes={\'y\':0, \'x\':1, \'c\':2}, autoLevels=True)\n', '  File "C:\\Users\\ZHao\\.conda\\envs\\scopefoundry\\lib\\site-packages\\pyqtgraph\\imageview\\ImageView.py", line 322, in setImage\n    self.updateImage(autoHistogramRange=autoHistogramRange)\n', '  File "C:\\Users\\ZHao\\.conda\\envs\\scopefoundry\\lib\\site-packages\\pyqtgraph\\imageview\\ImageView.py", line 714, in updateImage\n    image = self.getProcessedImage()\n', '  File "C:\\Users\\ZHao\\.conda\\envs\\scopefoundry\\lib\\site-packages\\pyqtgraph\\imageview\\ImageView.py", line 406, in getProcessedImage\n    self._imageLevels = self.quickMinMax(self.imageDisp)\n', '  File "C:\\Users\\ZHao\\.conda\\envs\\scopefoundry\\lib\\site-packages\\pyqtgraph\\imageview\\ImageView.py", line 648, in quickMinMax\n    float(nanmax(data.take(i, axis=cax)))) for i in range(data.shape[-1])]\n', '  File "C:\\Users\\ZHao\\.conda\\envs\\scopefoundry\\lib\\site-packages\\pyqtgraph\\imageview\\ImageView.py", line 648, in <listcomp>\n    float(nanmax(data.take(i, axis=cax)))) for i in range(data.shape[-1])]\n', 'numpy.AxisError: axis 2 is out of bounds for array of dimension 2\n']
2022-04-21T13:16:41|ERROR|ThorCamCaptureMeasure|thor_cam_capture Failed to update figure1: axis 2 is out of bounds for array of dimension 2. ['Traceback (most recent call last):\n', '  File "C:\\Users\\ZHao\\.conda\\envs\\scopefoundry\\lib\\site-packages\\ScopeFoundry\\measurement.py", line 273, in _on_display_update_timer\n    self.update_display()\n', '  File "C:\\Users\\Public\\quantum_sensing\\quantum_sensing\\fancy_microscope\\thorcam_capture.py", line 351, in update_display\n    self.imview.setImage(image, axes={\'y\':0, \'x\':1, \'c\':2}, autoLevels=True)\n', '  File "C:\\Users\\ZHao\\.conda\\envs\\scopefoundry\\lib\\site-packages\\pyqtgraph\\imageview\\ImageView.py", line 322, in setImage\n    self.updateImage(autoHistogramRange=autoHistogramRange)\n', '  File "C:\\Users\\ZHao\\.conda\\envs\\scopefoundry\\lib\\site-packages\\pyqtgraph\\imageview\\ImageView.py", line 714, in updateImage\n    image = self.getProcessedImage()\n', '  File "C:\\Users\\ZHao\\.conda\\envs\\scopefoundry\\lib\\site-packages\\pyqtgraph\\imageview\\ImageView.py", line 406, in getProcessedImage\n    self._imageLevels = self.quickMinMax(self.imageDisp)\n', '  File "C:\\Users\\ZHao\\.conda\\envs\\scopefoundry\\lib\\site-packages\\pyqtgraph\\imageview\\ImageView.py", line 648, in quickMinMax\n    float(nanmax(data.take(i, axis=cax)))) for i in range(data.shape[-1])]\n', '  File "C:\\Users\\ZHao\\.conda\\envs\\scopefoundry\\lib\\site-packages\\pyqtgraph\\imageview\\ImageView.py", line 648, in <listcomp>\n    float(nanmax(data.take(i, axis=cax)))) for i in range(data.shape[-1])]\n', 'numpy.AxisError: axis 2 is out of bounds for array of dimension 2\n']
2022-04-21T13:16:42|ERROR|ThorCamCaptureMeasure|thor_cam_capture Failed to update figure1: axis 2 is out of bounds for array of dimension 2. ['Traceback (most recent call last):\n', '  File "C:\\Users\\ZHao\\.conda\\envs\\scopefoundry\\lib\\site-packages\\ScopeFoundry\\measurement.py", line 273, in _on_display_update_timer\n    self.update_display()\n', '  File "C:\\Users\\Public\\quantum_sensing\\quantum_sensing\\fancy_microscope\\thorcam_capture.py", line 351, in update_display\n    self.imview.setImage(image, axes={\'y\':0, \'x\':1, \'c\':2}, autoLevels=True)\n', '  File "C:\\Users\\ZHao\\.conda\\envs\\scopefoundry\\lib\\site-packages\\pyqtgraph\\imageview\\ImageView.py", line 322, in setImage\n    self.updateImage(autoHistogramRange=autoHistogramRange)\n', '  File "C:\\Users\\ZHao\\.conda\\envs\\scopefoundry\\lib\\site-packages\\pyqtgraph\\imageview\\ImageView.py", line 714, in updateImage\n    image = self.getProcessedImage()\n', '  File "C:\\Users\\ZHao\\.conda\\envs\\scopefoundry\\lib\\site-packages\\pyqtgraph\\imageview\\ImageView.py", line 406, in getProcessedImage\n    self._imageLevels = self.quickMinMax(self.imageDisp)\n', '  File "C:\\Users\\ZHao\\.conda\\envs\\scopefoundry\\lib\\site-packages\\pyqtgraph\\imageview\\ImageView.py", line 648, in quickMinMax\n    float(nanmax(data.take(i, axis=cax)))) for i in range(data.shape[-1])]\n', '  File "C:\\Users\\ZHao\\.conda\\envs\\scopefoundry\\lib\\site-packages\\pyqtgraph\\imageview\\ImageView.py", line 648, in <listcomp>\n    float(nanmax(data.take(i, axis=cax)))) for i in range(data.shape[-1])]\n', 'numpy.AxisError: axis 2 is out of bounds for array of dimension 2\n']
2022-04-21T13:16:42|ERROR|ThorCamCaptureMeasure|thor_cam_capture Failed to update figure1: axis 2 is out of bounds for array of dimension 2. ['Traceback (most recent call last):\n', '  File "C:\\Users\\ZHao\\.conda\\envs\\scopefoundry\\lib\\site-packages\\ScopeFoundry\\measurement.py", line 273, in _on_display_update_timer\n    self.update_display()\n', '  File "C:\\Users\\Public\\quantum_sensing\\quantum_sensing\\fancy_microscope\\thorcam_capture.py", line 351, in update_display\n    self.imview.setImage(image, axes={\'y\':0, \'x\':1, \'c\':2}, autoLevels=True)\n', '  File "C:\\Users\\ZHao\\.conda\\envs\\scopefoundry\\lib\\site-packages\\pyqtgraph\\imageview\\ImageView.py", line 322, in setImage\n    self.updateImage(autoHistogramRange=autoHistogramRange)\n', '  File "C:\\Users\\ZHao\\.conda\\envs\\scopefoundry\\lib\\site-packages\\pyqtgraph\\imageview\\ImageView.py", line 714, in updateImage\n    image = self.getProcessedImage()\n', '  File "C:\\Users\\ZHao\\.conda\\envs\\scopefoundry\\lib\\site-packages\\pyqtgraph\\imageview\\ImageView.py", line 406, in getProcessedImage\n    self._imageLevels = self.quickMinMax(self.imageDisp)\n', '  File "C:\\Users\\ZHao\\.conda\\envs\\scopefoundry\\lib\\site-packages\\pyqtgraph\\imageview\\ImageView.py", line 648, in quickMinMax\n    float(nanmax(data.take(i, axis=cax)))) for i in range(data.shape[-1])]\n', '  File "C:\\Users\\ZHao\\.conda\\envs\\scopefoundry\\lib\\site-packages\\pyqtgraph\\imageview\\ImageView.py", line 648, in <listcomp>\n    float(nanmax(data.take(i, axis=cax)))) for i in range(data.shape[-1])]\n', 'numpy.AxisError: axis 2 is out of bounds for array of dimension 2\n']
2022-04-21T13:16:42|ERROR|ThorCamCaptureMeasure|thor_cam_capture Failed to update figure1: axis 2 is out of bounds for array of dimension 2. ['Traceback (most recent call last):\n', '  File "C:\\Users\\ZHao\\.conda\\envs\\scopefoundry\\lib\\site-packages\\ScopeFoundry\\measurement.py", line 273, in _on_display_update_timer\n    self.update_display()\n', '  File "C:\\Users\\Public\\quantum_sensing\\quantum_sensing\\fancy_microscope\\thorcam_capture.py", line 351, in update_display\n    self.imview.setImage(image, axes={\'y\':0, \'x\':1, \'c\':2}, autoLevels=True)\n', '  File "C:\\Users\\ZHao\\.conda\\envs\\scopefoundry\\lib\\site-packages\\pyqtgraph\\imageview\\ImageView.py", line 322, in setImage\n    self.updateImage(autoHistogramRange=autoHistogramRange)\n', '  File "C:\\Users\\ZHao\\.conda\\envs\\scopefoundry\\lib\\site-packages\\pyqtgraph\\imageview\\ImageView.py", line 714, in updateImage\n    image = self.getProcessedImage()\n', '  File "C:\\Users\\ZHao\\.conda\\envs\\scopefoundry\\lib\\site-packages\\pyqtgraph\\imageview\\ImageView.py", line 406, in getProcessedImage\n    self._imageLevels = self.quickMinMax(self.imageDisp)\n', '  File "C:\\Users\\ZHao\\.conda\\envs\\scopefoundry\\lib\\site-packages\\pyqtgraph\\imageview\\ImageView.py", line 648, in quickMinMax\n    float(nanmax(data.take(i, axis=cax)))) for i in range(data.shape[-1])]\n', '  File "C:\\Users\\ZHao\\.conda\\envs\\scopefoundry\\lib\\site-packages\\pyqtgraph\\imageview\\ImageView.py", line 648, in <listcomp>\n    float(nanmax(data.take(i, axis=cax)))) for i in range(data.shape[-1])]\n', 'numpy.AxisError: axis 2 is out of bounds for array of dimension 2\n']
2022-04-21T13:16:42|ERROR|ThorCamCaptureMeasure|thor_cam_capture Failed to update figure1: axis 2 is out of bounds for array of dimension 2. ['Traceback (most recent call last):\n', '  File "C:\\Users\\ZHao\\.conda\\envs\\scopefoundry\\lib\\site-packages\\ScopeFoundry\\measurement.py", line 273, in _on_display_update_timer\n    self.update_display()\n', '  File "C:\\Users\\Public\\quantum_sensing\\quantum_sensing\\fancy_microscope\\thorcam_capture.py", line 351, in update_display\n    self.imview.setImage(image, axes={\'y\':0, \'x\':1, \'c\':2}, autoLevels=True)\n', '  File "C:\\Users\\ZHao\\.conda\\envs\\scopefoundry\\lib\\site-packages\\pyqtgraph\\imageview\\ImageView.py", line 322, in setImage\n    self.updateImage(autoHistogramRange=autoHistogramRange)\n', '  File "C:\\Users\\ZHao\\.conda\\envs\\scopefoundry\\lib\\site-packages\\pyqtgraph\\imageview\\ImageView.py", line 714, in updateImage\n    image = self.getProcessedImage()\n', '  File "C:\\Users\\ZHao\\.conda\\envs\\scopefoundry\\lib\\site-packages\\pyqtgraph\\imageview\\ImageView.py", line 406, in getProcessedImage\n    self._imageLevels = self.quickMinMax(self.imageDisp)\n', '  File "C:\\Users\\ZHao\\.conda\\envs\\scopefoundry\\lib\\site-packages\\pyqtgraph\\imageview\\ImageView.py", line 648, in quickMinMax\n    float(nanmax(data.take(i, axis=cax)))) for i in range(data.shape[-1])]\n', '  File "C:\\Users\\ZHao\\.conda\\envs\\scopefoundry\\lib\\site-packages\\pyqtgraph\\imageview\\ImageView.py", line 648, in <listcomp>\n    float(nanmax(data.take(i, axis=cax)))) for i in range(data.shape[-1])]\n', 'numpy.AxisError: axis 2 is out of bounds for array of dimension 2\n']
2022-04-21T13:16:43|ERROR|ThorCamCaptureMeasure|thor_cam_capture Failed to update figure1: axis 2 is out of bounds for array of dimension 2. ['Traceback (most recent call last):\n', '  File "C:\\Users\\ZHao\\.conda\\envs\\scopefoundry\\lib\\site-packages\\ScopeFoundry\\measurement.py", line 273, in _on_display_update_timer\n    self.update_display()\n', '  File "C:\\Users\\Public\\quantum_sensing\\quantum_sensing\\fancy_microscope\\thorcam_capture.py", line 351, in update_display\n    self.imview.setImage(image, axes={\'y\':0, \'x\':1, \'c\':2}, autoLevels=True)\n', '  File "C:\\Users\\ZHao\\.conda\\envs\\scopefoundry\\lib\\site-packages\\pyqtgraph\\imageview\\ImageView.py", line 322, in setImage\n    self.updateImage(autoHistogramRange=autoHistogramRange)\n', '  File "C:\\Users\\ZHao\\.conda\\envs\\scopefoundry\\lib\\site-packages\\pyqtgraph\\imageview\\ImageView.py", line 714, in updateImage\n    image = self.getProcessedImage()\n', '  File "C:\\Users\\ZHao\\.conda\\envs\\scopefoundry\\lib\\site-packages\\pyqtgraph\\imageview\\ImageView.py", line 406, in getProcessedImage\n    self._imageLevels = self.quickMinMax(self.imageDisp)\n', '  File "C:\\Users\\ZHao\\.conda\\envs\\scopefoundry\\lib\\site-packages\\pyqtgraph\\imageview\\ImageView.py", line 648, in quickMinMax\n    float(nanmax(data.take(i, axis=cax)))) for i in range(data.shape[-1])]\n', '  File "C:\\Users\\ZHao\\.conda\\envs\\scopefoundry\\lib\\site-packages\\pyqtgraph\\imageview\\ImageView.py", line 648, in <listcomp>\n    float(nanmax(data.take(i, axis=cax)))) for i in range(data.shape[-1])]\n', 'numpy.AxisError: axis 2 is out of bounds for array of dimension 2\n']
2022-04-21T13:16:43|ERROR|ThorCamCaptureMeasure|thor_cam_capture Failed to update figure1: axis 2 is out of bounds for array of dimension 2. ['Traceback (most recent call last):\n', '  File "C:\\Users\\ZHao\\.conda\\envs\\scopefoundry\\lib\\site-packages\\ScopeFoundry\\measurement.py", line 273, in _on_display_update_timer\n    self.update_display()\n', '  File "C:\\Users\\Public\\quantum_sensing\\quantum_sensing\\fancy_microscope\\thorcam_capture.py", line 351, in update_display\n    self.imview.setImage(image, axes={\'y\':0, \'x\':1, \'c\':2}, autoLevels=True)\n', '  File "C:\\Users\\ZHao\\.conda\\envs\\scopefoundry\\lib\\site-packages\\pyqtgraph\\imageview\\ImageView.py", line 322, in setImage\n    self.updateImage(autoHistogramRange=autoHistogramRange)\n', '  File "C:\\Users\\ZHao\\.conda\\envs\\scopefoundry\\lib\\site-packages\\pyqtgraph\\imageview\\ImageView.py", line 714, in updateImage\n    image = self.getProcessedImage()\n', '  File "C:\\Users\\ZHao\\.conda\\envs\\scopefoundry\\lib\\site-packages\\pyqtgraph\\imageview\\ImageView.py", line 406, in getProcessedImage\n    self._imageLevels = self.quickMinMax(self.imageDisp)\n', '  File "C:\\Users\\ZHao\\.conda\\envs\\scopefoundry\\lib\\site-packages\\pyqtgraph\\imageview\\ImageView.py", line 648, in quickMinMax\n    float(nanmax(data.take(i, axis=cax)))) for i in range(data.shape[-1])]\n', '  File "C:\\Users\\ZHao\\.conda\\envs\\scopefoundry\\lib\\site-packages\\pyqtgraph\\imageview\\ImageView.py", line 648, in <listcomp>\n    float(nanmax(data.take(i, axis=cax)))) for i in range(data.shape[-1])]\n', 'numpy.AxisError: axis 2 is out of bounds for array of dimension 2\n']
2022-04-21T13:16:43|ERROR|ThorCamCaptureMeasure|thor_cam_capture Failed to update figure1: axis 2 is out of bounds for array of dimension 2. ['Traceback (most recent call last):\n', '  File "C:\\Users\\ZHao\\.conda\\envs\\scopefoundry\\lib\\site-packages\\ScopeFoundry\\measurement.py", line 273, in _on_display_update_timer\n    self.update_display()\n', '  File "C:\\Users\\Public\\quantum_sensing\\quantum_sensing\\fancy_microscope\\thorcam_capture.py", line 351, in update_display\n    self.imview.setImage(image, axes={\'y\':0, \'x\':1, \'c\':2}, autoLevels=True)\n', '  File "C:\\Users\\ZHao\\.conda\\envs\\scopefoundry\\lib\\site-packages\\pyqtgraph\\imageview\\ImageView.py", line 322, in setImage\n    self.updateImage(autoHistogramRange=autoHistogramRange)\n', '  File "C:\\Users\\ZHao\\.conda\\envs\\scopefoundry\\lib\\site-packages\\pyqtgraph\\imageview\\ImageView.py", line 714, in updateImage\n    image = self.getProcessedImage()\n', '  File "C:\\Users\\ZHao\\.conda\\envs\\scopefoundry\\lib\\site-packages\\pyqtgraph\\imageview\\ImageView.py", line 406, in getProcessedImage\n    self._imageLevels = self.quickMinMax(self.imageDisp)\n', '  File "C:\\Users\\ZHao\\.conda\\envs\\scopefoundry\\lib\\site-packages\\pyqtgraph\\imageview\\ImageView.py", line 648, in quickMinMax\n    float(nanmax(data.take(i, axis=cax)))) for i in range(data.shape[-1])]\n', '  File "C:\\Users\\ZHao\\.conda\\envs\\scopefoundry\\lib\\site-packages\\pyqtgraph\\imageview\\ImageView.py", line 648, in <listcomp>\n    float(nanmax(data.take(i, axis=cax)))) for i in range(data.shape[-1])]\n', 'numpy.AxisError: axis 2 is out of bounds for array of dimension 2\n']
2022-04-21T13:16:43|ERROR|ThorCamCaptureMeasure|thor_cam_capture Failed to update figure1: axis 2 is out of bounds for array of dimension 2. ['Traceback (most recent call last):\n', '  File "C:\\Users\\ZHao\\.conda\\envs\\scopefoundry\\lib\\site-packages\\ScopeFoundry\\measurement.py", line 273, in _on_display_update_timer\n    self.update_display()\n', '  File "C:\\Users\\Public\\quantum_sensing\\quantum_sensing\\fancy_microscope\\thorcam_capture.py", line 351, in update_display\n    self.imview.setImage(image, axes={\'y\':0, \'x\':1, \'c\':2}, autoLevels=True)\n', '  File "C:\\Users\\ZHao\\.conda\\envs\\scopefoundry\\lib\\site-packages\\pyqtgraph\\imageview\\ImageView.py", line 322, in setImage\n    self.updateImage(autoHistogramRange=autoHistogramRange)\n', '  File "C:\\Users\\ZHao\\.conda\\envs\\scopefoundry\\lib\\site-packages\\pyqtgraph\\imageview\\ImageView.py", line 714, in updateImage\n    image = self.getProcessedImage()\n', '  File "C:\\Users\\ZHao\\.conda\\envs\\scopefoundry\\lib\\site-packages\\pyqtgraph\\imageview\\ImageView.py", line 406, in getProcessedImage\n    self._imageLevels = self.quickMinMax(self.imageDisp)\n', '  File "C:\\Users\\ZHao\\.conda\\envs\\scopefoundry\\lib\\site-packages\\pyqtgraph\\imageview\\ImageView.py", line 648, in quickMinMax\n    float(nanmax(data.take(i, axis=cax)))) for i in range(data.shape[-1])]\n', '  File "C:\\Users\\ZHao\\.conda\\envs\\scopefoundry\\lib\\site-packages\\pyqtgraph\\imageview\\ImageView.py", line 648, in <listcomp>\n    float(nanmax(data.take(i, axis=cax)))) for i in range(data.shape[-1])]\n', 'numpy.AxisError: axis 2 is out of bounds for array of dimension 2\n']
2022-04-21T13:16:43|ERROR|ThorCamCaptureMeasure|thor_cam_capture Failed to update figure1: axis 2 is out of bounds for array of dimension 2. ['Traceback (most recent call last):\n', '  File "C:\\Users\\ZHao\\.conda\\envs\\scopefoundry\\lib\\site-packages\\ScopeFoundry\\measurement.py", line 273, in _on_display_update_timer\n    self.update_display()\n', '  File "C:\\Users\\Public\\quantum_sensing\\quantum_sensing\\fancy_microscope\\thorcam_capture.py", line 351, in update_display\n    self.imview.setImage(image, axes={\'y\':0, \'x\':1, \'c\':2}, autoLevels=True)\n', '  File "C:\\Users\\ZHao\\.conda\\envs\\scopefoundry\\lib\\site-packages\\pyqtgraph\\imageview\\ImageView.py", line 322, in setImage\n    self.updateImage(autoHistogramRange=autoHistogramRange)\n', '  File "C:\\Users\\ZHao\\.conda\\envs\\scopefoundry\\lib\\site-packages\\pyqtgraph\\imageview\\ImageView.py", line 714, in updateImage\n    image = self.getProcessedImage()\n', '  File "C:\\Users\\ZHao\\.conda\\envs\\scopefoundry\\lib\\site-packages\\pyqtgraph\\imageview\\ImageView.py", line 406, in getProcessedImage\n    self._imageLevels = self.quickMinMax(self.imageDisp)\n', '  File "C:\\Users\\ZHao\\.conda\\envs\\scopefoundry\\lib\\site-packages\\pyqtgraph\\imageview\\ImageView.py", line 648, in quickMinMax\n    float(nanmax(data.take(i, axis=cax)))) for i in range(data.shape[-1])]\n', '  File "C:\\Users\\ZHao\\.conda\\envs\\scopefoundry\\lib\\site-packages\\pyqtgraph\\imageview\\ImageView.py", line 648, in <listcomp>\n    float(nanmax(data.take(i, axis=cax)))) for i in range(data.shape[-1])]\n', 'numpy.AxisError: axis 2 is out of bounds for array of dimension 2\n']
2022-04-21T13:16:44|ERROR|ThorCamCaptureMeasure|thor_cam_capture Failed to update figure1: axis 2 is out of bounds for array of dimension 2. ['Traceback (most recent call last):\n', '  File "C:\\Users\\ZHao\\.conda\\envs\\scopefoundry\\lib\\site-packages\\ScopeFoundry\\measurement.py", line 273, in _on_display_update_timer\n    self.update_display()\n', '  File "C:\\Users\\Public\\quantum_sensing\\quantum_sensing\\fancy_microscope\\thorcam_capture.py", line 351, in update_display\n    self.imview.setImage(image, axes={\'y\':0, \'x\':1, \'c\':2}, autoLevels=True)\n', '  File "C:\\Users\\ZHao\\.conda\\envs\\scopefoundry\\lib\\site-packages\\pyqtgraph\\imageview\\ImageView.py", line 322, in setImage\n    self.updateImage(autoHistogramRange=autoHistogramRange)\n', '  File "C:\\Users\\ZHao\\.conda\\envs\\scopefoundry\\lib\\site-packages\\pyqtgraph\\imageview\\ImageView.py", line 714, in updateImage\n    image = self.getProcessedImage()\n', '  File "C:\\Users\\ZHao\\.conda\\envs\\scopefoundry\\lib\\site-packages\\pyqtgraph\\imageview\\ImageView.py", line 406, in getProcessedImage\n    self._imageLevels = self.quickMinMax(self.imageDisp)\n', '  File "C:\\Users\\ZHao\\.conda\\envs\\scopefoundry\\lib\\site-packages\\pyqtgraph\\imageview\\ImageView.py", line 648, in quickMinMax\n    float(nanmax(data.take(i, axis=cax)))) for i in range(data.shape[-1])]\n', '  File "C:\\Users\\ZHao\\.conda\\envs\\scopefoundry\\lib\\site-packages\\pyqtgraph\\imageview\\ImageView.py", line 648, in <listcomp>\n    float(nanmax(data.take(i, axis=cax)))) for i in range(data.shape[-1])]\n', 'numpy.AxisError: axis 2 is out of bounds for array of dimension 2\n']
2022-04-21T13:16:44|ERROR|ThorCamCaptureMeasure|thor_cam_capture Failed to update figure1: axis 2 is out of bounds for array of dimension 2. ['Traceback (most recent call last):\n', '  File "C:\\Users\\ZHao\\.conda\\envs\\scopefoundry\\lib\\site-packages\\ScopeFoundry\\measurement.py", line 273, in _on_display_update_timer\n    self.update_display()\n', '  File "C:\\Users\\Public\\quantum_sensing\\quantum_sensing\\fancy_microscope\\thorcam_capture.py", line 351, in update_display\n    self.imview.setImage(image, axes={\'y\':0, \'x\':1, \'c\':2}, autoLevels=True)\n', '  File "C:\\Users\\ZHao\\.conda\\envs\\scopefoundry\\lib\\site-packages\\pyqtgraph\\imageview\\ImageView.py", line 322, in setImage\n    self.updateImage(autoHistogramRange=autoHistogramRange)\n', '  File "C:\\Users\\ZHao\\.conda\\envs\\scopefoundry\\lib\\site-packages\\pyqtgraph\\imageview\\ImageView.py", line 714, in updateImage\n    image = self.getProcessedImage()\n', '  File "C:\\Users\\ZHao\\.conda\\envs\\scopefoundry\\lib\\site-packages\\pyqtgraph\\imageview\\ImageView.py", line 406, in getProcessedImage\n    self._imageLevels = self.quickMinMax(self.imageDisp)\n', '  File "C:\\Users\\ZHao\\.conda\\envs\\scopefoundry\\lib\\site-packages\\pyqtgraph\\imageview\\ImageView.py", line 648, in quickMinMax\n    float(nanmax(data.take(i, axis=cax)))) for i in range(data.shape[-1])]\n', '  File "C:\\Users\\ZHao\\.conda\\envs\\scopefoundry\\lib\\site-packages\\pyqtgraph\\imageview\\ImageView.py", line 648, in <listcomp>\n    float(nanmax(data.take(i, axis=cax)))) for i in range(data.shape[-1])]\n', 'numpy.AxisError: axis 2 is out of bounds for array of dimension 2\n']
2022-04-21T13:16:44|ERROR|ThorCamCaptureMeasure|thor_cam_capture Failed to update figure1: axis 2 is out of bounds for array of dimension 2. ['Traceback (most recent call last):\n', '  File "C:\\Users\\ZHao\\.conda\\envs\\scopefoundry\\lib\\site-packages\\ScopeFoundry\\measurement.py", line 273, in _on_display_update_timer\n    self.update_display()\n', '  File "C:\\Users\\Public\\quantum_sensing\\quantum_sensing\\fancy_microscope\\thorcam_capture.py", line 351, in update_display\n    self.imview.setImage(image, axes={\'y\':0, \'x\':1, \'c\':2}, autoLevels=True)\n', '  File "C:\\Users\\ZHao\\.conda\\envs\\scopefoundry\\lib\\site-packages\\pyqtgraph\\imageview\\ImageView.py", line 322, in setImage\n    self.updateImage(autoHistogramRange=autoHistogramRange)\n', '  File "C:\\Users\\ZHao\\.conda\\envs\\scopefoundry\\lib\\site-packages\\pyqtgraph\\imageview\\ImageView.py", line 714, in updateImage\n    image = self.getProcessedImage()\n', '  File "C:\\Users\\ZHao\\.conda\\envs\\scopefoundry\\lib\\site-packages\\pyqtgraph\\imageview\\ImageView.py", line 406, in getProcessedImage\n    self._imageLevels = self.quickMinMax(self.imageDisp)\n', '  File "C:\\Users\\ZHao\\.conda\\envs\\scopefoundry\\lib\\site-packages\\pyqtgraph\\imageview\\ImageView.py", line 648, in quickMinMax\n    float(nanmax(data.take(i, axis=cax)))) for i in range(data.shape[-1])]\n', '  File "C:\\Users\\ZHao\\.conda\\envs\\scopefoundry\\lib\\site-packages\\pyqtgraph\\imageview\\ImageView.py", line 648, in <listcomp>\n    float(nanmax(data.take(i, axis=cax)))) for i in range(data.shape[-1])]\n', 'numpy.AxisError: axis 2 is out of bounds for array of dimension 2\n']
2022-04-21T13:16:44|ERROR|ThorCamCaptureMeasure|thor_cam_capture Failed to update figure1: axis 2 is out of bounds for array of dimension 2. ['Traceback (most recent call last):\n', '  File "C:\\Users\\ZHao\\.conda\\envs\\scopefoundry\\lib\\site-packages\\ScopeFoundry\\measurement.py", line 273, in _on_display_update_timer\n    self.update_display()\n', '  File "C:\\Users\\Public\\quantum_sensing\\quantum_sensing\\fancy_microscope\\thorcam_capture.py", line 351, in update_display\n    self.imview.setImage(image, axes={\'y\':0, \'x\':1, \'c\':2}, autoLevels=True)\n', '  File "C:\\Users\\ZHao\\.conda\\envs\\scopefoundry\\lib\\site-packages\\pyqtgraph\\imageview\\ImageView.py", line 322, in setImage\n    self.updateImage(autoHistogramRange=autoHistogramRange)\n', '  File "C:\\Users\\ZHao\\.conda\\envs\\scopefoundry\\lib\\site-packages\\pyqtgraph\\imageview\\ImageView.py", line 714, in updateImage\n    image = self.getProcessedImage()\n', '  File "C:\\Users\\ZHao\\.conda\\envs\\scopefoundry\\lib\\site-packages\\pyqtgraph\\imageview\\ImageView.py", line 406, in getProcessedImage\n    self._imageLevels = self.quickMinMax(self.imageDisp)\n', '  File "C:\\Users\\ZHao\\.conda\\envs\\scopefoundry\\lib\\site-packages\\pyqtgraph\\imageview\\ImageView.py", line 648, in quickMinMax\n    float(nanmax(data.take(i, axis=cax)))) for i in range(data.shape[-1])]\n', '  File "C:\\Users\\ZHao\\.conda\\envs\\scopefoundry\\lib\\site-packages\\pyqtgraph\\imageview\\ImageView.py", line 648, in <listcomp>\n    float(nanmax(data.take(i, axis=cax)))) for i in range(data.shape[-1])]\n', 'numpy.AxisError: axis 2 is out of bounds for array of dimension 2\n']
2022-04-21T13:16:44|ERROR|ThorCamCaptureMeasure|thor_cam_capture Failed to update figure1: axis 2 is out of bounds for array of dimension 2. ['Traceback (most recent call last):\n', '  File "C:\\Users\\ZHao\\.conda\\envs\\scopefoundry\\lib\\site-packages\\ScopeFoundry\\measurement.py", line 273, in _on_display_update_timer\n    self.update_display()\n', '  File "C:\\Users\\Public\\quantum_sensing\\quantum_sensing\\fancy_microscope\\thorcam_capture.py", line 351, in update_display\n    self.imview.setImage(image, axes={\'y\':0, \'x\':1, \'c\':2}, autoLevels=True)\n', '  File "C:\\Users\\ZHao\\.conda\\envs\\scopefoundry\\lib\\site-packages\\pyqtgraph\\imageview\\ImageView.py", line 322, in setImage\n    self.updateImage(autoHistogramRange=autoHistogramRange)\n', '  File "C:\\Users\\ZHao\\.conda\\envs\\scopefoundry\\lib\\site-packages\\pyqtgraph\\imageview\\ImageView.py", line 714, in updateImage\n    image = self.getProcessedImage()\n', '  File "C:\\Users\\ZHao\\.conda\\envs\\scopefoundry\\lib\\site-packages\\pyqtgraph\\imageview\\ImageView.py", line 406, in getProcessedImage\n    self._imageLevels = self.quickMinMax(self.imageDisp)\n', '  File "C:\\Users\\ZHao\\.conda\\envs\\scopefoundry\\lib\\site-packages\\pyqtgraph\\imageview\\ImageView.py", line 648, in quickMinMax\n    float(nanmax(data.take(i, axis=cax)))) for i in range(data.shape[-1])]\n', '  File "C:\\Users\\ZHao\\.conda\\envs\\scopefoundry\\lib\\site-packages\\pyqtgraph\\imageview\\ImageView.py", line 648, in <listcomp>\n    float(nanmax(data.take(i, axis=cax)))) for i in range(data.shape[-1])]\n', 'numpy.AxisError: axis 2 is out of bounds for array of dimension 2\n']
2022-04-21T13:16:45|ERROR|ThorCamCaptureMeasure|thor_cam_capture Failed to update figure1: axis 2 is out of bounds for array of dimension 2. ['Traceback (most recent call last):\n', '  File "C:\\Users\\ZHao\\.conda\\envs\\scopefoundry\\lib\\site-packages\\ScopeFoundry\\measurement.py", line 273, in _on_display_update_timer\n    self.update_display()\n', '  File "C:\\Users\\Public\\quantum_sensing\\quantum_sensing\\fancy_microscope\\thorcam_capture.py", line 351, in update_display\n    self.imview.setImage(image, axes={\'y\':0, \'x\':1, \'c\':2}, autoLevels=True)\n', '  File "C:\\Users\\ZHao\\.conda\\envs\\scopefoundry\\lib\\site-packages\\pyqtgraph\\imageview\\ImageView.py", line 322, in setImage\n    self.updateImage(autoHistogramRange=autoHistogramRange)\n', '  File "C:\\Users\\ZHao\\.conda\\envs\\scopefoundry\\lib\\site-packages\\pyqtgraph\\imageview\\ImageView.py", line 714, in updateImage\n    image = self.getProcessedImage()\n', '  File "C:\\Users\\ZHao\\.conda\\envs\\scopefoundry\\lib\\site-packages\\pyqtgraph\\imageview\\ImageView.py", line 406, in getProcessedImage\n    self._imageLevels = self.quickMinMax(self.imageDisp)\n', '  File "C:\\Users\\ZHao\\.conda\\envs\\scopefoundry\\lib\\site-packages\\pyqtgraph\\imageview\\ImageView.py", line 648, in quickMinMax\n    float(nanmax(data.take(i, axis=cax)))) for i in range(data.shape[-1])]\n', '  File "C:\\Users\\ZHao\\.conda\\envs\\scopefoundry\\lib\\site-packages\\pyqtgraph\\imageview\\ImageView.py", line 648, in <listcomp>\n    float(nanmax(data.take(i, axis=cax)))) for i in range(data.shape[-1])]\n', 'numpy.AxisError: axis 2 is out of bounds for array of dimension 2\n']
2022-04-21T13:16:45|ERROR|ThorCamCaptureMeasure|thor_cam_capture Failed to update figure1: axis 2 is out of bounds for array of dimension 2. ['Traceback (most recent call last):\n', '  File "C:\\Users\\ZHao\\.conda\\envs\\scopefoundry\\lib\\site-packages\\ScopeFoundry\\measurement.py", line 273, in _on_display_update_timer\n    self.update_display()\n', '  File "C:\\Users\\Public\\quantum_sensing\\quantum_sensing\\fancy_microscope\\thorcam_capture.py", line 351, in update_display\n    self.imview.setImage(image, axes={\'y\':0, \'x\':1, \'c\':2}, autoLevels=True)\n', '  File "C:\\Users\\ZHao\\.conda\\envs\\scopefoundry\\lib\\site-packages\\pyqtgraph\\imageview\\ImageView.py", line 322, in setImage\n    self.updateImage(autoHistogramRange=autoHistogramRange)\n', '  File "C:\\Users\\ZHao\\.conda\\envs\\scopefoundry\\lib\\site-packages\\pyqtgraph\\imageview\\ImageView.py", line 714, in updateImage\n    image = self.getProcessedImage()\n', '  File "C:\\Users\\ZHao\\.conda\\envs\\scopefoundry\\lib\\site-packages\\pyqtgraph\\imageview\\ImageView.py", line 406, in getProcessedImage\n    self._imageLevels = self.quickMinMax(self.imageDisp)\n', '  File "C:\\Users\\ZHao\\.conda\\envs\\scopefoundry\\lib\\site-packages\\pyqtgraph\\imageview\\ImageView.py", line 648, in quickMinMax\n    float(nanmax(data.take(i, axis=cax)))) for i in range(data.shape[-1])]\n', '  File "C:\\Users\\ZHao\\.conda\\envs\\scopefoundry\\lib\\site-packages\\pyqtgraph\\imageview\\ImageView.py", line 648, in <listcomp>\n    float(nanmax(data.take(i, axis=cax)))) for i in range(data.shape[-1])]\n', 'numpy.AxisError: axis 2 is out of bounds for array of dimension 2\n']
2022-04-21T13:16:45|ERROR|ThorCamCaptureMeasure|thor_cam_capture Failed to update figure1: axis 2 is out of bounds for array of dimension 2. ['Traceback (most recent call last):\n', '  File "C:\\Users\\ZHao\\.conda\\envs\\scopefoundry\\lib\\site-packages\\ScopeFoundry\\measurement.py", line 273, in _on_display_update_timer\n    self.update_display()\n', '  File "C:\\Users\\Public\\quantum_sensing\\quantum_sensing\\fancy_microscope\\thorcam_capture.py", line 351, in update_display\n    self.imview.setImage(image, axes={\'y\':0, \'x\':1, \'c\':2}, autoLevels=True)\n', '  File "C:\\Users\\ZHao\\.conda\\envs\\scopefoundry\\lib\\site-packages\\pyqtgraph\\imageview\\ImageView.py", line 322, in setImage\n    self.updateImage(autoHistogramRange=autoHistogramRange)\n', '  File "C:\\Users\\ZHao\\.conda\\envs\\scopefoundry\\lib\\site-packages\\pyqtgraph\\imageview\\ImageView.py", line 714, in updateImage\n    image = self.getProcessedImage()\n', '  File "C:\\Users\\ZHao\\.conda\\envs\\scopefoundry\\lib\\site-packages\\pyqtgraph\\imageview\\ImageView.py", line 406, in getProcessedImage\n    self._imageLevels = self.quickMinMax(self.imageDisp)\n', '  File "C:\\Users\\ZHao\\.conda\\envs\\scopefoundry\\lib\\site-packages\\pyqtgraph\\imageview\\ImageView.py", line 648, in quickMinMax\n    float(nanmax(data.take(i, axis=cax)))) for i in range(data.shape[-1])]\n', '  File "C:\\Users\\ZHao\\.conda\\envs\\scopefoundry\\lib\\site-packages\\pyqtgraph\\imageview\\ImageView.py", line 648, in <listcomp>\n    float(nanmax(data.take(i, axis=cax)))) for i in range(data.shape[-1])]\n', 'numpy.AxisError: axis 2 is out of bounds for array of dimension 2\n']
2022-04-21T13:16:45|ERROR|ThorCamCaptureMeasure|thor_cam_capture Failed to update figure1: axis 2 is out of bounds for array of dimension 2. ['Traceback (most recent call last):\n', '  File "C:\\Users\\ZHao\\.conda\\envs\\scopefoundry\\lib\\site-packages\\ScopeFoundry\\measurement.py", line 273, in _on_display_update_timer\n    self.update_display()\n', '  File "C:\\Users\\Public\\quantum_sensing\\quantum_sensing\\fancy_microscope\\thorcam_capture.py", line 351, in update_display\n    self.imview.setImage(image, axes={\'y\':0, \'x\':1, \'c\':2}, autoLevels=True)\n', '  File "C:\\Users\\ZHao\\.conda\\envs\\scopefoundry\\lib\\site-packages\\pyqtgraph\\imageview\\ImageView.py", line 322, in setImage\n    self.updateImage(autoHistogramRange=autoHistogramRange)\n', '  File "C:\\Users\\ZHao\\.conda\\envs\\scopefoundry\\lib\\site-packages\\pyqtgraph\\imageview\\ImageView.py", line 714, in updateImage\n    image = self.getProcessedImage()\n', '  File "C:\\Users\\ZHao\\.conda\\envs\\scopefoundry\\lib\\site-packages\\pyqtgraph\\imageview\\ImageView.py", line 406, in getProcessedImage\n    self._imageLevels = self.quickMinMax(self.imageDisp)\n', '  File "C:\\Users\\ZHao\\.conda\\envs\\scopefoundry\\lib\\site-packages\\pyqtgraph\\imageview\\ImageView.py", line 648, in quickMinMax\n    float(nanmax(data.take(i, axis=cax)))) for i in range(data.shape[-1])]\n', '  File "C:\\Users\\ZHao\\.conda\\envs\\scopefoundry\\lib\\site-packages\\pyqtgraph\\imageview\\ImageView.py", line 648, in <listcomp>\n    float(nanmax(data.take(i, axis=cax)))) for i in range(data.shape[-1])]\n', 'numpy.AxisError: axis 2 is out of bounds for array of dimension 2\n']
2022-04-21T13:16:45|ERROR|ThorCamCaptureMeasure|thor_cam_capture Failed to update figure1: axis 2 is out of bounds for array of dimension 2. ['Traceback (most recent call last):\n', '  File "C:\\Users\\ZHao\\.conda\\envs\\scopefoundry\\lib\\site-packages\\ScopeFoundry\\measurement.py", line 273, in _on_display_update_timer\n    self.update_display()\n', '  File "C:\\Users\\Public\\quantum_sensing\\quantum_sensing\\fancy_microscope\\thorcam_capture.py", line 351, in update_display\n    self.imview.setImage(image, axes={\'y\':0, \'x\':1, \'c\':2}, autoLevels=True)\n', '  File "C:\\Users\\ZHao\\.conda\\envs\\scopefoundry\\lib\\site-packages\\pyqtgraph\\imageview\\ImageView.py", line 322, in setImage\n    self.updateImage(autoHistogramRange=autoHistogramRange)\n', '  File "C:\\Users\\ZHao\\.conda\\envs\\scopefoundry\\lib\\site-packages\\pyqtgraph\\imageview\\ImageView.py", line 714, in updateImage\n    image = self.getProcessedImage()\n', '  File "C:\\Users\\ZHao\\.conda\\envs\\scopefoundry\\lib\\site-packages\\pyqtgraph\\imageview\\ImageView.py", line 406, in getProcessedImage\n    self._imageLevels = self.quickMinMax(self.imageDisp)\n', '  File "C:\\Users\\ZHao\\.conda\\envs\\scopefoundry\\lib\\site-packages\\pyqtgraph\\imageview\\ImageView.py", line 648, in quickMinMax\n    float(nanmax(data.take(i, axis=cax)))) for i in range(data.shape[-1])]\n', '  File "C:\\Users\\ZHao\\.conda\\envs\\scopefoundry\\lib\\site-packages\\pyqtgraph\\imageview\\ImageView.py", line 648, in <listcomp>\n    float(nanmax(data.take(i, axis=cax)))) for i in range(data.shape[-1])]\n', 'numpy.AxisError: axis 2 is out of bounds for array of dimension 2\n']
2022-04-21T13:16:45|ERROR|ThorCamCaptureMeasure|thor_cam_capture Failed to update figure1: axis 2 is out of bounds for array of dimension 2. ['Traceback (most recent call last):\n', '  File "C:\\Users\\ZHao\\.conda\\envs\\scopefoundry\\lib\\site-packages\\ScopeFoundry\\measurement.py", line 273, in _on_display_update_timer\n    self.update_display()\n', '  File "C:\\Users\\Public\\quantum_sensing\\quantum_sensing\\fancy_microscope\\thorcam_capture.py", line 351, in update_display\n    self.imview.setImage(image, axes={\'y\':0, \'x\':1, \'c\':2}, autoLevels=True)\n', '  File "C:\\Users\\ZHao\\.conda\\envs\\scopefoundry\\lib\\site-packages\\pyqtgraph\\imageview\\ImageView.py", line 322, in setImage\n    self.updateImage(autoHistogramRange=autoHistogramRange)\n', '  File "C:\\Users\\ZHao\\.conda\\envs\\scopefoundry\\lib\\site-packages\\pyqtgraph\\imageview\\ImageView.py", line 714, in updateImage\n    image = self.getProcessedImage()\n', '  File "C:\\Users\\ZHao\\.conda\\envs\\scopefoundry\\lib\\site-packages\\pyqtgraph\\imageview\\ImageView.py", line 406, in getProcessedImage\n    self._imageLevels = self.quickMinMax(self.imageDisp)\n', '  File "C:\\Users\\ZHao\\.conda\\envs\\scopefoundry\\lib\\site-packages\\pyqtgraph\\imageview\\ImageView.py", line 648, in quickMinMax\n    float(nanmax(data.take(i, axis=cax)))) for i in range(data.shape[-1])]\n', '  File "C:\\Users\\ZHao\\.conda\\envs\\scopefoundry\\lib\\site-packages\\pyqtgraph\\imageview\\ImageView.py", line 648, in <listcomp>\n    float(nanmax(data.take(i, axis=cax)))) for i in range(data.shape[-1])]\n', 'numpy.AxisError: axis 2 is out of bounds for array of dimension 2\n']
2022-04-21T13:16:46|ERROR|ThorCamCaptureMeasure|thor_cam_capture Failed to update figure1: axis 2 is out of bounds for array of dimension 2. ['Traceback (most recent call last):\n', '  File "C:\\Users\\ZHao\\.conda\\envs\\scopefoundry\\lib\\site-packages\\ScopeFoundry\\measurement.py", line 273, in _on_display_update_timer\n    self.update_display()\n', '  File "C:\\Users\\Public\\quantum_sensing\\quantum_sensing\\fancy_microscope\\thorcam_capture.py", line 351, in update_display\n    self.imview.setImage(image, axes={\'y\':0, \'x\':1, \'c\':2}, autoLevels=True)\n', '  File "C:\\Users\\ZHao\\.conda\\envs\\scopefoundry\\lib\\site-packages\\pyqtgraph\\imageview\\ImageView.py", line 322, in setImage\n    self.updateImage(autoHistogramRange=autoHistogramRange)\n', '  File "C:\\Users\\ZHao\\.conda\\envs\\scopefoundry\\lib\\site-packages\\pyqtgraph\\imageview\\ImageView.py", line 714, in updateImage\n    image = self.getProcessedImage()\n', '  File "C:\\Users\\ZHao\\.conda\\envs\\scopefoundry\\lib\\site-packages\\pyqtgraph\\imageview\\ImageView.py", line 406, in getProcessedImage\n    self._imageLevels = self.quickMinMax(self.imageDisp)\n', '  File "C:\\Users\\ZHao\\.conda\\envs\\scopefoundry\\lib\\site-packages\\pyqtgraph\\imageview\\ImageView.py", line 648, in quickMinMax\n    float(nanmax(data.take(i, axis=cax)))) for i in range(data.shape[-1])]\n', '  File "C:\\Users\\ZHao\\.conda\\envs\\scopefoundry\\lib\\site-packages\\pyqtgraph\\imageview\\ImageView.py", line 648, in <listcomp>\n    float(nanmax(data.take(i, axis=cax)))) for i in range(data.shape[-1])]\n', 'numpy.AxisError: axis 2 is out of bounds for array of dimension 2\n']
2022-04-21T13:16:46|ERROR|ThorCamCaptureMeasure|thor_cam_capture Failed to update figure1: axis 2 is out of bounds for array of dimension 2. ['Traceback (most recent call last):\n', '  File "C:\\Users\\ZHao\\.conda\\envs\\scopefoundry\\lib\\site-packages\\ScopeFoundry\\measurement.py", line 273, in _on_display_update_timer\n    self.update_display()\n', '  File "C:\\Users\\Public\\quantum_sensing\\quantum_sensing\\fancy_microscope\\thorcam_capture.py", line 351, in update_display\n    self.imview.setImage(image, axes={\'y\':0, \'x\':1, \'c\':2}, autoLevels=True)\n', '  File "C:\\Users\\ZHao\\.conda\\envs\\scopefoundry\\lib\\site-packages\\pyqtgraph\\imageview\\ImageView.py", line 322, in setImage\n    self.updateImage(autoHistogramRange=autoHistogramRange)\n', '  File "C:\\Users\\ZHao\\.conda\\envs\\scopefoundry\\lib\\site-packages\\pyqtgraph\\imageview\\ImageView.py", line 714, in updateImage\n    image = self.getProcessedImage()\n', '  File "C:\\Users\\ZHao\\.conda\\envs\\scopefoundry\\lib\\site-packages\\pyqtgraph\\imageview\\ImageView.py", line 406, in getProcessedImage\n    self._imageLevels = self.quickMinMax(self.imageDisp)\n', '  File "C:\\Users\\ZHao\\.conda\\envs\\scopefoundry\\lib\\site-packages\\pyqtgraph\\imageview\\ImageView.py", line 648, in quickMinMax\n    float(nanmax(data.take(i, axis=cax)))) for i in range(data.shape[-1])]\n', '  File "C:\\Users\\ZHao\\.conda\\envs\\scopefoundry\\lib\\site-packages\\pyqtgraph\\imageview\\ImageView.py", line 648, in <listcomp>\n    float(nanmax(data.take(i, axis=cax)))) for i in range(data.shape[-1])]\n', 'numpy.AxisError: axis 2 is out of bounds for array of dimension 2\n']
2022-04-21T13:16:46|ERROR|ThorCamCaptureMeasure|thor_cam_capture Failed to update figure1: axis 2 is out of bounds for array of dimension 2. ['Traceback (most recent call last):\n', '  File "C:\\Users\\ZHao\\.conda\\envs\\scopefoundry\\lib\\site-packages\\ScopeFoundry\\measurement.py", line 273, in _on_display_update_timer\n    self.update_display()\n', '  File "C:\\Users\\Public\\quantum_sensing\\quantum_sensing\\fancy_microscope\\thorcam_capture.py", line 351, in update_display\n    self.imview.setImage(image, axes={\'y\':0, \'x\':1, \'c\':2}, autoLevels=True)\n', '  File "C:\\Users\\ZHao\\.conda\\envs\\scopefoundry\\lib\\site-packages\\pyqtgraph\\imageview\\ImageView.py", line 322, in setImage\n    self.updateImage(autoHistogramRange=autoHistogramRange)\n', '  File "C:\\Users\\ZHao\\.conda\\envs\\scopefoundry\\lib\\site-packages\\pyqtgraph\\imageview\\ImageView.py", line 714, in updateImage\n    image = self.getProcessedImage()\n', '  File "C:\\Users\\ZHao\\.conda\\envs\\scopefoundry\\lib\\site-packages\\pyqtgraph\\imageview\\ImageView.py", line 406, in getProcessedImage\n    self._imageLevels = self.quickMinMax(self.imageDisp)\n', '  File "C:\\Users\\ZHao\\.conda\\envs\\scopefoundry\\lib\\site-packages\\pyqtgraph\\imageview\\ImageView.py", line 648, in quickMinMax\n    float(nanmax(data.take(i, axis=cax)))) for i in range(data.shape[-1])]\n', '  File "C:\\Users\\ZHao\\.conda\\envs\\scopefoundry\\lib\\site-packages\\pyqtgraph\\imageview\\ImageView.py", line 648, in <listcomp>\n    float(nanmax(data.take(i, axis=cax)))) for i in range(data.shape[-1])]\n', 'numpy.AxisError: axis 2 is out of bounds for array of dimension 2\n']
2022-04-21T13:16:46|ERROR|ThorCamCaptureMeasure|thor_cam_capture Failed to update figure1: axis 2 is out of bounds for array of dimension 2. ['Traceback (most recent call last):\n', '  File "C:\\Users\\ZHao\\.conda\\envs\\scopefoundry\\lib\\site-packages\\ScopeFoundry\\measurement.py", line 273, in _on_display_update_timer\n    self.update_display()\n', '  File "C:\\Users\\Public\\quantum_sensing\\quantum_sensing\\fancy_microscope\\thorcam_capture.py", line 351, in update_display\n    self.imview.setImage(image, axes={\'y\':0, \'x\':1, \'c\':2}, autoLevels=True)\n', '  File "C:\\Users\\ZHao\\.conda\\envs\\scopefoundry\\lib\\site-packages\\pyqtgraph\\imageview\\ImageView.py", line 322, in setImage\n    self.updateImage(autoHistogramRange=autoHistogramRange)\n', '  File "C:\\Users\\ZHao\\.conda\\envs\\scopefoundry\\lib\\site-packages\\pyqtgraph\\imageview\\ImageView.py", line 714, in updateImage\n    image = self.getProcessedImage()\n', '  File "C:\\Users\\ZHao\\.conda\\envs\\scopefoundry\\lib\\site-packages\\pyqtgraph\\imageview\\ImageView.py", line 406, in getProcessedImage\n    self._imageLevels = self.quickMinMax(self.imageDisp)\n', '  File "C:\\Users\\ZHao\\.conda\\envs\\scopefoundry\\lib\\site-packages\\pyqtgraph\\imageview\\ImageView.py", line 648, in quickMinMax\n    float(nanmax(data.take(i, axis=cax)))) for i in range(data.shape[-1])]\n', '  File "C:\\Users\\ZHao\\.conda\\envs\\scopefoundry\\lib\\site-packages\\pyqtgraph\\imageview\\ImageView.py", line 648, in <listcomp>\n    float(nanmax(data.take(i, axis=cax)))) for i in range(data.shape[-1])]\n', 'numpy.AxisError: axis 2 is out of bounds for array of dimension 2\n']
2022-04-21T13:16:46|ERROR|ThorCamCaptureMeasure|thor_cam_capture Failed to update figure1: axis 2 is out of bounds for array of dimension 2. ['Traceback (most recent call last):\n', '  File "C:\\Users\\ZHao\\.conda\\envs\\scopefoundry\\lib\\site-packages\\ScopeFoundry\\measurement.py", line 273, in _on_display_update_timer\n    self.update_display()\n', '  File "C:\\Users\\Public\\quantum_sensing\\quantum_sensing\\fancy_microscope\\thorcam_capture.py", line 351, in update_display\n    self.imview.setImage(image, axes={\'y\':0, \'x\':1, \'c\':2}, autoLevels=True)\n', '  File "C:\\Users\\ZHao\\.conda\\envs\\scopefoundry\\lib\\site-packages\\pyqtgraph\\imageview\\ImageView.py", line 322, in setImage\n    self.updateImage(autoHistogramRange=autoHistogramRange)\n', '  File "C:\\Users\\ZHao\\.conda\\envs\\scopefoundry\\lib\\site-packages\\pyqtgraph\\imageview\\ImageView.py", line 714, in updateImage\n    image = self.getProcessedImage()\n', '  File "C:\\Users\\ZHao\\.conda\\envs\\scopefoundry\\lib\\site-packages\\pyqtgraph\\imageview\\ImageView.py", line 406, in getProcessedImage\n    self._imageLevels = self.quickMinMax(self.imageDisp)\n', '  File "C:\\Users\\ZHao\\.conda\\envs\\scopefoundry\\lib\\site-packages\\pyqtgraph\\imageview\\ImageView.py", line 648, in quickMinMax\n    float(nanmax(data.take(i, axis=cax)))) for i in range(data.shape[-1])]\n', '  File "C:\\Users\\ZHao\\.conda\\envs\\scopefoundry\\lib\\site-packages\\pyqtgraph\\imageview\\ImageView.py", line 648, in <listcomp>\n    float(nanmax(data.take(i, axis=cax)))) for i in range(data.shape[-1])]\n', 'numpy.AxisError: axis 2 is out of bounds for array of dimension 2\n']
2022-04-21T13:16:46|ERROR|ThorCamCaptureMeasure|thor_cam_capture Failed to update figure1: axis 2 is out of bounds for array of dimension 2. ['Traceback (most recent call last):\n', '  File "C:\\Users\\ZHao\\.conda\\envs\\scopefoundry\\lib\\site-packages\\ScopeFoundry\\measurement.py", line 273, in _on_display_update_timer\n    self.update_display()\n', '  File "C:\\Users\\Public\\quantum_sensing\\quantum_sensing\\fancy_microscope\\thorcam_capture.py", line 351, in update_display\n    self.imview.setImage(image, axes={\'y\':0, \'x\':1, \'c\':2}, autoLevels=True)\n', '  File "C:\\Users\\ZHao\\.conda\\envs\\scopefoundry\\lib\\site-packages\\pyqtgraph\\imageview\\ImageView.py", line 322, in setImage\n    self.updateImage(autoHistogramRange=autoHistogramRange)\n', '  File "C:\\Users\\ZHao\\.conda\\envs\\scopefoundry\\lib\\site-packages\\pyqtgraph\\imageview\\ImageView.py", line 714, in updateImage\n    image = self.getProcessedImage()\n', '  File "C:\\Users\\ZHao\\.conda\\envs\\scopefoundry\\lib\\site-packages\\pyqtgraph\\imageview\\ImageView.py", line 406, in getProcessedImage\n    self._imageLevels = self.quickMinMax(self.imageDisp)\n', '  File "C:\\Users\\ZHao\\.conda\\envs\\scopefoundry\\lib\\site-packages\\pyqtgraph\\imageview\\ImageView.py", line 648, in quickMinMax\n    float(nanmax(data.take(i, axis=cax)))) for i in range(data.shape[-1])]\n', '  File "C:\\Users\\ZHao\\.conda\\envs\\scopefoundry\\lib\\site-packages\\pyqtgraph\\imageview\\ImageView.py", line 648, in <listcomp>\n    float(nanmax(data.take(i, axis=cax)))) for i in range(data.shape[-1])]\n', 'numpy.AxisError: axis 2 is out of bounds for array of dimension 2\n']
2022-04-21T13:16:46|ERROR|ThorCamCaptureMeasure|thor_cam_capture Failed to update figure1: axis 2 is out of bounds for array of dimension 2. ['Traceback (most recent call last):\n', '  File "C:\\Users\\ZHao\\.conda\\envs\\scopefoundry\\lib\\site-packages\\ScopeFoundry\\measurement.py", line 273, in _on_display_update_timer\n    self.update_display()\n', '  File "C:\\Users\\Public\\quantum_sensing\\quantum_sensing\\fancy_microscope\\thorcam_capture.py", line 351, in update_display\n    self.imview.setImage(image, axes={\'y\':0, \'x\':1, \'c\':2}, autoLevels=True)\n', '  File "C:\\Users\\ZHao\\.conda\\envs\\scopefoundry\\lib\\site-packages\\pyqtgraph\\imageview\\ImageView.py", line 322, in setImage\n    self.updateImage(autoHistogramRange=autoHistogramRange)\n', '  File "C:\\Users\\ZHao\\.conda\\envs\\scopefoundry\\lib\\site-packages\\pyqtgraph\\imageview\\ImageView.py", line 714, in updateImage\n    image = self.getProcessedImage()\n', '  File "C:\\Users\\ZHao\\.conda\\envs\\scopefoundry\\lib\\site-packages\\pyqtgraph\\imageview\\ImageView.py", line 406, in getProcessedImage\n    self._imageLevels = self.quickMinMax(self.imageDisp)\n', '  File "C:\\Users\\ZHao\\.conda\\envs\\scopefoundry\\lib\\site-packages\\pyqtgraph\\imageview\\ImageView.py", line 648, in quickMinMax\n    float(nanmax(data.take(i, axis=cax)))) for i in range(data.shape[-1])]\n', '  File "C:\\Users\\ZHao\\.conda\\envs\\scopefoundry\\lib\\site-packages\\pyqtgraph\\imageview\\ImageView.py", line 648, in <listcomp>\n    float(nanmax(data.take(i, axis=cax)))) for i in range(data.shape[-1])]\n', 'numpy.AxisError: axis 2 is out of bounds for array of dimension 2\n']
2022-04-21T13:16:58|CRITICAL|root|Unhandled exception:Traceback (most recent call last):
  File "C:\Users\ZHao\.conda\envs\scopefoundry\lib\site-packages\ScopeFoundry\measurement.py", line 25, in run
    self.measurement._thread_run()
  File "C:\Users\ZHao\.conda\envs\scopefoundry\lib\site-packages\ScopeFoundry\measurement.py", line 179, in _thread_run
    self.run()
  File "C:\Users\Public\quantum_sensing\quantum_sensing\fancy_microscope\thorcam_capture.py", line 248, in run
    sdk = TLCameraSDK()
  File "C:\Users\ZHao\.conda\envs\scopefoundry\lib\site-packages\thorlabs_tsi_sdk\tl_camera.py", line 172, in __init__
    raise TLCameraError("TLCameraSDK is already in use. Please dispose of the current instance before"
thorlabs_tsi_sdk.tl_camera.TLCameraError: TLCameraSDK is already in use. Please dispose of the current instance before trying to create another

2022-04-21T13:16:58|ERROR|ThorCamCaptureMeasure|thor_cam_capture Failed to update figure1: axis 2 is out of bounds for array of dimension 2. ['Traceback (most recent call last):\n', '  File "C:\\Users\\ZHao\\.conda\\envs\\scopefoundry\\lib\\site-packages\\ScopeFoundry\\measurement.py", line 273, in _on_display_update_timer\n    self.update_display()\n', '  File "C:\\Users\\Public\\quantum_sensing\\quantum_sensing\\fancy_microscope\\thorcam_capture.py", line 351, in update_display\n    self.imview.setImage(image, axes={\'y\':0, \'x\':1, \'c\':2}, autoLevels=True)\n', '  File "C:\\Users\\ZHao\\.conda\\envs\\scopefoundry\\lib\\site-packages\\pyqtgraph\\imageview\\ImageView.py", line 322, in setImage\n    self.updateImage(autoHistogramRange=autoHistogramRange)\n', '  File "C:\\Users\\ZHao\\.conda\\envs\\scopefoundry\\lib\\site-packages\\pyqtgraph\\imageview\\ImageView.py", line 714, in updateImage\n    image = self.getProcessedImage()\n', '  File "C:\\Users\\ZHao\\.conda\\envs\\scopefoundry\\lib\\site-packages\\pyqtgraph\\imageview\\ImageView.py", line 406, in getProcessedImage\n    self._imageLevels = self.quickMinMax(self.imageDisp)\n', '  File "C:\\Users\\ZHao\\.conda\\envs\\scopefoundry\\lib\\site-packages\\pyqtgraph\\imageview\\ImageView.py", line 648, in quickMinMax\n    float(nanmax(data.take(i, axis=cax)))) for i in range(data.shape[-1])]\n', '  File "C:\\Users\\ZHao\\.conda\\envs\\scopefoundry\\lib\\site-packages\\pyqtgraph\\imageview\\ImageView.py", line 648, in <listcomp>\n    float(nanmax(data.take(i, axis=cax)))) for i in range(data.shape[-1])]\n', 'numpy.AxisError: axis 2 is out of bounds for array of dimension 2\n']
2022-04-21T13:17:00|CRITICAL|root|Unhandled exception:Traceback (most recent call last):
  File "C:\Users\ZHao\.conda\envs\scopefoundry\lib\site-packages\ScopeFoundry\measurement.py", line 25, in run
    self.measurement._thread_run()
  File "C:\Users\ZHao\.conda\envs\scopefoundry\lib\site-packages\ScopeFoundry\measurement.py", line 179, in _thread_run
    self.run()
  File "C:\Users\Public\quantum_sensing\quantum_sensing\fancy_microscope\thorcam_capture.py", line 248, in run
    sdk = TLCameraSDK()
  File "C:\Users\ZHao\.conda\envs\scopefoundry\lib\site-packages\thorlabs_tsi_sdk\tl_camera.py", line 172, in __init__
    raise TLCameraError("TLCameraSDK is already in use. Please dispose of the current instance before"
thorlabs_tsi_sdk.tl_camera.TLCameraError: TLCameraSDK is already in use. Please dispose of the current instance before trying to create another

2022-04-21T13:17:00|ERROR|ThorCamCaptureMeasure|thor_cam_capture Failed to update figure1: axis 2 is out of bounds for array of dimension 2. ['Traceback (most recent call last):\n', '  File "C:\\Users\\ZHao\\.conda\\envs\\scopefoundry\\lib\\site-packages\\ScopeFoundry\\measurement.py", line 273, in _on_display_update_timer\n    self.update_display()\n', '  File "C:\\Users\\Public\\quantum_sensing\\quantum_sensing\\fancy_microscope\\thorcam_capture.py", line 351, in update_display\n    self.imview.setImage(image, axes={\'y\':0, \'x\':1, \'c\':2}, autoLevels=True)\n', '  File "C:\\Users\\ZHao\\.conda\\envs\\scopefoundry\\lib\\site-packages\\pyqtgraph\\imageview\\ImageView.py", line 322, in setImage\n    self.updateImage(autoHistogramRange=autoHistogramRange)\n', '  File "C:\\Users\\ZHao\\.conda\\envs\\scopefoundry\\lib\\site-packages\\pyqtgraph\\imageview\\ImageView.py", line 714, in updateImage\n    image = self.getProcessedImage()\n', '  File "C:\\Users\\ZHao\\.conda\\envs\\scopefoundry\\lib\\site-packages\\pyqtgraph\\imageview\\ImageView.py", line 406, in getProcessedImage\n    self._imageLevels = self.quickMinMax(self.imageDisp)\n', '  File "C:\\Users\\ZHao\\.conda\\envs\\scopefoundry\\lib\\site-packages\\pyqtgraph\\imageview\\ImageView.py", line 648, in quickMinMax\n    float(nanmax(data.take(i, axis=cax)))) for i in range(data.shape[-1])]\n', '  File "C:\\Users\\ZHao\\.conda\\envs\\scopefoundry\\lib\\site-packages\\pyqtgraph\\imageview\\ImageView.py", line 648, in <listcomp>\n    float(nanmax(data.take(i, axis=cax)))) for i in range(data.shape[-1])]\n', 'numpy.AxisError: axis 2 is out of bounds for array of dimension 2\n']
