2022-03-31T15:29:15|CRITICAL|root|Unhandled exception:Traceback (most recent call last):
  File "fancy_microscope.py", line 46, in <module>
    app = FancyMicroscopeApp(sys.argv)
  File "C:\Users\ZHao\.conda\envs\ScopeFoundry\lib\site-packages\ScopeFoundry\base_app.py", line 332, in __init__
    self.setup()
  File "fancy_microscope.py", line 32, in setup
    self.add_measurement(ThorCamCaptureMeasure(self))
  File "C:\Users\ZHao\.conda\envs\ScopeFoundry\lib\site-packages\ScopeFoundry\measurement.py", line 93, in __init__
    self.setup()
  File "C:\Users\Public\quantum_sensing\quantum_sensing\fancy_microscope\thorcam_capture.py", line 63, in setup
    self.cam_hw.settings.get_lq(lq_name).connect_to_widget(getattr(self.ui, widget_name))
  File "C:\Users\ZHao\.conda\envs\ScopeFoundry\lib\site-packages\ScopeFoundry\logged_quantity.py", line 1122, in get_lq
    return self._logged_quantities[key]
KeyError: 'exp_time'

