2022-02-17T14:51:21|CRITICAL|root|Unhandled exception:Traceback (most recent call last):
  File "fancy_microscope.py", line 40, in <module>
    app = FancyMicroscopeApp(sys.argv)
  File "C:\Users\ZHao\.conda\envs\scopefoundry\lib\site-packages\ScopeFoundry\base_app.py", line 334, in __init__
    self.setup_default_ui()
  File "C:\Users\ZHao\.conda\envs\scopefoundry\lib\site-packages\ScopeFoundry\base_app.py", line 365, in setup_default_ui
    measure.setup_figure()
  File "C:\Users\Public\quantum_sensing\quantum_sensing\fancy_microscope\custommeasure2.py", line 108, in setup_figure
    line, = ax.plot(xs, ys, 'b-')
NameError: name 'ax' is not defined

