2022-02-18T10:45:56|CRITICAL|root|Unhandled exception:Traceback (most recent call last):
  File "C:\Users\ZHao\.conda\envs\scopefoundry\lib\site-packages\ScopeFoundry\hardware.py", line 208, in enable_connection
    raise err
  File "C:\Users\ZHao\.conda\envs\scopefoundry\lib\site-packages\ScopeFoundry\hardware.py", line 204, in enable_connection
    self.connect()
  File "C:\Users\Public\quantum_sensing\quantum_sensing\fancy_microscope\custommeasure.py", line 131, in connect
    self.dev = PMD24(port=S['port'], debug=S['debug_mode'])
NameError: name 'PMD24' is not defined

2022-02-18T10:46:01|ERROR|ESRMeasure|ESR_measurement Failed to update figure1: 'ESRMeasure' object has no attribute 'plotlines'. ['Traceback (most recent call last):\n', '  File "C:\\Users\\ZHao\\.conda\\envs\\scopefoundry\\lib\\site-packages\\ScopeFoundry\\measurement.py", line 273, in _on_display_update_timer\n    self.update_display()\n', '  File "C:\\Users\\Public\\quantum_sensing\\quantum_sensing\\fancy_microscope\\custommeasure2.py", line 359, in update_display\n    self.plotlines[rate].setVisible(self.settings[\'{}_visible\'.format(rate)])\n', "AttributeError: 'ESRMeasure' object has no attribute 'plotlines'\n"]
2022-02-18T10:46:01|ERROR|ESRMeasure|ESR_measurement Failed to update figure1: 'ESRMeasure' object has no attribute 'plotlines'. ['Traceback (most recent call last):\n', '  File "C:\\Users\\ZHao\\.conda\\envs\\scopefoundry\\lib\\site-packages\\ScopeFoundry\\measurement.py", line 273, in _on_display_update_timer\n    self.update_display()\n', '  File "C:\\Users\\Public\\quantum_sensing\\quantum_sensing\\fancy_microscope\\custommeasure2.py", line 359, in update_display\n    self.plotlines[rate].setVisible(self.settings[\'{}_visible\'.format(rate)])\n', "AttributeError: 'ESRMeasure' object has no attribute 'plotlines'\n"]
2022-02-18T10:46:01|ERROR|ESRMeasure|ESR_measurement Failed to update figure1: 'ESRMeasure' object has no attribute 'plotlines'. ['Traceback (most recent call last):\n', '  File "C:\\Users\\ZHao\\.conda\\envs\\scopefoundry\\lib\\site-packages\\ScopeFoundry\\measurement.py", line 273, in _on_display_update_timer\n    self.update_display()\n', '  File "C:\\Users\\Public\\quantum_sensing\\quantum_sensing\\fancy_microscope\\custommeasure2.py", line 359, in update_display\n    self.plotlines[rate].setVisible(self.settings[\'{}_visible\'.format(rate)])\n', "AttributeError: 'ESRMeasure' object has no attribute 'plotlines'\n"]
2022-02-18T10:46:01|ERROR|ESRMeasure|ESR_measurement Failed to update figure1: 'ESRMeasure' object has no attribute 'plotlines'. ['Traceback (most recent call last):\n', '  File "C:\\Users\\ZHao\\.conda\\envs\\scopefoundry\\lib\\site-packages\\ScopeFoundry\\measurement.py", line 273, in _on_display_update_timer\n    self.update_display()\n', '  File "C:\\Users\\Public\\quantum_sensing\\quantum_sensing\\fancy_microscope\\custommeasure2.py", line 359, in update_display\n    self.plotlines[rate].setVisible(self.settings[\'{}_visible\'.format(rate)])\n', "AttributeError: 'ESRMeasure' object has no attribute 'plotlines'\n"]
2022-02-18T10:46:02|ERROR|ESRMeasure|ESR_measurement Failed to update figure1: 'ESRMeasure' object has no attribute 'plotlines'. ['Traceback (most recent call last):\n', '  File "C:\\Users\\ZHao\\.conda\\envs\\scopefoundry\\lib\\site-packages\\ScopeFoundry\\measurement.py", line 273, in _on_display_update_timer\n    self.update_display()\n', '  File "C:\\Users\\Public\\quantum_sensing\\quantum_sensing\\fancy_microscope\\custommeasure2.py", line 359, in update_display\n    self.plotlines[rate].setVisible(self.settings[\'{}_visible\'.format(rate)])\n', "AttributeError: 'ESRMeasure' object has no attribute 'plotlines'\n"]
2022-02-18T10:46:02|ERROR|ESRMeasure|ESR_measurement Failed to update figure1: 'ESRMeasure' object has no attribute 'plotlines'. ['Traceback (most recent call last):\n', '  File "C:\\Users\\ZHao\\.conda\\envs\\scopefoundry\\lib\\site-packages\\ScopeFoundry\\measurement.py", line 273, in _on_display_update_timer\n    self.update_display()\n', '  File "C:\\Users\\Public\\quantum_sensing\\quantum_sensing\\fancy_microscope\\custommeasure2.py", line 359, in update_display\n    self.plotlines[rate].setVisible(self.settings[\'{}_visible\'.format(rate)])\n', "AttributeError: 'ESRMeasure' object has no attribute 'plotlines'\n"]
2022-02-18T10:46:02|ERROR|ESRMeasure|ESR_measurement Failed to update figure1: 'ESRMeasure' object has no attribute 'plotlines'. ['Traceback (most recent call last):\n', '  File "C:\\Users\\ZHao\\.conda\\envs\\scopefoundry\\lib\\site-packages\\ScopeFoundry\\measurement.py", line 273, in _on_display_update_timer\n    self.update_display()\n', '  File "C:\\Users\\Public\\quantum_sensing\\quantum_sensing\\fancy_microscope\\custommeasure2.py", line 359, in update_display\n    self.plotlines[rate].setVisible(self.settings[\'{}_visible\'.format(rate)])\n', "AttributeError: 'ESRMeasure' object has no attribute 'plotlines'\n"]
2022-02-18T10:46:02|ERROR|ESRMeasure|ESR_measurement Failed to update figure1: 'ESRMeasure' object has no attribute 'plotlines'. ['Traceback (most recent call last):\n', '  File "C:\\Users\\ZHao\\.conda\\envs\\scopefoundry\\lib\\site-packages\\ScopeFoundry\\measurement.py", line 273, in _on_display_update_timer\n    self.update_display()\n', '  File "C:\\Users\\Public\\quantum_sensing\\quantum_sensing\\fancy_microscope\\custommeasure2.py", line 359, in update_display\n    self.plotlines[rate].setVisible(self.settings[\'{}_visible\'.format(rate)])\n', "AttributeError: 'ESRMeasure' object has no attribute 'plotlines'\n"]
2022-02-18T10:46:02|ERROR|ESRMeasure|ESR_measurement Failed to update figure1: 'ESRMeasure' object has no attribute 'plotlines'. ['Traceback (most recent call last):\n', '  File "C:\\Users\\ZHao\\.conda\\envs\\scopefoundry\\lib\\site-packages\\ScopeFoundry\\measurement.py", line 273, in _on_display_update_timer\n    self.update_display()\n', '  File "C:\\Users\\Public\\quantum_sensing\\quantum_sensing\\fancy_microscope\\custommeasure2.py", line 359, in update_display\n    self.plotlines[rate].setVisible(self.settings[\'{}_visible\'.format(rate)])\n', "AttributeError: 'ESRMeasure' object has no attribute 'plotlines'\n"]
2022-02-18T10:46:02|ERROR|ESRMeasure|ESR_measurement Failed to update figure1: 'ESRMeasure' object has no attribute 'plotlines'. ['Traceback (most recent call last):\n', '  File "C:\\Users\\ZHao\\.conda\\envs\\scopefoundry\\lib\\site-packages\\ScopeFoundry\\measurement.py", line 273, in _on_display_update_timer\n    self.update_display()\n', '  File "C:\\Users\\Public\\quantum_sensing\\quantum_sensing\\fancy_microscope\\custommeasure2.py", line 359, in update_display\n    self.plotlines[rate].setVisible(self.settings[\'{}_visible\'.format(rate)])\n', "AttributeError: 'ESRMeasure' object has no attribute 'plotlines'\n"]
2022-02-18T10:46:02|ERROR|ESRMeasure|ESR_measurement Failed to update figure1: 'ESRMeasure' object has no attribute 'plotlines'. ['Traceback (most recent call last):\n', '  File "C:\\Users\\ZHao\\.conda\\envs\\scopefoundry\\lib\\site-packages\\ScopeFoundry\\measurement.py", line 273, in _on_display_update_timer\n    self.update_display()\n', '  File "C:\\Users\\Public\\quantum_sensing\\quantum_sensing\\fancy_microscope\\custommeasure2.py", line 359, in update_display\n    self.plotlines[rate].setVisible(self.settings[\'{}_visible\'.format(rate)])\n', "AttributeError: 'ESRMeasure' object has no attribute 'plotlines'\n"]
2022-02-18T10:46:02|ERROR|ESRMeasure|ESR_measurement Failed to update figure1: 'ESRMeasure' object has no attribute 'plotlines'. ['Traceback (most recent call last):\n', '  File "C:\\Users\\ZHao\\.conda\\envs\\scopefoundry\\lib\\site-packages\\ScopeFoundry\\measurement.py", line 273, in _on_display_update_timer\n    self.update_display()\n', '  File "C:\\Users\\Public\\quantum_sensing\\quantum_sensing\\fancy_microscope\\custommeasure2.py", line 359, in update_display\n    self.plotlines[rate].setVisible(self.settings[\'{}_visible\'.format(rate)])\n', "AttributeError: 'ESRMeasure' object has no attribute 'plotlines'\n"]
2022-02-18T10:46:02|ERROR|ESRMeasure|ESR_measurement Failed to update figure1: 'ESRMeasure' object has no attribute 'plotlines'. ['Traceback (most recent call last):\n', '  File "C:\\Users\\ZHao\\.conda\\envs\\scopefoundry\\lib\\site-packages\\ScopeFoundry\\measurement.py", line 273, in _on_display_update_timer\n    self.update_display()\n', '  File "C:\\Users\\Public\\quantum_sensing\\quantum_sensing\\fancy_microscope\\custommeasure2.py", line 359, in update_display\n    self.plotlines[rate].setVisible(self.settings[\'{}_visible\'.format(rate)])\n', "AttributeError: 'ESRMeasure' object has no attribute 'plotlines'\n"]
2022-02-18T10:46:03|ERROR|ESRMeasure|ESR_measurement Failed to update figure1: 'ESRMeasure' object has no attribute 'plotlines'. ['Traceback (most recent call last):\n', '  File "C:\\Users\\ZHao\\.conda\\envs\\scopefoundry\\lib\\site-packages\\ScopeFoundry\\measurement.py", line 273, in _on_display_update_timer\n    self.update_display()\n', '  File "C:\\Users\\Public\\quantum_sensing\\quantum_sensing\\fancy_microscope\\custommeasure2.py", line 359, in update_display\n    self.plotlines[rate].setVisible(self.settings[\'{}_visible\'.format(rate)])\n', "AttributeError: 'ESRMeasure' object has no attribute 'plotlines'\n"]
2022-02-18T10:46:03|ERROR|ESRMeasure|ESR_measurement Failed to update figure1: 'ESRMeasure' object has no attribute 'plotlines'. ['Traceback (most recent call last):\n', '  File "C:\\Users\\ZHao\\.conda\\envs\\scopefoundry\\lib\\site-packages\\ScopeFoundry\\measurement.py", line 273, in _on_display_update_timer\n    self.update_display()\n', '  File "C:\\Users\\Public\\quantum_sensing\\quantum_sensing\\fancy_microscope\\custommeasure2.py", line 359, in update_display\n    self.plotlines[rate].setVisible(self.settings[\'{}_visible\'.format(rate)])\n', "AttributeError: 'ESRMeasure' object has no attribute 'plotlines'\n"]
2022-02-18T10:46:03|ERROR|ESRMeasure|ESR_measurement Failed to update figure1: 'ESRMeasure' object has no attribute 'plotlines'. ['Traceback (most recent call last):\n', '  File "C:\\Users\\ZHao\\.conda\\envs\\scopefoundry\\lib\\site-packages\\ScopeFoundry\\measurement.py", line 273, in _on_display_update_timer\n    self.update_display()\n', '  File "C:\\Users\\Public\\quantum_sensing\\quantum_sensing\\fancy_microscope\\custommeasure2.py", line 359, in update_display\n    self.plotlines[rate].setVisible(self.settings[\'{}_visible\'.format(rate)])\n', "AttributeError: 'ESRMeasure' object has no attribute 'plotlines'\n"]
2022-02-18T10:46:03|ERROR|ESRMeasure|ESR_measurement Failed to update figure1: 'ESRMeasure' object has no attribute 'plotlines'. ['Traceback (most recent call last):\n', '  File "C:\\Users\\ZHao\\.conda\\envs\\scopefoundry\\lib\\site-packages\\ScopeFoundry\\measurement.py", line 273, in _on_display_update_timer\n    self.update_display()\n', '  File "C:\\Users\\Public\\quantum_sensing\\quantum_sensing\\fancy_microscope\\custommeasure2.py", line 359, in update_display\n    self.plotlines[rate].setVisible(self.settings[\'{}_visible\'.format(rate)])\n', "AttributeError: 'ESRMeasure' object has no attribute 'plotlines'\n"]
2022-02-18T10:46:03|ERROR|ESRMeasure|ESR_measurement Failed to update figure1: 'ESRMeasure' object has no attribute 'plotlines'. ['Traceback (most recent call last):\n', '  File "C:\\Users\\ZHao\\.conda\\envs\\scopefoundry\\lib\\site-packages\\ScopeFoundry\\measurement.py", line 273, in _on_display_update_timer\n    self.update_display()\n', '  File "C:\\Users\\Public\\quantum_sensing\\quantum_sensing\\fancy_microscope\\custommeasure2.py", line 359, in update_display\n    self.plotlines[rate].setVisible(self.settings[\'{}_visible\'.format(rate)])\n', "AttributeError: 'ESRMeasure' object has no attribute 'plotlines'\n"]
2022-02-18T10:46:03|ERROR|ESRMeasure|ESR_measurement Failed to update figure1: 'ESRMeasure' object has no attribute 'plotlines'. ['Traceback (most recent call last):\n', '  File "C:\\Users\\ZHao\\.conda\\envs\\scopefoundry\\lib\\site-packages\\ScopeFoundry\\measurement.py", line 273, in _on_display_update_timer\n    self.update_display()\n', '  File "C:\\Users\\Public\\quantum_sensing\\quantum_sensing\\fancy_microscope\\custommeasure2.py", line 359, in update_display\n    self.plotlines[rate].setVisible(self.settings[\'{}_visible\'.format(rate)])\n', "AttributeError: 'ESRMeasure' object has no attribute 'plotlines'\n"]
2022-02-18T10:46:03|ERROR|ESRMeasure|ESR_measurement Failed to update figure1: 'ESRMeasure' object has no attribute 'plotlines'. ['Traceback (most recent call last):\n', '  File "C:\\Users\\ZHao\\.conda\\envs\\scopefoundry\\lib\\site-packages\\ScopeFoundry\\measurement.py", line 273, in _on_display_update_timer\n    self.update_display()\n', '  File "C:\\Users\\Public\\quantum_sensing\\quantum_sensing\\fancy_microscope\\custommeasure2.py", line 359, in update_display\n    self.plotlines[rate].setVisible(self.settings[\'{}_visible\'.format(rate)])\n', "AttributeError: 'ESRMeasure' object has no attribute 'plotlines'\n"]
2022-02-18T10:46:03|ERROR|ESRMeasure|ESR_measurement Failed to update figure1: 'ESRMeasure' object has no attribute 'plotlines'. ['Traceback (most recent call last):\n', '  File "C:\\Users\\ZHao\\.conda\\envs\\scopefoundry\\lib\\site-packages\\ScopeFoundry\\measurement.py", line 273, in _on_display_update_timer\n    self.update_display()\n', '  File "C:\\Users\\Public\\quantum_sensing\\quantum_sensing\\fancy_microscope\\custommeasure2.py", line 359, in update_display\n    self.plotlines[rate].setVisible(self.settings[\'{}_visible\'.format(rate)])\n', "AttributeError: 'ESRMeasure' object has no attribute 'plotlines'\n"]
2022-02-18T10:46:03|ERROR|ESRMeasure|ESR_measurement Failed to update figure1: 'ESRMeasure' object has no attribute 'plotlines'. ['Traceback (most recent call last):\n', '  File "C:\\Users\\ZHao\\.conda\\envs\\scopefoundry\\lib\\site-packages\\ScopeFoundry\\measurement.py", line 273, in _on_display_update_timer\n    self.update_display()\n', '  File "C:\\Users\\Public\\quantum_sensing\\quantum_sensing\\fancy_microscope\\custommeasure2.py", line 359, in update_display\n    self.plotlines[rate].setVisible(self.settings[\'{}_visible\'.format(rate)])\n', "AttributeError: 'ESRMeasure' object has no attribute 'plotlines'\n"]
2022-02-18T10:46:03|ERROR|ESRMeasure|ESR_measurement Failed to update figure1: 'ESRMeasure' object has no attribute 'plotlines'. ['Traceback (most recent call last):\n', '  File "C:\\Users\\ZHao\\.conda\\envs\\scopefoundry\\lib\\site-packages\\ScopeFoundry\\measurement.py", line 273, in _on_display_update_timer\n    self.update_display()\n', '  File "C:\\Users\\Public\\quantum_sensing\\quantum_sensing\\fancy_microscope\\custommeasure2.py", line 359, in update_display\n    self.plotlines[rate].setVisible(self.settings[\'{}_visible\'.format(rate)])\n', "AttributeError: 'ESRMeasure' object has no attribute 'plotlines'\n"]
2022-02-18T10:46:04|ERROR|ESRMeasure|ESR_measurement Failed to update figure1: 'ESRMeasure' object has no attribute 'plotlines'. ['Traceback (most recent call last):\n', '  File "C:\\Users\\ZHao\\.conda\\envs\\scopefoundry\\lib\\site-packages\\ScopeFoundry\\measurement.py", line 273, in _on_display_update_timer\n    self.update_display()\n', '  File "C:\\Users\\Public\\quantum_sensing\\quantum_sensing\\fancy_microscope\\custommeasure2.py", line 359, in update_display\n    self.plotlines[rate].setVisible(self.settings[\'{}_visible\'.format(rate)])\n', "AttributeError: 'ESRMeasure' object has no attribute 'plotlines'\n"]
2022-02-18T10:46:04|ERROR|ESRMeasure|ESR_measurement Failed to update figure1: 'ESRMeasure' object has no attribute 'plotlines'. ['Traceback (most recent call last):\n', '  File "C:\\Users\\ZHao\\.conda\\envs\\scopefoundry\\lib\\site-packages\\ScopeFoundry\\measurement.py", line 273, in _on_display_update_timer\n    self.update_display()\n', '  File "C:\\Users\\Public\\quantum_sensing\\quantum_sensing\\fancy_microscope\\custommeasure2.py", line 359, in update_display\n    self.plotlines[rate].setVisible(self.settings[\'{}_visible\'.format(rate)])\n', "AttributeError: 'ESRMeasure' object has no attribute 'plotlines'\n"]
2022-02-18T10:46:04|ERROR|ESRMeasure|ESR_measurement Failed to update figure1: 'ESRMeasure' object has no attribute 'plotlines'. ['Traceback (most recent call last):\n', '  File "C:\\Users\\ZHao\\.conda\\envs\\scopefoundry\\lib\\site-packages\\ScopeFoundry\\measurement.py", line 273, in _on_display_update_timer\n    self.update_display()\n', '  File "C:\\Users\\Public\\quantum_sensing\\quantum_sensing\\fancy_microscope\\custommeasure2.py", line 359, in update_display\n    self.plotlines[rate].setVisible(self.settings[\'{}_visible\'.format(rate)])\n', "AttributeError: 'ESRMeasure' object has no attribute 'plotlines'\n"]
2022-02-18T10:46:04|ERROR|ESRMeasure|ESR_measurement Failed to update figure1: 'ESRMeasure' object has no attribute 'plotlines'. ['Traceback (most recent call last):\n', '  File "C:\\Users\\ZHao\\.conda\\envs\\scopefoundry\\lib\\site-packages\\ScopeFoundry\\measurement.py", line 273, in _on_display_update_timer\n    self.update_display()\n', '  File "C:\\Users\\Public\\quantum_sensing\\quantum_sensing\\fancy_microscope\\custommeasure2.py", line 359, in update_display\n    self.plotlines[rate].setVisible(self.settings[\'{}_visible\'.format(rate)])\n', "AttributeError: 'ESRMeasure' object has no attribute 'plotlines'\n"]
2022-02-18T10:46:04|ERROR|ESRMeasure|ESR_measurement Failed to update figure1: 'ESRMeasure' object has no attribute 'plotlines'. ['Traceback (most recent call last):\n', '  File "C:\\Users\\ZHao\\.conda\\envs\\scopefoundry\\lib\\site-packages\\ScopeFoundry\\measurement.py", line 273, in _on_display_update_timer\n    self.update_display()\n', '  File "C:\\Users\\Public\\quantum_sensing\\quantum_sensing\\fancy_microscope\\custommeasure2.py", line 359, in update_display\n    self.plotlines[rate].setVisible(self.settings[\'{}_visible\'.format(rate)])\n', "AttributeError: 'ESRMeasure' object has no attribute 'plotlines'\n"]
2022-02-18T10:46:04|ERROR|ESRMeasure|ESR_measurement Failed to update figure1: 'ESRMeasure' object has no attribute 'plotlines'. ['Traceback (most recent call last):\n', '  File "C:\\Users\\ZHao\\.conda\\envs\\scopefoundry\\lib\\site-packages\\ScopeFoundry\\measurement.py", line 273, in _on_display_update_timer\n    self.update_display()\n', '  File "C:\\Users\\Public\\quantum_sensing\\quantum_sensing\\fancy_microscope\\custommeasure2.py", line 359, in update_display\n    self.plotlines[rate].setVisible(self.settings[\'{}_visible\'.format(rate)])\n', "AttributeError: 'ESRMeasure' object has no attribute 'plotlines'\n"]
2022-02-18T10:46:04|ERROR|ESRMeasure|ESR_measurement Failed to update figure1: 'ESRMeasure' object has no attribute 'plotlines'. ['Traceback (most recent call last):\n', '  File "C:\\Users\\ZHao\\.conda\\envs\\scopefoundry\\lib\\site-packages\\ScopeFoundry\\measurement.py", line 273, in _on_display_update_timer\n    self.update_display()\n', '  File "C:\\Users\\Public\\quantum_sensing\\quantum_sensing\\fancy_microscope\\custommeasure2.py", line 359, in update_display\n    self.plotlines[rate].setVisible(self.settings[\'{}_visible\'.format(rate)])\n', "AttributeError: 'ESRMeasure' object has no attribute 'plotlines'\n"]
2022-02-18T10:46:04|ERROR|ESRMeasure|ESR_measurement Failed to update figure1: 'ESRMeasure' object has no attribute 'plotlines'. ['Traceback (most recent call last):\n', '  File "C:\\Users\\ZHao\\.conda\\envs\\scopefoundry\\lib\\site-packages\\ScopeFoundry\\measurement.py", line 273, in _on_display_update_timer\n    self.update_display()\n', '  File "C:\\Users\\Public\\quantum_sensing\\quantum_sensing\\fancy_microscope\\custommeasure2.py", line 359, in update_display\n    self.plotlines[rate].setVisible(self.settings[\'{}_visible\'.format(rate)])\n', "AttributeError: 'ESRMeasure' object has no attribute 'plotlines'\n"]
2022-02-18T10:46:04|ERROR|ESRMeasure|ESR_measurement Failed to update figure1: 'ESRMeasure' object has no attribute 'plotlines'. ['Traceback (most recent call last):\n', '  File "C:\\Users\\ZHao\\.conda\\envs\\scopefoundry\\lib\\site-packages\\ScopeFoundry\\measurement.py", line 273, in _on_display_update_timer\n    self.update_display()\n', '  File "C:\\Users\\Public\\quantum_sensing\\quantum_sensing\\fancy_microscope\\custommeasure2.py", line 359, in update_display\n    self.plotlines[rate].setVisible(self.settings[\'{}_visible\'.format(rate)])\n', "AttributeError: 'ESRMeasure' object has no attribute 'plotlines'\n"]
2022-02-18T10:46:05|ERROR|ESRMeasure|ESR_measurement Failed to update figure1: 'ESRMeasure' object has no attribute 'plotlines'. ['Traceback (most recent call last):\n', '  File "C:\\Users\\ZHao\\.conda\\envs\\scopefoundry\\lib\\site-packages\\ScopeFoundry\\measurement.py", line 273, in _on_display_update_timer\n    self.update_display()\n', '  File "C:\\Users\\Public\\quantum_sensing\\quantum_sensing\\fancy_microscope\\custommeasure2.py", line 359, in update_display\n    self.plotlines[rate].setVisible(self.settings[\'{}_visible\'.format(rate)])\n', "AttributeError: 'ESRMeasure' object has no attribute 'plotlines'\n"]
2022-02-18T10:46:05|ERROR|ESRMeasure|ESR_measurement Failed to update figure1: 'ESRMeasure' object has no attribute 'plotlines'. ['Traceback (most recent call last):\n', '  File "C:\\Users\\ZHao\\.conda\\envs\\scopefoundry\\lib\\site-packages\\ScopeFoundry\\measurement.py", line 273, in _on_display_update_timer\n    self.update_display()\n', '  File "C:\\Users\\Public\\quantum_sensing\\quantum_sensing\\fancy_microscope\\custommeasure2.py", line 359, in update_display\n    self.plotlines[rate].setVisible(self.settings[\'{}_visible\'.format(rate)])\n', "AttributeError: 'ESRMeasure' object has no attribute 'plotlines'\n"]
2022-02-18T10:46:05|ERROR|ESRMeasure|ESR_measurement Failed to update figure1: 'ESRMeasure' object has no attribute 'plotlines'. ['Traceback (most recent call last):\n', '  File "C:\\Users\\ZHao\\.conda\\envs\\scopefoundry\\lib\\site-packages\\ScopeFoundry\\measurement.py", line 273, in _on_display_update_timer\n    self.update_display()\n', '  File "C:\\Users\\Public\\quantum_sensing\\quantum_sensing\\fancy_microscope\\custommeasure2.py", line 359, in update_display\n    self.plotlines[rate].setVisible(self.settings[\'{}_visible\'.format(rate)])\n', "AttributeError: 'ESRMeasure' object has no attribute 'plotlines'\n"]
2022-02-18T10:46:05|ERROR|ESRMeasure|ESR_measurement Failed to update figure1: 'ESRMeasure' object has no attribute 'plotlines'. ['Traceback (most recent call last):\n', '  File "C:\\Users\\ZHao\\.conda\\envs\\scopefoundry\\lib\\site-packages\\ScopeFoundry\\measurement.py", line 273, in _on_display_update_timer\n    self.update_display()\n', '  File "C:\\Users\\Public\\quantum_sensing\\quantum_sensing\\fancy_microscope\\custommeasure2.py", line 359, in update_display\n    self.plotlines[rate].setVisible(self.settings[\'{}_visible\'.format(rate)])\n', "AttributeError: 'ESRMeasure' object has no attribute 'plotlines'\n"]
2022-02-18T10:46:05|ERROR|ESRMeasure|ESR_measurement Failed to update figure1: 'ESRMeasure' object has no attribute 'plotlines'. ['Traceback (most recent call last):\n', '  File "C:\\Users\\ZHao\\.conda\\envs\\scopefoundry\\lib\\site-packages\\ScopeFoundry\\measurement.py", line 273, in _on_display_update_timer\n    self.update_display()\n', '  File "C:\\Users\\Public\\quantum_sensing\\quantum_sensing\\fancy_microscope\\custommeasure2.py", line 359, in update_display\n    self.plotlines[rate].setVisible(self.settings[\'{}_visible\'.format(rate)])\n', "AttributeError: 'ESRMeasure' object has no attribute 'plotlines'\n"]
2022-02-18T10:46:05|ERROR|ESRMeasure|ESR_measurement Failed to update figure1: 'ESRMeasure' object has no attribute 'plotlines'. ['Traceback (most recent call last):\n', '  File "C:\\Users\\ZHao\\.conda\\envs\\scopefoundry\\lib\\site-packages\\ScopeFoundry\\measurement.py", line 273, in _on_display_update_timer\n    self.update_display()\n', '  File "C:\\Users\\Public\\quantum_sensing\\quantum_sensing\\fancy_microscope\\custommeasure2.py", line 359, in update_display\n    self.plotlines[rate].setVisible(self.settings[\'{}_visible\'.format(rate)])\n', "AttributeError: 'ESRMeasure' object has no attribute 'plotlines'\n"]
2022-02-18T10:46:05|ERROR|ESRMeasure|ESR_measurement Failed to update figure1: 'ESRMeasure' object has no attribute 'plotlines'. ['Traceback (most recent call last):\n', '  File "C:\\Users\\ZHao\\.conda\\envs\\scopefoundry\\lib\\site-packages\\ScopeFoundry\\measurement.py", line 273, in _on_display_update_timer\n    self.update_display()\n', '  File "C:\\Users\\Public\\quantum_sensing\\quantum_sensing\\fancy_microscope\\custommeasure2.py", line 359, in update_display\n    self.plotlines[rate].setVisible(self.settings[\'{}_visible\'.format(rate)])\n', "AttributeError: 'ESRMeasure' object has no attribute 'plotlines'\n"]
2022-02-18T10:46:05|ERROR|ESRMeasure|ESR_measurement Failed to update figure1: 'ESRMeasure' object has no attribute 'plotlines'. ['Traceback (most recent call last):\n', '  File "C:\\Users\\ZHao\\.conda\\envs\\scopefoundry\\lib\\site-packages\\ScopeFoundry\\measurement.py", line 273, in _on_display_update_timer\n    self.update_display()\n', '  File "C:\\Users\\Public\\quantum_sensing\\quantum_sensing\\fancy_microscope\\custommeasure2.py", line 359, in update_display\n    self.plotlines[rate].setVisible(self.settings[\'{}_visible\'.format(rate)])\n', "AttributeError: 'ESRMeasure' object has no attribute 'plotlines'\n"]
2022-02-18T10:46:05|ERROR|ESRMeasure|ESR_measurement Failed to update figure1: 'ESRMeasure' object has no attribute 'plotlines'. ['Traceback (most recent call last):\n', '  File "C:\\Users\\ZHao\\.conda\\envs\\scopefoundry\\lib\\site-packages\\ScopeFoundry\\measurement.py", line 273, in _on_display_update_timer\n    self.update_display()\n', '  File "C:\\Users\\Public\\quantum_sensing\\quantum_sensing\\fancy_microscope\\custommeasure2.py", line 359, in update_display\n    self.plotlines[rate].setVisible(self.settings[\'{}_visible\'.format(rate)])\n', "AttributeError: 'ESRMeasure' object has no attribute 'plotlines'\n"]
2022-02-18T10:46:06|ERROR|ESRMeasure|ESR_measurement Failed to update figure1: 'ESRMeasure' object has no attribute 'plotlines'. ['Traceback (most recent call last):\n', '  File "C:\\Users\\ZHao\\.conda\\envs\\scopefoundry\\lib\\site-packages\\ScopeFoundry\\measurement.py", line 273, in _on_display_update_timer\n    self.update_display()\n', '  File "C:\\Users\\Public\\quantum_sensing\\quantum_sensing\\fancy_microscope\\custommeasure2.py", line 359, in update_display\n    self.plotlines[rate].setVisible(self.settings[\'{}_visible\'.format(rate)])\n', "AttributeError: 'ESRMeasure' object has no attribute 'plotlines'\n"]
2022-02-18T10:46:06|ERROR|ESRMeasure|ESR_measurement Failed to update figure1: 'ESRMeasure' object has no attribute 'plotlines'. ['Traceback (most recent call last):\n', '  File "C:\\Users\\ZHao\\.conda\\envs\\scopefoundry\\lib\\site-packages\\ScopeFoundry\\measurement.py", line 273, in _on_display_update_timer\n    self.update_display()\n', '  File "C:\\Users\\Public\\quantum_sensing\\quantum_sensing\\fancy_microscope\\custommeasure2.py", line 359, in update_display\n    self.plotlines[rate].setVisible(self.settings[\'{}_visible\'.format(rate)])\n', "AttributeError: 'ESRMeasure' object has no attribute 'plotlines'\n"]
2022-02-18T10:46:06|ERROR|ESRMeasure|ESR_measurement Failed to update figure1: 'ESRMeasure' object has no attribute 'plotlines'. ['Traceback (most recent call last):\n', '  File "C:\\Users\\ZHao\\.conda\\envs\\scopefoundry\\lib\\site-packages\\ScopeFoundry\\measurement.py", line 273, in _on_display_update_timer\n    self.update_display()\n', '  File "C:\\Users\\Public\\quantum_sensing\\quantum_sensing\\fancy_microscope\\custommeasure2.py", line 359, in update_display\n    self.plotlines[rate].setVisible(self.settings[\'{}_visible\'.format(rate)])\n', "AttributeError: 'ESRMeasure' object has no attribute 'plotlines'\n"]
2022-02-18T10:46:06|ERROR|ESRMeasure|ESR_measurement Failed to update figure1: 'ESRMeasure' object has no attribute 'plotlines'. ['Traceback (most recent call last):\n', '  File "C:\\Users\\ZHao\\.conda\\envs\\scopefoundry\\lib\\site-packages\\ScopeFoundry\\measurement.py", line 273, in _on_display_update_timer\n    self.update_display()\n', '  File "C:\\Users\\Public\\quantum_sensing\\quantum_sensing\\fancy_microscope\\custommeasure2.py", line 359, in update_display\n    self.plotlines[rate].setVisible(self.settings[\'{}_visible\'.format(rate)])\n', "AttributeError: 'ESRMeasure' object has no attribute 'plotlines'\n"]
2022-02-18T10:46:06|ERROR|ESRMeasure|ESR_measurement Failed to update figure1: 'ESRMeasure' object has no attribute 'plotlines'. ['Traceback (most recent call last):\n', '  File "C:\\Users\\ZHao\\.conda\\envs\\scopefoundry\\lib\\site-packages\\ScopeFoundry\\measurement.py", line 273, in _on_display_update_timer\n    self.update_display()\n', '  File "C:\\Users\\Public\\quantum_sensing\\quantum_sensing\\fancy_microscope\\custommeasure2.py", line 359, in update_display\n    self.plotlines[rate].setVisible(self.settings[\'{}_visible\'.format(rate)])\n', "AttributeError: 'ESRMeasure' object has no attribute 'plotlines'\n"]
2022-02-18T10:46:06|ERROR|ESRMeasure|ESR_measurement Failed to update figure1: 'ESRMeasure' object has no attribute 'plotlines'. ['Traceback (most recent call last):\n', '  File "C:\\Users\\ZHao\\.conda\\envs\\scopefoundry\\lib\\site-packages\\ScopeFoundry\\measurement.py", line 273, in _on_display_update_timer\n    self.update_display()\n', '  File "C:\\Users\\Public\\quantum_sensing\\quantum_sensing\\fancy_microscope\\custommeasure2.py", line 359, in update_display\n    self.plotlines[rate].setVisible(self.settings[\'{}_visible\'.format(rate)])\n', "AttributeError: 'ESRMeasure' object has no attribute 'plotlines'\n"]
2022-02-18T10:46:06|ERROR|ESRMeasure|ESR_measurement Failed to update figure1: 'ESRMeasure' object has no attribute 'plotlines'. ['Traceback (most recent call last):\n', '  File "C:\\Users\\ZHao\\.conda\\envs\\scopefoundry\\lib\\site-packages\\ScopeFoundry\\measurement.py", line 273, in _on_display_update_timer\n    self.update_display()\n', '  File "C:\\Users\\Public\\quantum_sensing\\quantum_sensing\\fancy_microscope\\custommeasure2.py", line 359, in update_display\n    self.plotlines[rate].setVisible(self.settings[\'{}_visible\'.format(rate)])\n', "AttributeError: 'ESRMeasure' object has no attribute 'plotlines'\n"]
2022-02-18T10:46:06|ERROR|ESRMeasure|ESR_measurement Failed to update figure1: 'ESRMeasure' object has no attribute 'plotlines'. ['Traceback (most recent call last):\n', '  File "C:\\Users\\ZHao\\.conda\\envs\\scopefoundry\\lib\\site-packages\\ScopeFoundry\\measurement.py", line 273, in _on_display_update_timer\n    self.update_display()\n', '  File "C:\\Users\\Public\\quantum_sensing\\quantum_sensing\\fancy_microscope\\custommeasure2.py", line 359, in update_display\n    self.plotlines[rate].setVisible(self.settings[\'{}_visible\'.format(rate)])\n', "AttributeError: 'ESRMeasure' object has no attribute 'plotlines'\n"]
2022-02-18T10:46:06|ERROR|ESRMeasure|ESR_measurement Failed to update figure1: 'ESRMeasure' object has no attribute 'plotlines'. ['Traceback (most recent call last):\n', '  File "C:\\Users\\ZHao\\.conda\\envs\\scopefoundry\\lib\\site-packages\\ScopeFoundry\\measurement.py", line 273, in _on_display_update_timer\n    self.update_display()\n', '  File "C:\\Users\\Public\\quantum_sensing\\quantum_sensing\\fancy_microscope\\custommeasure2.py", line 359, in update_display\n    self.plotlines[rate].setVisible(self.settings[\'{}_visible\'.format(rate)])\n', "AttributeError: 'ESRMeasure' object has no attribute 'plotlines'\n"]
2022-02-18T10:46:07|ERROR|ESRMeasure|ESR_measurement Failed to update figure1: 'ESRMeasure' object has no attribute 'plotlines'. ['Traceback (most recent call last):\n', '  File "C:\\Users\\ZHao\\.conda\\envs\\scopefoundry\\lib\\site-packages\\ScopeFoundry\\measurement.py", line 273, in _on_display_update_timer\n    self.update_display()\n', '  File "C:\\Users\\Public\\quantum_sensing\\quantum_sensing\\fancy_microscope\\custommeasure2.py", line 359, in update_display\n    self.plotlines[rate].setVisible(self.settings[\'{}_visible\'.format(rate)])\n', "AttributeError: 'ESRMeasure' object has no attribute 'plotlines'\n"]
2022-02-18T10:46:07|ERROR|ESRMeasure|ESR_measurement Failed to update figure1: 'ESRMeasure' object has no attribute 'plotlines'. ['Traceback (most recent call last):\n', '  File "C:\\Users\\ZHao\\.conda\\envs\\scopefoundry\\lib\\site-packages\\ScopeFoundry\\measurement.py", line 273, in _on_display_update_timer\n    self.update_display()\n', '  File "C:\\Users\\Public\\quantum_sensing\\quantum_sensing\\fancy_microscope\\custommeasure2.py", line 359, in update_display\n    self.plotlines[rate].setVisible(self.settings[\'{}_visible\'.format(rate)])\n', "AttributeError: 'ESRMeasure' object has no attribute 'plotlines'\n"]
2022-02-18T10:46:07|ERROR|ESRMeasure|ESR_measurement Failed to update figure1: 'ESRMeasure' object has no attribute 'plotlines'. ['Traceback (most recent call last):\n', '  File "C:\\Users\\ZHao\\.conda\\envs\\scopefoundry\\lib\\site-packages\\ScopeFoundry\\measurement.py", line 273, in _on_display_update_timer\n    self.update_display()\n', '  File "C:\\Users\\Public\\quantum_sensing\\quantum_sensing\\fancy_microscope\\custommeasure2.py", line 359, in update_display\n    self.plotlines[rate].setVisible(self.settings[\'{}_visible\'.format(rate)])\n', "AttributeError: 'ESRMeasure' object has no attribute 'plotlines'\n"]
2022-02-18T10:46:07|ERROR|ESRMeasure|ESR_measurement Failed to update figure1: 'ESRMeasure' object has no attribute 'plotlines'. ['Traceback (most recent call last):\n', '  File "C:\\Users\\ZHao\\.conda\\envs\\scopefoundry\\lib\\site-packages\\ScopeFoundry\\measurement.py", line 273, in _on_display_update_timer\n    self.update_display()\n', '  File "C:\\Users\\Public\\quantum_sensing\\quantum_sensing\\fancy_microscope\\custommeasure2.py", line 359, in update_display\n    self.plotlines[rate].setVisible(self.settings[\'{}_visible\'.format(rate)])\n', "AttributeError: 'ESRMeasure' object has no attribute 'plotlines'\n"]
2022-02-18T10:46:07|ERROR|ESRMeasure|ESR_measurement Failed to update figure1: 'ESRMeasure' object has no attribute 'plotlines'. ['Traceback (most recent call last):\n', '  File "C:\\Users\\ZHao\\.conda\\envs\\scopefoundry\\lib\\site-packages\\ScopeFoundry\\measurement.py", line 273, in _on_display_update_timer\n    self.update_display()\n', '  File "C:\\Users\\Public\\quantum_sensing\\quantum_sensing\\fancy_microscope\\custommeasure2.py", line 359, in update_display\n    self.plotlines[rate].setVisible(self.settings[\'{}_visible\'.format(rate)])\n', "AttributeError: 'ESRMeasure' object has no attribute 'plotlines'\n"]
2022-02-18T10:46:07|ERROR|ESRMeasure|ESR_measurement Failed to update figure1: 'ESRMeasure' object has no attribute 'plotlines'. ['Traceback (most recent call last):\n', '  File "C:\\Users\\ZHao\\.conda\\envs\\scopefoundry\\lib\\site-packages\\ScopeFoundry\\measurement.py", line 273, in _on_display_update_timer\n    self.update_display()\n', '  File "C:\\Users\\Public\\quantum_sensing\\quantum_sensing\\fancy_microscope\\custommeasure2.py", line 359, in update_display\n    self.plotlines[rate].setVisible(self.settings[\'{}_visible\'.format(rate)])\n', "AttributeError: 'ESRMeasure' object has no attribute 'plotlines'\n"]
2022-02-18T10:46:07|ERROR|ESRMeasure|ESR_measurement Failed to update figure1: 'ESRMeasure' object has no attribute 'plotlines'. ['Traceback (most recent call last):\n', '  File "C:\\Users\\ZHao\\.conda\\envs\\scopefoundry\\lib\\site-packages\\ScopeFoundry\\measurement.py", line 273, in _on_display_update_timer\n    self.update_display()\n', '  File "C:\\Users\\Public\\quantum_sensing\\quantum_sensing\\fancy_microscope\\custommeasure2.py", line 359, in update_display\n    self.plotlines[rate].setVisible(self.settings[\'{}_visible\'.format(rate)])\n', "AttributeError: 'ESRMeasure' object has no attribute 'plotlines'\n"]
2022-02-18T10:46:07|ERROR|ESRMeasure|ESR_measurement Failed to update figure1: 'ESRMeasure' object has no attribute 'plotlines'. ['Traceback (most recent call last):\n', '  File "C:\\Users\\ZHao\\.conda\\envs\\scopefoundry\\lib\\site-packages\\ScopeFoundry\\measurement.py", line 273, in _on_display_update_timer\n    self.update_display()\n', '  File "C:\\Users\\Public\\quantum_sensing\\quantum_sensing\\fancy_microscope\\custommeasure2.py", line 359, in update_display\n    self.plotlines[rate].setVisible(self.settings[\'{}_visible\'.format(rate)])\n', "AttributeError: 'ESRMeasure' object has no attribute 'plotlines'\n"]
2022-02-18T10:46:07|ERROR|ESRMeasure|ESR_measurement Failed to update figure1: 'ESRMeasure' object has no attribute 'plotlines'. ['Traceback (most recent call last):\n', '  File "C:\\Users\\ZHao\\.conda\\envs\\scopefoundry\\lib\\site-packages\\ScopeFoundry\\measurement.py", line 273, in _on_display_update_timer\n    self.update_display()\n', '  File "C:\\Users\\Public\\quantum_sensing\\quantum_sensing\\fancy_microscope\\custommeasure2.py", line 359, in update_display\n    self.plotlines[rate].setVisible(self.settings[\'{}_visible\'.format(rate)])\n', "AttributeError: 'ESRMeasure' object has no attribute 'plotlines'\n"]
2022-02-18T10:46:08|ERROR|ESRMeasure|ESR_measurement Failed to update figure1: 'ESRMeasure' object has no attribute 'plotlines'. ['Traceback (most recent call last):\n', '  File "C:\\Users\\ZHao\\.conda\\envs\\scopefoundry\\lib\\site-packages\\ScopeFoundry\\measurement.py", line 273, in _on_display_update_timer\n    self.update_display()\n', '  File "C:\\Users\\Public\\quantum_sensing\\quantum_sensing\\fancy_microscope\\custommeasure2.py", line 359, in update_display\n    self.plotlines[rate].setVisible(self.settings[\'{}_visible\'.format(rate)])\n', "AttributeError: 'ESRMeasure' object has no attribute 'plotlines'\n"]
2022-02-18T10:46:08|ERROR|ESRMeasure|ESR_measurement Failed to update figure1: 'ESRMeasure' object has no attribute 'plotlines'. ['Traceback (most recent call last):\n', '  File "C:\\Users\\ZHao\\.conda\\envs\\scopefoundry\\lib\\site-packages\\ScopeFoundry\\measurement.py", line 273, in _on_display_update_timer\n    self.update_display()\n', '  File "C:\\Users\\Public\\quantum_sensing\\quantum_sensing\\fancy_microscope\\custommeasure2.py", line 359, in update_display\n    self.plotlines[rate].setVisible(self.settings[\'{}_visible\'.format(rate)])\n', "AttributeError: 'ESRMeasure' object has no attribute 'plotlines'\n"]
2022-02-18T10:46:08|ERROR|ESRMeasure|ESR_measurement Failed to update figure1: 'ESRMeasure' object has no attribute 'plotlines'. ['Traceback (most recent call last):\n', '  File "C:\\Users\\ZHao\\.conda\\envs\\scopefoundry\\lib\\site-packages\\ScopeFoundry\\measurement.py", line 273, in _on_display_update_timer\n    self.update_display()\n', '  File "C:\\Users\\Public\\quantum_sensing\\quantum_sensing\\fancy_microscope\\custommeasure2.py", line 359, in update_display\n    self.plotlines[rate].setVisible(self.settings[\'{}_visible\'.format(rate)])\n', "AttributeError: 'ESRMeasure' object has no attribute 'plotlines'\n"]
2022-02-18T10:46:08|ERROR|ESRMeasure|ESR_measurement Failed to update figure1: 'ESRMeasure' object has no attribute 'plotlines'. ['Traceback (most recent call last):\n', '  File "C:\\Users\\ZHao\\.conda\\envs\\scopefoundry\\lib\\site-packages\\ScopeFoundry\\measurement.py", line 273, in _on_display_update_timer\n    self.update_display()\n', '  File "C:\\Users\\Public\\quantum_sensing\\quantum_sensing\\fancy_microscope\\custommeasure2.py", line 359, in update_display\n    self.plotlines[rate].setVisible(self.settings[\'{}_visible\'.format(rate)])\n', "AttributeError: 'ESRMeasure' object has no attribute 'plotlines'\n"]
2022-02-18T10:46:08|ERROR|ESRMeasure|ESR_measurement Failed to update figure1: 'ESRMeasure' object has no attribute 'plotlines'. ['Traceback (most recent call last):\n', '  File "C:\\Users\\ZHao\\.conda\\envs\\scopefoundry\\lib\\site-packages\\ScopeFoundry\\measurement.py", line 273, in _on_display_update_timer\n    self.update_display()\n', '  File "C:\\Users\\Public\\quantum_sensing\\quantum_sensing\\fancy_microscope\\custommeasure2.py", line 359, in update_display\n    self.plotlines[rate].setVisible(self.settings[\'{}_visible\'.format(rate)])\n', "AttributeError: 'ESRMeasure' object has no attribute 'plotlines'\n"]
2022-02-18T10:46:08|ERROR|ESRMeasure|ESR_measurement Failed to update figure1: 'ESRMeasure' object has no attribute 'plotlines'. ['Traceback (most recent call last):\n', '  File "C:\\Users\\ZHao\\.conda\\envs\\scopefoundry\\lib\\site-packages\\ScopeFoundry\\measurement.py", line 273, in _on_display_update_timer\n    self.update_display()\n', '  File "C:\\Users\\Public\\quantum_sensing\\quantum_sensing\\fancy_microscope\\custommeasure2.py", line 359, in update_display\n    self.plotlines[rate].setVisible(self.settings[\'{}_visible\'.format(rate)])\n', "AttributeError: 'ESRMeasure' object has no attribute 'plotlines'\n"]
2022-02-18T10:46:08|ERROR|ESRMeasure|ESR_measurement Failed to update figure1: 'ESRMeasure' object has no attribute 'plotlines'. ['Traceback (most recent call last):\n', '  File "C:\\Users\\ZHao\\.conda\\envs\\scopefoundry\\lib\\site-packages\\ScopeFoundry\\measurement.py", line 273, in _on_display_update_timer\n    self.update_display()\n', '  File "C:\\Users\\Public\\quantum_sensing\\quantum_sensing\\fancy_microscope\\custommeasure2.py", line 359, in update_display\n    self.plotlines[rate].setVisible(self.settings[\'{}_visible\'.format(rate)])\n', "AttributeError: 'ESRMeasure' object has no attribute 'plotlines'\n"]
2022-02-18T10:46:08|ERROR|ESRMeasure|ESR_measurement Failed to update figure1: 'ESRMeasure' object has no attribute 'plotlines'. ['Traceback (most recent call last):\n', '  File "C:\\Users\\ZHao\\.conda\\envs\\scopefoundry\\lib\\site-packages\\ScopeFoundry\\measurement.py", line 273, in _on_display_update_timer\n    self.update_display()\n', '  File "C:\\Users\\Public\\quantum_sensing\\quantum_sensing\\fancy_microscope\\custommeasure2.py", line 359, in update_display\n    self.plotlines[rate].setVisible(self.settings[\'{}_visible\'.format(rate)])\n', "AttributeError: 'ESRMeasure' object has no attribute 'plotlines'\n"]
2022-02-18T10:46:09|ERROR|ESRMeasure|ESR_measurement Failed to update figure1: 'ESRMeasure' object has no attribute 'plotlines'. ['Traceback (most recent call last):\n', '  File "C:\\Users\\ZHao\\.conda\\envs\\scopefoundry\\lib\\site-packages\\ScopeFoundry\\measurement.py", line 273, in _on_display_update_timer\n    self.update_display()\n', '  File "C:\\Users\\Public\\quantum_sensing\\quantum_sensing\\fancy_microscope\\custommeasure2.py", line 359, in update_display\n    self.plotlines[rate].setVisible(self.settings[\'{}_visible\'.format(rate)])\n', "AttributeError: 'ESRMeasure' object has no attribute 'plotlines'\n"]
2022-02-18T10:46:09|ERROR|ESRMeasure|ESR_measurement Failed to update figure1: 'ESRMeasure' object has no attribute 'plotlines'. ['Traceback (most recent call last):\n', '  File "C:\\Users\\ZHao\\.conda\\envs\\scopefoundry\\lib\\site-packages\\ScopeFoundry\\measurement.py", line 273, in _on_display_update_timer\n    self.update_display()\n', '  File "C:\\Users\\Public\\quantum_sensing\\quantum_sensing\\fancy_microscope\\custommeasure2.py", line 359, in update_display\n    self.plotlines[rate].setVisible(self.settings[\'{}_visible\'.format(rate)])\n', "AttributeError: 'ESRMeasure' object has no attribute 'plotlines'\n"]
2022-02-18T10:46:09|ERROR|ESRMeasure|ESR_measurement Failed to update figure1: 'ESRMeasure' object has no attribute 'plotlines'. ['Traceback (most recent call last):\n', '  File "C:\\Users\\ZHao\\.conda\\envs\\scopefoundry\\lib\\site-packages\\ScopeFoundry\\measurement.py", line 273, in _on_display_update_timer\n    self.update_display()\n', '  File "C:\\Users\\Public\\quantum_sensing\\quantum_sensing\\fancy_microscope\\custommeasure2.py", line 359, in update_display\n    self.plotlines[rate].setVisible(self.settings[\'{}_visible\'.format(rate)])\n', "AttributeError: 'ESRMeasure' object has no attribute 'plotlines'\n"]
2022-02-18T10:46:09|ERROR|ESRMeasure|ESR_measurement Failed to update figure1: 'ESRMeasure' object has no attribute 'plotlines'. ['Traceback (most recent call last):\n', '  File "C:\\Users\\ZHao\\.conda\\envs\\scopefoundry\\lib\\site-packages\\ScopeFoundry\\measurement.py", line 273, in _on_display_update_timer\n    self.update_display()\n', '  File "C:\\Users\\Public\\quantum_sensing\\quantum_sensing\\fancy_microscope\\custommeasure2.py", line 359, in update_display\n    self.plotlines[rate].setVisible(self.settings[\'{}_visible\'.format(rate)])\n', "AttributeError: 'ESRMeasure' object has no attribute 'plotlines'\n"]
2022-02-18T10:46:09|ERROR|ESRMeasure|ESR_measurement Failed to update figure1: 'ESRMeasure' object has no attribute 'plotlines'. ['Traceback (most recent call last):\n', '  File "C:\\Users\\ZHao\\.conda\\envs\\scopefoundry\\lib\\site-packages\\ScopeFoundry\\measurement.py", line 273, in _on_display_update_timer\n    self.update_display()\n', '  File "C:\\Users\\Public\\quantum_sensing\\quantum_sensing\\fancy_microscope\\custommeasure2.py", line 359, in update_display\n    self.plotlines[rate].setVisible(self.settings[\'{}_visible\'.format(rate)])\n', "AttributeError: 'ESRMeasure' object has no attribute 'plotlines'\n"]
2022-02-18T10:46:09|ERROR|ESRMeasure|ESR_measurement Failed to update figure1: 'ESRMeasure' object has no attribute 'plotlines'. ['Traceback (most recent call last):\n', '  File "C:\\Users\\ZHao\\.conda\\envs\\scopefoundry\\lib\\site-packages\\ScopeFoundry\\measurement.py", line 273, in _on_display_update_timer\n    self.update_display()\n', '  File "C:\\Users\\Public\\quantum_sensing\\quantum_sensing\\fancy_microscope\\custommeasure2.py", line 359, in update_display\n    self.plotlines[rate].setVisible(self.settings[\'{}_visible\'.format(rate)])\n', "AttributeError: 'ESRMeasure' object has no attribute 'plotlines'\n"]
2022-02-18T10:46:09|ERROR|ESRMeasure|ESR_measurement Failed to update figure1: 'ESRMeasure' object has no attribute 'plotlines'. ['Traceback (most recent call last):\n', '  File "C:\\Users\\ZHao\\.conda\\envs\\scopefoundry\\lib\\site-packages\\ScopeFoundry\\measurement.py", line 273, in _on_display_update_timer\n    self.update_display()\n', '  File "C:\\Users\\Public\\quantum_sensing\\quantum_sensing\\fancy_microscope\\custommeasure2.py", line 359, in update_display\n    self.plotlines[rate].setVisible(self.settings[\'{}_visible\'.format(rate)])\n', "AttributeError: 'ESRMeasure' object has no attribute 'plotlines'\n"]
2022-02-18T10:46:10|ERROR|ESRMeasure|ESR_measurement Failed to update figure1: 'ESRMeasure' object has no attribute 'plotlines'. ['Traceback (most recent call last):\n', '  File "C:\\Users\\ZHao\\.conda\\envs\\scopefoundry\\lib\\site-packages\\ScopeFoundry\\measurement.py", line 273, in _on_display_update_timer\n    self.update_display()\n', '  File "C:\\Users\\Public\\quantum_sensing\\quantum_sensing\\fancy_microscope\\custommeasure2.py", line 359, in update_display\n    self.plotlines[rate].setVisible(self.settings[\'{}_visible\'.format(rate)])\n', "AttributeError: 'ESRMeasure' object has no attribute 'plotlines'\n"]
2022-02-18T10:46:10|ERROR|ESRMeasure|ESR_measurement Failed to update figure1: 'ESRMeasure' object has no attribute 'plotlines'. ['Traceback (most recent call last):\n', '  File "C:\\Users\\ZHao\\.conda\\envs\\scopefoundry\\lib\\site-packages\\ScopeFoundry\\measurement.py", line 273, in _on_display_update_timer\n    self.update_display()\n', '  File "C:\\Users\\Public\\quantum_sensing\\quantum_sensing\\fancy_microscope\\custommeasure2.py", line 359, in update_display\n    self.plotlines[rate].setVisible(self.settings[\'{}_visible\'.format(rate)])\n', "AttributeError: 'ESRMeasure' object has no attribute 'plotlines'\n"]
2022-02-18T10:46:10|ERROR|ESRMeasure|ESR_measurement Failed to update figure1: 'ESRMeasure' object has no attribute 'plotlines'. ['Traceback (most recent call last):\n', '  File "C:\\Users\\ZHao\\.conda\\envs\\scopefoundry\\lib\\site-packages\\ScopeFoundry\\measurement.py", line 273, in _on_display_update_timer\n    self.update_display()\n', '  File "C:\\Users\\Public\\quantum_sensing\\quantum_sensing\\fancy_microscope\\custommeasure2.py", line 359, in update_display\n    self.plotlines[rate].setVisible(self.settings[\'{}_visible\'.format(rate)])\n', "AttributeError: 'ESRMeasure' object has no attribute 'plotlines'\n"]
2022-02-18T10:46:10|ERROR|ESRMeasure|ESR_measurement Failed to update figure1: 'ESRMeasure' object has no attribute 'plotlines'. ['Traceback (most recent call last):\n', '  File "C:\\Users\\ZHao\\.conda\\envs\\scopefoundry\\lib\\site-packages\\ScopeFoundry\\measurement.py", line 273, in _on_display_update_timer\n    self.update_display()\n', '  File "C:\\Users\\Public\\quantum_sensing\\quantum_sensing\\fancy_microscope\\custommeasure2.py", line 359, in update_display\n    self.plotlines[rate].setVisible(self.settings[\'{}_visible\'.format(rate)])\n', "AttributeError: 'ESRMeasure' object has no attribute 'plotlines'\n"]
2022-02-18T10:46:10|ERROR|ESRMeasure|ESR_measurement Failed to update figure1: 'ESRMeasure' object has no attribute 'plotlines'. ['Traceback (most recent call last):\n', '  File "C:\\Users\\ZHao\\.conda\\envs\\scopefoundry\\lib\\site-packages\\ScopeFoundry\\measurement.py", line 273, in _on_display_update_timer\n    self.update_display()\n', '  File "C:\\Users\\Public\\quantum_sensing\\quantum_sensing\\fancy_microscope\\custommeasure2.py", line 359, in update_display\n    self.plotlines[rate].setVisible(self.settings[\'{}_visible\'.format(rate)])\n', "AttributeError: 'ESRMeasure' object has no attribute 'plotlines'\n"]
2022-02-18T10:46:10|ERROR|ESRMeasure|ESR_measurement Failed to update figure1: 'ESRMeasure' object has no attribute 'plotlines'. ['Traceback (most recent call last):\n', '  File "C:\\Users\\ZHao\\.conda\\envs\\scopefoundry\\lib\\site-packages\\ScopeFoundry\\measurement.py", line 273, in _on_display_update_timer\n    self.update_display()\n', '  File "C:\\Users\\Public\\quantum_sensing\\quantum_sensing\\fancy_microscope\\custommeasure2.py", line 359, in update_display\n    self.plotlines[rate].setVisible(self.settings[\'{}_visible\'.format(rate)])\n', "AttributeError: 'ESRMeasure' object has no attribute 'plotlines'\n"]
2022-02-18T10:46:10|ERROR|ESRMeasure|ESR_measurement Failed to update figure1: 'ESRMeasure' object has no attribute 'plotlines'. ['Traceback (most recent call last):\n', '  File "C:\\Users\\ZHao\\.conda\\envs\\scopefoundry\\lib\\site-packages\\ScopeFoundry\\measurement.py", line 273, in _on_display_update_timer\n    self.update_display()\n', '  File "C:\\Users\\Public\\quantum_sensing\\quantum_sensing\\fancy_microscope\\custommeasure2.py", line 359, in update_display\n    self.plotlines[rate].setVisible(self.settings[\'{}_visible\'.format(rate)])\n', "AttributeError: 'ESRMeasure' object has no attribute 'plotlines'\n"]
2022-02-18T10:46:10|ERROR|ESRMeasure|ESR_measurement Failed to update figure1: 'ESRMeasure' object has no attribute 'plotlines'. ['Traceback (most recent call last):\n', '  File "C:\\Users\\ZHao\\.conda\\envs\\scopefoundry\\lib\\site-packages\\ScopeFoundry\\measurement.py", line 273, in _on_display_update_timer\n    self.update_display()\n', '  File "C:\\Users\\Public\\quantum_sensing\\quantum_sensing\\fancy_microscope\\custommeasure2.py", line 359, in update_display\n    self.plotlines[rate].setVisible(self.settings[\'{}_visible\'.format(rate)])\n', "AttributeError: 'ESRMeasure' object has no attribute 'plotlines'\n"]
2022-02-18T11:03:29|ERROR|ESRMeasure|ESR_measurement Failed to update figure1: 'ESRMeasure' object has no attribute 'plotlines'. ['Traceback (most recent call last):\n', '  File "C:\\Users\\ZHao\\.conda\\envs\\scopefoundry\\lib\\site-packages\\ScopeFoundry\\measurement.py", line 273, in _on_display_update_timer\n    self.update_display()\n', '  File "C:\\Users\\Public\\quantum_sensing\\quantum_sensing\\fancy_microscope\\custommeasure2.py", line 359, in update_display\n    self.plotlines[rate].setVisible(self.settings[\'{}_visible\'.format(rate)])\n', "AttributeError: 'ESRMeasure' object has no attribute 'plotlines'\n"]
2022-02-18T11:03:29|ERROR|ESRMeasure|ESR_measurement Failed to update figure1: 'ESRMeasure' object has no attribute 'plotlines'. ['Traceback (most recent call last):\n', '  File "C:\\Users\\ZHao\\.conda\\envs\\scopefoundry\\lib\\site-packages\\ScopeFoundry\\measurement.py", line 273, in _on_display_update_timer\n    self.update_display()\n', '  File "C:\\Users\\Public\\quantum_sensing\\quantum_sensing\\fancy_microscope\\custommeasure2.py", line 359, in update_display\n    self.plotlines[rate].setVisible(self.settings[\'{}_visible\'.format(rate)])\n', "AttributeError: 'ESRMeasure' object has no attribute 'plotlines'\n"]
2022-02-18T11:03:29|ERROR|ESRMeasure|ESR_measurement Failed to update figure1: 'ESRMeasure' object has no attribute 'plotlines'. ['Traceback (most recent call last):\n', '  File "C:\\Users\\ZHao\\.conda\\envs\\scopefoundry\\lib\\site-packages\\ScopeFoundry\\measurement.py", line 273, in _on_display_update_timer\n    self.update_display()\n', '  File "C:\\Users\\Public\\quantum_sensing\\quantum_sensing\\fancy_microscope\\custommeasure2.py", line 359, in update_display\n    self.plotlines[rate].setVisible(self.settings[\'{}_visible\'.format(rate)])\n', "AttributeError: 'ESRMeasure' object has no attribute 'plotlines'\n"]
2022-02-18T11:03:29|ERROR|ESRMeasure|ESR_measurement Failed to update figure1: 'ESRMeasure' object has no attribute 'plotlines'. ['Traceback (most recent call last):\n', '  File "C:\\Users\\ZHao\\.conda\\envs\\scopefoundry\\lib\\site-packages\\ScopeFoundry\\measurement.py", line 273, in _on_display_update_timer\n    self.update_display()\n', '  File "C:\\Users\\Public\\quantum_sensing\\quantum_sensing\\fancy_microscope\\custommeasure2.py", line 359, in update_display\n    self.plotlines[rate].setVisible(self.settings[\'{}_visible\'.format(rate)])\n', "AttributeError: 'ESRMeasure' object has no attribute 'plotlines'\n"]
2022-02-18T11:03:29|ERROR|ESRMeasure|ESR_measurement Failed to update figure1: 'ESRMeasure' object has no attribute 'plotlines'. ['Traceback (most recent call last):\n', '  File "C:\\Users\\ZHao\\.conda\\envs\\scopefoundry\\lib\\site-packages\\ScopeFoundry\\measurement.py", line 273, in _on_display_update_timer\n    self.update_display()\n', '  File "C:\\Users\\Public\\quantum_sensing\\quantum_sensing\\fancy_microscope\\custommeasure2.py", line 359, in update_display\n    self.plotlines[rate].setVisible(self.settings[\'{}_visible\'.format(rate)])\n', "AttributeError: 'ESRMeasure' object has no attribute 'plotlines'\n"]
2022-02-18T11:03:30|ERROR|ESRMeasure|ESR_measurement Failed to update figure1: 'ESRMeasure' object has no attribute 'plotlines'. ['Traceback (most recent call last):\n', '  File "C:\\Users\\ZHao\\.conda\\envs\\scopefoundry\\lib\\site-packages\\ScopeFoundry\\measurement.py", line 273, in _on_display_update_timer\n    self.update_display()\n', '  File "C:\\Users\\Public\\quantum_sensing\\quantum_sensing\\fancy_microscope\\custommeasure2.py", line 359, in update_display\n    self.plotlines[rate].setVisible(self.settings[\'{}_visible\'.format(rate)])\n', "AttributeError: 'ESRMeasure' object has no attribute 'plotlines'\n"]
2022-02-18T11:03:30|ERROR|ESRMeasure|ESR_measurement Failed to update figure1: 'ESRMeasure' object has no attribute 'plotlines'. ['Traceback (most recent call last):\n', '  File "C:\\Users\\ZHao\\.conda\\envs\\scopefoundry\\lib\\site-packages\\ScopeFoundry\\measurement.py", line 273, in _on_display_update_timer\n    self.update_display()\n', '  File "C:\\Users\\Public\\quantum_sensing\\quantum_sensing\\fancy_microscope\\custommeasure2.py", line 359, in update_display\n    self.plotlines[rate].setVisible(self.settings[\'{}_visible\'.format(rate)])\n', "AttributeError: 'ESRMeasure' object has no attribute 'plotlines'\n"]
2022-02-18T11:03:30|ERROR|ESRMeasure|ESR_measurement Failed to update figure1: 'ESRMeasure' object has no attribute 'plotlines'. ['Traceback (most recent call last):\n', '  File "C:\\Users\\ZHao\\.conda\\envs\\scopefoundry\\lib\\site-packages\\ScopeFoundry\\measurement.py", line 273, in _on_display_update_timer\n    self.update_display()\n', '  File "C:\\Users\\Public\\quantum_sensing\\quantum_sensing\\fancy_microscope\\custommeasure2.py", line 359, in update_display\n    self.plotlines[rate].setVisible(self.settings[\'{}_visible\'.format(rate)])\n', "AttributeError: 'ESRMeasure' object has no attribute 'plotlines'\n"]
2022-02-18T11:03:30|ERROR|ESRMeasure|ESR_measurement Failed to update figure1: 'ESRMeasure' object has no attribute 'plotlines'. ['Traceback (most recent call last):\n', '  File "C:\\Users\\ZHao\\.conda\\envs\\scopefoundry\\lib\\site-packages\\ScopeFoundry\\measurement.py", line 273, in _on_display_update_timer\n    self.update_display()\n', '  File "C:\\Users\\Public\\quantum_sensing\\quantum_sensing\\fancy_microscope\\custommeasure2.py", line 359, in update_display\n    self.plotlines[rate].setVisible(self.settings[\'{}_visible\'.format(rate)])\n', "AttributeError: 'ESRMeasure' object has no attribute 'plotlines'\n"]
2022-02-18T11:03:30|ERROR|ESRMeasure|ESR_measurement Failed to update figure1: 'ESRMeasure' object has no attribute 'plotlines'. ['Traceback (most recent call last):\n', '  File "C:\\Users\\ZHao\\.conda\\envs\\scopefoundry\\lib\\site-packages\\ScopeFoundry\\measurement.py", line 273, in _on_display_update_timer\n    self.update_display()\n', '  File "C:\\Users\\Public\\quantum_sensing\\quantum_sensing\\fancy_microscope\\custommeasure2.py", line 359, in update_display\n    self.plotlines[rate].setVisible(self.settings[\'{}_visible\'.format(rate)])\n', "AttributeError: 'ESRMeasure' object has no attribute 'plotlines'\n"]
2022-02-18T11:03:30|ERROR|ESRMeasure|ESR_measurement Failed to update figure1: 'ESRMeasure' object has no attribute 'plotlines'. ['Traceback (most recent call last):\n', '  File "C:\\Users\\ZHao\\.conda\\envs\\scopefoundry\\lib\\site-packages\\ScopeFoundry\\measurement.py", line 273, in _on_display_update_timer\n    self.update_display()\n', '  File "C:\\Users\\Public\\quantum_sensing\\quantum_sensing\\fancy_microscope\\custommeasure2.py", line 359, in update_display\n    self.plotlines[rate].setVisible(self.settings[\'{}_visible\'.format(rate)])\n', "AttributeError: 'ESRMeasure' object has no attribute 'plotlines'\n"]
2022-02-18T11:03:30|ERROR|ESRMeasure|ESR_measurement Failed to update figure1: 'ESRMeasure' object has no attribute 'plotlines'. ['Traceback (most recent call last):\n', '  File "C:\\Users\\ZHao\\.conda\\envs\\scopefoundry\\lib\\site-packages\\ScopeFoundry\\measurement.py", line 273, in _on_display_update_timer\n    self.update_display()\n', '  File "C:\\Users\\Public\\quantum_sensing\\quantum_sensing\\fancy_microscope\\custommeasure2.py", line 359, in update_display\n    self.plotlines[rate].setVisible(self.settings[\'{}_visible\'.format(rate)])\n', "AttributeError: 'ESRMeasure' object has no attribute 'plotlines'\n"]
2022-02-18T11:03:30|ERROR|ESRMeasure|ESR_measurement Failed to update figure1: 'ESRMeasure' object has no attribute 'plotlines'. ['Traceback (most recent call last):\n', '  File "C:\\Users\\ZHao\\.conda\\envs\\scopefoundry\\lib\\site-packages\\ScopeFoundry\\measurement.py", line 273, in _on_display_update_timer\n    self.update_display()\n', '  File "C:\\Users\\Public\\quantum_sensing\\quantum_sensing\\fancy_microscope\\custommeasure2.py", line 359, in update_display\n    self.plotlines[rate].setVisible(self.settings[\'{}_visible\'.format(rate)])\n', "AttributeError: 'ESRMeasure' object has no attribute 'plotlines'\n"]
2022-02-18T11:03:30|ERROR|ESRMeasure|ESR_measurement Failed to update figure1: 'ESRMeasure' object has no attribute 'plotlines'. ['Traceback (most recent call last):\n', '  File "C:\\Users\\ZHao\\.conda\\envs\\scopefoundry\\lib\\site-packages\\ScopeFoundry\\measurement.py", line 273, in _on_display_update_timer\n    self.update_display()\n', '  File "C:\\Users\\Public\\quantum_sensing\\quantum_sensing\\fancy_microscope\\custommeasure2.py", line 359, in update_display\n    self.plotlines[rate].setVisible(self.settings[\'{}_visible\'.format(rate)])\n', "AttributeError: 'ESRMeasure' object has no attribute 'plotlines'\n"]
2022-02-18T11:03:31|ERROR|ESRMeasure|ESR_measurement Failed to update figure1: 'ESRMeasure' object has no attribute 'plotlines'. ['Traceback (most recent call last):\n', '  File "C:\\Users\\ZHao\\.conda\\envs\\scopefoundry\\lib\\site-packages\\ScopeFoundry\\measurement.py", line 273, in _on_display_update_timer\n    self.update_display()\n', '  File "C:\\Users\\Public\\quantum_sensing\\quantum_sensing\\fancy_microscope\\custommeasure2.py", line 359, in update_display\n    self.plotlines[rate].setVisible(self.settings[\'{}_visible\'.format(rate)])\n', "AttributeError: 'ESRMeasure' object has no attribute 'plotlines'\n"]
2022-02-18T11:03:31|ERROR|ESRMeasure|ESR_measurement Failed to update figure1: 'ESRMeasure' object has no attribute 'plotlines'. ['Traceback (most recent call last):\n', '  File "C:\\Users\\ZHao\\.conda\\envs\\scopefoundry\\lib\\site-packages\\ScopeFoundry\\measurement.py", line 273, in _on_display_update_timer\n    self.update_display()\n', '  File "C:\\Users\\Public\\quantum_sensing\\quantum_sensing\\fancy_microscope\\custommeasure2.py", line 359, in update_display\n    self.plotlines[rate].setVisible(self.settings[\'{}_visible\'.format(rate)])\n', "AttributeError: 'ESRMeasure' object has no attribute 'plotlines'\n"]
2022-02-18T11:03:31|ERROR|ESRMeasure|ESR_measurement Failed to update figure1: 'ESRMeasure' object has no attribute 'plotlines'. ['Traceback (most recent call last):\n', '  File "C:\\Users\\ZHao\\.conda\\envs\\scopefoundry\\lib\\site-packages\\ScopeFoundry\\measurement.py", line 273, in _on_display_update_timer\n    self.update_display()\n', '  File "C:\\Users\\Public\\quantum_sensing\\quantum_sensing\\fancy_microscope\\custommeasure2.py", line 359, in update_display\n    self.plotlines[rate].setVisible(self.settings[\'{}_visible\'.format(rate)])\n', "AttributeError: 'ESRMeasure' object has no attribute 'plotlines'\n"]
2022-02-18T11:03:31|ERROR|ESRMeasure|ESR_measurement Failed to update figure1: 'ESRMeasure' object has no attribute 'plotlines'. ['Traceback (most recent call last):\n', '  File "C:\\Users\\ZHao\\.conda\\envs\\scopefoundry\\lib\\site-packages\\ScopeFoundry\\measurement.py", line 273, in _on_display_update_timer\n    self.update_display()\n', '  File "C:\\Users\\Public\\quantum_sensing\\quantum_sensing\\fancy_microscope\\custommeasure2.py", line 359, in update_display\n    self.plotlines[rate].setVisible(self.settings[\'{}_visible\'.format(rate)])\n', "AttributeError: 'ESRMeasure' object has no attribute 'plotlines'\n"]
2022-02-18T11:03:31|ERROR|ESRMeasure|ESR_measurement Failed to update figure1: 'ESRMeasure' object has no attribute 'plotlines'. ['Traceback (most recent call last):\n', '  File "C:\\Users\\ZHao\\.conda\\envs\\scopefoundry\\lib\\site-packages\\ScopeFoundry\\measurement.py", line 273, in _on_display_update_timer\n    self.update_display()\n', '  File "C:\\Users\\Public\\quantum_sensing\\quantum_sensing\\fancy_microscope\\custommeasure2.py", line 359, in update_display\n    self.plotlines[rate].setVisible(self.settings[\'{}_visible\'.format(rate)])\n', "AttributeError: 'ESRMeasure' object has no attribute 'plotlines'\n"]
2022-02-18T11:03:31|ERROR|ESRMeasure|ESR_measurement Failed to update figure1: 'ESRMeasure' object has no attribute 'plotlines'. ['Traceback (most recent call last):\n', '  File "C:\\Users\\ZHao\\.conda\\envs\\scopefoundry\\lib\\site-packages\\ScopeFoundry\\measurement.py", line 273, in _on_display_update_timer\n    self.update_display()\n', '  File "C:\\Users\\Public\\quantum_sensing\\quantum_sensing\\fancy_microscope\\custommeasure2.py", line 359, in update_display\n    self.plotlines[rate].setVisible(self.settings[\'{}_visible\'.format(rate)])\n', "AttributeError: 'ESRMeasure' object has no attribute 'plotlines'\n"]
2022-02-18T11:03:31|ERROR|ESRMeasure|ESR_measurement Failed to update figure1: 'ESRMeasure' object has no attribute 'plotlines'. ['Traceback (most recent call last):\n', '  File "C:\\Users\\ZHao\\.conda\\envs\\scopefoundry\\lib\\site-packages\\ScopeFoundry\\measurement.py", line 273, in _on_display_update_timer\n    self.update_display()\n', '  File "C:\\Users\\Public\\quantum_sensing\\quantum_sensing\\fancy_microscope\\custommeasure2.py", line 359, in update_display\n    self.plotlines[rate].setVisible(self.settings[\'{}_visible\'.format(rate)])\n', "AttributeError: 'ESRMeasure' object has no attribute 'plotlines'\n"]
2022-02-18T11:03:31|ERROR|ESRMeasure|ESR_measurement Failed to update figure1: 'ESRMeasure' object has no attribute 'plotlines'. ['Traceback (most recent call last):\n', '  File "C:\\Users\\ZHao\\.conda\\envs\\scopefoundry\\lib\\site-packages\\ScopeFoundry\\measurement.py", line 273, in _on_display_update_timer\n    self.update_display()\n', '  File "C:\\Users\\Public\\quantum_sensing\\quantum_sensing\\fancy_microscope\\custommeasure2.py", line 359, in update_display\n    self.plotlines[rate].setVisible(self.settings[\'{}_visible\'.format(rate)])\n', "AttributeError: 'ESRMeasure' object has no attribute 'plotlines'\n"]
2022-02-18T11:03:31|ERROR|ESRMeasure|ESR_measurement Failed to update figure1: 'ESRMeasure' object has no attribute 'plotlines'. ['Traceback (most recent call last):\n', '  File "C:\\Users\\ZHao\\.conda\\envs\\scopefoundry\\lib\\site-packages\\ScopeFoundry\\measurement.py", line 273, in _on_display_update_timer\n    self.update_display()\n', '  File "C:\\Users\\Public\\quantum_sensing\\quantum_sensing\\fancy_microscope\\custommeasure2.py", line 359, in update_display\n    self.plotlines[rate].setVisible(self.settings[\'{}_visible\'.format(rate)])\n', "AttributeError: 'ESRMeasure' object has no attribute 'plotlines'\n"]
2022-02-18T11:03:32|ERROR|ESRMeasure|ESR_measurement Failed to update figure1: 'ESRMeasure' object has no attribute 'plotlines'. ['Traceback (most recent call last):\n', '  File "C:\\Users\\ZHao\\.conda\\envs\\scopefoundry\\lib\\site-packages\\ScopeFoundry\\measurement.py", line 273, in _on_display_update_timer\n    self.update_display()\n', '  File "C:\\Users\\Public\\quantum_sensing\\quantum_sensing\\fancy_microscope\\custommeasure2.py", line 359, in update_display\n    self.plotlines[rate].setVisible(self.settings[\'{}_visible\'.format(rate)])\n', "AttributeError: 'ESRMeasure' object has no attribute 'plotlines'\n"]
2022-02-18T11:03:32|ERROR|ESRMeasure|ESR_measurement Failed to update figure1: 'ESRMeasure' object has no attribute 'plotlines'. ['Traceback (most recent call last):\n', '  File "C:\\Users\\ZHao\\.conda\\envs\\scopefoundry\\lib\\site-packages\\ScopeFoundry\\measurement.py", line 273, in _on_display_update_timer\n    self.update_display()\n', '  File "C:\\Users\\Public\\quantum_sensing\\quantum_sensing\\fancy_microscope\\custommeasure2.py", line 359, in update_display\n    self.plotlines[rate].setVisible(self.settings[\'{}_visible\'.format(rate)])\n', "AttributeError: 'ESRMeasure' object has no attribute 'plotlines'\n"]
2022-02-18T11:03:32|ERROR|ESRMeasure|ESR_measurement Failed to update figure1: 'ESRMeasure' object has no attribute 'plotlines'. ['Traceback (most recent call last):\n', '  File "C:\\Users\\ZHao\\.conda\\envs\\scopefoundry\\lib\\site-packages\\ScopeFoundry\\measurement.py", line 273, in _on_display_update_timer\n    self.update_display()\n', '  File "C:\\Users\\Public\\quantum_sensing\\quantum_sensing\\fancy_microscope\\custommeasure2.py", line 359, in update_display\n    self.plotlines[rate].setVisible(self.settings[\'{}_visible\'.format(rate)])\n', "AttributeError: 'ESRMeasure' object has no attribute 'plotlines'\n"]
2022-02-18T11:03:32|ERROR|ESRMeasure|ESR_measurement Failed to update figure1: 'ESRMeasure' object has no attribute 'plotlines'. ['Traceback (most recent call last):\n', '  File "C:\\Users\\ZHao\\.conda\\envs\\scopefoundry\\lib\\site-packages\\ScopeFoundry\\measurement.py", line 273, in _on_display_update_timer\n    self.update_display()\n', '  File "C:\\Users\\Public\\quantum_sensing\\quantum_sensing\\fancy_microscope\\custommeasure2.py", line 359, in update_display\n    self.plotlines[rate].setVisible(self.settings[\'{}_visible\'.format(rate)])\n', "AttributeError: 'ESRMeasure' object has no attribute 'plotlines'\n"]
2022-02-18T11:03:32|ERROR|ESRMeasure|ESR_measurement Failed to update figure1: 'ESRMeasure' object has no attribute 'plotlines'. ['Traceback (most recent call last):\n', '  File "C:\\Users\\ZHao\\.conda\\envs\\scopefoundry\\lib\\site-packages\\ScopeFoundry\\measurement.py", line 273, in _on_display_update_timer\n    self.update_display()\n', '  File "C:\\Users\\Public\\quantum_sensing\\quantum_sensing\\fancy_microscope\\custommeasure2.py", line 359, in update_display\n    self.plotlines[rate].setVisible(self.settings[\'{}_visible\'.format(rate)])\n', "AttributeError: 'ESRMeasure' object has no attribute 'plotlines'\n"]
2022-02-18T11:03:32|ERROR|ESRMeasure|ESR_measurement Failed to update figure1: 'ESRMeasure' object has no attribute 'plotlines'. ['Traceback (most recent call last):\n', '  File "C:\\Users\\ZHao\\.conda\\envs\\scopefoundry\\lib\\site-packages\\ScopeFoundry\\measurement.py", line 273, in _on_display_update_timer\n    self.update_display()\n', '  File "C:\\Users\\Public\\quantum_sensing\\quantum_sensing\\fancy_microscope\\custommeasure2.py", line 359, in update_display\n    self.plotlines[rate].setVisible(self.settings[\'{}_visible\'.format(rate)])\n', "AttributeError: 'ESRMeasure' object has no attribute 'plotlines'\n"]
2022-02-18T11:03:32|ERROR|ESRMeasure|ESR_measurement Failed to update figure1: 'ESRMeasure' object has no attribute 'plotlines'. ['Traceback (most recent call last):\n', '  File "C:\\Users\\ZHao\\.conda\\envs\\scopefoundry\\lib\\site-packages\\ScopeFoundry\\measurement.py", line 273, in _on_display_update_timer\n    self.update_display()\n', '  File "C:\\Users\\Public\\quantum_sensing\\quantum_sensing\\fancy_microscope\\custommeasure2.py", line 359, in update_display\n    self.plotlines[rate].setVisible(self.settings[\'{}_visible\'.format(rate)])\n', "AttributeError: 'ESRMeasure' object has no attribute 'plotlines'\n"]
2022-02-18T11:03:32|ERROR|ESRMeasure|ESR_measurement Failed to update figure1: 'ESRMeasure' object has no attribute 'plotlines'. ['Traceback (most recent call last):\n', '  File "C:\\Users\\ZHao\\.conda\\envs\\scopefoundry\\lib\\site-packages\\ScopeFoundry\\measurement.py", line 273, in _on_display_update_timer\n    self.update_display()\n', '  File "C:\\Users\\Public\\quantum_sensing\\quantum_sensing\\fancy_microscope\\custommeasure2.py", line 359, in update_display\n    self.plotlines[rate].setVisible(self.settings[\'{}_visible\'.format(rate)])\n', "AttributeError: 'ESRMeasure' object has no attribute 'plotlines'\n"]
2022-02-18T11:03:32|ERROR|ESRMeasure|ESR_measurement Failed to update figure1: 'ESRMeasure' object has no attribute 'plotlines'. ['Traceback (most recent call last):\n', '  File "C:\\Users\\ZHao\\.conda\\envs\\scopefoundry\\lib\\site-packages\\ScopeFoundry\\measurement.py", line 273, in _on_display_update_timer\n    self.update_display()\n', '  File "C:\\Users\\Public\\quantum_sensing\\quantum_sensing\\fancy_microscope\\custommeasure2.py", line 359, in update_display\n    self.plotlines[rate].setVisible(self.settings[\'{}_visible\'.format(rate)])\n', "AttributeError: 'ESRMeasure' object has no attribute 'plotlines'\n"]
2022-02-18T11:03:33|ERROR|ESRMeasure|ESR_measurement Failed to update figure1: 'ESRMeasure' object has no attribute 'plotlines'. ['Traceback (most recent call last):\n', '  File "C:\\Users\\ZHao\\.conda\\envs\\scopefoundry\\lib\\site-packages\\ScopeFoundry\\measurement.py", line 273, in _on_display_update_timer\n    self.update_display()\n', '  File "C:\\Users\\Public\\quantum_sensing\\quantum_sensing\\fancy_microscope\\custommeasure2.py", line 359, in update_display\n    self.plotlines[rate].setVisible(self.settings[\'{}_visible\'.format(rate)])\n', "AttributeError: 'ESRMeasure' object has no attribute 'plotlines'\n"]
2022-02-18T11:03:33|ERROR|ESRMeasure|ESR_measurement Failed to update figure1: 'ESRMeasure' object has no attribute 'plotlines'. ['Traceback (most recent call last):\n', '  File "C:\\Users\\ZHao\\.conda\\envs\\scopefoundry\\lib\\site-packages\\ScopeFoundry\\measurement.py", line 273, in _on_display_update_timer\n    self.update_display()\n', '  File "C:\\Users\\Public\\quantum_sensing\\quantum_sensing\\fancy_microscope\\custommeasure2.py", line 359, in update_display\n    self.plotlines[rate].setVisible(self.settings[\'{}_visible\'.format(rate)])\n', "AttributeError: 'ESRMeasure' object has no attribute 'plotlines'\n"]
2022-02-18T11:03:33|ERROR|ESRMeasure|ESR_measurement Failed to update figure1: 'ESRMeasure' object has no attribute 'plotlines'. ['Traceback (most recent call last):\n', '  File "C:\\Users\\ZHao\\.conda\\envs\\scopefoundry\\lib\\site-packages\\ScopeFoundry\\measurement.py", line 273, in _on_display_update_timer\n    self.update_display()\n', '  File "C:\\Users\\Public\\quantum_sensing\\quantum_sensing\\fancy_microscope\\custommeasure2.py", line 359, in update_display\n    self.plotlines[rate].setVisible(self.settings[\'{}_visible\'.format(rate)])\n', "AttributeError: 'ESRMeasure' object has no attribute 'plotlines'\n"]
2022-02-18T11:03:33|ERROR|ESRMeasure|ESR_measurement Failed to update figure1: 'ESRMeasure' object has no attribute 'plotlines'. ['Traceback (most recent call last):\n', '  File "C:\\Users\\ZHao\\.conda\\envs\\scopefoundry\\lib\\site-packages\\ScopeFoundry\\measurement.py", line 273, in _on_display_update_timer\n    self.update_display()\n', '  File "C:\\Users\\Public\\quantum_sensing\\quantum_sensing\\fancy_microscope\\custommeasure2.py", line 359, in update_display\n    self.plotlines[rate].setVisible(self.settings[\'{}_visible\'.format(rate)])\n', "AttributeError: 'ESRMeasure' object has no attribute 'plotlines'\n"]
2022-02-18T11:03:33|ERROR|ESRMeasure|ESR_measurement Failed to update figure1: 'ESRMeasure' object has no attribute 'plotlines'. ['Traceback (most recent call last):\n', '  File "C:\\Users\\ZHao\\.conda\\envs\\scopefoundry\\lib\\site-packages\\ScopeFoundry\\measurement.py", line 273, in _on_display_update_timer\n    self.update_display()\n', '  File "C:\\Users\\Public\\quantum_sensing\\quantum_sensing\\fancy_microscope\\custommeasure2.py", line 359, in update_display\n    self.plotlines[rate].setVisible(self.settings[\'{}_visible\'.format(rate)])\n', "AttributeError: 'ESRMeasure' object has no attribute 'plotlines'\n"]
2022-02-18T11:03:33|ERROR|ESRMeasure|ESR_measurement Failed to update figure1: 'ESRMeasure' object has no attribute 'plotlines'. ['Traceback (most recent call last):\n', '  File "C:\\Users\\ZHao\\.conda\\envs\\scopefoundry\\lib\\site-packages\\ScopeFoundry\\measurement.py", line 273, in _on_display_update_timer\n    self.update_display()\n', '  File "C:\\Users\\Public\\quantum_sensing\\quantum_sensing\\fancy_microscope\\custommeasure2.py", line 359, in update_display\n    self.plotlines[rate].setVisible(self.settings[\'{}_visible\'.format(rate)])\n', "AttributeError: 'ESRMeasure' object has no attribute 'plotlines'\n"]
2022-02-18T11:03:33|ERROR|ESRMeasure|ESR_measurement Failed to update figure1: 'ESRMeasure' object has no attribute 'plotlines'. ['Traceback (most recent call last):\n', '  File "C:\\Users\\ZHao\\.conda\\envs\\scopefoundry\\lib\\site-packages\\ScopeFoundry\\measurement.py", line 273, in _on_display_update_timer\n    self.update_display()\n', '  File "C:\\Users\\Public\\quantum_sensing\\quantum_sensing\\fancy_microscope\\custommeasure2.py", line 359, in update_display\n    self.plotlines[rate].setVisible(self.settings[\'{}_visible\'.format(rate)])\n', "AttributeError: 'ESRMeasure' object has no attribute 'plotlines'\n"]
2022-02-18T11:03:35|ERROR|ESRMeasure|ESR_measurement Failed to update figure1: 'ESRMeasure' object has no attribute 'plotlines'. ['Traceback (most recent call last):\n', '  File "C:\\Users\\ZHao\\.conda\\envs\\scopefoundry\\lib\\site-packages\\ScopeFoundry\\measurement.py", line 273, in _on_display_update_timer\n    self.update_display()\n', '  File "C:\\Users\\Public\\quantum_sensing\\quantum_sensing\\fancy_microscope\\custommeasure2.py", line 359, in update_display\n    self.plotlines[rate].setVisible(self.settings[\'{}_visible\'.format(rate)])\n', "AttributeError: 'ESRMeasure' object has no attribute 'plotlines'\n"]
2022-02-18T11:03:35|ERROR|ESRMeasure|ESR_measurement Failed to update figure1: 'ESRMeasure' object has no attribute 'plotlines'. ['Traceback (most recent call last):\n', '  File "C:\\Users\\ZHao\\.conda\\envs\\scopefoundry\\lib\\site-packages\\ScopeFoundry\\measurement.py", line 273, in _on_display_update_timer\n    self.update_display()\n', '  File "C:\\Users\\Public\\quantum_sensing\\quantum_sensing\\fancy_microscope\\custommeasure2.py", line 359, in update_display\n    self.plotlines[rate].setVisible(self.settings[\'{}_visible\'.format(rate)])\n', "AttributeError: 'ESRMeasure' object has no attribute 'plotlines'\n"]
2022-02-18T11:03:35|CRITICAL|root|Unhandled exception:Traceback (most recent call last):
  File "C:\Users\ZHao\.conda\envs\scopefoundry\lib\site-packages\ScopeFoundry\measurement.py", line 272, in _on_display_update_timer
    try:
KeyboardInterrupt

2022-02-18T11:03:35|ERROR|ESRMeasure|ESR_measurement Failed to update figure1: 'ESRMeasure' object has no attribute 'plotlines'. ['Traceback (most recent call last):\n', '  File "C:\\Users\\ZHao\\.conda\\envs\\scopefoundry\\lib\\site-packages\\ScopeFoundry\\measurement.py", line 273, in _on_display_update_timer\n    self.update_display()\n', '  File "C:\\Users\\Public\\quantum_sensing\\quantum_sensing\\fancy_microscope\\custommeasure2.py", line 359, in update_display\n    self.plotlines[rate].setVisible(self.settings[\'{}_visible\'.format(rate)])\n', "AttributeError: 'ESRMeasure' object has no attribute 'plotlines'\n"]
2022-02-18T11:03:35|ERROR|ESRMeasure|ESR_measurement Failed to update figure1: 'ESRMeasure' object has no attribute 'plotlines'. ['Traceback (most recent call last):\n', '  File "C:\\Users\\ZHao\\.conda\\envs\\scopefoundry\\lib\\site-packages\\ScopeFoundry\\measurement.py", line 273, in _on_display_update_timer\n    self.update_display()\n', '  File "C:\\Users\\Public\\quantum_sensing\\quantum_sensing\\fancy_microscope\\custommeasure2.py", line 359, in update_display\n    self.plotlines[rate].setVisible(self.settings[\'{}_visible\'.format(rate)])\n', "AttributeError: 'ESRMeasure' object has no attribute 'plotlines'\n"]
2022-02-18T11:03:36|ERROR|ESRMeasure|ESR_measurement Failed to update figure1: 'ESRMeasure' object has no attribute 'plotlines'. ['Traceback (most recent call last):\n', '  File "C:\\Users\\ZHao\\.conda\\envs\\scopefoundry\\lib\\site-packages\\ScopeFoundry\\measurement.py", line 273, in _on_display_update_timer\n    self.update_display()\n', '  File "C:\\Users\\Public\\quantum_sensing\\quantum_sensing\\fancy_microscope\\custommeasure2.py", line 359, in update_display\n    self.plotlines[rate].setVisible(self.settings[\'{}_visible\'.format(rate)])\n', "AttributeError: 'ESRMeasure' object has no attribute 'plotlines'\n"]
2022-02-18T11:03:36|CRITICAL|root|Unhandled exception:Traceback (most recent call last):
  File "C:\Users\ZHao\.conda\envs\scopefoundry\lib\site-packages\ScopeFoundry\measurement.py", line 272, in _on_display_update_timer
    try:
KeyboardInterrupt

2022-02-18T11:03:36|ERROR|ESRMeasure|ESR_measurement Failed to update figure1: 'ESRMeasure' object has no attribute 'plotlines'. ['Traceback (most recent call last):\n', '  File "C:\\Users\\ZHao\\.conda\\envs\\scopefoundry\\lib\\site-packages\\ScopeFoundry\\measurement.py", line 273, in _on_display_update_timer\n    self.update_display()\n', '  File "C:\\Users\\Public\\quantum_sensing\\quantum_sensing\\fancy_microscope\\custommeasure2.py", line 359, in update_display\n    self.plotlines[rate].setVisible(self.settings[\'{}_visible\'.format(rate)])\n', "AttributeError: 'ESRMeasure' object has no attribute 'plotlines'\n"]
2022-02-18T11:03:36|ERROR|ESRMeasure|ESR_measurement Failed to update figure1: 'ESRMeasure' object has no attribute 'plotlines'. ['Traceback (most recent call last):\n', '  File "C:\\Users\\ZHao\\.conda\\envs\\scopefoundry\\lib\\site-packages\\ScopeFoundry\\measurement.py", line 273, in _on_display_update_timer\n    self.update_display()\n', '  File "C:\\Users\\Public\\quantum_sensing\\quantum_sensing\\fancy_microscope\\custommeasure2.py", line 359, in update_display\n    self.plotlines[rate].setVisible(self.settings[\'{}_visible\'.format(rate)])\n', "AttributeError: 'ESRMeasure' object has no attribute 'plotlines'\n"]
2022-02-18T11:03:36|ERROR|ESRMeasure|ESR_measurement Failed to update figure1: 'ESRMeasure' object has no attribute 'plotlines'. ['Traceback (most recent call last):\n', '  File "C:\\Users\\ZHao\\.conda\\envs\\scopefoundry\\lib\\site-packages\\ScopeFoundry\\measurement.py", line 273, in _on_display_update_timer\n    self.update_display()\n', '  File "C:\\Users\\Public\\quantum_sensing\\quantum_sensing\\fancy_microscope\\custommeasure2.py", line 359, in update_display\n    self.plotlines[rate].setVisible(self.settings[\'{}_visible\'.format(rate)])\n', "AttributeError: 'ESRMeasure' object has no attribute 'plotlines'\n"]
2022-02-18T11:03:36|CRITICAL|root|Unhandled exception:Traceback (most recent call last):
  File "C:\Users\ZHao\.conda\envs\scopefoundry\lib\site-packages\ScopeFoundry\measurement.py", line 272, in _on_display_update_timer
    try:
KeyboardInterrupt

2022-02-18T11:03:36|ERROR|ESRMeasure|ESR_measurement Failed to update figure1: 'ESRMeasure' object has no attribute 'plotlines'. ['Traceback (most recent call last):\n', '  File "C:\\Users\\ZHao\\.conda\\envs\\scopefoundry\\lib\\site-packages\\ScopeFoundry\\measurement.py", line 273, in _on_display_update_timer\n    self.update_display()\n', '  File "C:\\Users\\Public\\quantum_sensing\\quantum_sensing\\fancy_microscope\\custommeasure2.py", line 359, in update_display\n    self.plotlines[rate].setVisible(self.settings[\'{}_visible\'.format(rate)])\n', "AttributeError: 'ESRMeasure' object has no attribute 'plotlines'\n"]
2022-02-18T11:03:36|CRITICAL|root|Unhandled exception:Traceback (most recent call last):
  File "C:\Users\ZHao\.conda\envs\scopefoundry\lib\site-packages\ScopeFoundry\measurement.py", line 272, in _on_display_update_timer
    try:
KeyboardInterrupt

2022-02-18T11:03:36|ERROR|ESRMeasure|ESR_measurement Failed to update figure1: 'ESRMeasure' object has no attribute 'plotlines'. ['Traceback (most recent call last):\n', '  File "C:\\Users\\ZHao\\.conda\\envs\\scopefoundry\\lib\\site-packages\\ScopeFoundry\\measurement.py", line 273, in _on_display_update_timer\n    self.update_display()\n', '  File "C:\\Users\\Public\\quantum_sensing\\quantum_sensing\\fancy_microscope\\custommeasure2.py", line 359, in update_display\n    self.plotlines[rate].setVisible(self.settings[\'{}_visible\'.format(rate)])\n', "AttributeError: 'ESRMeasure' object has no attribute 'plotlines'\n"]
2022-02-18T11:03:37|CRITICAL|root|Unhandled exception:Traceback (most recent call last):
  File "C:\Users\ZHao\.conda\envs\scopefoundry\lib\site-packages\ScopeFoundry\measurement.py", line 272, in _on_display_update_timer
    try:
KeyboardInterrupt

2022-02-18T11:03:37|ERROR|ESRMeasure|ESR_measurement Failed to update figure1: 'ESRMeasure' object has no attribute 'plotlines'. ['Traceback (most recent call last):\n', '  File "C:\\Users\\ZHao\\.conda\\envs\\scopefoundry\\lib\\site-packages\\ScopeFoundry\\measurement.py", line 273, in _on_display_update_timer\n    self.update_display()\n', '  File "C:\\Users\\Public\\quantum_sensing\\quantum_sensing\\fancy_microscope\\custommeasure2.py", line 359, in update_display\n    self.plotlines[rate].setVisible(self.settings[\'{}_visible\'.format(rate)])\n', "AttributeError: 'ESRMeasure' object has no attribute 'plotlines'\n"]
2022-02-18T11:03:37|CRITICAL|root|Unhandled exception:Traceback (most recent call last):
  File "C:\Users\ZHao\.conda\envs\scopefoundry\lib\site-packages\ScopeFoundry\measurement.py", line 272, in _on_display_update_timer
    try:
KeyboardInterrupt

2022-02-18T11:03:37|CRITICAL|root|Unhandled exception:Traceback (most recent call last):
  File "C:\Users\ZHao\.conda\envs\scopefoundry\lib\site-packages\ScopeFoundry\measurement.py", line 272, in _on_display_update_timer
    try:
KeyboardInterrupt

2022-02-18T11:03:37|ERROR|ESRMeasure|ESR_measurement Failed to update figure1: 'ESRMeasure' object has no attribute 'plotlines'. ['Traceback (most recent call last):\n', '  File "C:\\Users\\ZHao\\.conda\\envs\\scopefoundry\\lib\\site-packages\\ScopeFoundry\\measurement.py", line 273, in _on_display_update_timer\n    self.update_display()\n', '  File "C:\\Users\\Public\\quantum_sensing\\quantum_sensing\\fancy_microscope\\custommeasure2.py", line 359, in update_display\n    self.plotlines[rate].setVisible(self.settings[\'{}_visible\'.format(rate)])\n', "AttributeError: 'ESRMeasure' object has no attribute 'plotlines'\n"]
2022-02-18T11:03:37|ERROR|ESRMeasure|ESR_measurement Failed to update figure1: 'ESRMeasure' object has no attribute 'plotlines'. ['Traceback (most recent call last):\n', '  File "C:\\Users\\ZHao\\.conda\\envs\\scopefoundry\\lib\\site-packages\\ScopeFoundry\\measurement.py", line 273, in _on_display_update_timer\n    self.update_display()\n', '  File "C:\\Users\\Public\\quantum_sensing\\quantum_sensing\\fancy_microscope\\custommeasure2.py", line 359, in update_display\n    self.plotlines[rate].setVisible(self.settings[\'{}_visible\'.format(rate)])\n', "AttributeError: 'ESRMeasure' object has no attribute 'plotlines'\n"]
2022-02-18T11:03:37|ERROR|ESRMeasure|ESR_measurement Failed to update figure1: 'ESRMeasure' object has no attribute 'plotlines'. ['Traceback (most recent call last):\n', '  File "C:\\Users\\ZHao\\.conda\\envs\\scopefoundry\\lib\\site-packages\\ScopeFoundry\\measurement.py", line 273, in _on_display_update_timer\n    self.update_display()\n', '  File "C:\\Users\\Public\\quantum_sensing\\quantum_sensing\\fancy_microscope\\custommeasure2.py", line 359, in update_display\n    self.plotlines[rate].setVisible(self.settings[\'{}_visible\'.format(rate)])\n', "AttributeError: 'ESRMeasure' object has no attribute 'plotlines'\n"]
2022-02-18T11:03:37|ERROR|ESRMeasure|ESR_measurement Failed to update figure1: 'ESRMeasure' object has no attribute 'plotlines'. ['Traceback (most recent call last):\n', '  File "C:\\Users\\ZHao\\.conda\\envs\\scopefoundry\\lib\\site-packages\\ScopeFoundry\\measurement.py", line 273, in _on_display_update_timer\n    self.update_display()\n', '  File "C:\\Users\\Public\\quantum_sensing\\quantum_sensing\\fancy_microscope\\custommeasure2.py", line 359, in update_display\n    self.plotlines[rate].setVisible(self.settings[\'{}_visible\'.format(rate)])\n', "AttributeError: 'ESRMeasure' object has no attribute 'plotlines'\n"]
2022-02-18T11:03:37|ERROR|ESRMeasure|ESR_measurement Failed to update figure1: 'ESRMeasure' object has no attribute 'plotlines'. ['Traceback (most recent call last):\n', '  File "C:\\Users\\ZHao\\.conda\\envs\\scopefoundry\\lib\\site-packages\\ScopeFoundry\\measurement.py", line 273, in _on_display_update_timer\n    self.update_display()\n', '  File "C:\\Users\\Public\\quantum_sensing\\quantum_sensing\\fancy_microscope\\custommeasure2.py", line 359, in update_display\n    self.plotlines[rate].setVisible(self.settings[\'{}_visible\'.format(rate)])\n', "AttributeError: 'ESRMeasure' object has no attribute 'plotlines'\n"]
2022-02-18T11:03:38|ERROR|ESRMeasure|ESR_measurement Failed to update figure1: 'ESRMeasure' object has no attribute 'plotlines'. ['Traceback (most recent call last):\n', '  File "C:\\Users\\ZHao\\.conda\\envs\\scopefoundry\\lib\\site-packages\\ScopeFoundry\\measurement.py", line 273, in _on_display_update_timer\n    self.update_display()\n', '  File "C:\\Users\\Public\\quantum_sensing\\quantum_sensing\\fancy_microscope\\custommeasure2.py", line 359, in update_display\n    self.plotlines[rate].setVisible(self.settings[\'{}_visible\'.format(rate)])\n', "AttributeError: 'ESRMeasure' object has no attribute 'plotlines'\n"]
2022-02-18T11:03:38|CRITICAL|root|Unhandled exception:Traceback (most recent call last):
  File "C:\Users\ZHao\.conda\envs\scopefoundry\lib\site-packages\ScopeFoundry\measurement.py", line 272, in _on_display_update_timer
    try:
KeyboardInterrupt

2022-02-18T11:03:38|ERROR|ESRMeasure|ESR_measurement Failed to update figure1: 'ESRMeasure' object has no attribute 'plotlines'. ['Traceback (most recent call last):\n', '  File "C:\\Users\\ZHao\\.conda\\envs\\scopefoundry\\lib\\site-packages\\ScopeFoundry\\measurement.py", line 273, in _on_display_update_timer\n    self.update_display()\n', '  File "C:\\Users\\Public\\quantum_sensing\\quantum_sensing\\fancy_microscope\\custommeasure2.py", line 359, in update_display\n    self.plotlines[rate].setVisible(self.settings[\'{}_visible\'.format(rate)])\n', "AttributeError: 'ESRMeasure' object has no attribute 'plotlines'\n"]
2022-02-18T11:03:38|CRITICAL|root|Unhandled exception:Traceback (most recent call last):
  File "C:\Users\ZHao\.conda\envs\scopefoundry\lib\site-packages\ScopeFoundry\measurement.py", line 272, in _on_display_update_timer
    try:
KeyboardInterrupt

2022-02-18T11:03:38|ERROR|ESRMeasure|ESR_measurement Failed to update figure1: 'ESRMeasure' object has no attribute 'plotlines'. ['Traceback (most recent call last):\n', '  File "C:\\Users\\ZHao\\.conda\\envs\\scopefoundry\\lib\\site-packages\\ScopeFoundry\\measurement.py", line 273, in _on_display_update_timer\n    self.update_display()\n', '  File "C:\\Users\\Public\\quantum_sensing\\quantum_sensing\\fancy_microscope\\custommeasure2.py", line 359, in update_display\n    self.plotlines[rate].setVisible(self.settings[\'{}_visible\'.format(rate)])\n', "AttributeError: 'ESRMeasure' object has no attribute 'plotlines'\n"]
2022-02-18T11:03:38|CRITICAL|root|Unhandled exception:Traceback (most recent call last):
  File "C:\Users\ZHao\.conda\envs\scopefoundry\lib\site-packages\ScopeFoundry\measurement.py", line 272, in _on_display_update_timer
    try:
KeyboardInterrupt

2022-02-18T11:03:38|CRITICAL|root|Unhandled exception:Traceback (most recent call last):
  File "C:\Users\ZHao\.conda\envs\scopefoundry\lib\site-packages\ScopeFoundry\measurement.py", line 272, in _on_display_update_timer
    try:
KeyboardInterrupt

2022-02-18T11:03:38|ERROR|ESRMeasure|ESR_measurement Failed to update figure1: 'ESRMeasure' object has no attribute 'plotlines'. ['Traceback (most recent call last):\n', '  File "C:\\Users\\ZHao\\.conda\\envs\\scopefoundry\\lib\\site-packages\\ScopeFoundry\\measurement.py", line 273, in _on_display_update_timer\n    self.update_display()\n', '  File "C:\\Users\\Public\\quantum_sensing\\quantum_sensing\\fancy_microscope\\custommeasure2.py", line 359, in update_display\n    self.plotlines[rate].setVisible(self.settings[\'{}_visible\'.format(rate)])\n', "AttributeError: 'ESRMeasure' object has no attribute 'plotlines'\n"]
2022-02-18T11:03:38|ERROR|ESRMeasure|ESR_measurement Failed to update figure1: 'ESRMeasure' object has no attribute 'plotlines'. ['Traceback (most recent call last):\n', '  File "C:\\Users\\ZHao\\.conda\\envs\\scopefoundry\\lib\\site-packages\\ScopeFoundry\\measurement.py", line 273, in _on_display_update_timer\n    self.update_display()\n', '  File "C:\\Users\\Public\\quantum_sensing\\quantum_sensing\\fancy_microscope\\custommeasure2.py", line 359, in update_display\n    self.plotlines[rate].setVisible(self.settings[\'{}_visible\'.format(rate)])\n', "AttributeError: 'ESRMeasure' object has no attribute 'plotlines'\n"]
2022-02-18T11:03:39|CRITICAL|root|Unhandled exception:Traceback (most recent call last):
  File "C:\Users\ZHao\.conda\envs\scopefoundry\lib\site-packages\ScopeFoundry\measurement.py", line 272, in _on_display_update_timer
    try:
KeyboardInterrupt

2022-02-18T11:03:39|ERROR|ESRMeasure|ESR_measurement Failed to update figure1: 'ESRMeasure' object has no attribute 'plotlines'. ['Traceback (most recent call last):\n', '  File "C:\\Users\\ZHao\\.conda\\envs\\scopefoundry\\lib\\site-packages\\ScopeFoundry\\measurement.py", line 273, in _on_display_update_timer\n    self.update_display()\n', '  File "C:\\Users\\Public\\quantum_sensing\\quantum_sensing\\fancy_microscope\\custommeasure2.py", line 359, in update_display\n    self.plotlines[rate].setVisible(self.settings[\'{}_visible\'.format(rate)])\n', "AttributeError: 'ESRMeasure' object has no attribute 'plotlines'\n"]
2022-02-18T11:03:39|CRITICAL|root|Unhandled exception:Traceback (most recent call last):
  File "C:\Users\ZHao\.conda\envs\scopefoundry\lib\site-packages\ScopeFoundry\measurement.py", line 272, in _on_display_update_timer
    try:
KeyboardInterrupt

2022-02-18T11:03:39|ERROR|ESRMeasure|ESR_measurement Failed to update figure1: 'ESRMeasure' object has no attribute 'plotlines'. ['Traceback (most recent call last):\n', '  File "C:\\Users\\ZHao\\.conda\\envs\\scopefoundry\\lib\\site-packages\\ScopeFoundry\\measurement.py", line 273, in _on_display_update_timer\n    self.update_display()\n', '  File "C:\\Users\\Public\\quantum_sensing\\quantum_sensing\\fancy_microscope\\custommeasure2.py", line 359, in update_display\n    self.plotlines[rate].setVisible(self.settings[\'{}_visible\'.format(rate)])\n', "AttributeError: 'ESRMeasure' object has no attribute 'plotlines'\n"]
2022-02-18T11:03:39|ERROR|ESRMeasure|ESR_measurement Failed to update figure1: 'ESRMeasure' object has no attribute 'plotlines'. ['Traceback (most recent call last):\n', '  File "C:\\Users\\ZHao\\.conda\\envs\\scopefoundry\\lib\\site-packages\\ScopeFoundry\\measurement.py", line 273, in _on_display_update_timer\n    self.update_display()\n', '  File "C:\\Users\\Public\\quantum_sensing\\quantum_sensing\\fancy_microscope\\custommeasure2.py", line 359, in update_display\n    self.plotlines[rate].setVisible(self.settings[\'{}_visible\'.format(rate)])\n', "AttributeError: 'ESRMeasure' object has no attribute 'plotlines'\n"]
2022-02-18T11:03:39|ERROR|ESRMeasure|ESR_measurement Failed to update figure1: 'ESRMeasure' object has no attribute 'plotlines'. ['Traceback (most recent call last):\n', '  File "C:\\Users\\ZHao\\.conda\\envs\\scopefoundry\\lib\\site-packages\\ScopeFoundry\\measurement.py", line 273, in _on_display_update_timer\n    self.update_display()\n', '  File "C:\\Users\\Public\\quantum_sensing\\quantum_sensing\\fancy_microscope\\custommeasure2.py", line 359, in update_display\n    self.plotlines[rate].setVisible(self.settings[\'{}_visible\'.format(rate)])\n', "AttributeError: 'ESRMeasure' object has no attribute 'plotlines'\n"]
2022-02-18T11:03:39|ERROR|ESRMeasure|ESR_measurement Failed to update figure1: 'ESRMeasure' object has no attribute 'plotlines'. ['Traceback (most recent call last):\n', '  File "C:\\Users\\ZHao\\.conda\\envs\\scopefoundry\\lib\\site-packages\\ScopeFoundry\\measurement.py", line 273, in _on_display_update_timer\n    self.update_display()\n', '  File "C:\\Users\\Public\\quantum_sensing\\quantum_sensing\\fancy_microscope\\custommeasure2.py", line 359, in update_display\n    self.plotlines[rate].setVisible(self.settings[\'{}_visible\'.format(rate)])\n', "AttributeError: 'ESRMeasure' object has no attribute 'plotlines'\n"]
2022-02-18T11:03:39|ERROR|ESRMeasure|ESR_measurement Failed to update figure1: 'ESRMeasure' object has no attribute 'plotlines'. ['Traceback (most recent call last):\n', '  File "C:\\Users\\ZHao\\.conda\\envs\\scopefoundry\\lib\\site-packages\\ScopeFoundry\\measurement.py", line 273, in _on_display_update_timer\n    self.update_display()\n', '  File "C:\\Users\\Public\\quantum_sensing\\quantum_sensing\\fancy_microscope\\custommeasure2.py", line 359, in update_display\n    self.plotlines[rate].setVisible(self.settings[\'{}_visible\'.format(rate)])\n', "AttributeError: 'ESRMeasure' object has no attribute 'plotlines'\n"]
2022-02-18T11:03:39|ERROR|ESRMeasure|ESR_measurement Failed to update figure1: 'ESRMeasure' object has no attribute 'plotlines'. ['Traceback (most recent call last):\n', '  File "C:\\Users\\ZHao\\.conda\\envs\\scopefoundry\\lib\\site-packages\\ScopeFoundry\\measurement.py", line 273, in _on_display_update_timer\n    self.update_display()\n', '  File "C:\\Users\\Public\\quantum_sensing\\quantum_sensing\\fancy_microscope\\custommeasure2.py", line 359, in update_display\n    self.plotlines[rate].setVisible(self.settings[\'{}_visible\'.format(rate)])\n', "AttributeError: 'ESRMeasure' object has no attribute 'plotlines'\n"]
2022-02-18T11:03:40|ERROR|ESRMeasure|ESR_measurement Failed to update figure1: 'ESRMeasure' object has no attribute 'plotlines'. ['Traceback (most recent call last):\n', '  File "C:\\Users\\ZHao\\.conda\\envs\\scopefoundry\\lib\\site-packages\\ScopeFoundry\\measurement.py", line 273, in _on_display_update_timer\n    self.update_display()\n', '  File "C:\\Users\\Public\\quantum_sensing\\quantum_sensing\\fancy_microscope\\custommeasure2.py", line 359, in update_display\n    self.plotlines[rate].setVisible(self.settings[\'{}_visible\'.format(rate)])\n', "AttributeError: 'ESRMeasure' object has no attribute 'plotlines'\n"]
2022-02-18T11:03:40|ERROR|ESRMeasure|ESR_measurement Failed to update figure1: 'ESRMeasure' object has no attribute 'plotlines'. ['Traceback (most recent call last):\n', '  File "C:\\Users\\ZHao\\.conda\\envs\\scopefoundry\\lib\\site-packages\\ScopeFoundry\\measurement.py", line 273, in _on_display_update_timer\n    self.update_display()\n', '  File "C:\\Users\\Public\\quantum_sensing\\quantum_sensing\\fancy_microscope\\custommeasure2.py", line 359, in update_display\n    self.plotlines[rate].setVisible(self.settings[\'{}_visible\'.format(rate)])\n', "AttributeError: 'ESRMeasure' object has no attribute 'plotlines'\n"]
2022-02-18T11:03:40|ERROR|ESRMeasure|ESR_measurement Failed to update figure1: 'ESRMeasure' object has no attribute 'plotlines'. ['Traceback (most recent call last):\n', '  File "C:\\Users\\ZHao\\.conda\\envs\\scopefoundry\\lib\\site-packages\\ScopeFoundry\\measurement.py", line 273, in _on_display_update_timer\n    self.update_display()\n', '  File "C:\\Users\\Public\\quantum_sensing\\quantum_sensing\\fancy_microscope\\custommeasure2.py", line 359, in update_display\n    self.plotlines[rate].setVisible(self.settings[\'{}_visible\'.format(rate)])\n', "AttributeError: 'ESRMeasure' object has no attribute 'plotlines'\n"]
2022-02-18T11:03:40|ERROR|ESRMeasure|ESR_measurement Failed to update figure1: 'ESRMeasure' object has no attribute 'plotlines'. ['Traceback (most recent call last):\n', '  File "C:\\Users\\ZHao\\.conda\\envs\\scopefoundry\\lib\\site-packages\\ScopeFoundry\\measurement.py", line 273, in _on_display_update_timer\n    self.update_display()\n', '  File "C:\\Users\\Public\\quantum_sensing\\quantum_sensing\\fancy_microscope\\custommeasure2.py", line 359, in update_display\n    self.plotlines[rate].setVisible(self.settings[\'{}_visible\'.format(rate)])\n', "AttributeError: 'ESRMeasure' object has no attribute 'plotlines'\n"]
2022-02-18T11:03:40|ERROR|ESRMeasure|ESR_measurement Failed to update figure1: 'ESRMeasure' object has no attribute 'plotlines'. ['Traceback (most recent call last):\n', '  File "C:\\Users\\ZHao\\.conda\\envs\\scopefoundry\\lib\\site-packages\\ScopeFoundry\\measurement.py", line 273, in _on_display_update_timer\n    self.update_display()\n', '  File "C:\\Users\\Public\\quantum_sensing\\quantum_sensing\\fancy_microscope\\custommeasure2.py", line 359, in update_display\n    self.plotlines[rate].setVisible(self.settings[\'{}_visible\'.format(rate)])\n', "AttributeError: 'ESRMeasure' object has no attribute 'plotlines'\n"]
2022-02-18T11:03:40|ERROR|ESRMeasure|ESR_measurement Failed to update figure1: 'ESRMeasure' object has no attribute 'plotlines'. ['Traceback (most recent call last):\n', '  File "C:\\Users\\ZHao\\.conda\\envs\\scopefoundry\\lib\\site-packages\\ScopeFoundry\\measurement.py", line 273, in _on_display_update_timer\n    self.update_display()\n', '  File "C:\\Users\\Public\\quantum_sensing\\quantum_sensing\\fancy_microscope\\custommeasure2.py", line 359, in update_display\n    self.plotlines[rate].setVisible(self.settings[\'{}_visible\'.format(rate)])\n', "AttributeError: 'ESRMeasure' object has no attribute 'plotlines'\n"]
2022-02-18T11:03:40|ERROR|ESRMeasure|ESR_measurement Failed to update figure1: 'ESRMeasure' object has no attribute 'plotlines'. ['Traceback (most recent call last):\n', '  File "C:\\Users\\ZHao\\.conda\\envs\\scopefoundry\\lib\\site-packages\\ScopeFoundry\\measurement.py", line 273, in _on_display_update_timer\n    self.update_display()\n', '  File "C:\\Users\\Public\\quantum_sensing\\quantum_sensing\\fancy_microscope\\custommeasure2.py", line 359, in update_display\n    self.plotlines[rate].setVisible(self.settings[\'{}_visible\'.format(rate)])\n', "AttributeError: 'ESRMeasure' object has no attribute 'plotlines'\n"]
2022-02-18T11:03:40|ERROR|ESRMeasure|ESR_measurement Failed to update figure1: 'ESRMeasure' object has no attribute 'plotlines'. ['Traceback (most recent call last):\n', '  File "C:\\Users\\ZHao\\.conda\\envs\\scopefoundry\\lib\\site-packages\\ScopeFoundry\\measurement.py", line 273, in _on_display_update_timer\n    self.update_display()\n', '  File "C:\\Users\\Public\\quantum_sensing\\quantum_sensing\\fancy_microscope\\custommeasure2.py", line 359, in update_display\n    self.plotlines[rate].setVisible(self.settings[\'{}_visible\'.format(rate)])\n', "AttributeError: 'ESRMeasure' object has no attribute 'plotlines'\n"]
2022-02-18T11:03:40|CRITICAL|root|Unhandled exception:Traceback (most recent call last):
  File "C:\Users\ZHao\.conda\envs\scopefoundry\lib\site-packages\ScopeFoundry\measurement.py", line 272, in _on_display_update_timer
    try:
KeyboardInterrupt

2022-02-18T11:03:41|ERROR|ESRMeasure|ESR_measurement Failed to update figure1: 'ESRMeasure' object has no attribute 'plotlines'. ['Traceback (most recent call last):\n', '  File "C:\\Users\\ZHao\\.conda\\envs\\scopefoundry\\lib\\site-packages\\ScopeFoundry\\measurement.py", line 273, in _on_display_update_timer\n    self.update_display()\n', '  File "C:\\Users\\Public\\quantum_sensing\\quantum_sensing\\fancy_microscope\\custommeasure2.py", line 359, in update_display\n    self.plotlines[rate].setVisible(self.settings[\'{}_visible\'.format(rate)])\n', "AttributeError: 'ESRMeasure' object has no attribute 'plotlines'\n"]
2022-02-18T11:03:41|ERROR|ESRMeasure|ESR_measurement Failed to update figure1: 'ESRMeasure' object has no attribute 'plotlines'. ['Traceback (most recent call last):\n', '  File "C:\\Users\\ZHao\\.conda\\envs\\scopefoundry\\lib\\site-packages\\ScopeFoundry\\measurement.py", line 273, in _on_display_update_timer\n    self.update_display()\n', '  File "C:\\Users\\Public\\quantum_sensing\\quantum_sensing\\fancy_microscope\\custommeasure2.py", line 359, in update_display\n    self.plotlines[rate].setVisible(self.settings[\'{}_visible\'.format(rate)])\n', "AttributeError: 'ESRMeasure' object has no attribute 'plotlines'\n"]
2022-02-18T11:03:41|CRITICAL|root|Unhandled exception:Traceback (most recent call last):
  File "C:\Users\ZHao\.conda\envs\scopefoundry\lib\site-packages\ScopeFoundry\measurement.py", line 272, in _on_display_update_timer
    try:
KeyboardInterrupt

2022-02-18T11:03:41|ERROR|ESRMeasure|ESR_measurement Failed to update figure1: 'ESRMeasure' object has no attribute 'plotlines'. ['Traceback (most recent call last):\n', '  File "C:\\Users\\ZHao\\.conda\\envs\\scopefoundry\\lib\\site-packages\\ScopeFoundry\\measurement.py", line 273, in _on_display_update_timer\n    self.update_display()\n', '  File "C:\\Users\\Public\\quantum_sensing\\quantum_sensing\\fancy_microscope\\custommeasure2.py", line 359, in update_display\n    self.plotlines[rate].setVisible(self.settings[\'{}_visible\'.format(rate)])\n', "AttributeError: 'ESRMeasure' object has no attribute 'plotlines'\n"]
2022-02-18T11:03:41|ERROR|ESRMeasure|ESR_measurement Failed to update figure1: 'ESRMeasure' object has no attribute 'plotlines'. ['Traceback (most recent call last):\n', '  File "C:\\Users\\ZHao\\.conda\\envs\\scopefoundry\\lib\\site-packages\\ScopeFoundry\\measurement.py", line 273, in _on_display_update_timer\n    self.update_display()\n', '  File "C:\\Users\\Public\\quantum_sensing\\quantum_sensing\\fancy_microscope\\custommeasure2.py", line 359, in update_display\n    self.plotlines[rate].setVisible(self.settings[\'{}_visible\'.format(rate)])\n', "AttributeError: 'ESRMeasure' object has no attribute 'plotlines'\n"]
2022-02-18T11:03:41|ERROR|ESRMeasure|ESR_measurement Failed to update figure1: 'ESRMeasure' object has no attribute 'plotlines'. ['Traceback (most recent call last):\n', '  File "C:\\Users\\ZHao\\.conda\\envs\\scopefoundry\\lib\\site-packages\\ScopeFoundry\\measurement.py", line 273, in _on_display_update_timer\n    self.update_display()\n', '  File "C:\\Users\\Public\\quantum_sensing\\quantum_sensing\\fancy_microscope\\custommeasure2.py", line 359, in update_display\n    self.plotlines[rate].setVisible(self.settings[\'{}_visible\'.format(rate)])\n', "AttributeError: 'ESRMeasure' object has no attribute 'plotlines'\n"]
2022-02-18T11:03:41|ERROR|ESRMeasure|ESR_measurement Failed to update figure1: 'ESRMeasure' object has no attribute 'plotlines'. ['Traceback (most recent call last):\n', '  File "C:\\Users\\ZHao\\.conda\\envs\\scopefoundry\\lib\\site-packages\\ScopeFoundry\\measurement.py", line 273, in _on_display_update_timer\n    self.update_display()\n', '  File "C:\\Users\\Public\\quantum_sensing\\quantum_sensing\\fancy_microscope\\custommeasure2.py", line 359, in update_display\n    self.plotlines[rate].setVisible(self.settings[\'{}_visible\'.format(rate)])\n', "AttributeError: 'ESRMeasure' object has no attribute 'plotlines'\n"]
2022-02-18T11:03:41|ERROR|ESRMeasure|ESR_measurement Failed to update figure1: 'ESRMeasure' object has no attribute 'plotlines'. ['Traceback (most recent call last):\n', '  File "C:\\Users\\ZHao\\.conda\\envs\\scopefoundry\\lib\\site-packages\\ScopeFoundry\\measurement.py", line 273, in _on_display_update_timer\n    self.update_display()\n', '  File "C:\\Users\\Public\\quantum_sensing\\quantum_sensing\\fancy_microscope\\custommeasure2.py", line 359, in update_display\n    self.plotlines[rate].setVisible(self.settings[\'{}_visible\'.format(rate)])\n', "AttributeError: 'ESRMeasure' object has no attribute 'plotlines'\n"]
2022-02-18T11:03:41|ERROR|ESRMeasure|ESR_measurement Failed to update figure1: 'ESRMeasure' object has no attribute 'plotlines'. ['Traceback (most recent call last):\n', '  File "C:\\Users\\ZHao\\.conda\\envs\\scopefoundry\\lib\\site-packages\\ScopeFoundry\\measurement.py", line 273, in _on_display_update_timer\n    self.update_display()\n', '  File "C:\\Users\\Public\\quantum_sensing\\quantum_sensing\\fancy_microscope\\custommeasure2.py", line 359, in update_display\n    self.plotlines[rate].setVisible(self.settings[\'{}_visible\'.format(rate)])\n', "AttributeError: 'ESRMeasure' object has no attribute 'plotlines'\n"]
2022-02-18T11:03:41|ERROR|ESRMeasure|ESR_measurement Failed to update figure1: 'ESRMeasure' object has no attribute 'plotlines'. ['Traceback (most recent call last):\n', '  File "C:\\Users\\ZHao\\.conda\\envs\\scopefoundry\\lib\\site-packages\\ScopeFoundry\\measurement.py", line 273, in _on_display_update_timer\n    self.update_display()\n', '  File "C:\\Users\\Public\\quantum_sensing\\quantum_sensing\\fancy_microscope\\custommeasure2.py", line 359, in update_display\n    self.plotlines[rate].setVisible(self.settings[\'{}_visible\'.format(rate)])\n', "AttributeError: 'ESRMeasure' object has no attribute 'plotlines'\n"]
2022-02-18T11:03:42|ERROR|ESRMeasure|ESR_measurement Failed to update figure1: 'ESRMeasure' object has no attribute 'plotlines'. ['Traceback (most recent call last):\n', '  File "C:\\Users\\ZHao\\.conda\\envs\\scopefoundry\\lib\\site-packages\\ScopeFoundry\\measurement.py", line 273, in _on_display_update_timer\n    self.update_display()\n', '  File "C:\\Users\\Public\\quantum_sensing\\quantum_sensing\\fancy_microscope\\custommeasure2.py", line 359, in update_display\n    self.plotlines[rate].setVisible(self.settings[\'{}_visible\'.format(rate)])\n', "AttributeError: 'ESRMeasure' object has no attribute 'plotlines'\n"]
2022-02-18T11:03:43|ERROR|ESRMeasure|ESR_measurement Failed to update figure1: 'ESRMeasure' object has no attribute 'plotlines'. ['Traceback (most recent call last):\n', '  File "C:\\Users\\ZHao\\.conda\\envs\\scopefoundry\\lib\\site-packages\\ScopeFoundry\\measurement.py", line 273, in _on_display_update_timer\n    self.update_display()\n', '  File "C:\\Users\\Public\\quantum_sensing\\quantum_sensing\\fancy_microscope\\custommeasure2.py", line 359, in update_display\n    self.plotlines[rate].setVisible(self.settings[\'{}_visible\'.format(rate)])\n', "AttributeError: 'ESRMeasure' object has no attribute 'plotlines'\n"]
2022-02-18T11:03:43|ERROR|ESRMeasure|ESR_measurement Failed to update figure1: 'ESRMeasure' object has no attribute 'plotlines'. ['Traceback (most recent call last):\n', '  File "C:\\Users\\ZHao\\.conda\\envs\\scopefoundry\\lib\\site-packages\\ScopeFoundry\\measurement.py", line 273, in _on_display_update_timer\n    self.update_display()\n', '  File "C:\\Users\\Public\\quantum_sensing\\quantum_sensing\\fancy_microscope\\custommeasure2.py", line 359, in update_display\n    self.plotlines[rate].setVisible(self.settings[\'{}_visible\'.format(rate)])\n', "AttributeError: 'ESRMeasure' object has no attribute 'plotlines'\n"]
2022-02-18T11:03:43|ERROR|ESRMeasure|ESR_measurement Failed to update figure1: 'ESRMeasure' object has no attribute 'plotlines'. ['Traceback (most recent call last):\n', '  File "C:\\Users\\ZHao\\.conda\\envs\\scopefoundry\\lib\\site-packages\\ScopeFoundry\\measurement.py", line 273, in _on_display_update_timer\n    self.update_display()\n', '  File "C:\\Users\\Public\\quantum_sensing\\quantum_sensing\\fancy_microscope\\custommeasure2.py", line 359, in update_display\n    self.plotlines[rate].setVisible(self.settings[\'{}_visible\'.format(rate)])\n', "AttributeError: 'ESRMeasure' object has no attribute 'plotlines'\n"]
2022-02-18T11:03:44|ERROR|ESRMeasure|ESR_measurement Failed to update figure1: 'ESRMeasure' object has no attribute 'plotlines'. ['Traceback (most recent call last):\n', '  File "C:\\Users\\ZHao\\.conda\\envs\\scopefoundry\\lib\\site-packages\\ScopeFoundry\\measurement.py", line 273, in _on_display_update_timer\n    self.update_display()\n', '  File "C:\\Users\\Public\\quantum_sensing\\quantum_sensing\\fancy_microscope\\custommeasure2.py", line 359, in update_display\n    self.plotlines[rate].setVisible(self.settings[\'{}_visible\'.format(rate)])\n', "AttributeError: 'ESRMeasure' object has no attribute 'plotlines'\n"]
2022-02-18T11:03:44|ERROR|ESRMeasure|ESR_measurement Failed to update figure1: 'ESRMeasure' object has no attribute 'plotlines'. ['Traceback (most recent call last):\n', '  File "C:\\Users\\ZHao\\.conda\\envs\\scopefoundry\\lib\\site-packages\\ScopeFoundry\\measurement.py", line 273, in _on_display_update_timer\n    self.update_display()\n', '  File "C:\\Users\\Public\\quantum_sensing\\quantum_sensing\\fancy_microscope\\custommeasure2.py", line 359, in update_display\n    self.plotlines[rate].setVisible(self.settings[\'{}_visible\'.format(rate)])\n', "AttributeError: 'ESRMeasure' object has no attribute 'plotlines'\n"]
2022-02-18T11:03:44|ERROR|ESRMeasure|ESR_measurement Failed to update figure1: 'ESRMeasure' object has no attribute 'plotlines'. ['Traceback (most recent call last):\n', '  File "C:\\Users\\ZHao\\.conda\\envs\\scopefoundry\\lib\\site-packages\\ScopeFoundry\\measurement.py", line 273, in _on_display_update_timer\n    self.update_display()\n', '  File "C:\\Users\\Public\\quantum_sensing\\quantum_sensing\\fancy_microscope\\custommeasure2.py", line 359, in update_display\n    self.plotlines[rate].setVisible(self.settings[\'{}_visible\'.format(rate)])\n', "AttributeError: 'ESRMeasure' object has no attribute 'plotlines'\n"]
2022-02-18T11:03:44|ERROR|ESRMeasure|ESR_measurement Failed to update figure1: 'ESRMeasure' object has no attribute 'plotlines'. ['Traceback (most recent call last):\n', '  File "C:\\Users\\ZHao\\.conda\\envs\\scopefoundry\\lib\\site-packages\\ScopeFoundry\\measurement.py", line 273, in _on_display_update_timer\n    self.update_display()\n', '  File "C:\\Users\\Public\\quantum_sensing\\quantum_sensing\\fancy_microscope\\custommeasure2.py", line 359, in update_display\n    self.plotlines[rate].setVisible(self.settings[\'{}_visible\'.format(rate)])\n', "AttributeError: 'ESRMeasure' object has no attribute 'plotlines'\n"]
2022-02-18T11:03:44|ERROR|ESRMeasure|ESR_measurement Failed to update figure1: 'ESRMeasure' object has no attribute 'plotlines'. ['Traceback (most recent call last):\n', '  File "C:\\Users\\ZHao\\.conda\\envs\\scopefoundry\\lib\\site-packages\\ScopeFoundry\\measurement.py", line 273, in _on_display_update_timer\n    self.update_display()\n', '  File "C:\\Users\\Public\\quantum_sensing\\quantum_sensing\\fancy_microscope\\custommeasure2.py", line 359, in update_display\n    self.plotlines[rate].setVisible(self.settings[\'{}_visible\'.format(rate)])\n', "AttributeError: 'ESRMeasure' object has no attribute 'plotlines'\n"]
2022-02-18T11:03:44|ERROR|ESRMeasure|ESR_measurement Failed to update figure1: 'ESRMeasure' object has no attribute 'plotlines'. ['Traceback (most recent call last):\n', '  File "C:\\Users\\ZHao\\.conda\\envs\\scopefoundry\\lib\\site-packages\\ScopeFoundry\\measurement.py", line 273, in _on_display_update_timer\n    self.update_display()\n', '  File "C:\\Users\\Public\\quantum_sensing\\quantum_sensing\\fancy_microscope\\custommeasure2.py", line 359, in update_display\n    self.plotlines[rate].setVisible(self.settings[\'{}_visible\'.format(rate)])\n', "AttributeError: 'ESRMeasure' object has no attribute 'plotlines'\n"]
2022-02-18T11:03:44|ERROR|ESRMeasure|ESR_measurement Failed to update figure1: 'ESRMeasure' object has no attribute 'plotlines'. ['Traceback (most recent call last):\n', '  File "C:\\Users\\ZHao\\.conda\\envs\\scopefoundry\\lib\\site-packages\\ScopeFoundry\\measurement.py", line 273, in _on_display_update_timer\n    self.update_display()\n', '  File "C:\\Users\\Public\\quantum_sensing\\quantum_sensing\\fancy_microscope\\custommeasure2.py", line 359, in update_display\n    self.plotlines[rate].setVisible(self.settings[\'{}_visible\'.format(rate)])\n', "AttributeError: 'ESRMeasure' object has no attribute 'plotlines'\n"]
2022-02-18T11:03:44|ERROR|ESRMeasure|ESR_measurement Failed to update figure1: 'ESRMeasure' object has no attribute 'plotlines'. ['Traceback (most recent call last):\n', '  File "C:\\Users\\ZHao\\.conda\\envs\\scopefoundry\\lib\\site-packages\\ScopeFoundry\\measurement.py", line 273, in _on_display_update_timer\n    self.update_display()\n', '  File "C:\\Users\\Public\\quantum_sensing\\quantum_sensing\\fancy_microscope\\custommeasure2.py", line 359, in update_display\n    self.plotlines[rate].setVisible(self.settings[\'{}_visible\'.format(rate)])\n', "AttributeError: 'ESRMeasure' object has no attribute 'plotlines'\n"]
2022-02-18T11:03:44|ERROR|ESRMeasure|ESR_measurement Failed to update figure1: 'ESRMeasure' object has no attribute 'plotlines'. ['Traceback (most recent call last):\n', '  File "C:\\Users\\ZHao\\.conda\\envs\\scopefoundry\\lib\\site-packages\\ScopeFoundry\\measurement.py", line 273, in _on_display_update_timer\n    self.update_display()\n', '  File "C:\\Users\\Public\\quantum_sensing\\quantum_sensing\\fancy_microscope\\custommeasure2.py", line 359, in update_display\n    self.plotlines[rate].setVisible(self.settings[\'{}_visible\'.format(rate)])\n', "AttributeError: 'ESRMeasure' object has no attribute 'plotlines'\n"]
2022-02-18T11:03:45|ERROR|ESRMeasure|ESR_measurement Failed to update figure1: 'ESRMeasure' object has no attribute 'plotlines'. ['Traceback (most recent call last):\n', '  File "C:\\Users\\ZHao\\.conda\\envs\\scopefoundry\\lib\\site-packages\\ScopeFoundry\\measurement.py", line 273, in _on_display_update_timer\n    self.update_display()\n', '  File "C:\\Users\\Public\\quantum_sensing\\quantum_sensing\\fancy_microscope\\custommeasure2.py", line 359, in update_display\n    self.plotlines[rate].setVisible(self.settings[\'{}_visible\'.format(rate)])\n', "AttributeError: 'ESRMeasure' object has no attribute 'plotlines'\n"]
2022-02-18T11:03:45|ERROR|ESRMeasure|ESR_measurement Failed to update figure1: 'ESRMeasure' object has no attribute 'plotlines'. ['Traceback (most recent call last):\n', '  File "C:\\Users\\ZHao\\.conda\\envs\\scopefoundry\\lib\\site-packages\\ScopeFoundry\\measurement.py", line 273, in _on_display_update_timer\n    self.update_display()\n', '  File "C:\\Users\\Public\\quantum_sensing\\quantum_sensing\\fancy_microscope\\custommeasure2.py", line 359, in update_display\n    self.plotlines[rate].setVisible(self.settings[\'{}_visible\'.format(rate)])\n', "AttributeError: 'ESRMeasure' object has no attribute 'plotlines'\n"]
2022-02-18T11:03:45|ERROR|ESRMeasure|ESR_measurement Failed to update figure1: 'ESRMeasure' object has no attribute 'plotlines'. ['Traceback (most recent call last):\n', '  File "C:\\Users\\ZHao\\.conda\\envs\\scopefoundry\\lib\\site-packages\\ScopeFoundry\\measurement.py", line 273, in _on_display_update_timer\n    self.update_display()\n', '  File "C:\\Users\\Public\\quantum_sensing\\quantum_sensing\\fancy_microscope\\custommeasure2.py", line 359, in update_display\n    self.plotlines[rate].setVisible(self.settings[\'{}_visible\'.format(rate)])\n', "AttributeError: 'ESRMeasure' object has no attribute 'plotlines'\n"]
2022-02-18T11:03:45|ERROR|ESRMeasure|ESR_measurement Failed to update figure1: 'ESRMeasure' object has no attribute 'plotlines'. ['Traceback (most recent call last):\n', '  File "C:\\Users\\ZHao\\.conda\\envs\\scopefoundry\\lib\\site-packages\\ScopeFoundry\\measurement.py", line 273, in _on_display_update_timer\n    self.update_display()\n', '  File "C:\\Users\\Public\\quantum_sensing\\quantum_sensing\\fancy_microscope\\custommeasure2.py", line 359, in update_display\n    self.plotlines[rate].setVisible(self.settings[\'{}_visible\'.format(rate)])\n', "AttributeError: 'ESRMeasure' object has no attribute 'plotlines'\n"]
2022-02-18T11:03:45|ERROR|ESRMeasure|ESR_measurement Failed to update figure1: 'ESRMeasure' object has no attribute 'plotlines'. ['Traceback (most recent call last):\n', '  File "C:\\Users\\ZHao\\.conda\\envs\\scopefoundry\\lib\\site-packages\\ScopeFoundry\\measurement.py", line 273, in _on_display_update_timer\n    self.update_display()\n', '  File "C:\\Users\\Public\\quantum_sensing\\quantum_sensing\\fancy_microscope\\custommeasure2.py", line 359, in update_display\n    self.plotlines[rate].setVisible(self.settings[\'{}_visible\'.format(rate)])\n', "AttributeError: 'ESRMeasure' object has no attribute 'plotlines'\n"]
2022-02-18T11:03:45|ERROR|ESRMeasure|ESR_measurement Failed to update figure1: 'ESRMeasure' object has no attribute 'plotlines'. ['Traceback (most recent call last):\n', '  File "C:\\Users\\ZHao\\.conda\\envs\\scopefoundry\\lib\\site-packages\\ScopeFoundry\\measurement.py", line 273, in _on_display_update_timer\n    self.update_display()\n', '  File "C:\\Users\\Public\\quantum_sensing\\quantum_sensing\\fancy_microscope\\custommeasure2.py", line 359, in update_display\n    self.plotlines[rate].setVisible(self.settings[\'{}_visible\'.format(rate)])\n', "AttributeError: 'ESRMeasure' object has no attribute 'plotlines'\n"]
2022-02-18T11:03:45|ERROR|ESRMeasure|ESR_measurement Failed to update figure1: 'ESRMeasure' object has no attribute 'plotlines'. ['Traceback (most recent call last):\n', '  File "C:\\Users\\ZHao\\.conda\\envs\\scopefoundry\\lib\\site-packages\\ScopeFoundry\\measurement.py", line 273, in _on_display_update_timer\n    self.update_display()\n', '  File "C:\\Users\\Public\\quantum_sensing\\quantum_sensing\\fancy_microscope\\custommeasure2.py", line 359, in update_display\n    self.plotlines[rate].setVisible(self.settings[\'{}_visible\'.format(rate)])\n', "AttributeError: 'ESRMeasure' object has no attribute 'plotlines'\n"]
2022-02-18T11:03:45|ERROR|ESRMeasure|ESR_measurement Failed to update figure1: 'ESRMeasure' object has no attribute 'plotlines'. ['Traceback (most recent call last):\n', '  File "C:\\Users\\ZHao\\.conda\\envs\\scopefoundry\\lib\\site-packages\\ScopeFoundry\\measurement.py", line 273, in _on_display_update_timer\n    self.update_display()\n', '  File "C:\\Users\\Public\\quantum_sensing\\quantum_sensing\\fancy_microscope\\custommeasure2.py", line 359, in update_display\n    self.plotlines[rate].setVisible(self.settings[\'{}_visible\'.format(rate)])\n', "AttributeError: 'ESRMeasure' object has no attribute 'plotlines'\n"]
2022-02-18T11:03:45|ERROR|ESRMeasure|ESR_measurement Failed to update figure1: 'ESRMeasure' object has no attribute 'plotlines'. ['Traceback (most recent call last):\n', '  File "C:\\Users\\ZHao\\.conda\\envs\\scopefoundry\\lib\\site-packages\\ScopeFoundry\\measurement.py", line 273, in _on_display_update_timer\n    self.update_display()\n', '  File "C:\\Users\\Public\\quantum_sensing\\quantum_sensing\\fancy_microscope\\custommeasure2.py", line 359, in update_display\n    self.plotlines[rate].setVisible(self.settings[\'{}_visible\'.format(rate)])\n', "AttributeError: 'ESRMeasure' object has no attribute 'plotlines'\n"]
2022-02-18T11:03:46|ERROR|ESRMeasure|ESR_measurement Failed to update figure1: 'ESRMeasure' object has no attribute 'plotlines'. ['Traceback (most recent call last):\n', '  File "C:\\Users\\ZHao\\.conda\\envs\\scopefoundry\\lib\\site-packages\\ScopeFoundry\\measurement.py", line 273, in _on_display_update_timer\n    self.update_display()\n', '  File "C:\\Users\\Public\\quantum_sensing\\quantum_sensing\\fancy_microscope\\custommeasure2.py", line 359, in update_display\n    self.plotlines[rate].setVisible(self.settings[\'{}_visible\'.format(rate)])\n', "AttributeError: 'ESRMeasure' object has no attribute 'plotlines'\n"]
2022-02-18T11:03:46|ERROR|ESRMeasure|ESR_measurement Failed to update figure1: 'ESRMeasure' object has no attribute 'plotlines'. ['Traceback (most recent call last):\n', '  File "C:\\Users\\ZHao\\.conda\\envs\\scopefoundry\\lib\\site-packages\\ScopeFoundry\\measurement.py", line 273, in _on_display_update_timer\n    self.update_display()\n', '  File "C:\\Users\\Public\\quantum_sensing\\quantum_sensing\\fancy_microscope\\custommeasure2.py", line 359, in update_display\n    self.plotlines[rate].setVisible(self.settings[\'{}_visible\'.format(rate)])\n', "AttributeError: 'ESRMeasure' object has no attribute 'plotlines'\n"]
2022-02-18T11:03:46|ERROR|ESRMeasure|ESR_measurement Failed to update figure1: 'ESRMeasure' object has no attribute 'plotlines'. ['Traceback (most recent call last):\n', '  File "C:\\Users\\ZHao\\.conda\\envs\\scopefoundry\\lib\\site-packages\\ScopeFoundry\\measurement.py", line 273, in _on_display_update_timer\n    self.update_display()\n', '  File "C:\\Users\\Public\\quantum_sensing\\quantum_sensing\\fancy_microscope\\custommeasure2.py", line 359, in update_display\n    self.plotlines[rate].setVisible(self.settings[\'{}_visible\'.format(rate)])\n', "AttributeError: 'ESRMeasure' object has no attribute 'plotlines'\n"]
2022-02-18T11:03:46|ERROR|ESRMeasure|ESR_measurement Failed to update figure1: 'ESRMeasure' object has no attribute 'plotlines'. ['Traceback (most recent call last):\n', '  File "C:\\Users\\ZHao\\.conda\\envs\\scopefoundry\\lib\\site-packages\\ScopeFoundry\\measurement.py", line 273, in _on_display_update_timer\n    self.update_display()\n', '  File "C:\\Users\\Public\\quantum_sensing\\quantum_sensing\\fancy_microscope\\custommeasure2.py", line 359, in update_display\n    self.plotlines[rate].setVisible(self.settings[\'{}_visible\'.format(rate)])\n', "AttributeError: 'ESRMeasure' object has no attribute 'plotlines'\n"]
2022-02-18T11:03:46|ERROR|ESRMeasure|ESR_measurement Failed to update figure1: 'ESRMeasure' object has no attribute 'plotlines'. ['Traceback (most recent call last):\n', '  File "C:\\Users\\ZHao\\.conda\\envs\\scopefoundry\\lib\\site-packages\\ScopeFoundry\\measurement.py", line 273, in _on_display_update_timer\n    self.update_display()\n', '  File "C:\\Users\\Public\\quantum_sensing\\quantum_sensing\\fancy_microscope\\custommeasure2.py", line 359, in update_display\n    self.plotlines[rate].setVisible(self.settings[\'{}_visible\'.format(rate)])\n', "AttributeError: 'ESRMeasure' object has no attribute 'plotlines'\n"]
2022-02-18T11:03:46|ERROR|ESRMeasure|ESR_measurement Failed to update figure1: 'ESRMeasure' object has no attribute 'plotlines'. ['Traceback (most recent call last):\n', '  File "C:\\Users\\ZHao\\.conda\\envs\\scopefoundry\\lib\\site-packages\\ScopeFoundry\\measurement.py", line 273, in _on_display_update_timer\n    self.update_display()\n', '  File "C:\\Users\\Public\\quantum_sensing\\quantum_sensing\\fancy_microscope\\custommeasure2.py", line 359, in update_display\n    self.plotlines[rate].setVisible(self.settings[\'{}_visible\'.format(rate)])\n', "AttributeError: 'ESRMeasure' object has no attribute 'plotlines'\n"]
2022-02-18T11:03:46|ERROR|ESRMeasure|ESR_measurement Failed to update figure1: 'ESRMeasure' object has no attribute 'plotlines'. ['Traceback (most recent call last):\n', '  File "C:\\Users\\ZHao\\.conda\\envs\\scopefoundry\\lib\\site-packages\\ScopeFoundry\\measurement.py", line 273, in _on_display_update_timer\n    self.update_display()\n', '  File "C:\\Users\\Public\\quantum_sensing\\quantum_sensing\\fancy_microscope\\custommeasure2.py", line 359, in update_display\n    self.plotlines[rate].setVisible(self.settings[\'{}_visible\'.format(rate)])\n', "AttributeError: 'ESRMeasure' object has no attribute 'plotlines'\n"]
2022-02-18T11:03:46|ERROR|ESRMeasure|ESR_measurement Failed to update figure1: 'ESRMeasure' object has no attribute 'plotlines'. ['Traceback (most recent call last):\n', '  File "C:\\Users\\ZHao\\.conda\\envs\\scopefoundry\\lib\\site-packages\\ScopeFoundry\\measurement.py", line 273, in _on_display_update_timer\n    self.update_display()\n', '  File "C:\\Users\\Public\\quantum_sensing\\quantum_sensing\\fancy_microscope\\custommeasure2.py", line 359, in update_display\n    self.plotlines[rate].setVisible(self.settings[\'{}_visible\'.format(rate)])\n', "AttributeError: 'ESRMeasure' object has no attribute 'plotlines'\n"]
2022-02-18T11:03:46|ERROR|ESRMeasure|ESR_measurement Failed to update figure1: 'ESRMeasure' object has no attribute 'plotlines'. ['Traceback (most recent call last):\n', '  File "C:\\Users\\ZHao\\.conda\\envs\\scopefoundry\\lib\\site-packages\\ScopeFoundry\\measurement.py", line 273, in _on_display_update_timer\n    self.update_display()\n', '  File "C:\\Users\\Public\\quantum_sensing\\quantum_sensing\\fancy_microscope\\custommeasure2.py", line 359, in update_display\n    self.plotlines[rate].setVisible(self.settings[\'{}_visible\'.format(rate)])\n', "AttributeError: 'ESRMeasure' object has no attribute 'plotlines'\n"]
2022-02-18T11:03:47|ERROR|ESRMeasure|ESR_measurement Failed to update figure1: 'ESRMeasure' object has no attribute 'plotlines'. ['Traceback (most recent call last):\n', '  File "C:\\Users\\ZHao\\.conda\\envs\\scopefoundry\\lib\\site-packages\\ScopeFoundry\\measurement.py", line 273, in _on_display_update_timer\n    self.update_display()\n', '  File "C:\\Users\\Public\\quantum_sensing\\quantum_sensing\\fancy_microscope\\custommeasure2.py", line 359, in update_display\n    self.plotlines[rate].setVisible(self.settings[\'{}_visible\'.format(rate)])\n', "AttributeError: 'ESRMeasure' object has no attribute 'plotlines'\n"]
2022-02-18T11:03:47|ERROR|ESRMeasure|ESR_measurement Failed to update figure1: 'ESRMeasure' object has no attribute 'plotlines'. ['Traceback (most recent call last):\n', '  File "C:\\Users\\ZHao\\.conda\\envs\\scopefoundry\\lib\\site-packages\\ScopeFoundry\\measurement.py", line 273, in _on_display_update_timer\n    self.update_display()\n', '  File "C:\\Users\\Public\\quantum_sensing\\quantum_sensing\\fancy_microscope\\custommeasure2.py", line 359, in update_display\n    self.plotlines[rate].setVisible(self.settings[\'{}_visible\'.format(rate)])\n', "AttributeError: 'ESRMeasure' object has no attribute 'plotlines'\n"]
2022-02-18T11:03:47|ERROR|ESRMeasure|ESR_measurement Failed to update figure1: 'ESRMeasure' object has no attribute 'plotlines'. ['Traceback (most recent call last):\n', '  File "C:\\Users\\ZHao\\.conda\\envs\\scopefoundry\\lib\\site-packages\\ScopeFoundry\\measurement.py", line 273, in _on_display_update_timer\n    self.update_display()\n', '  File "C:\\Users\\Public\\quantum_sensing\\quantum_sensing\\fancy_microscope\\custommeasure2.py", line 359, in update_display\n    self.plotlines[rate].setVisible(self.settings[\'{}_visible\'.format(rate)])\n', "AttributeError: 'ESRMeasure' object has no attribute 'plotlines'\n"]
2022-02-18T11:03:47|ERROR|ESRMeasure|ESR_measurement Failed to update figure1: 'ESRMeasure' object has no attribute 'plotlines'. ['Traceback (most recent call last):\n', '  File "C:\\Users\\ZHao\\.conda\\envs\\scopefoundry\\lib\\site-packages\\ScopeFoundry\\measurement.py", line 273, in _on_display_update_timer\n    self.update_display()\n', '  File "C:\\Users\\Public\\quantum_sensing\\quantum_sensing\\fancy_microscope\\custommeasure2.py", line 359, in update_display\n    self.plotlines[rate].setVisible(self.settings[\'{}_visible\'.format(rate)])\n', "AttributeError: 'ESRMeasure' object has no attribute 'plotlines'\n"]
2022-02-18T11:03:47|ERROR|ESRMeasure|ESR_measurement Failed to update figure1: 'ESRMeasure' object has no attribute 'plotlines'. ['Traceback (most recent call last):\n', '  File "C:\\Users\\ZHao\\.conda\\envs\\scopefoundry\\lib\\site-packages\\ScopeFoundry\\measurement.py", line 273, in _on_display_update_timer\n    self.update_display()\n', '  File "C:\\Users\\Public\\quantum_sensing\\quantum_sensing\\fancy_microscope\\custommeasure2.py", line 359, in update_display\n    self.plotlines[rate].setVisible(self.settings[\'{}_visible\'.format(rate)])\n', "AttributeError: 'ESRMeasure' object has no attribute 'plotlines'\n"]
2022-02-18T11:03:47|ERROR|ESRMeasure|ESR_measurement Failed to update figure1: 'ESRMeasure' object has no attribute 'plotlines'. ['Traceback (most recent call last):\n', '  File "C:\\Users\\ZHao\\.conda\\envs\\scopefoundry\\lib\\site-packages\\ScopeFoundry\\measurement.py", line 273, in _on_display_update_timer\n    self.update_display()\n', '  File "C:\\Users\\Public\\quantum_sensing\\quantum_sensing\\fancy_microscope\\custommeasure2.py", line 359, in update_display\n    self.plotlines[rate].setVisible(self.settings[\'{}_visible\'.format(rate)])\n', "AttributeError: 'ESRMeasure' object has no attribute 'plotlines'\n"]
2022-02-18T11:03:47|ERROR|ESRMeasure|ESR_measurement Failed to update figure1: 'ESRMeasure' object has no attribute 'plotlines'. ['Traceback (most recent call last):\n', '  File "C:\\Users\\ZHao\\.conda\\envs\\scopefoundry\\lib\\site-packages\\ScopeFoundry\\measurement.py", line 273, in _on_display_update_timer\n    self.update_display()\n', '  File "C:\\Users\\Public\\quantum_sensing\\quantum_sensing\\fancy_microscope\\custommeasure2.py", line 359, in update_display\n    self.plotlines[rate].setVisible(self.settings[\'{}_visible\'.format(rate)])\n', "AttributeError: 'ESRMeasure' object has no attribute 'plotlines'\n"]
2022-02-18T11:03:47|ERROR|ESRMeasure|ESR_measurement Failed to update figure1: 'ESRMeasure' object has no attribute 'plotlines'. ['Traceback (most recent call last):\n', '  File "C:\\Users\\ZHao\\.conda\\envs\\scopefoundry\\lib\\site-packages\\ScopeFoundry\\measurement.py", line 273, in _on_display_update_timer\n    self.update_display()\n', '  File "C:\\Users\\Public\\quantum_sensing\\quantum_sensing\\fancy_microscope\\custommeasure2.py", line 359, in update_display\n    self.plotlines[rate].setVisible(self.settings[\'{}_visible\'.format(rate)])\n', "AttributeError: 'ESRMeasure' object has no attribute 'plotlines'\n"]
2022-02-18T11:03:47|ERROR|ESRMeasure|ESR_measurement Failed to update figure1: 'ESRMeasure' object has no attribute 'plotlines'. ['Traceback (most recent call last):\n', '  File "C:\\Users\\ZHao\\.conda\\envs\\scopefoundry\\lib\\site-packages\\ScopeFoundry\\measurement.py", line 273, in _on_display_update_timer\n    self.update_display()\n', '  File "C:\\Users\\Public\\quantum_sensing\\quantum_sensing\\fancy_microscope\\custommeasure2.py", line 359, in update_display\n    self.plotlines[rate].setVisible(self.settings[\'{}_visible\'.format(rate)])\n', "AttributeError: 'ESRMeasure' object has no attribute 'plotlines'\n"]
2022-02-18T11:03:48|ERROR|ESRMeasure|ESR_measurement Failed to update figure1: 'ESRMeasure' object has no attribute 'plotlines'. ['Traceback (most recent call last):\n', '  File "C:\\Users\\ZHao\\.conda\\envs\\scopefoundry\\lib\\site-packages\\ScopeFoundry\\measurement.py", line 273, in _on_display_update_timer\n    self.update_display()\n', '  File "C:\\Users\\Public\\quantum_sensing\\quantum_sensing\\fancy_microscope\\custommeasure2.py", line 359, in update_display\n    self.plotlines[rate].setVisible(self.settings[\'{}_visible\'.format(rate)])\n', "AttributeError: 'ESRMeasure' object has no attribute 'plotlines'\n"]
2022-02-18T11:03:48|ERROR|ESRMeasure|ESR_measurement Failed to update figure1: 'ESRMeasure' object has no attribute 'plotlines'. ['Traceback (most recent call last):\n', '  File "C:\\Users\\ZHao\\.conda\\envs\\scopefoundry\\lib\\site-packages\\ScopeFoundry\\measurement.py", line 273, in _on_display_update_timer\n    self.update_display()\n', '  File "C:\\Users\\Public\\quantum_sensing\\quantum_sensing\\fancy_microscope\\custommeasure2.py", line 359, in update_display\n    self.plotlines[rate].setVisible(self.settings[\'{}_visible\'.format(rate)])\n', "AttributeError: 'ESRMeasure' object has no attribute 'plotlines'\n"]
2022-02-18T11:03:48|ERROR|ESRMeasure|ESR_measurement Failed to update figure1: 'ESRMeasure' object has no attribute 'plotlines'. ['Traceback (most recent call last):\n', '  File "C:\\Users\\ZHao\\.conda\\envs\\scopefoundry\\lib\\site-packages\\ScopeFoundry\\measurement.py", line 273, in _on_display_update_timer\n    self.update_display()\n', '  File "C:\\Users\\Public\\quantum_sensing\\quantum_sensing\\fancy_microscope\\custommeasure2.py", line 359, in update_display\n    self.plotlines[rate].setVisible(self.settings[\'{}_visible\'.format(rate)])\n', "AttributeError: 'ESRMeasure' object has no attribute 'plotlines'\n"]
2022-02-18T11:03:48|ERROR|ESRMeasure|ESR_measurement Failed to update figure1: 'ESRMeasure' object has no attribute 'plotlines'. ['Traceback (most recent call last):\n', '  File "C:\\Users\\ZHao\\.conda\\envs\\scopefoundry\\lib\\site-packages\\ScopeFoundry\\measurement.py", line 273, in _on_display_update_timer\n    self.update_display()\n', '  File "C:\\Users\\Public\\quantum_sensing\\quantum_sensing\\fancy_microscope\\custommeasure2.py", line 359, in update_display\n    self.plotlines[rate].setVisible(self.settings[\'{}_visible\'.format(rate)])\n', "AttributeError: 'ESRMeasure' object has no attribute 'plotlines'\n"]
2022-02-18T11:03:48|ERROR|ESRMeasure|ESR_measurement Failed to update figure1: 'ESRMeasure' object has no attribute 'plotlines'. ['Traceback (most recent call last):\n', '  File "C:\\Users\\ZHao\\.conda\\envs\\scopefoundry\\lib\\site-packages\\ScopeFoundry\\measurement.py", line 273, in _on_display_update_timer\n    self.update_display()\n', '  File "C:\\Users\\Public\\quantum_sensing\\quantum_sensing\\fancy_microscope\\custommeasure2.py", line 359, in update_display\n    self.plotlines[rate].setVisible(self.settings[\'{}_visible\'.format(rate)])\n', "AttributeError: 'ESRMeasure' object has no attribute 'plotlines'\n"]
2022-02-18T11:03:48|ERROR|ESRMeasure|ESR_measurement Failed to update figure1: 'ESRMeasure' object has no attribute 'plotlines'. ['Traceback (most recent call last):\n', '  File "C:\\Users\\ZHao\\.conda\\envs\\scopefoundry\\lib\\site-packages\\ScopeFoundry\\measurement.py", line 273, in _on_display_update_timer\n    self.update_display()\n', '  File "C:\\Users\\Public\\quantum_sensing\\quantum_sensing\\fancy_microscope\\custommeasure2.py", line 359, in update_display\n    self.plotlines[rate].setVisible(self.settings[\'{}_visible\'.format(rate)])\n', "AttributeError: 'ESRMeasure' object has no attribute 'plotlines'\n"]
2022-02-18T11:03:48|ERROR|ESRMeasure|ESR_measurement Failed to update figure1: 'ESRMeasure' object has no attribute 'plotlines'. ['Traceback (most recent call last):\n', '  File "C:\\Users\\ZHao\\.conda\\envs\\scopefoundry\\lib\\site-packages\\ScopeFoundry\\measurement.py", line 273, in _on_display_update_timer\n    self.update_display()\n', '  File "C:\\Users\\Public\\quantum_sensing\\quantum_sensing\\fancy_microscope\\custommeasure2.py", line 359, in update_display\n    self.plotlines[rate].setVisible(self.settings[\'{}_visible\'.format(rate)])\n', "AttributeError: 'ESRMeasure' object has no attribute 'plotlines'\n"]
2022-02-18T11:03:48|ERROR|ESRMeasure|ESR_measurement Failed to update figure1: 'ESRMeasure' object has no attribute 'plotlines'. ['Traceback (most recent call last):\n', '  File "C:\\Users\\ZHao\\.conda\\envs\\scopefoundry\\lib\\site-packages\\ScopeFoundry\\measurement.py", line 273, in _on_display_update_timer\n    self.update_display()\n', '  File "C:\\Users\\Public\\quantum_sensing\\quantum_sensing\\fancy_microscope\\custommeasure2.py", line 359, in update_display\n    self.plotlines[rate].setVisible(self.settings[\'{}_visible\'.format(rate)])\n', "AttributeError: 'ESRMeasure' object has no attribute 'plotlines'\n"]
2022-02-18T11:03:48|ERROR|ESRMeasure|ESR_measurement Failed to update figure1: 'ESRMeasure' object has no attribute 'plotlines'. ['Traceback (most recent call last):\n', '  File "C:\\Users\\ZHao\\.conda\\envs\\scopefoundry\\lib\\site-packages\\ScopeFoundry\\measurement.py", line 273, in _on_display_update_timer\n    self.update_display()\n', '  File "C:\\Users\\Public\\quantum_sensing\\quantum_sensing\\fancy_microscope\\custommeasure2.py", line 359, in update_display\n    self.plotlines[rate].setVisible(self.settings[\'{}_visible\'.format(rate)])\n', "AttributeError: 'ESRMeasure' object has no attribute 'plotlines'\n"]
2022-02-18T11:03:49|ERROR|ESRMeasure|ESR_measurement Failed to update figure1: 'ESRMeasure' object has no attribute 'plotlines'. ['Traceback (most recent call last):\n', '  File "C:\\Users\\ZHao\\.conda\\envs\\scopefoundry\\lib\\site-packages\\ScopeFoundry\\measurement.py", line 273, in _on_display_update_timer\n    self.update_display()\n', '  File "C:\\Users\\Public\\quantum_sensing\\quantum_sensing\\fancy_microscope\\custommeasure2.py", line 359, in update_display\n    self.plotlines[rate].setVisible(self.settings[\'{}_visible\'.format(rate)])\n', "AttributeError: 'ESRMeasure' object has no attribute 'plotlines'\n"]
2022-02-18T11:03:49|ERROR|ESRMeasure|ESR_measurement Failed to update figure1: 'ESRMeasure' object has no attribute 'plotlines'. ['Traceback (most recent call last):\n', '  File "C:\\Users\\ZHao\\.conda\\envs\\scopefoundry\\lib\\site-packages\\ScopeFoundry\\measurement.py", line 273, in _on_display_update_timer\n    self.update_display()\n', '  File "C:\\Users\\Public\\quantum_sensing\\quantum_sensing\\fancy_microscope\\custommeasure2.py", line 359, in update_display\n    self.plotlines[rate].setVisible(self.settings[\'{}_visible\'.format(rate)])\n', "AttributeError: 'ESRMeasure' object has no attribute 'plotlines'\n"]
2022-02-18T11:03:49|ERROR|ESRMeasure|ESR_measurement Failed to update figure1: 'ESRMeasure' object has no attribute 'plotlines'. ['Traceback (most recent call last):\n', '  File "C:\\Users\\ZHao\\.conda\\envs\\scopefoundry\\lib\\site-packages\\ScopeFoundry\\measurement.py", line 273, in _on_display_update_timer\n    self.update_display()\n', '  File "C:\\Users\\Public\\quantum_sensing\\quantum_sensing\\fancy_microscope\\custommeasure2.py", line 359, in update_display\n    self.plotlines[rate].setVisible(self.settings[\'{}_visible\'.format(rate)])\n', "AttributeError: 'ESRMeasure' object has no attribute 'plotlines'\n"]
2022-02-18T11:03:49|ERROR|ESRMeasure|ESR_measurement Failed to update figure1: 'ESRMeasure' object has no attribute 'plotlines'. ['Traceback (most recent call last):\n', '  File "C:\\Users\\ZHao\\.conda\\envs\\scopefoundry\\lib\\site-packages\\ScopeFoundry\\measurement.py", line 273, in _on_display_update_timer\n    self.update_display()\n', '  File "C:\\Users\\Public\\quantum_sensing\\quantum_sensing\\fancy_microscope\\custommeasure2.py", line 359, in update_display\n    self.plotlines[rate].setVisible(self.settings[\'{}_visible\'.format(rate)])\n', "AttributeError: 'ESRMeasure' object has no attribute 'plotlines'\n"]
2022-02-18T11:03:49|ERROR|ESRMeasure|ESR_measurement Failed to update figure1: 'ESRMeasure' object has no attribute 'plotlines'. ['Traceback (most recent call last):\n', '  File "C:\\Users\\ZHao\\.conda\\envs\\scopefoundry\\lib\\site-packages\\ScopeFoundry\\measurement.py", line 273, in _on_display_update_timer\n    self.update_display()\n', '  File "C:\\Users\\Public\\quantum_sensing\\quantum_sensing\\fancy_microscope\\custommeasure2.py", line 359, in update_display\n    self.plotlines[rate].setVisible(self.settings[\'{}_visible\'.format(rate)])\n', "AttributeError: 'ESRMeasure' object has no attribute 'plotlines'\n"]
2022-02-18T11:03:49|ERROR|ESRMeasure|ESR_measurement Failed to update figure1: 'ESRMeasure' object has no attribute 'plotlines'. ['Traceback (most recent call last):\n', '  File "C:\\Users\\ZHao\\.conda\\envs\\scopefoundry\\lib\\site-packages\\ScopeFoundry\\measurement.py", line 273, in _on_display_update_timer\n    self.update_display()\n', '  File "C:\\Users\\Public\\quantum_sensing\\quantum_sensing\\fancy_microscope\\custommeasure2.py", line 359, in update_display\n    self.plotlines[rate].setVisible(self.settings[\'{}_visible\'.format(rate)])\n', "AttributeError: 'ESRMeasure' object has no attribute 'plotlines'\n"]
2022-02-18T11:03:49|ERROR|ESRMeasure|ESR_measurement Failed to update figure1: 'ESRMeasure' object has no attribute 'plotlines'. ['Traceback (most recent call last):\n', '  File "C:\\Users\\ZHao\\.conda\\envs\\scopefoundry\\lib\\site-packages\\ScopeFoundry\\measurement.py", line 273, in _on_display_update_timer\n    self.update_display()\n', '  File "C:\\Users\\Public\\quantum_sensing\\quantum_sensing\\fancy_microscope\\custommeasure2.py", line 359, in update_display\n    self.plotlines[rate].setVisible(self.settings[\'{}_visible\'.format(rate)])\n', "AttributeError: 'ESRMeasure' object has no attribute 'plotlines'\n"]
2022-02-18T11:03:49|ERROR|ESRMeasure|ESR_measurement Failed to update figure1: 'ESRMeasure' object has no attribute 'plotlines'. ['Traceback (most recent call last):\n', '  File "C:\\Users\\ZHao\\.conda\\envs\\scopefoundry\\lib\\site-packages\\ScopeFoundry\\measurement.py", line 273, in _on_display_update_timer\n    self.update_display()\n', '  File "C:\\Users\\Public\\quantum_sensing\\quantum_sensing\\fancy_microscope\\custommeasure2.py", line 359, in update_display\n    self.plotlines[rate].setVisible(self.settings[\'{}_visible\'.format(rate)])\n', "AttributeError: 'ESRMeasure' object has no attribute 'plotlines'\n"]
2022-02-18T11:03:49|ERROR|ESRMeasure|ESR_measurement Failed to update figure1: 'ESRMeasure' object has no attribute 'plotlines'. ['Traceback (most recent call last):\n', '  File "C:\\Users\\ZHao\\.conda\\envs\\scopefoundry\\lib\\site-packages\\ScopeFoundry\\measurement.py", line 273, in _on_display_update_timer\n    self.update_display()\n', '  File "C:\\Users\\Public\\quantum_sensing\\quantum_sensing\\fancy_microscope\\custommeasure2.py", line 359, in update_display\n    self.plotlines[rate].setVisible(self.settings[\'{}_visible\'.format(rate)])\n', "AttributeError: 'ESRMeasure' object has no attribute 'plotlines'\n"]
2022-02-18T11:03:50|ERROR|ESRMeasure|ESR_measurement Failed to update figure1: 'ESRMeasure' object has no attribute 'plotlines'. ['Traceback (most recent call last):\n', '  File "C:\\Users\\ZHao\\.conda\\envs\\scopefoundry\\lib\\site-packages\\ScopeFoundry\\measurement.py", line 273, in _on_display_update_timer\n    self.update_display()\n', '  File "C:\\Users\\Public\\quantum_sensing\\quantum_sensing\\fancy_microscope\\custommeasure2.py", line 359, in update_display\n    self.plotlines[rate].setVisible(self.settings[\'{}_visible\'.format(rate)])\n', "AttributeError: 'ESRMeasure' object has no attribute 'plotlines'\n"]
2022-02-18T11:03:50|ERROR|ESRMeasure|ESR_measurement Failed to update figure1: 'ESRMeasure' object has no attribute 'plotlines'. ['Traceback (most recent call last):\n', '  File "C:\\Users\\ZHao\\.conda\\envs\\scopefoundry\\lib\\site-packages\\ScopeFoundry\\measurement.py", line 273, in _on_display_update_timer\n    self.update_display()\n', '  File "C:\\Users\\Public\\quantum_sensing\\quantum_sensing\\fancy_microscope\\custommeasure2.py", line 359, in update_display\n    self.plotlines[rate].setVisible(self.settings[\'{}_visible\'.format(rate)])\n', "AttributeError: 'ESRMeasure' object has no attribute 'plotlines'\n"]
2022-02-18T11:03:50|ERROR|ESRMeasure|ESR_measurement Failed to update figure1: 'ESRMeasure' object has no attribute 'plotlines'. ['Traceback (most recent call last):\n', '  File "C:\\Users\\ZHao\\.conda\\envs\\scopefoundry\\lib\\site-packages\\ScopeFoundry\\measurement.py", line 273, in _on_display_update_timer\n    self.update_display()\n', '  File "C:\\Users\\Public\\quantum_sensing\\quantum_sensing\\fancy_microscope\\custommeasure2.py", line 359, in update_display\n    self.plotlines[rate].setVisible(self.settings[\'{}_visible\'.format(rate)])\n', "AttributeError: 'ESRMeasure' object has no attribute 'plotlines'\n"]
2022-02-18T11:03:50|ERROR|ESRMeasure|ESR_measurement Failed to update figure1: 'ESRMeasure' object has no attribute 'plotlines'. ['Traceback (most recent call last):\n', '  File "C:\\Users\\ZHao\\.conda\\envs\\scopefoundry\\lib\\site-packages\\ScopeFoundry\\measurement.py", line 273, in _on_display_update_timer\n    self.update_display()\n', '  File "C:\\Users\\Public\\quantum_sensing\\quantum_sensing\\fancy_microscope\\custommeasure2.py", line 359, in update_display\n    self.plotlines[rate].setVisible(self.settings[\'{}_visible\'.format(rate)])\n', "AttributeError: 'ESRMeasure' object has no attribute 'plotlines'\n"]
2022-02-18T11:03:50|ERROR|ESRMeasure|ESR_measurement Failed to update figure1: 'ESRMeasure' object has no attribute 'plotlines'. ['Traceback (most recent call last):\n', '  File "C:\\Users\\ZHao\\.conda\\envs\\scopefoundry\\lib\\site-packages\\ScopeFoundry\\measurement.py", line 273, in _on_display_update_timer\n    self.update_display()\n', '  File "C:\\Users\\Public\\quantum_sensing\\quantum_sensing\\fancy_microscope\\custommeasure2.py", line 359, in update_display\n    self.plotlines[rate].setVisible(self.settings[\'{}_visible\'.format(rate)])\n', "AttributeError: 'ESRMeasure' object has no attribute 'plotlines'\n"]
2022-02-18T11:03:50|ERROR|ESRMeasure|ESR_measurement Failed to update figure1: 'ESRMeasure' object has no attribute 'plotlines'. ['Traceback (most recent call last):\n', '  File "C:\\Users\\ZHao\\.conda\\envs\\scopefoundry\\lib\\site-packages\\ScopeFoundry\\measurement.py", line 273, in _on_display_update_timer\n    self.update_display()\n', '  File "C:\\Users\\Public\\quantum_sensing\\quantum_sensing\\fancy_microscope\\custommeasure2.py", line 359, in update_display\n    self.plotlines[rate].setVisible(self.settings[\'{}_visible\'.format(rate)])\n', "AttributeError: 'ESRMeasure' object has no attribute 'plotlines'\n"]
2022-02-18T11:03:50|ERROR|ESRMeasure|ESR_measurement Failed to update figure1: 'ESRMeasure' object has no attribute 'plotlines'. ['Traceback (most recent call last):\n', '  File "C:\\Users\\ZHao\\.conda\\envs\\scopefoundry\\lib\\site-packages\\ScopeFoundry\\measurement.py", line 273, in _on_display_update_timer\n    self.update_display()\n', '  File "C:\\Users\\Public\\quantum_sensing\\quantum_sensing\\fancy_microscope\\custommeasure2.py", line 359, in update_display\n    self.plotlines[rate].setVisible(self.settings[\'{}_visible\'.format(rate)])\n', "AttributeError: 'ESRMeasure' object has no attribute 'plotlines'\n"]
2022-02-18T11:03:51|ERROR|ESRMeasure|ESR_measurement Failed to update figure1: 'ESRMeasure' object has no attribute 'plotlines'. ['Traceback (most recent call last):\n', '  File "C:\\Users\\ZHao\\.conda\\envs\\scopefoundry\\lib\\site-packages\\ScopeFoundry\\measurement.py", line 273, in _on_display_update_timer\n    self.update_display()\n', '  File "C:\\Users\\Public\\quantum_sensing\\quantum_sensing\\fancy_microscope\\custommeasure2.py", line 359, in update_display\n    self.plotlines[rate].setVisible(self.settings[\'{}_visible\'.format(rate)])\n', "AttributeError: 'ESRMeasure' object has no attribute 'plotlines'\n"]
2022-02-18T11:03:51|ERROR|ESRMeasure|ESR_measurement Failed to update figure1: 'ESRMeasure' object has no attribute 'plotlines'. ['Traceback (most recent call last):\n', '  File "C:\\Users\\ZHao\\.conda\\envs\\scopefoundry\\lib\\site-packages\\ScopeFoundry\\measurement.py", line 273, in _on_display_update_timer\n    self.update_display()\n', '  File "C:\\Users\\Public\\quantum_sensing\\quantum_sensing\\fancy_microscope\\custommeasure2.py", line 359, in update_display\n    self.plotlines[rate].setVisible(self.settings[\'{}_visible\'.format(rate)])\n', "AttributeError: 'ESRMeasure' object has no attribute 'plotlines'\n"]
2022-02-18T11:03:51|ERROR|ESRMeasure|ESR_measurement Failed to update figure1: 'ESRMeasure' object has no attribute 'plotlines'. ['Traceback (most recent call last):\n', '  File "C:\\Users\\ZHao\\.conda\\envs\\scopefoundry\\lib\\site-packages\\ScopeFoundry\\measurement.py", line 273, in _on_display_update_timer\n    self.update_display()\n', '  File "C:\\Users\\Public\\quantum_sensing\\quantum_sensing\\fancy_microscope\\custommeasure2.py", line 359, in update_display\n    self.plotlines[rate].setVisible(self.settings[\'{}_visible\'.format(rate)])\n', "AttributeError: 'ESRMeasure' object has no attribute 'plotlines'\n"]
2022-02-18T11:03:51|ERROR|ESRMeasure|ESR_measurement Failed to update figure1: 'ESRMeasure' object has no attribute 'plotlines'. ['Traceback (most recent call last):\n', '  File "C:\\Users\\ZHao\\.conda\\envs\\scopefoundry\\lib\\site-packages\\ScopeFoundry\\measurement.py", line 273, in _on_display_update_timer\n    self.update_display()\n', '  File "C:\\Users\\Public\\quantum_sensing\\quantum_sensing\\fancy_microscope\\custommeasure2.py", line 359, in update_display\n    self.plotlines[rate].setVisible(self.settings[\'{}_visible\'.format(rate)])\n', "AttributeError: 'ESRMeasure' object has no attribute 'plotlines'\n"]
2022-02-18T11:03:51|ERROR|ESRMeasure|ESR_measurement Failed to update figure1: 'ESRMeasure' object has no attribute 'plotlines'. ['Traceback (most recent call last):\n', '  File "C:\\Users\\ZHao\\.conda\\envs\\scopefoundry\\lib\\site-packages\\ScopeFoundry\\measurement.py", line 273, in _on_display_update_timer\n    self.update_display()\n', '  File "C:\\Users\\Public\\quantum_sensing\\quantum_sensing\\fancy_microscope\\custommeasure2.py", line 359, in update_display\n    self.plotlines[rate].setVisible(self.settings[\'{}_visible\'.format(rate)])\n', "AttributeError: 'ESRMeasure' object has no attribute 'plotlines'\n"]
2022-02-18T11:03:51|ERROR|ESRMeasure|ESR_measurement Failed to update figure1: 'ESRMeasure' object has no attribute 'plotlines'. ['Traceback (most recent call last):\n', '  File "C:\\Users\\ZHao\\.conda\\envs\\scopefoundry\\lib\\site-packages\\ScopeFoundry\\measurement.py", line 273, in _on_display_update_timer\n    self.update_display()\n', '  File "C:\\Users\\Public\\quantum_sensing\\quantum_sensing\\fancy_microscope\\custommeasure2.py", line 359, in update_display\n    self.plotlines[rate].setVisible(self.settings[\'{}_visible\'.format(rate)])\n', "AttributeError: 'ESRMeasure' object has no attribute 'plotlines'\n"]
2022-02-18T11:03:52|ERROR|ESRMeasure|ESR_measurement Failed to update figure1: 'ESRMeasure' object has no attribute 'plotlines'. ['Traceback (most recent call last):\n', '  File "C:\\Users\\ZHao\\.conda\\envs\\scopefoundry\\lib\\site-packages\\ScopeFoundry\\measurement.py", line 273, in _on_display_update_timer\n    self.update_display()\n', '  File "C:\\Users\\Public\\quantum_sensing\\quantum_sensing\\fancy_microscope\\custommeasure2.py", line 359, in update_display\n    self.plotlines[rate].setVisible(self.settings[\'{}_visible\'.format(rate)])\n', "AttributeError: 'ESRMeasure' object has no attribute 'plotlines'\n"]
2022-02-18T11:03:52|ERROR|ESRMeasure|ESR_measurement Failed to update figure1: 'ESRMeasure' object has no attribute 'plotlines'. ['Traceback (most recent call last):\n', '  File "C:\\Users\\ZHao\\.conda\\envs\\scopefoundry\\lib\\site-packages\\ScopeFoundry\\measurement.py", line 273, in _on_display_update_timer\n    self.update_display()\n', '  File "C:\\Users\\Public\\quantum_sensing\\quantum_sensing\\fancy_microscope\\custommeasure2.py", line 359, in update_display\n    self.plotlines[rate].setVisible(self.settings[\'{}_visible\'.format(rate)])\n', "AttributeError: 'ESRMeasure' object has no attribute 'plotlines'\n"]
2022-02-18T11:03:52|ERROR|ESRMeasure|ESR_measurement Failed to update figure1: 'ESRMeasure' object has no attribute 'plotlines'. ['Traceback (most recent call last):\n', '  File "C:\\Users\\ZHao\\.conda\\envs\\scopefoundry\\lib\\site-packages\\ScopeFoundry\\measurement.py", line 273, in _on_display_update_timer\n    self.update_display()\n', '  File "C:\\Users\\Public\\quantum_sensing\\quantum_sensing\\fancy_microscope\\custommeasure2.py", line 359, in update_display\n    self.plotlines[rate].setVisible(self.settings[\'{}_visible\'.format(rate)])\n', "AttributeError: 'ESRMeasure' object has no attribute 'plotlines'\n"]
2022-02-18T11:03:52|ERROR|ESRMeasure|ESR_measurement Failed to update figure1: 'ESRMeasure' object has no attribute 'plotlines'. ['Traceback (most recent call last):\n', '  File "C:\\Users\\ZHao\\.conda\\envs\\scopefoundry\\lib\\site-packages\\ScopeFoundry\\measurement.py", line 273, in _on_display_update_timer\n    self.update_display()\n', '  File "C:\\Users\\Public\\quantum_sensing\\quantum_sensing\\fancy_microscope\\custommeasure2.py", line 359, in update_display\n    self.plotlines[rate].setVisible(self.settings[\'{}_visible\'.format(rate)])\n', "AttributeError: 'ESRMeasure' object has no attribute 'plotlines'\n"]
2022-02-18T11:03:52|ERROR|ESRMeasure|ESR_measurement Failed to update figure1: 'ESRMeasure' object has no attribute 'plotlines'. ['Traceback (most recent call last):\n', '  File "C:\\Users\\ZHao\\.conda\\envs\\scopefoundry\\lib\\site-packages\\ScopeFoundry\\measurement.py", line 273, in _on_display_update_timer\n    self.update_display()\n', '  File "C:\\Users\\Public\\quantum_sensing\\quantum_sensing\\fancy_microscope\\custommeasure2.py", line 359, in update_display\n    self.plotlines[rate].setVisible(self.settings[\'{}_visible\'.format(rate)])\n', "AttributeError: 'ESRMeasure' object has no attribute 'plotlines'\n"]
2022-02-18T11:03:52|ERROR|ESRMeasure|ESR_measurement Failed to update figure1: 'ESRMeasure' object has no attribute 'plotlines'. ['Traceback (most recent call last):\n', '  File "C:\\Users\\ZHao\\.conda\\envs\\scopefoundry\\lib\\site-packages\\ScopeFoundry\\measurement.py", line 273, in _on_display_update_timer\n    self.update_display()\n', '  File "C:\\Users\\Public\\quantum_sensing\\quantum_sensing\\fancy_microscope\\custommeasure2.py", line 359, in update_display\n    self.plotlines[rate].setVisible(self.settings[\'{}_visible\'.format(rate)])\n', "AttributeError: 'ESRMeasure' object has no attribute 'plotlines'\n"]
2022-02-18T11:03:52|ERROR|ESRMeasure|ESR_measurement Failed to update figure1: 'ESRMeasure' object has no attribute 'plotlines'. ['Traceback (most recent call last):\n', '  File "C:\\Users\\ZHao\\.conda\\envs\\scopefoundry\\lib\\site-packages\\ScopeFoundry\\measurement.py", line 273, in _on_display_update_timer\n    self.update_display()\n', '  File "C:\\Users\\Public\\quantum_sensing\\quantum_sensing\\fancy_microscope\\custommeasure2.py", line 359, in update_display\n    self.plotlines[rate].setVisible(self.settings[\'{}_visible\'.format(rate)])\n', "AttributeError: 'ESRMeasure' object has no attribute 'plotlines'\n"]
2022-02-18T11:03:52|ERROR|ESRMeasure|ESR_measurement Failed to update figure1: 'ESRMeasure' object has no attribute 'plotlines'. ['Traceback (most recent call last):\n', '  File "C:\\Users\\ZHao\\.conda\\envs\\scopefoundry\\lib\\site-packages\\ScopeFoundry\\measurement.py", line 273, in _on_display_update_timer\n    self.update_display()\n', '  File "C:\\Users\\Public\\quantum_sensing\\quantum_sensing\\fancy_microscope\\custommeasure2.py", line 359, in update_display\n    self.plotlines[rate].setVisible(self.settings[\'{}_visible\'.format(rate)])\n', "AttributeError: 'ESRMeasure' object has no attribute 'plotlines'\n"]
2022-02-18T11:03:53|ERROR|ESRMeasure|ESR_measurement Failed to update figure1: 'ESRMeasure' object has no attribute 'plotlines'. ['Traceback (most recent call last):\n', '  File "C:\\Users\\ZHao\\.conda\\envs\\scopefoundry\\lib\\site-packages\\ScopeFoundry\\measurement.py", line 273, in _on_display_update_timer\n    self.update_display()\n', '  File "C:\\Users\\Public\\quantum_sensing\\quantum_sensing\\fancy_microscope\\custommeasure2.py", line 359, in update_display\n    self.plotlines[rate].setVisible(self.settings[\'{}_visible\'.format(rate)])\n', "AttributeError: 'ESRMeasure' object has no attribute 'plotlines'\n"]
2022-02-18T11:03:53|ERROR|ESRMeasure|ESR_measurement Failed to update figure1: 'ESRMeasure' object has no attribute 'plotlines'. ['Traceback (most recent call last):\n', '  File "C:\\Users\\ZHao\\.conda\\envs\\scopefoundry\\lib\\site-packages\\ScopeFoundry\\measurement.py", line 273, in _on_display_update_timer\n    self.update_display()\n', '  File "C:\\Users\\Public\\quantum_sensing\\quantum_sensing\\fancy_microscope\\custommeasure2.py", line 359, in update_display\n    self.plotlines[rate].setVisible(self.settings[\'{}_visible\'.format(rate)])\n', "AttributeError: 'ESRMeasure' object has no attribute 'plotlines'\n"]
2022-02-18T11:03:53|ERROR|ESRMeasure|ESR_measurement Failed to update figure1: 'ESRMeasure' object has no attribute 'plotlines'. ['Traceback (most recent call last):\n', '  File "C:\\Users\\ZHao\\.conda\\envs\\scopefoundry\\lib\\site-packages\\ScopeFoundry\\measurement.py", line 273, in _on_display_update_timer\n    self.update_display()\n', '  File "C:\\Users\\Public\\quantum_sensing\\quantum_sensing\\fancy_microscope\\custommeasure2.py", line 359, in update_display\n    self.plotlines[rate].setVisible(self.settings[\'{}_visible\'.format(rate)])\n', "AttributeError: 'ESRMeasure' object has no attribute 'plotlines'\n"]
2022-02-18T11:03:53|ERROR|ESRMeasure|ESR_measurement Failed to update figure1: 'ESRMeasure' object has no attribute 'plotlines'. ['Traceback (most recent call last):\n', '  File "C:\\Users\\ZHao\\.conda\\envs\\scopefoundry\\lib\\site-packages\\ScopeFoundry\\measurement.py", line 273, in _on_display_update_timer\n    self.update_display()\n', '  File "C:\\Users\\Public\\quantum_sensing\\quantum_sensing\\fancy_microscope\\custommeasure2.py", line 359, in update_display\n    self.plotlines[rate].setVisible(self.settings[\'{}_visible\'.format(rate)])\n', "AttributeError: 'ESRMeasure' object has no attribute 'plotlines'\n"]
2022-02-18T11:03:53|ERROR|ESRMeasure|ESR_measurement Failed to update figure1: 'ESRMeasure' object has no attribute 'plotlines'. ['Traceback (most recent call last):\n', '  File "C:\\Users\\ZHao\\.conda\\envs\\scopefoundry\\lib\\site-packages\\ScopeFoundry\\measurement.py", line 273, in _on_display_update_timer\n    self.update_display()\n', '  File "C:\\Users\\Public\\quantum_sensing\\quantum_sensing\\fancy_microscope\\custommeasure2.py", line 359, in update_display\n    self.plotlines[rate].setVisible(self.settings[\'{}_visible\'.format(rate)])\n', "AttributeError: 'ESRMeasure' object has no attribute 'plotlines'\n"]
2022-02-18T11:03:53|ERROR|ESRMeasure|ESR_measurement Failed to update figure1: 'ESRMeasure' object has no attribute 'plotlines'. ['Traceback (most recent call last):\n', '  File "C:\\Users\\ZHao\\.conda\\envs\\scopefoundry\\lib\\site-packages\\ScopeFoundry\\measurement.py", line 273, in _on_display_update_timer\n    self.update_display()\n', '  File "C:\\Users\\Public\\quantum_sensing\\quantum_sensing\\fancy_microscope\\custommeasure2.py", line 359, in update_display\n    self.plotlines[rate].setVisible(self.settings[\'{}_visible\'.format(rate)])\n', "AttributeError: 'ESRMeasure' object has no attribute 'plotlines'\n"]
2022-02-18T11:03:53|ERROR|ESRMeasure|ESR_measurement Failed to update figure1: 'ESRMeasure' object has no attribute 'plotlines'. ['Traceback (most recent call last):\n', '  File "C:\\Users\\ZHao\\.conda\\envs\\scopefoundry\\lib\\site-packages\\ScopeFoundry\\measurement.py", line 273, in _on_display_update_timer\n    self.update_display()\n', '  File "C:\\Users\\Public\\quantum_sensing\\quantum_sensing\\fancy_microscope\\custommeasure2.py", line 359, in update_display\n    self.plotlines[rate].setVisible(self.settings[\'{}_visible\'.format(rate)])\n', "AttributeError: 'ESRMeasure' object has no attribute 'plotlines'\n"]
2022-02-18T11:03:53|ERROR|ESRMeasure|ESR_measurement Failed to update figure1: 'ESRMeasure' object has no attribute 'plotlines'. ['Traceback (most recent call last):\n', '  File "C:\\Users\\ZHao\\.conda\\envs\\scopefoundry\\lib\\site-packages\\ScopeFoundry\\measurement.py", line 273, in _on_display_update_timer\n    self.update_display()\n', '  File "C:\\Users\\Public\\quantum_sensing\\quantum_sensing\\fancy_microscope\\custommeasure2.py", line 359, in update_display\n    self.plotlines[rate].setVisible(self.settings[\'{}_visible\'.format(rate)])\n', "AttributeError: 'ESRMeasure' object has no attribute 'plotlines'\n"]
2022-02-18T11:03:53|ERROR|ESRMeasure|ESR_measurement Failed to update figure1: 'ESRMeasure' object has no attribute 'plotlines'. ['Traceback (most recent call last):\n', '  File "C:\\Users\\ZHao\\.conda\\envs\\scopefoundry\\lib\\site-packages\\ScopeFoundry\\measurement.py", line 273, in _on_display_update_timer\n    self.update_display()\n', '  File "C:\\Users\\Public\\quantum_sensing\\quantum_sensing\\fancy_microscope\\custommeasure2.py", line 359, in update_display\n    self.plotlines[rate].setVisible(self.settings[\'{}_visible\'.format(rate)])\n', "AttributeError: 'ESRMeasure' object has no attribute 'plotlines'\n"]
2022-02-18T11:03:54|ERROR|ESRMeasure|ESR_measurement Failed to update figure1: 'ESRMeasure' object has no attribute 'plotlines'. ['Traceback (most recent call last):\n', '  File "C:\\Users\\ZHao\\.conda\\envs\\scopefoundry\\lib\\site-packages\\ScopeFoundry\\measurement.py", line 273, in _on_display_update_timer\n    self.update_display()\n', '  File "C:\\Users\\Public\\quantum_sensing\\quantum_sensing\\fancy_microscope\\custommeasure2.py", line 359, in update_display\n    self.plotlines[rate].setVisible(self.settings[\'{}_visible\'.format(rate)])\n', "AttributeError: 'ESRMeasure' object has no attribute 'plotlines'\n"]
2022-02-18T11:03:54|ERROR|ESRMeasure|ESR_measurement Failed to update figure1: 'ESRMeasure' object has no attribute 'plotlines'. ['Traceback (most recent call last):\n', '  File "C:\\Users\\ZHao\\.conda\\envs\\scopefoundry\\lib\\site-packages\\ScopeFoundry\\measurement.py", line 273, in _on_display_update_timer\n    self.update_display()\n', '  File "C:\\Users\\Public\\quantum_sensing\\quantum_sensing\\fancy_microscope\\custommeasure2.py", line 359, in update_display\n    self.plotlines[rate].setVisible(self.settings[\'{}_visible\'.format(rate)])\n', "AttributeError: 'ESRMeasure' object has no attribute 'plotlines'\n"]
2022-02-18T11:03:54|ERROR|ESRMeasure|ESR_measurement Failed to update figure1: 'ESRMeasure' object has no attribute 'plotlines'. ['Traceback (most recent call last):\n', '  File "C:\\Users\\ZHao\\.conda\\envs\\scopefoundry\\lib\\site-packages\\ScopeFoundry\\measurement.py", line 273, in _on_display_update_timer\n    self.update_display()\n', '  File "C:\\Users\\Public\\quantum_sensing\\quantum_sensing\\fancy_microscope\\custommeasure2.py", line 359, in update_display\n    self.plotlines[rate].setVisible(self.settings[\'{}_visible\'.format(rate)])\n', "AttributeError: 'ESRMeasure' object has no attribute 'plotlines'\n"]
2022-02-18T11:03:54|ERROR|ESRMeasure|ESR_measurement Failed to update figure1: 'ESRMeasure' object has no attribute 'plotlines'. ['Traceback (most recent call last):\n', '  File "C:\\Users\\ZHao\\.conda\\envs\\scopefoundry\\lib\\site-packages\\ScopeFoundry\\measurement.py", line 273, in _on_display_update_timer\n    self.update_display()\n', '  File "C:\\Users\\Public\\quantum_sensing\\quantum_sensing\\fancy_microscope\\custommeasure2.py", line 359, in update_display\n    self.plotlines[rate].setVisible(self.settings[\'{}_visible\'.format(rate)])\n', "AttributeError: 'ESRMeasure' object has no attribute 'plotlines'\n"]
2022-02-18T11:03:54|ERROR|ESRMeasure|ESR_measurement Failed to update figure1: 'ESRMeasure' object has no attribute 'plotlines'. ['Traceback (most recent call last):\n', '  File "C:\\Users\\ZHao\\.conda\\envs\\scopefoundry\\lib\\site-packages\\ScopeFoundry\\measurement.py", line 273, in _on_display_update_timer\n    self.update_display()\n', '  File "C:\\Users\\Public\\quantum_sensing\\quantum_sensing\\fancy_microscope\\custommeasure2.py", line 359, in update_display\n    self.plotlines[rate].setVisible(self.settings[\'{}_visible\'.format(rate)])\n', "AttributeError: 'ESRMeasure' object has no attribute 'plotlines'\n"]
2022-02-18T11:03:54|ERROR|ESRMeasure|ESR_measurement Failed to update figure1: 'ESRMeasure' object has no attribute 'plotlines'. ['Traceback (most recent call last):\n', '  File "C:\\Users\\ZHao\\.conda\\envs\\scopefoundry\\lib\\site-packages\\ScopeFoundry\\measurement.py", line 273, in _on_display_update_timer\n    self.update_display()\n', '  File "C:\\Users\\Public\\quantum_sensing\\quantum_sensing\\fancy_microscope\\custommeasure2.py", line 359, in update_display\n    self.plotlines[rate].setVisible(self.settings[\'{}_visible\'.format(rate)])\n', "AttributeError: 'ESRMeasure' object has no attribute 'plotlines'\n"]
2022-02-18T11:03:54|ERROR|ESRMeasure|ESR_measurement Failed to update figure1: 'ESRMeasure' object has no attribute 'plotlines'. ['Traceback (most recent call last):\n', '  File "C:\\Users\\ZHao\\.conda\\envs\\scopefoundry\\lib\\site-packages\\ScopeFoundry\\measurement.py", line 273, in _on_display_update_timer\n    self.update_display()\n', '  File "C:\\Users\\Public\\quantum_sensing\\quantum_sensing\\fancy_microscope\\custommeasure2.py", line 359, in update_display\n    self.plotlines[rate].setVisible(self.settings[\'{}_visible\'.format(rate)])\n', "AttributeError: 'ESRMeasure' object has no attribute 'plotlines'\n"]
2022-02-18T11:03:54|ERROR|ESRMeasure|ESR_measurement Failed to update figure1: 'ESRMeasure' object has no attribute 'plotlines'. ['Traceback (most recent call last):\n', '  File "C:\\Users\\ZHao\\.conda\\envs\\scopefoundry\\lib\\site-packages\\ScopeFoundry\\measurement.py", line 273, in _on_display_update_timer\n    self.update_display()\n', '  File "C:\\Users\\Public\\quantum_sensing\\quantum_sensing\\fancy_microscope\\custommeasure2.py", line 359, in update_display\n    self.plotlines[rate].setVisible(self.settings[\'{}_visible\'.format(rate)])\n', "AttributeError: 'ESRMeasure' object has no attribute 'plotlines'\n"]
2022-02-18T11:03:54|ERROR|ESRMeasure|ESR_measurement Failed to update figure1: 'ESRMeasure' object has no attribute 'plotlines'. ['Traceback (most recent call last):\n', '  File "C:\\Users\\ZHao\\.conda\\envs\\scopefoundry\\lib\\site-packages\\ScopeFoundry\\measurement.py", line 273, in _on_display_update_timer\n    self.update_display()\n', '  File "C:\\Users\\Public\\quantum_sensing\\quantum_sensing\\fancy_microscope\\custommeasure2.py", line 359, in update_display\n    self.plotlines[rate].setVisible(self.settings[\'{}_visible\'.format(rate)])\n', "AttributeError: 'ESRMeasure' object has no attribute 'plotlines'\n"]
2022-02-18T11:03:55|ERROR|ESRMeasure|ESR_measurement Failed to update figure1: 'ESRMeasure' object has no attribute 'plotlines'. ['Traceback (most recent call last):\n', '  File "C:\\Users\\ZHao\\.conda\\envs\\scopefoundry\\lib\\site-packages\\ScopeFoundry\\measurement.py", line 273, in _on_display_update_timer\n    self.update_display()\n', '  File "C:\\Users\\Public\\quantum_sensing\\quantum_sensing\\fancy_microscope\\custommeasure2.py", line 359, in update_display\n    self.plotlines[rate].setVisible(self.settings[\'{}_visible\'.format(rate)])\n', "AttributeError: 'ESRMeasure' object has no attribute 'plotlines'\n"]
2022-02-18T11:03:55|ERROR|ESRMeasure|ESR_measurement Failed to update figure1: 'ESRMeasure' object has no attribute 'plotlines'. ['Traceback (most recent call last):\n', '  File "C:\\Users\\ZHao\\.conda\\envs\\scopefoundry\\lib\\site-packages\\ScopeFoundry\\measurement.py", line 273, in _on_display_update_timer\n    self.update_display()\n', '  File "C:\\Users\\Public\\quantum_sensing\\quantum_sensing\\fancy_microscope\\custommeasure2.py", line 359, in update_display\n    self.plotlines[rate].setVisible(self.settings[\'{}_visible\'.format(rate)])\n', "AttributeError: 'ESRMeasure' object has no attribute 'plotlines'\n"]
2022-02-18T11:03:55|ERROR|ESRMeasure|ESR_measurement Failed to update figure1: 'ESRMeasure' object has no attribute 'plotlines'. ['Traceback (most recent call last):\n', '  File "C:\\Users\\ZHao\\.conda\\envs\\scopefoundry\\lib\\site-packages\\ScopeFoundry\\measurement.py", line 273, in _on_display_update_timer\n    self.update_display()\n', '  File "C:\\Users\\Public\\quantum_sensing\\quantum_sensing\\fancy_microscope\\custommeasure2.py", line 359, in update_display\n    self.plotlines[rate].setVisible(self.settings[\'{}_visible\'.format(rate)])\n', "AttributeError: 'ESRMeasure' object has no attribute 'plotlines'\n"]
2022-02-18T11:03:55|ERROR|ESRMeasure|ESR_measurement Failed to update figure1: 'ESRMeasure' object has no attribute 'plotlines'. ['Traceback (most recent call last):\n', '  File "C:\\Users\\ZHao\\.conda\\envs\\scopefoundry\\lib\\site-packages\\ScopeFoundry\\measurement.py", line 273, in _on_display_update_timer\n    self.update_display()\n', '  File "C:\\Users\\Public\\quantum_sensing\\quantum_sensing\\fancy_microscope\\custommeasure2.py", line 359, in update_display\n    self.plotlines[rate].setVisible(self.settings[\'{}_visible\'.format(rate)])\n', "AttributeError: 'ESRMeasure' object has no attribute 'plotlines'\n"]
2022-02-18T11:03:55|ERROR|ESRMeasure|ESR_measurement Failed to update figure1: 'ESRMeasure' object has no attribute 'plotlines'. ['Traceback (most recent call last):\n', '  File "C:\\Users\\ZHao\\.conda\\envs\\scopefoundry\\lib\\site-packages\\ScopeFoundry\\measurement.py", line 273, in _on_display_update_timer\n    self.update_display()\n', '  File "C:\\Users\\Public\\quantum_sensing\\quantum_sensing\\fancy_microscope\\custommeasure2.py", line 359, in update_display\n    self.plotlines[rate].setVisible(self.settings[\'{}_visible\'.format(rate)])\n', "AttributeError: 'ESRMeasure' object has no attribute 'plotlines'\n"]
2022-02-18T11:03:55|ERROR|ESRMeasure|ESR_measurement Failed to update figure1: 'ESRMeasure' object has no attribute 'plotlines'. ['Traceback (most recent call last):\n', '  File "C:\\Users\\ZHao\\.conda\\envs\\scopefoundry\\lib\\site-packages\\ScopeFoundry\\measurement.py", line 273, in _on_display_update_timer\n    self.update_display()\n', '  File "C:\\Users\\Public\\quantum_sensing\\quantum_sensing\\fancy_microscope\\custommeasure2.py", line 359, in update_display\n    self.plotlines[rate].setVisible(self.settings[\'{}_visible\'.format(rate)])\n', "AttributeError: 'ESRMeasure' object has no attribute 'plotlines'\n"]
2022-02-18T11:03:55|ERROR|ESRMeasure|ESR_measurement Failed to update figure1: 'ESRMeasure' object has no attribute 'plotlines'. ['Traceback (most recent call last):\n', '  File "C:\\Users\\ZHao\\.conda\\envs\\scopefoundry\\lib\\site-packages\\ScopeFoundry\\measurement.py", line 273, in _on_display_update_timer\n    self.update_display()\n', '  File "C:\\Users\\Public\\quantum_sensing\\quantum_sensing\\fancy_microscope\\custommeasure2.py", line 359, in update_display\n    self.plotlines[rate].setVisible(self.settings[\'{}_visible\'.format(rate)])\n', "AttributeError: 'ESRMeasure' object has no attribute 'plotlines'\n"]
2022-02-18T11:03:55|ERROR|ESRMeasure|ESR_measurement Failed to update figure1: 'ESRMeasure' object has no attribute 'plotlines'. ['Traceback (most recent call last):\n', '  File "C:\\Users\\ZHao\\.conda\\envs\\scopefoundry\\lib\\site-packages\\ScopeFoundry\\measurement.py", line 273, in _on_display_update_timer\n    self.update_display()\n', '  File "C:\\Users\\Public\\quantum_sensing\\quantum_sensing\\fancy_microscope\\custommeasure2.py", line 359, in update_display\n    self.plotlines[rate].setVisible(self.settings[\'{}_visible\'.format(rate)])\n', "AttributeError: 'ESRMeasure' object has no attribute 'plotlines'\n"]
2022-02-18T11:03:55|ERROR|ESRMeasure|ESR_measurement Failed to update figure1: 'ESRMeasure' object has no attribute 'plotlines'. ['Traceback (most recent call last):\n', '  File "C:\\Users\\ZHao\\.conda\\envs\\scopefoundry\\lib\\site-packages\\ScopeFoundry\\measurement.py", line 273, in _on_display_update_timer\n    self.update_display()\n', '  File "C:\\Users\\Public\\quantum_sensing\\quantum_sensing\\fancy_microscope\\custommeasure2.py", line 359, in update_display\n    self.plotlines[rate].setVisible(self.settings[\'{}_visible\'.format(rate)])\n', "AttributeError: 'ESRMeasure' object has no attribute 'plotlines'\n"]
2022-02-18T11:03:56|ERROR|ESRMeasure|ESR_measurement Failed to update figure1: 'ESRMeasure' object has no attribute 'plotlines'. ['Traceback (most recent call last):\n', '  File "C:\\Users\\ZHao\\.conda\\envs\\scopefoundry\\lib\\site-packages\\ScopeFoundry\\measurement.py", line 273, in _on_display_update_timer\n    self.update_display()\n', '  File "C:\\Users\\Public\\quantum_sensing\\quantum_sensing\\fancy_microscope\\custommeasure2.py", line 359, in update_display\n    self.plotlines[rate].setVisible(self.settings[\'{}_visible\'.format(rate)])\n', "AttributeError: 'ESRMeasure' object has no attribute 'plotlines'\n"]
2022-02-18T11:03:56|ERROR|ESRMeasure|ESR_measurement Failed to update figure1: 'ESRMeasure' object has no attribute 'plotlines'. ['Traceback (most recent call last):\n', '  File "C:\\Users\\ZHao\\.conda\\envs\\scopefoundry\\lib\\site-packages\\ScopeFoundry\\measurement.py", line 273, in _on_display_update_timer\n    self.update_display()\n', '  File "C:\\Users\\Public\\quantum_sensing\\quantum_sensing\\fancy_microscope\\custommeasure2.py", line 359, in update_display\n    self.plotlines[rate].setVisible(self.settings[\'{}_visible\'.format(rate)])\n', "AttributeError: 'ESRMeasure' object has no attribute 'plotlines'\n"]
2022-02-18T11:03:59|ERROR|ESRMeasure|ESR_measurement Failed to update figure1: 'ESRMeasure' object has no attribute 'plotlines'. ['Traceback (most recent call last):\n', '  File "C:\\Users\\ZHao\\.conda\\envs\\scopefoundry\\lib\\site-packages\\ScopeFoundry\\measurement.py", line 273, in _on_display_update_timer\n    self.update_display()\n', '  File "C:\\Users\\Public\\quantum_sensing\\quantum_sensing\\fancy_microscope\\custommeasure2.py", line 359, in update_display\n    self.plotlines[rate].setVisible(self.settings[\'{}_visible\'.format(rate)])\n', "AttributeError: 'ESRMeasure' object has no attribute 'plotlines'\n"]
2022-02-18T11:03:59|ERROR|ESRMeasure|ESR_measurement Failed to update figure1: 'ESRMeasure' object has no attribute 'plotlines'. ['Traceback (most recent call last):\n', '  File "C:\\Users\\ZHao\\.conda\\envs\\scopefoundry\\lib\\site-packages\\ScopeFoundry\\measurement.py", line 273, in _on_display_update_timer\n    self.update_display()\n', '  File "C:\\Users\\Public\\quantum_sensing\\quantum_sensing\\fancy_microscope\\custommeasure2.py", line 359, in update_display\n    self.plotlines[rate].setVisible(self.settings[\'{}_visible\'.format(rate)])\n', "AttributeError: 'ESRMeasure' object has no attribute 'plotlines'\n"]
2022-02-18T11:03:59|ERROR|ESRMeasure|ESR_measurement Failed to update figure1: 'ESRMeasure' object has no attribute 'plotlines'. ['Traceback (most recent call last):\n', '  File "C:\\Users\\ZHao\\.conda\\envs\\scopefoundry\\lib\\site-packages\\ScopeFoundry\\measurement.py", line 273, in _on_display_update_timer\n    self.update_display()\n', '  File "C:\\Users\\Public\\quantum_sensing\\quantum_sensing\\fancy_microscope\\custommeasure2.py", line 359, in update_display\n    self.plotlines[rate].setVisible(self.settings[\'{}_visible\'.format(rate)])\n', "AttributeError: 'ESRMeasure' object has no attribute 'plotlines'\n"]
2022-02-18T11:03:59|ERROR|ESRMeasure|ESR_measurement Failed to update figure1: 'ESRMeasure' object has no attribute 'plotlines'. ['Traceback (most recent call last):\n', '  File "C:\\Users\\ZHao\\.conda\\envs\\scopefoundry\\lib\\site-packages\\ScopeFoundry\\measurement.py", line 273, in _on_display_update_timer\n    self.update_display()\n', '  File "C:\\Users\\Public\\quantum_sensing\\quantum_sensing\\fancy_microscope\\custommeasure2.py", line 359, in update_display\n    self.plotlines[rate].setVisible(self.settings[\'{}_visible\'.format(rate)])\n', "AttributeError: 'ESRMeasure' object has no attribute 'plotlines'\n"]
2022-02-18T11:04:00|ERROR|ESRMeasure|ESR_measurement Failed to update figure1: 'ESRMeasure' object has no attribute 'plotlines'. ['Traceback (most recent call last):\n', '  File "C:\\Users\\ZHao\\.conda\\envs\\scopefoundry\\lib\\site-packages\\ScopeFoundry\\measurement.py", line 273, in _on_display_update_timer\n    self.update_display()\n', '  File "C:\\Users\\Public\\quantum_sensing\\quantum_sensing\\fancy_microscope\\custommeasure2.py", line 359, in update_display\n    self.plotlines[rate].setVisible(self.settings[\'{}_visible\'.format(rate)])\n', "AttributeError: 'ESRMeasure' object has no attribute 'plotlines'\n"]
2022-02-18T11:04:00|ERROR|ESRMeasure|ESR_measurement Failed to update figure1: 'ESRMeasure' object has no attribute 'plotlines'. ['Traceback (most recent call last):\n', '  File "C:\\Users\\ZHao\\.conda\\envs\\scopefoundry\\lib\\site-packages\\ScopeFoundry\\measurement.py", line 273, in _on_display_update_timer\n    self.update_display()\n', '  File "C:\\Users\\Public\\quantum_sensing\\quantum_sensing\\fancy_microscope\\custommeasure2.py", line 359, in update_display\n    self.plotlines[rate].setVisible(self.settings[\'{}_visible\'.format(rate)])\n', "AttributeError: 'ESRMeasure' object has no attribute 'plotlines'\n"]
2022-02-18T11:04:00|ERROR|ESRMeasure|ESR_measurement Failed to update figure1: 'ESRMeasure' object has no attribute 'plotlines'. ['Traceback (most recent call last):\n', '  File "C:\\Users\\ZHao\\.conda\\envs\\scopefoundry\\lib\\site-packages\\ScopeFoundry\\measurement.py", line 273, in _on_display_update_timer\n    self.update_display()\n', '  File "C:\\Users\\Public\\quantum_sensing\\quantum_sensing\\fancy_microscope\\custommeasure2.py", line 359, in update_display\n    self.plotlines[rate].setVisible(self.settings[\'{}_visible\'.format(rate)])\n', "AttributeError: 'ESRMeasure' object has no attribute 'plotlines'\n"]
2022-02-18T11:04:00|ERROR|ESRMeasure|ESR_measurement Failed to update figure1: 'ESRMeasure' object has no attribute 'plotlines'. ['Traceback (most recent call last):\n', '  File "C:\\Users\\ZHao\\.conda\\envs\\scopefoundry\\lib\\site-packages\\ScopeFoundry\\measurement.py", line 273, in _on_display_update_timer\n    self.update_display()\n', '  File "C:\\Users\\Public\\quantum_sensing\\quantum_sensing\\fancy_microscope\\custommeasure2.py", line 359, in update_display\n    self.plotlines[rate].setVisible(self.settings[\'{}_visible\'.format(rate)])\n', "AttributeError: 'ESRMeasure' object has no attribute 'plotlines'\n"]
2022-02-18T11:04:00|ERROR|ESRMeasure|ESR_measurement Failed to update figure1: 'ESRMeasure' object has no attribute 'plotlines'. ['Traceback (most recent call last):\n', '  File "C:\\Users\\ZHao\\.conda\\envs\\scopefoundry\\lib\\site-packages\\ScopeFoundry\\measurement.py", line 273, in _on_display_update_timer\n    self.update_display()\n', '  File "C:\\Users\\Public\\quantum_sensing\\quantum_sensing\\fancy_microscope\\custommeasure2.py", line 359, in update_display\n    self.plotlines[rate].setVisible(self.settings[\'{}_visible\'.format(rate)])\n', "AttributeError: 'ESRMeasure' object has no attribute 'plotlines'\n"]
2022-02-18T11:04:00|ERROR|ESRMeasure|ESR_measurement Failed to update figure1: 'ESRMeasure' object has no attribute 'plotlines'. ['Traceback (most recent call last):\n', '  File "C:\\Users\\ZHao\\.conda\\envs\\scopefoundry\\lib\\site-packages\\ScopeFoundry\\measurement.py", line 273, in _on_display_update_timer\n    self.update_display()\n', '  File "C:\\Users\\Public\\quantum_sensing\\quantum_sensing\\fancy_microscope\\custommeasure2.py", line 359, in update_display\n    self.plotlines[rate].setVisible(self.settings[\'{}_visible\'.format(rate)])\n', "AttributeError: 'ESRMeasure' object has no attribute 'plotlines'\n"]
2022-02-18T11:04:00|ERROR|ESRMeasure|ESR_measurement Failed to update figure1: 'ESRMeasure' object has no attribute 'plotlines'. ['Traceback (most recent call last):\n', '  File "C:\\Users\\ZHao\\.conda\\envs\\scopefoundry\\lib\\site-packages\\ScopeFoundry\\measurement.py", line 273, in _on_display_update_timer\n    self.update_display()\n', '  File "C:\\Users\\Public\\quantum_sensing\\quantum_sensing\\fancy_microscope\\custommeasure2.py", line 359, in update_display\n    self.plotlines[rate].setVisible(self.settings[\'{}_visible\'.format(rate)])\n', "AttributeError: 'ESRMeasure' object has no attribute 'plotlines'\n"]
2022-02-18T11:04:00|ERROR|ESRMeasure|ESR_measurement Failed to update figure1: 'ESRMeasure' object has no attribute 'plotlines'. ['Traceback (most recent call last):\n', '  File "C:\\Users\\ZHao\\.conda\\envs\\scopefoundry\\lib\\site-packages\\ScopeFoundry\\measurement.py", line 273, in _on_display_update_timer\n    self.update_display()\n', '  File "C:\\Users\\Public\\quantum_sensing\\quantum_sensing\\fancy_microscope\\custommeasure2.py", line 359, in update_display\n    self.plotlines[rate].setVisible(self.settings[\'{}_visible\'.format(rate)])\n', "AttributeError: 'ESRMeasure' object has no attribute 'plotlines'\n"]
2022-02-18T11:04:00|ERROR|ESRMeasure|ESR_measurement Failed to update figure1: 'ESRMeasure' object has no attribute 'plotlines'. ['Traceback (most recent call last):\n', '  File "C:\\Users\\ZHao\\.conda\\envs\\scopefoundry\\lib\\site-packages\\ScopeFoundry\\measurement.py", line 273, in _on_display_update_timer\n    self.update_display()\n', '  File "C:\\Users\\Public\\quantum_sensing\\quantum_sensing\\fancy_microscope\\custommeasure2.py", line 359, in update_display\n    self.plotlines[rate].setVisible(self.settings[\'{}_visible\'.format(rate)])\n', "AttributeError: 'ESRMeasure' object has no attribute 'plotlines'\n"]
2022-02-18T11:04:01|ERROR|ESRMeasure|ESR_measurement Failed to update figure1: 'ESRMeasure' object has no attribute 'plotlines'. ['Traceback (most recent call last):\n', '  File "C:\\Users\\ZHao\\.conda\\envs\\scopefoundry\\lib\\site-packages\\ScopeFoundry\\measurement.py", line 273, in _on_display_update_timer\n    self.update_display()\n', '  File "C:\\Users\\Public\\quantum_sensing\\quantum_sensing\\fancy_microscope\\custommeasure2.py", line 359, in update_display\n    self.plotlines[rate].setVisible(self.settings[\'{}_visible\'.format(rate)])\n', "AttributeError: 'ESRMeasure' object has no attribute 'plotlines'\n"]
2022-02-18T11:04:01|ERROR|ESRMeasure|ESR_measurement Failed to update figure1: 'ESRMeasure' object has no attribute 'plotlines'. ['Traceback (most recent call last):\n', '  File "C:\\Users\\ZHao\\.conda\\envs\\scopefoundry\\lib\\site-packages\\ScopeFoundry\\measurement.py", line 273, in _on_display_update_timer\n    self.update_display()\n', '  File "C:\\Users\\Public\\quantum_sensing\\quantum_sensing\\fancy_microscope\\custommeasure2.py", line 359, in update_display\n    self.plotlines[rate].setVisible(self.settings[\'{}_visible\'.format(rate)])\n', "AttributeError: 'ESRMeasure' object has no attribute 'plotlines'\n"]
2022-02-18T11:04:01|ERROR|ESRMeasure|ESR_measurement Failed to update figure1: 'ESRMeasure' object has no attribute 'plotlines'. ['Traceback (most recent call last):\n', '  File "C:\\Users\\ZHao\\.conda\\envs\\scopefoundry\\lib\\site-packages\\ScopeFoundry\\measurement.py", line 273, in _on_display_update_timer\n    self.update_display()\n', '  File "C:\\Users\\Public\\quantum_sensing\\quantum_sensing\\fancy_microscope\\custommeasure2.py", line 359, in update_display\n    self.plotlines[rate].setVisible(self.settings[\'{}_visible\'.format(rate)])\n', "AttributeError: 'ESRMeasure' object has no attribute 'plotlines'\n"]
2022-02-18T11:04:01|ERROR|ESRMeasure|ESR_measurement Failed to update figure1: 'ESRMeasure' object has no attribute 'plotlines'. ['Traceback (most recent call last):\n', '  File "C:\\Users\\ZHao\\.conda\\envs\\scopefoundry\\lib\\site-packages\\ScopeFoundry\\measurement.py", line 273, in _on_display_update_timer\n    self.update_display()\n', '  File "C:\\Users\\Public\\quantum_sensing\\quantum_sensing\\fancy_microscope\\custommeasure2.py", line 359, in update_display\n    self.plotlines[rate].setVisible(self.settings[\'{}_visible\'.format(rate)])\n', "AttributeError: 'ESRMeasure' object has no attribute 'plotlines'\n"]
