2022-10-19T16:51:45|ERROR|ThorCamCaptureMeasure|thor_cam_capture Failed to update figure1: axes don't match array. ['Traceback (most recent call last):\n', '  File "C:\\Users\\ZHao\\.conda\\envs\\scopefoundry\\lib\\site-packages\\ScopeFoundry\\measurement.py", line 273, in _on_display_update_timer\n    self.update_display()\n', '  File "C:\\Users\\Public\\quantum_sensing\\quantum_sensing\\fancy_microscope\\thorcam_capture.py", line 362, in update_display\n    self.imview.setImage(image, axes={\'y\':0, \'x\':1}, autoLevels=True)\n', '  File "C:\\Users\\ZHao\\.conda\\envs\\scopefoundry\\lib\\site-packages\\pyqtgraph\\imageview\\ImageView.py", line 322, in setImage\n    self.updateImage(autoHistogramRange=autoHistogramRange)\n', '  File "C:\\Users\\ZHao\\.conda\\envs\\scopefoundry\\lib\\site-packages\\pyqtgraph\\imageview\\ImageView.py", line 725, in updateImage\n    image = image.transpose(axorder)\n', "ValueError: axes don't match array\n"]
2022-10-19T16:51:45|ERROR|ThorCamCaptureMeasure|thor_cam_capture Failed to update figure1: axes don't match array. ['Traceback (most recent call last):\n', '  File "C:\\Users\\ZHao\\.conda\\envs\\scopefoundry\\lib\\site-packages\\ScopeFoundry\\measurement.py", line 273, in _on_display_update_timer\n    self.update_display()\n', '  File "C:\\Users\\Public\\quantum_sensing\\quantum_sensing\\fancy_microscope\\thorcam_capture.py", line 362, in update_display\n    self.imview.setImage(image, axes={\'y\':0, \'x\':1}, autoLevels=True)\n', '  File "C:\\Users\\ZHao\\.conda\\envs\\scopefoundry\\lib\\site-packages\\pyqtgraph\\imageview\\ImageView.py", line 322, in setImage\n    self.updateImage(autoHistogramRange=autoHistogramRange)\n', '  File "C:\\Users\\ZHao\\.conda\\envs\\scopefoundry\\lib\\site-packages\\pyqtgraph\\imageview\\ImageView.py", line 725, in updateImage\n    image = image.transpose(axorder)\n', "ValueError: axes don't match array\n"]
2022-10-19T16:51:45|ERROR|ThorCamCaptureMeasure|thor_cam_capture Failed to update figure1: axes don't match array. ['Traceback (most recent call last):\n', '  File "C:\\Users\\ZHao\\.conda\\envs\\scopefoundry\\lib\\site-packages\\ScopeFoundry\\measurement.py", line 273, in _on_display_update_timer\n    self.update_display()\n', '  File "C:\\Users\\Public\\quantum_sensing\\quantum_sensing\\fancy_microscope\\thorcam_capture.py", line 362, in update_display\n    self.imview.setImage(image, axes={\'y\':0, \'x\':1}, autoLevels=True)\n', '  File "C:\\Users\\ZHao\\.conda\\envs\\scopefoundry\\lib\\site-packages\\pyqtgraph\\imageview\\ImageView.py", line 322, in setImage\n    self.updateImage(autoHistogramRange=autoHistogramRange)\n', '  File "C:\\Users\\ZHao\\.conda\\envs\\scopefoundry\\lib\\site-packages\\pyqtgraph\\imageview\\ImageView.py", line 725, in updateImage\n    image = image.transpose(axorder)\n', "ValueError: axes don't match array\n"]
2022-10-19T16:51:45|ERROR|ThorCamCaptureMeasure|thor_cam_capture Failed to update figure1: axes don't match array. ['Traceback (most recent call last):\n', '  File "C:\\Users\\ZHao\\.conda\\envs\\scopefoundry\\lib\\site-packages\\ScopeFoundry\\measurement.py", line 273, in _on_display_update_timer\n    self.update_display()\n', '  File "C:\\Users\\Public\\quantum_sensing\\quantum_sensing\\fancy_microscope\\thorcam_capture.py", line 362, in update_display\n    self.imview.setImage(image, axes={\'y\':0, \'x\':1}, autoLevels=True)\n', '  File "C:\\Users\\ZHao\\.conda\\envs\\scopefoundry\\lib\\site-packages\\pyqtgraph\\imageview\\ImageView.py", line 322, in setImage\n    self.updateImage(autoHistogramRange=autoHistogramRange)\n', '  File "C:\\Users\\ZHao\\.conda\\envs\\scopefoundry\\lib\\site-packages\\pyqtgraph\\imageview\\ImageView.py", line 725, in updateImage\n    image = image.transpose(axorder)\n', "ValueError: axes don't match array\n"]
2022-10-19T16:51:45|ERROR|ThorCamCaptureMeasure|thor_cam_capture Failed to update figure1: axes don't match array. ['Traceback (most recent call last):\n', '  File "C:\\Users\\ZHao\\.conda\\envs\\scopefoundry\\lib\\site-packages\\ScopeFoundry\\measurement.py", line 273, in _on_display_update_timer\n    self.update_display()\n', '  File "C:\\Users\\Public\\quantum_sensing\\quantum_sensing\\fancy_microscope\\thorcam_capture.py", line 362, in update_display\n    self.imview.setImage(image, axes={\'y\':0, \'x\':1}, autoLevels=True)\n', '  File "C:\\Users\\ZHao\\.conda\\envs\\scopefoundry\\lib\\site-packages\\pyqtgraph\\imageview\\ImageView.py", line 322, in setImage\n    self.updateImage(autoHistogramRange=autoHistogramRange)\n', '  File "C:\\Users\\ZHao\\.conda\\envs\\scopefoundry\\lib\\site-packages\\pyqtgraph\\imageview\\ImageView.py", line 725, in updateImage\n    image = image.transpose(axorder)\n', "ValueError: axes don't match array\n"]
2022-10-19T16:51:46|ERROR|ThorCamCaptureMeasure|thor_cam_capture Failed to update figure1: axes don't match array. ['Traceback (most recent call last):\n', '  File "C:\\Users\\ZHao\\.conda\\envs\\scopefoundry\\lib\\site-packages\\ScopeFoundry\\measurement.py", line 273, in _on_display_update_timer\n    self.update_display()\n', '  File "C:\\Users\\Public\\quantum_sensing\\quantum_sensing\\fancy_microscope\\thorcam_capture.py", line 362, in update_display\n    self.imview.setImage(image, axes={\'y\':0, \'x\':1}, autoLevels=True)\n', '  File "C:\\Users\\ZHao\\.conda\\envs\\scopefoundry\\lib\\site-packages\\pyqtgraph\\imageview\\ImageView.py", line 322, in setImage\n    self.updateImage(autoHistogramRange=autoHistogramRange)\n', '  File "C:\\Users\\ZHao\\.conda\\envs\\scopefoundry\\lib\\site-packages\\pyqtgraph\\imageview\\ImageView.py", line 725, in updateImage\n    image = image.transpose(axorder)\n', "ValueError: axes don't match array\n"]
2022-10-19T16:51:46|ERROR|ThorCamCaptureMeasure|thor_cam_capture Failed to update figure1: axes don't match array. ['Traceback (most recent call last):\n', '  File "C:\\Users\\ZHao\\.conda\\envs\\scopefoundry\\lib\\site-packages\\ScopeFoundry\\measurement.py", line 273, in _on_display_update_timer\n    self.update_display()\n', '  File "C:\\Users\\Public\\quantum_sensing\\quantum_sensing\\fancy_microscope\\thorcam_capture.py", line 362, in update_display\n    self.imview.setImage(image, axes={\'y\':0, \'x\':1}, autoLevels=True)\n', '  File "C:\\Users\\ZHao\\.conda\\envs\\scopefoundry\\lib\\site-packages\\pyqtgraph\\imageview\\ImageView.py", line 322, in setImage\n    self.updateImage(autoHistogramRange=autoHistogramRange)\n', '  File "C:\\Users\\ZHao\\.conda\\envs\\scopefoundry\\lib\\site-packages\\pyqtgraph\\imageview\\ImageView.py", line 725, in updateImage\n    image = image.transpose(axorder)\n', "ValueError: axes don't match array\n"]
2022-10-19T16:51:46|ERROR|ThorCamCaptureMeasure|thor_cam_capture Failed to update figure1: axes don't match array. ['Traceback (most recent call last):\n', '  File "C:\\Users\\ZHao\\.conda\\envs\\scopefoundry\\lib\\site-packages\\ScopeFoundry\\measurement.py", line 273, in _on_display_update_timer\n    self.update_display()\n', '  File "C:\\Users\\Public\\quantum_sensing\\quantum_sensing\\fancy_microscope\\thorcam_capture.py", line 362, in update_display\n    self.imview.setImage(image, axes={\'y\':0, \'x\':1}, autoLevels=True)\n', '  File "C:\\Users\\ZHao\\.conda\\envs\\scopefoundry\\lib\\site-packages\\pyqtgraph\\imageview\\ImageView.py", line 322, in setImage\n    self.updateImage(autoHistogramRange=autoHistogramRange)\n', '  File "C:\\Users\\ZHao\\.conda\\envs\\scopefoundry\\lib\\site-packages\\pyqtgraph\\imageview\\ImageView.py", line 725, in updateImage\n    image = image.transpose(axorder)\n', "ValueError: axes don't match array\n"]
2022-10-19T16:51:46|ERROR|ThorCamCaptureMeasure|thor_cam_capture Failed to update figure1: axes don't match array. ['Traceback (most recent call last):\n', '  File "C:\\Users\\ZHao\\.conda\\envs\\scopefoundry\\lib\\site-packages\\ScopeFoundry\\measurement.py", line 273, in _on_display_update_timer\n    self.update_display()\n', '  File "C:\\Users\\Public\\quantum_sensing\\quantum_sensing\\fancy_microscope\\thorcam_capture.py", line 362, in update_display\n    self.imview.setImage(image, axes={\'y\':0, \'x\':1}, autoLevels=True)\n', '  File "C:\\Users\\ZHao\\.conda\\envs\\scopefoundry\\lib\\site-packages\\pyqtgraph\\imageview\\ImageView.py", line 322, in setImage\n    self.updateImage(autoHistogramRange=autoHistogramRange)\n', '  File "C:\\Users\\ZHao\\.conda\\envs\\scopefoundry\\lib\\site-packages\\pyqtgraph\\imageview\\ImageView.py", line 725, in updateImage\n    image = image.transpose(axorder)\n', "ValueError: axes don't match array\n"]
2022-10-19T16:51:46|ERROR|ThorCamCaptureMeasure|thor_cam_capture Failed to update figure1: axes don't match array. ['Traceback (most recent call last):\n', '  File "C:\\Users\\ZHao\\.conda\\envs\\scopefoundry\\lib\\site-packages\\ScopeFoundry\\measurement.py", line 273, in _on_display_update_timer\n    self.update_display()\n', '  File "C:\\Users\\Public\\quantum_sensing\\quantum_sensing\\fancy_microscope\\thorcam_capture.py", line 362, in update_display\n    self.imview.setImage(image, axes={\'y\':0, \'x\':1}, autoLevels=True)\n', '  File "C:\\Users\\ZHao\\.conda\\envs\\scopefoundry\\lib\\site-packages\\pyqtgraph\\imageview\\ImageView.py", line 322, in setImage\n    self.updateImage(autoHistogramRange=autoHistogramRange)\n', '  File "C:\\Users\\ZHao\\.conda\\envs\\scopefoundry\\lib\\site-packages\\pyqtgraph\\imageview\\ImageView.py", line 725, in updateImage\n    image = image.transpose(axorder)\n', "ValueError: axes don't match array\n"]
2022-10-19T16:51:46|ERROR|ThorCamCaptureMeasure|thor_cam_capture Failed to update figure1: axes don't match array. ['Traceback (most recent call last):\n', '  File "C:\\Users\\ZHao\\.conda\\envs\\scopefoundry\\lib\\site-packages\\ScopeFoundry\\measurement.py", line 273, in _on_display_update_timer\n    self.update_display()\n', '  File "C:\\Users\\Public\\quantum_sensing\\quantum_sensing\\fancy_microscope\\thorcam_capture.py", line 362, in update_display\n    self.imview.setImage(image, axes={\'y\':0, \'x\':1}, autoLevels=True)\n', '  File "C:\\Users\\ZHao\\.conda\\envs\\scopefoundry\\lib\\site-packages\\pyqtgraph\\imageview\\ImageView.py", line 322, in setImage\n    self.updateImage(autoHistogramRange=autoHistogramRange)\n', '  File "C:\\Users\\ZHao\\.conda\\envs\\scopefoundry\\lib\\site-packages\\pyqtgraph\\imageview\\ImageView.py", line 725, in updateImage\n    image = image.transpose(axorder)\n', "ValueError: axes don't match array\n"]
2022-10-19T16:51:46|ERROR|ThorCamCaptureMeasure|thor_cam_capture Failed to update figure1: axes don't match array. ['Traceback (most recent call last):\n', '  File "C:\\Users\\ZHao\\.conda\\envs\\scopefoundry\\lib\\site-packages\\ScopeFoundry\\measurement.py", line 273, in _on_display_update_timer\n    self.update_display()\n', '  File "C:\\Users\\Public\\quantum_sensing\\quantum_sensing\\fancy_microscope\\thorcam_capture.py", line 362, in update_display\n    self.imview.setImage(image, axes={\'y\':0, \'x\':1}, autoLevels=True)\n', '  File "C:\\Users\\ZHao\\.conda\\envs\\scopefoundry\\lib\\site-packages\\pyqtgraph\\imageview\\ImageView.py", line 322, in setImage\n    self.updateImage(autoHistogramRange=autoHistogramRange)\n', '  File "C:\\Users\\ZHao\\.conda\\envs\\scopefoundry\\lib\\site-packages\\pyqtgraph\\imageview\\ImageView.py", line 725, in updateImage\n    image = image.transpose(axorder)\n', "ValueError: axes don't match array\n"]
2022-10-19T16:51:46|ERROR|ThorCamCaptureMeasure|thor_cam_capture Failed to update figure1: axes don't match array. ['Traceback (most recent call last):\n', '  File "C:\\Users\\ZHao\\.conda\\envs\\scopefoundry\\lib\\site-packages\\ScopeFoundry\\measurement.py", line 273, in _on_display_update_timer\n    self.update_display()\n', '  File "C:\\Users\\Public\\quantum_sensing\\quantum_sensing\\fancy_microscope\\thorcam_capture.py", line 362, in update_display\n    self.imview.setImage(image, axes={\'y\':0, \'x\':1}, autoLevels=True)\n', '  File "C:\\Users\\ZHao\\.conda\\envs\\scopefoundry\\lib\\site-packages\\pyqtgraph\\imageview\\ImageView.py", line 322, in setImage\n    self.updateImage(autoHistogramRange=autoHistogramRange)\n', '  File "C:\\Users\\ZHao\\.conda\\envs\\scopefoundry\\lib\\site-packages\\pyqtgraph\\imageview\\ImageView.py", line 725, in updateImage\n    image = image.transpose(axorder)\n', "ValueError: axes don't match array\n"]
2022-10-19T16:51:46|ERROR|ThorCamCaptureMeasure|thor_cam_capture Failed to update figure1: axes don't match array. ['Traceback (most recent call last):\n', '  File "C:\\Users\\ZHao\\.conda\\envs\\scopefoundry\\lib\\site-packages\\ScopeFoundry\\measurement.py", line 273, in _on_display_update_timer\n    self.update_display()\n', '  File "C:\\Users\\Public\\quantum_sensing\\quantum_sensing\\fancy_microscope\\thorcam_capture.py", line 362, in update_display\n    self.imview.setImage(image, axes={\'y\':0, \'x\':1}, autoLevels=True)\n', '  File "C:\\Users\\ZHao\\.conda\\envs\\scopefoundry\\lib\\site-packages\\pyqtgraph\\imageview\\ImageView.py", line 322, in setImage\n    self.updateImage(autoHistogramRange=autoHistogramRange)\n', '  File "C:\\Users\\ZHao\\.conda\\envs\\scopefoundry\\lib\\site-packages\\pyqtgraph\\imageview\\ImageView.py", line 725, in updateImage\n    image = image.transpose(axorder)\n', "ValueError: axes don't match array\n"]
2022-10-19T16:51:47|ERROR|ThorCamCaptureMeasure|thor_cam_capture Failed to update figure1: axes don't match array. ['Traceback (most recent call last):\n', '  File "C:\\Users\\ZHao\\.conda\\envs\\scopefoundry\\lib\\site-packages\\ScopeFoundry\\measurement.py", line 273, in _on_display_update_timer\n    self.update_display()\n', '  File "C:\\Users\\Public\\quantum_sensing\\quantum_sensing\\fancy_microscope\\thorcam_capture.py", line 362, in update_display\n    self.imview.setImage(image, axes={\'y\':0, \'x\':1}, autoLevels=True)\n', '  File "C:\\Users\\ZHao\\.conda\\envs\\scopefoundry\\lib\\site-packages\\pyqtgraph\\imageview\\ImageView.py", line 322, in setImage\n    self.updateImage(autoHistogramRange=autoHistogramRange)\n', '  File "C:\\Users\\ZHao\\.conda\\envs\\scopefoundry\\lib\\site-packages\\pyqtgraph\\imageview\\ImageView.py", line 725, in updateImage\n    image = image.transpose(axorder)\n', "ValueError: axes don't match array\n"]
2022-10-19T16:51:47|ERROR|ThorCamCaptureMeasure|thor_cam_capture Failed to update figure1: axes don't match array. ['Traceback (most recent call last):\n', '  File "C:\\Users\\ZHao\\.conda\\envs\\scopefoundry\\lib\\site-packages\\ScopeFoundry\\measurement.py", line 273, in _on_display_update_timer\n    self.update_display()\n', '  File "C:\\Users\\Public\\quantum_sensing\\quantum_sensing\\fancy_microscope\\thorcam_capture.py", line 362, in update_display\n    self.imview.setImage(image, axes={\'y\':0, \'x\':1}, autoLevels=True)\n', '  File "C:\\Users\\ZHao\\.conda\\envs\\scopefoundry\\lib\\site-packages\\pyqtgraph\\imageview\\ImageView.py", line 322, in setImage\n    self.updateImage(autoHistogramRange=autoHistogramRange)\n', '  File "C:\\Users\\ZHao\\.conda\\envs\\scopefoundry\\lib\\site-packages\\pyqtgraph\\imageview\\ImageView.py", line 725, in updateImage\n    image = image.transpose(axorder)\n', "ValueError: axes don't match array\n"]
2022-10-19T16:51:47|ERROR|ThorCamCaptureMeasure|thor_cam_capture Failed to update figure1: axes don't match array. ['Traceback (most recent call last):\n', '  File "C:\\Users\\ZHao\\.conda\\envs\\scopefoundry\\lib\\site-packages\\ScopeFoundry\\measurement.py", line 273, in _on_display_update_timer\n    self.update_display()\n', '  File "C:\\Users\\Public\\quantum_sensing\\quantum_sensing\\fancy_microscope\\thorcam_capture.py", line 362, in update_display\n    self.imview.setImage(image, axes={\'y\':0, \'x\':1}, autoLevels=True)\n', '  File "C:\\Users\\ZHao\\.conda\\envs\\scopefoundry\\lib\\site-packages\\pyqtgraph\\imageview\\ImageView.py", line 322, in setImage\n    self.updateImage(autoHistogramRange=autoHistogramRange)\n', '  File "C:\\Users\\ZHao\\.conda\\envs\\scopefoundry\\lib\\site-packages\\pyqtgraph\\imageview\\ImageView.py", line 725, in updateImage\n    image = image.transpose(axorder)\n', "ValueError: axes don't match array\n"]
2022-10-19T16:51:47|ERROR|ThorCamCaptureMeasure|thor_cam_capture Failed to update figure1: axes don't match array. ['Traceback (most recent call last):\n', '  File "C:\\Users\\ZHao\\.conda\\envs\\scopefoundry\\lib\\site-packages\\ScopeFoundry\\measurement.py", line 273, in _on_display_update_timer\n    self.update_display()\n', '  File "C:\\Users\\Public\\quantum_sensing\\quantum_sensing\\fancy_microscope\\thorcam_capture.py", line 362, in update_display\n    self.imview.setImage(image, axes={\'y\':0, \'x\':1}, autoLevels=True)\n', '  File "C:\\Users\\ZHao\\.conda\\envs\\scopefoundry\\lib\\site-packages\\pyqtgraph\\imageview\\ImageView.py", line 322, in setImage\n    self.updateImage(autoHistogramRange=autoHistogramRange)\n', '  File "C:\\Users\\ZHao\\.conda\\envs\\scopefoundry\\lib\\site-packages\\pyqtgraph\\imageview\\ImageView.py", line 725, in updateImage\n    image = image.transpose(axorder)\n', "ValueError: axes don't match array\n"]
2022-10-19T16:51:47|ERROR|ThorCamCaptureMeasure|thor_cam_capture Failed to update figure1: axes don't match array. ['Traceback (most recent call last):\n', '  File "C:\\Users\\ZHao\\.conda\\envs\\scopefoundry\\lib\\site-packages\\ScopeFoundry\\measurement.py", line 273, in _on_display_update_timer\n    self.update_display()\n', '  File "C:\\Users\\Public\\quantum_sensing\\quantum_sensing\\fancy_microscope\\thorcam_capture.py", line 362, in update_display\n    self.imview.setImage(image, axes={\'y\':0, \'x\':1}, autoLevels=True)\n', '  File "C:\\Users\\ZHao\\.conda\\envs\\scopefoundry\\lib\\site-packages\\pyqtgraph\\imageview\\ImageView.py", line 322, in setImage\n    self.updateImage(autoHistogramRange=autoHistogramRange)\n', '  File "C:\\Users\\ZHao\\.conda\\envs\\scopefoundry\\lib\\site-packages\\pyqtgraph\\imageview\\ImageView.py", line 725, in updateImage\n    image = image.transpose(axorder)\n', "ValueError: axes don't match array\n"]
2022-10-19T16:51:47|ERROR|ThorCamCaptureMeasure|thor_cam_capture Failed to update figure1: axes don't match array. ['Traceback (most recent call last):\n', '  File "C:\\Users\\ZHao\\.conda\\envs\\scopefoundry\\lib\\site-packages\\ScopeFoundry\\measurement.py", line 273, in _on_display_update_timer\n    self.update_display()\n', '  File "C:\\Users\\Public\\quantum_sensing\\quantum_sensing\\fancy_microscope\\thorcam_capture.py", line 362, in update_display\n    self.imview.setImage(image, axes={\'y\':0, \'x\':1}, autoLevels=True)\n', '  File "C:\\Users\\ZHao\\.conda\\envs\\scopefoundry\\lib\\site-packages\\pyqtgraph\\imageview\\ImageView.py", line 322, in setImage\n    self.updateImage(autoHistogramRange=autoHistogramRange)\n', '  File "C:\\Users\\ZHao\\.conda\\envs\\scopefoundry\\lib\\site-packages\\pyqtgraph\\imageview\\ImageView.py", line 725, in updateImage\n    image = image.transpose(axorder)\n', "ValueError: axes don't match array\n"]
2022-10-19T16:51:47|ERROR|ThorCamCaptureMeasure|thor_cam_capture Failed to update figure1: axes don't match array. ['Traceback (most recent call last):\n', '  File "C:\\Users\\ZHao\\.conda\\envs\\scopefoundry\\lib\\site-packages\\ScopeFoundry\\measurement.py", line 273, in _on_display_update_timer\n    self.update_display()\n', '  File "C:\\Users\\Public\\quantum_sensing\\quantum_sensing\\fancy_microscope\\thorcam_capture.py", line 362, in update_display\n    self.imview.setImage(image, axes={\'y\':0, \'x\':1}, autoLevels=True)\n', '  File "C:\\Users\\ZHao\\.conda\\envs\\scopefoundry\\lib\\site-packages\\pyqtgraph\\imageview\\ImageView.py", line 322, in setImage\n    self.updateImage(autoHistogramRange=autoHistogramRange)\n', '  File "C:\\Users\\ZHao\\.conda\\envs\\scopefoundry\\lib\\site-packages\\pyqtgraph\\imageview\\ImageView.py", line 725, in updateImage\n    image = image.transpose(axorder)\n', "ValueError: axes don't match array\n"]
2022-10-19T16:51:47|ERROR|ThorCamCaptureMeasure|thor_cam_capture Failed to update figure1: axes don't match array. ['Traceback (most recent call last):\n', '  File "C:\\Users\\ZHao\\.conda\\envs\\scopefoundry\\lib\\site-packages\\ScopeFoundry\\measurement.py", line 273, in _on_display_update_timer\n    self.update_display()\n', '  File "C:\\Users\\Public\\quantum_sensing\\quantum_sensing\\fancy_microscope\\thorcam_capture.py", line 362, in update_display\n    self.imview.setImage(image, axes={\'y\':0, \'x\':1}, autoLevels=True)\n', '  File "C:\\Users\\ZHao\\.conda\\envs\\scopefoundry\\lib\\site-packages\\pyqtgraph\\imageview\\ImageView.py", line 322, in setImage\n    self.updateImage(autoHistogramRange=autoHistogramRange)\n', '  File "C:\\Users\\ZHao\\.conda\\envs\\scopefoundry\\lib\\site-packages\\pyqtgraph\\imageview\\ImageView.py", line 725, in updateImage\n    image = image.transpose(axorder)\n', "ValueError: axes don't match array\n"]
2022-10-19T16:51:47|ERROR|ThorCamCaptureMeasure|thor_cam_capture Failed to update figure1: axes don't match array. ['Traceback (most recent call last):\n', '  File "C:\\Users\\ZHao\\.conda\\envs\\scopefoundry\\lib\\site-packages\\ScopeFoundry\\measurement.py", line 273, in _on_display_update_timer\n    self.update_display()\n', '  File "C:\\Users\\Public\\quantum_sensing\\quantum_sensing\\fancy_microscope\\thorcam_capture.py", line 362, in update_display\n    self.imview.setImage(image, axes={\'y\':0, \'x\':1}, autoLevels=True)\n', '  File "C:\\Users\\ZHao\\.conda\\envs\\scopefoundry\\lib\\site-packages\\pyqtgraph\\imageview\\ImageView.py", line 322, in setImage\n    self.updateImage(autoHistogramRange=autoHistogramRange)\n', '  File "C:\\Users\\ZHao\\.conda\\envs\\scopefoundry\\lib\\site-packages\\pyqtgraph\\imageview\\ImageView.py", line 725, in updateImage\n    image = image.transpose(axorder)\n', "ValueError: axes don't match array\n"]
2022-10-19T16:51:48|ERROR|ThorCamCaptureMeasure|thor_cam_capture Failed to update figure1: axes don't match array. ['Traceback (most recent call last):\n', '  File "C:\\Users\\ZHao\\.conda\\envs\\scopefoundry\\lib\\site-packages\\ScopeFoundry\\measurement.py", line 273, in _on_display_update_timer\n    self.update_display()\n', '  File "C:\\Users\\Public\\quantum_sensing\\quantum_sensing\\fancy_microscope\\thorcam_capture.py", line 362, in update_display\n    self.imview.setImage(image, axes={\'y\':0, \'x\':1}, autoLevels=True)\n', '  File "C:\\Users\\ZHao\\.conda\\envs\\scopefoundry\\lib\\site-packages\\pyqtgraph\\imageview\\ImageView.py", line 322, in setImage\n    self.updateImage(autoHistogramRange=autoHistogramRange)\n', '  File "C:\\Users\\ZHao\\.conda\\envs\\scopefoundry\\lib\\site-packages\\pyqtgraph\\imageview\\ImageView.py", line 725, in updateImage\n    image = image.transpose(axorder)\n', "ValueError: axes don't match array\n"]
2022-10-19T16:51:48|ERROR|ThorCamCaptureMeasure|thor_cam_capture Failed to update figure1: axes don't match array. ['Traceback (most recent call last):\n', '  File "C:\\Users\\ZHao\\.conda\\envs\\scopefoundry\\lib\\site-packages\\ScopeFoundry\\measurement.py", line 273, in _on_display_update_timer\n    self.update_display()\n', '  File "C:\\Users\\Public\\quantum_sensing\\quantum_sensing\\fancy_microscope\\thorcam_capture.py", line 362, in update_display\n    self.imview.setImage(image, axes={\'y\':0, \'x\':1}, autoLevels=True)\n', '  File "C:\\Users\\ZHao\\.conda\\envs\\scopefoundry\\lib\\site-packages\\pyqtgraph\\imageview\\ImageView.py", line 322, in setImage\n    self.updateImage(autoHistogramRange=autoHistogramRange)\n', '  File "C:\\Users\\ZHao\\.conda\\envs\\scopefoundry\\lib\\site-packages\\pyqtgraph\\imageview\\ImageView.py", line 725, in updateImage\n    image = image.transpose(axorder)\n', "ValueError: axes don't match array\n"]
2022-10-19T16:51:48|ERROR|ThorCamCaptureMeasure|thor_cam_capture Failed to update figure1: axes don't match array. ['Traceback (most recent call last):\n', '  File "C:\\Users\\ZHao\\.conda\\envs\\scopefoundry\\lib\\site-packages\\ScopeFoundry\\measurement.py", line 273, in _on_display_update_timer\n    self.update_display()\n', '  File "C:\\Users\\Public\\quantum_sensing\\quantum_sensing\\fancy_microscope\\thorcam_capture.py", line 362, in update_display\n    self.imview.setImage(image, axes={\'y\':0, \'x\':1}, autoLevels=True)\n', '  File "C:\\Users\\ZHao\\.conda\\envs\\scopefoundry\\lib\\site-packages\\pyqtgraph\\imageview\\ImageView.py", line 322, in setImage\n    self.updateImage(autoHistogramRange=autoHistogramRange)\n', '  File "C:\\Users\\ZHao\\.conda\\envs\\scopefoundry\\lib\\site-packages\\pyqtgraph\\imageview\\ImageView.py", line 725, in updateImage\n    image = image.transpose(axorder)\n', "ValueError: axes don't match array\n"]
2022-10-19T16:51:48|ERROR|ThorCamCaptureMeasure|thor_cam_capture Failed to update figure1: axes don't match array. ['Traceback (most recent call last):\n', '  File "C:\\Users\\ZHao\\.conda\\envs\\scopefoundry\\lib\\site-packages\\ScopeFoundry\\measurement.py", line 273, in _on_display_update_timer\n    self.update_display()\n', '  File "C:\\Users\\Public\\quantum_sensing\\quantum_sensing\\fancy_microscope\\thorcam_capture.py", line 362, in update_display\n    self.imview.setImage(image, axes={\'y\':0, \'x\':1}, autoLevels=True)\n', '  File "C:\\Users\\ZHao\\.conda\\envs\\scopefoundry\\lib\\site-packages\\pyqtgraph\\imageview\\ImageView.py", line 322, in setImage\n    self.updateImage(autoHistogramRange=autoHistogramRange)\n', '  File "C:\\Users\\ZHao\\.conda\\envs\\scopefoundry\\lib\\site-packages\\pyqtgraph\\imageview\\ImageView.py", line 725, in updateImage\n    image = image.transpose(axorder)\n', "ValueError: axes don't match array\n"]
2022-10-19T16:51:48|ERROR|ThorCamCaptureMeasure|thor_cam_capture Failed to update figure1: axes don't match array. ['Traceback (most recent call last):\n', '  File "C:\\Users\\ZHao\\.conda\\envs\\scopefoundry\\lib\\site-packages\\ScopeFoundry\\measurement.py", line 273, in _on_display_update_timer\n    self.update_display()\n', '  File "C:\\Users\\Public\\quantum_sensing\\quantum_sensing\\fancy_microscope\\thorcam_capture.py", line 362, in update_display\n    self.imview.setImage(image, axes={\'y\':0, \'x\':1}, autoLevels=True)\n', '  File "C:\\Users\\ZHao\\.conda\\envs\\scopefoundry\\lib\\site-packages\\pyqtgraph\\imageview\\ImageView.py", line 322, in setImage\n    self.updateImage(autoHistogramRange=autoHistogramRange)\n', '  File "C:\\Users\\ZHao\\.conda\\envs\\scopefoundry\\lib\\site-packages\\pyqtgraph\\imageview\\ImageView.py", line 725, in updateImage\n    image = image.transpose(axorder)\n', "ValueError: axes don't match array\n"]
2022-10-19T16:51:48|ERROR|ThorCamCaptureMeasure|thor_cam_capture Failed to update figure1: axes don't match array. ['Traceback (most recent call last):\n', '  File "C:\\Users\\ZHao\\.conda\\envs\\scopefoundry\\lib\\site-packages\\ScopeFoundry\\measurement.py", line 273, in _on_display_update_timer\n    self.update_display()\n', '  File "C:\\Users\\Public\\quantum_sensing\\quantum_sensing\\fancy_microscope\\thorcam_capture.py", line 362, in update_display\n    self.imview.setImage(image, axes={\'y\':0, \'x\':1}, autoLevels=True)\n', '  File "C:\\Users\\ZHao\\.conda\\envs\\scopefoundry\\lib\\site-packages\\pyqtgraph\\imageview\\ImageView.py", line 322, in setImage\n    self.updateImage(autoHistogramRange=autoHistogramRange)\n', '  File "C:\\Users\\ZHao\\.conda\\envs\\scopefoundry\\lib\\site-packages\\pyqtgraph\\imageview\\ImageView.py", line 725, in updateImage\n    image = image.transpose(axorder)\n', "ValueError: axes don't match array\n"]
2022-10-19T16:51:48|ERROR|ThorCamCaptureMeasure|thor_cam_capture Failed to update figure1: axes don't match array. ['Traceback (most recent call last):\n', '  File "C:\\Users\\ZHao\\.conda\\envs\\scopefoundry\\lib\\site-packages\\ScopeFoundry\\measurement.py", line 273, in _on_display_update_timer\n    self.update_display()\n', '  File "C:\\Users\\Public\\quantum_sensing\\quantum_sensing\\fancy_microscope\\thorcam_capture.py", line 362, in update_display\n    self.imview.setImage(image, axes={\'y\':0, \'x\':1}, autoLevels=True)\n', '  File "C:\\Users\\ZHao\\.conda\\envs\\scopefoundry\\lib\\site-packages\\pyqtgraph\\imageview\\ImageView.py", line 322, in setImage\n    self.updateImage(autoHistogramRange=autoHistogramRange)\n', '  File "C:\\Users\\ZHao\\.conda\\envs\\scopefoundry\\lib\\site-packages\\pyqtgraph\\imageview\\ImageView.py", line 725, in updateImage\n    image = image.transpose(axorder)\n', "ValueError: axes don't match array\n"]
2022-10-19T16:51:48|ERROR|ThorCamCaptureMeasure|thor_cam_capture Failed to update figure1: axes don't match array. ['Traceback (most recent call last):\n', '  File "C:\\Users\\ZHao\\.conda\\envs\\scopefoundry\\lib\\site-packages\\ScopeFoundry\\measurement.py", line 273, in _on_display_update_timer\n    self.update_display()\n', '  File "C:\\Users\\Public\\quantum_sensing\\quantum_sensing\\fancy_microscope\\thorcam_capture.py", line 362, in update_display\n    self.imview.setImage(image, axes={\'y\':0, \'x\':1}, autoLevels=True)\n', '  File "C:\\Users\\ZHao\\.conda\\envs\\scopefoundry\\lib\\site-packages\\pyqtgraph\\imageview\\ImageView.py", line 322, in setImage\n    self.updateImage(autoHistogramRange=autoHistogramRange)\n', '  File "C:\\Users\\ZHao\\.conda\\envs\\scopefoundry\\lib\\site-packages\\pyqtgraph\\imageview\\ImageView.py", line 725, in updateImage\n    image = image.transpose(axorder)\n', "ValueError: axes don't match array\n"]
2022-10-19T16:51:48|ERROR|ThorCamCaptureMeasure|thor_cam_capture Failed to update figure1: axes don't match array. ['Traceback (most recent call last):\n', '  File "C:\\Users\\ZHao\\.conda\\envs\\scopefoundry\\lib\\site-packages\\ScopeFoundry\\measurement.py", line 273, in _on_display_update_timer\n    self.update_display()\n', '  File "C:\\Users\\Public\\quantum_sensing\\quantum_sensing\\fancy_microscope\\thorcam_capture.py", line 362, in update_display\n    self.imview.setImage(image, axes={\'y\':0, \'x\':1}, autoLevels=True)\n', '  File "C:\\Users\\ZHao\\.conda\\envs\\scopefoundry\\lib\\site-packages\\pyqtgraph\\imageview\\ImageView.py", line 322, in setImage\n    self.updateImage(autoHistogramRange=autoHistogramRange)\n', '  File "C:\\Users\\ZHao\\.conda\\envs\\scopefoundry\\lib\\site-packages\\pyqtgraph\\imageview\\ImageView.py", line 725, in updateImage\n    image = image.transpose(axorder)\n', "ValueError: axes don't match array\n"]
2022-10-19T16:51:49|ERROR|ThorCamCaptureMeasure|thor_cam_capture Failed to update figure1: axes don't match array. ['Traceback (most recent call last):\n', '  File "C:\\Users\\ZHao\\.conda\\envs\\scopefoundry\\lib\\site-packages\\ScopeFoundry\\measurement.py", line 273, in _on_display_update_timer\n    self.update_display()\n', '  File "C:\\Users\\Public\\quantum_sensing\\quantum_sensing\\fancy_microscope\\thorcam_capture.py", line 362, in update_display\n    self.imview.setImage(image, axes={\'y\':0, \'x\':1}, autoLevels=True)\n', '  File "C:\\Users\\ZHao\\.conda\\envs\\scopefoundry\\lib\\site-packages\\pyqtgraph\\imageview\\ImageView.py", line 322, in setImage\n    self.updateImage(autoHistogramRange=autoHistogramRange)\n', '  File "C:\\Users\\ZHao\\.conda\\envs\\scopefoundry\\lib\\site-packages\\pyqtgraph\\imageview\\ImageView.py", line 725, in updateImage\n    image = image.transpose(axorder)\n', "ValueError: axes don't match array\n"]
2022-10-19T16:51:49|ERROR|ThorCamCaptureMeasure|thor_cam_capture Failed to update figure1: axes don't match array. ['Traceback (most recent call last):\n', '  File "C:\\Users\\ZHao\\.conda\\envs\\scopefoundry\\lib\\site-packages\\ScopeFoundry\\measurement.py", line 273, in _on_display_update_timer\n    self.update_display()\n', '  File "C:\\Users\\Public\\quantum_sensing\\quantum_sensing\\fancy_microscope\\thorcam_capture.py", line 362, in update_display\n    self.imview.setImage(image, axes={\'y\':0, \'x\':1}, autoLevels=True)\n', '  File "C:\\Users\\ZHao\\.conda\\envs\\scopefoundry\\lib\\site-packages\\pyqtgraph\\imageview\\ImageView.py", line 322, in setImage\n    self.updateImage(autoHistogramRange=autoHistogramRange)\n', '  File "C:\\Users\\ZHao\\.conda\\envs\\scopefoundry\\lib\\site-packages\\pyqtgraph\\imageview\\ImageView.py", line 725, in updateImage\n    image = image.transpose(axorder)\n', "ValueError: axes don't match array\n"]
2022-10-19T16:51:49|ERROR|ThorCamCaptureMeasure|thor_cam_capture Failed to update figure1: axes don't match array. ['Traceback (most recent call last):\n', '  File "C:\\Users\\ZHao\\.conda\\envs\\scopefoundry\\lib\\site-packages\\ScopeFoundry\\measurement.py", line 273, in _on_display_update_timer\n    self.update_display()\n', '  File "C:\\Users\\Public\\quantum_sensing\\quantum_sensing\\fancy_microscope\\thorcam_capture.py", line 362, in update_display\n    self.imview.setImage(image, axes={\'y\':0, \'x\':1}, autoLevels=True)\n', '  File "C:\\Users\\ZHao\\.conda\\envs\\scopefoundry\\lib\\site-packages\\pyqtgraph\\imageview\\ImageView.py", line 322, in setImage\n    self.updateImage(autoHistogramRange=autoHistogramRange)\n', '  File "C:\\Users\\ZHao\\.conda\\envs\\scopefoundry\\lib\\site-packages\\pyqtgraph\\imageview\\ImageView.py", line 725, in updateImage\n    image = image.transpose(axorder)\n', "ValueError: axes don't match array\n"]
2022-10-19T16:51:49|ERROR|ThorCamCaptureMeasure|thor_cam_capture Failed to update figure1: axes don't match array. ['Traceback (most recent call last):\n', '  File "C:\\Users\\ZHao\\.conda\\envs\\scopefoundry\\lib\\site-packages\\ScopeFoundry\\measurement.py", line 273, in _on_display_update_timer\n    self.update_display()\n', '  File "C:\\Users\\Public\\quantum_sensing\\quantum_sensing\\fancy_microscope\\thorcam_capture.py", line 362, in update_display\n    self.imview.setImage(image, axes={\'y\':0, \'x\':1}, autoLevels=True)\n', '  File "C:\\Users\\ZHao\\.conda\\envs\\scopefoundry\\lib\\site-packages\\pyqtgraph\\imageview\\ImageView.py", line 322, in setImage\n    self.updateImage(autoHistogramRange=autoHistogramRange)\n', '  File "C:\\Users\\ZHao\\.conda\\envs\\scopefoundry\\lib\\site-packages\\pyqtgraph\\imageview\\ImageView.py", line 725, in updateImage\n    image = image.transpose(axorder)\n', "ValueError: axes don't match array\n"]
2022-10-19T16:51:49|ERROR|ThorCamCaptureMeasure|thor_cam_capture Failed to update figure1: axes don't match array. ['Traceback (most recent call last):\n', '  File "C:\\Users\\ZHao\\.conda\\envs\\scopefoundry\\lib\\site-packages\\ScopeFoundry\\measurement.py", line 273, in _on_display_update_timer\n    self.update_display()\n', '  File "C:\\Users\\Public\\quantum_sensing\\quantum_sensing\\fancy_microscope\\thorcam_capture.py", line 362, in update_display\n    self.imview.setImage(image, axes={\'y\':0, \'x\':1}, autoLevels=True)\n', '  File "C:\\Users\\ZHao\\.conda\\envs\\scopefoundry\\lib\\site-packages\\pyqtgraph\\imageview\\ImageView.py", line 322, in setImage\n    self.updateImage(autoHistogramRange=autoHistogramRange)\n', '  File "C:\\Users\\ZHao\\.conda\\envs\\scopefoundry\\lib\\site-packages\\pyqtgraph\\imageview\\ImageView.py", line 725, in updateImage\n    image = image.transpose(axorder)\n', "ValueError: axes don't match array\n"]
2022-10-19T16:51:49|ERROR|ThorCamCaptureMeasure|thor_cam_capture Failed to update figure1: axes don't match array. ['Traceback (most recent call last):\n', '  File "C:\\Users\\ZHao\\.conda\\envs\\scopefoundry\\lib\\site-packages\\ScopeFoundry\\measurement.py", line 273, in _on_display_update_timer\n    self.update_display()\n', '  File "C:\\Users\\Public\\quantum_sensing\\quantum_sensing\\fancy_microscope\\thorcam_capture.py", line 362, in update_display\n    self.imview.setImage(image, axes={\'y\':0, \'x\':1}, autoLevels=True)\n', '  File "C:\\Users\\ZHao\\.conda\\envs\\scopefoundry\\lib\\site-packages\\pyqtgraph\\imageview\\ImageView.py", line 322, in setImage\n    self.updateImage(autoHistogramRange=autoHistogramRange)\n', '  File "C:\\Users\\ZHao\\.conda\\envs\\scopefoundry\\lib\\site-packages\\pyqtgraph\\imageview\\ImageView.py", line 725, in updateImage\n    image = image.transpose(axorder)\n', "ValueError: axes don't match array\n"]
2022-10-19T16:51:49|ERROR|ThorCamCaptureMeasure|thor_cam_capture Failed to update figure1: axes don't match array. ['Traceback (most recent call last):\n', '  File "C:\\Users\\ZHao\\.conda\\envs\\scopefoundry\\lib\\site-packages\\ScopeFoundry\\measurement.py", line 273, in _on_display_update_timer\n    self.update_display()\n', '  File "C:\\Users\\Public\\quantum_sensing\\quantum_sensing\\fancy_microscope\\thorcam_capture.py", line 362, in update_display\n    self.imview.setImage(image, axes={\'y\':0, \'x\':1}, autoLevels=True)\n', '  File "C:\\Users\\ZHao\\.conda\\envs\\scopefoundry\\lib\\site-packages\\pyqtgraph\\imageview\\ImageView.py", line 322, in setImage\n    self.updateImage(autoHistogramRange=autoHistogramRange)\n', '  File "C:\\Users\\ZHao\\.conda\\envs\\scopefoundry\\lib\\site-packages\\pyqtgraph\\imageview\\ImageView.py", line 725, in updateImage\n    image = image.transpose(axorder)\n', "ValueError: axes don't match array\n"]
2022-10-19T16:51:49|ERROR|ThorCamCaptureMeasure|thor_cam_capture Failed to update figure1: axes don't match array. ['Traceback (most recent call last):\n', '  File "C:\\Users\\ZHao\\.conda\\envs\\scopefoundry\\lib\\site-packages\\ScopeFoundry\\measurement.py", line 273, in _on_display_update_timer\n    self.update_display()\n', '  File "C:\\Users\\Public\\quantum_sensing\\quantum_sensing\\fancy_microscope\\thorcam_capture.py", line 362, in update_display\n    self.imview.setImage(image, axes={\'y\':0, \'x\':1}, autoLevels=True)\n', '  File "C:\\Users\\ZHao\\.conda\\envs\\scopefoundry\\lib\\site-packages\\pyqtgraph\\imageview\\ImageView.py", line 322, in setImage\n    self.updateImage(autoHistogramRange=autoHistogramRange)\n', '  File "C:\\Users\\ZHao\\.conda\\envs\\scopefoundry\\lib\\site-packages\\pyqtgraph\\imageview\\ImageView.py", line 725, in updateImage\n    image = image.transpose(axorder)\n', "ValueError: axes don't match array\n"]
2022-10-19T16:51:49|ERROR|ThorCamCaptureMeasure|thor_cam_capture Failed to update figure1: axes don't match array. ['Traceback (most recent call last):\n', '  File "C:\\Users\\ZHao\\.conda\\envs\\scopefoundry\\lib\\site-packages\\ScopeFoundry\\measurement.py", line 273, in _on_display_update_timer\n    self.update_display()\n', '  File "C:\\Users\\Public\\quantum_sensing\\quantum_sensing\\fancy_microscope\\thorcam_capture.py", line 362, in update_display\n    self.imview.setImage(image, axes={\'y\':0, \'x\':1}, autoLevels=True)\n', '  File "C:\\Users\\ZHao\\.conda\\envs\\scopefoundry\\lib\\site-packages\\pyqtgraph\\imageview\\ImageView.py", line 322, in setImage\n    self.updateImage(autoHistogramRange=autoHistogramRange)\n', '  File "C:\\Users\\ZHao\\.conda\\envs\\scopefoundry\\lib\\site-packages\\pyqtgraph\\imageview\\ImageView.py", line 725, in updateImage\n    image = image.transpose(axorder)\n', "ValueError: axes don't match array\n"]
2022-10-19T16:51:49|ERROR|ThorCamCaptureMeasure|thor_cam_capture Failed to update figure1: axes don't match array. ['Traceback (most recent call last):\n', '  File "C:\\Users\\ZHao\\.conda\\envs\\scopefoundry\\lib\\site-packages\\ScopeFoundry\\measurement.py", line 273, in _on_display_update_timer\n    self.update_display()\n', '  File "C:\\Users\\Public\\quantum_sensing\\quantum_sensing\\fancy_microscope\\thorcam_capture.py", line 362, in update_display\n    self.imview.setImage(image, axes={\'y\':0, \'x\':1}, autoLevels=True)\n', '  File "C:\\Users\\ZHao\\.conda\\envs\\scopefoundry\\lib\\site-packages\\pyqtgraph\\imageview\\ImageView.py", line 322, in setImage\n    self.updateImage(autoHistogramRange=autoHistogramRange)\n', '  File "C:\\Users\\ZHao\\.conda\\envs\\scopefoundry\\lib\\site-packages\\pyqtgraph\\imageview\\ImageView.py", line 725, in updateImage\n    image = image.transpose(axorder)\n', "ValueError: axes don't match array\n"]
2022-10-19T16:51:50|ERROR|ThorCamCaptureMeasure|thor_cam_capture Failed to update figure1: axes don't match array. ['Traceback (most recent call last):\n', '  File "C:\\Users\\ZHao\\.conda\\envs\\scopefoundry\\lib\\site-packages\\ScopeFoundry\\measurement.py", line 273, in _on_display_update_timer\n    self.update_display()\n', '  File "C:\\Users\\Public\\quantum_sensing\\quantum_sensing\\fancy_microscope\\thorcam_capture.py", line 362, in update_display\n    self.imview.setImage(image, axes={\'y\':0, \'x\':1}, autoLevels=True)\n', '  File "C:\\Users\\ZHao\\.conda\\envs\\scopefoundry\\lib\\site-packages\\pyqtgraph\\imageview\\ImageView.py", line 322, in setImage\n    self.updateImage(autoHistogramRange=autoHistogramRange)\n', '  File "C:\\Users\\ZHao\\.conda\\envs\\scopefoundry\\lib\\site-packages\\pyqtgraph\\imageview\\ImageView.py", line 725, in updateImage\n    image = image.transpose(axorder)\n', "ValueError: axes don't match array\n"]
2022-10-19T16:51:50|ERROR|ThorCamCaptureMeasure|thor_cam_capture Failed to update figure1: axes don't match array. ['Traceback (most recent call last):\n', '  File "C:\\Users\\ZHao\\.conda\\envs\\scopefoundry\\lib\\site-packages\\ScopeFoundry\\measurement.py", line 273, in _on_display_update_timer\n    self.update_display()\n', '  File "C:\\Users\\Public\\quantum_sensing\\quantum_sensing\\fancy_microscope\\thorcam_capture.py", line 362, in update_display\n    self.imview.setImage(image, axes={\'y\':0, \'x\':1}, autoLevels=True)\n', '  File "C:\\Users\\ZHao\\.conda\\envs\\scopefoundry\\lib\\site-packages\\pyqtgraph\\imageview\\ImageView.py", line 322, in setImage\n    self.updateImage(autoHistogramRange=autoHistogramRange)\n', '  File "C:\\Users\\ZHao\\.conda\\envs\\scopefoundry\\lib\\site-packages\\pyqtgraph\\imageview\\ImageView.py", line 725, in updateImage\n    image = image.transpose(axorder)\n', "ValueError: axes don't match array\n"]
2022-10-19T16:51:50|ERROR|ThorCamCaptureMeasure|thor_cam_capture Failed to update figure1: axes don't match array. ['Traceback (most recent call last):\n', '  File "C:\\Users\\ZHao\\.conda\\envs\\scopefoundry\\lib\\site-packages\\ScopeFoundry\\measurement.py", line 273, in _on_display_update_timer\n    self.update_display()\n', '  File "C:\\Users\\Public\\quantum_sensing\\quantum_sensing\\fancy_microscope\\thorcam_capture.py", line 362, in update_display\n    self.imview.setImage(image, axes={\'y\':0, \'x\':1}, autoLevels=True)\n', '  File "C:\\Users\\ZHao\\.conda\\envs\\scopefoundry\\lib\\site-packages\\pyqtgraph\\imageview\\ImageView.py", line 322, in setImage\n    self.updateImage(autoHistogramRange=autoHistogramRange)\n', '  File "C:\\Users\\ZHao\\.conda\\envs\\scopefoundry\\lib\\site-packages\\pyqtgraph\\imageview\\ImageView.py", line 725, in updateImage\n    image = image.transpose(axorder)\n', "ValueError: axes don't match array\n"]
2022-10-19T16:51:50|ERROR|ThorCamCaptureMeasure|thor_cam_capture Failed to update figure1: axes don't match array. ['Traceback (most recent call last):\n', '  File "C:\\Users\\ZHao\\.conda\\envs\\scopefoundry\\lib\\site-packages\\ScopeFoundry\\measurement.py", line 273, in _on_display_update_timer\n    self.update_display()\n', '  File "C:\\Users\\Public\\quantum_sensing\\quantum_sensing\\fancy_microscope\\thorcam_capture.py", line 362, in update_display\n    self.imview.setImage(image, axes={\'y\':0, \'x\':1}, autoLevels=True)\n', '  File "C:\\Users\\ZHao\\.conda\\envs\\scopefoundry\\lib\\site-packages\\pyqtgraph\\imageview\\ImageView.py", line 322, in setImage\n    self.updateImage(autoHistogramRange=autoHistogramRange)\n', '  File "C:\\Users\\ZHao\\.conda\\envs\\scopefoundry\\lib\\site-packages\\pyqtgraph\\imageview\\ImageView.py", line 725, in updateImage\n    image = image.transpose(axorder)\n', "ValueError: axes don't match array\n"]
2022-10-19T16:51:50|ERROR|ThorCamCaptureMeasure|thor_cam_capture Failed to update figure1: axes don't match array. ['Traceback (most recent call last):\n', '  File "C:\\Users\\ZHao\\.conda\\envs\\scopefoundry\\lib\\site-packages\\ScopeFoundry\\measurement.py", line 273, in _on_display_update_timer\n    self.update_display()\n', '  File "C:\\Users\\Public\\quantum_sensing\\quantum_sensing\\fancy_microscope\\thorcam_capture.py", line 362, in update_display\n    self.imview.setImage(image, axes={\'y\':0, \'x\':1}, autoLevels=True)\n', '  File "C:\\Users\\ZHao\\.conda\\envs\\scopefoundry\\lib\\site-packages\\pyqtgraph\\imageview\\ImageView.py", line 322, in setImage\n    self.updateImage(autoHistogramRange=autoHistogramRange)\n', '  File "C:\\Users\\ZHao\\.conda\\envs\\scopefoundry\\lib\\site-packages\\pyqtgraph\\imageview\\ImageView.py", line 725, in updateImage\n    image = image.transpose(axorder)\n', "ValueError: axes don't match array\n"]
2022-10-19T16:51:50|ERROR|ThorCamCaptureMeasure|thor_cam_capture Failed to update figure1: axes don't match array. ['Traceback (most recent call last):\n', '  File "C:\\Users\\ZHao\\.conda\\envs\\scopefoundry\\lib\\site-packages\\ScopeFoundry\\measurement.py", line 273, in _on_display_update_timer\n    self.update_display()\n', '  File "C:\\Users\\Public\\quantum_sensing\\quantum_sensing\\fancy_microscope\\thorcam_capture.py", line 362, in update_display\n    self.imview.setImage(image, axes={\'y\':0, \'x\':1}, autoLevels=True)\n', '  File "C:\\Users\\ZHao\\.conda\\envs\\scopefoundry\\lib\\site-packages\\pyqtgraph\\imageview\\ImageView.py", line 322, in setImage\n    self.updateImage(autoHistogramRange=autoHistogramRange)\n', '  File "C:\\Users\\ZHao\\.conda\\envs\\scopefoundry\\lib\\site-packages\\pyqtgraph\\imageview\\ImageView.py", line 725, in updateImage\n    image = image.transpose(axorder)\n', "ValueError: axes don't match array\n"]
2022-10-19T16:51:50|ERROR|ThorCamCaptureMeasure|thor_cam_capture Failed to update figure1: axes don't match array. ['Traceback (most recent call last):\n', '  File "C:\\Users\\ZHao\\.conda\\envs\\scopefoundry\\lib\\site-packages\\ScopeFoundry\\measurement.py", line 273, in _on_display_update_timer\n    self.update_display()\n', '  File "C:\\Users\\Public\\quantum_sensing\\quantum_sensing\\fancy_microscope\\thorcam_capture.py", line 362, in update_display\n    self.imview.setImage(image, axes={\'y\':0, \'x\':1}, autoLevels=True)\n', '  File "C:\\Users\\ZHao\\.conda\\envs\\scopefoundry\\lib\\site-packages\\pyqtgraph\\imageview\\ImageView.py", line 322, in setImage\n    self.updateImage(autoHistogramRange=autoHistogramRange)\n', '  File "C:\\Users\\ZHao\\.conda\\envs\\scopefoundry\\lib\\site-packages\\pyqtgraph\\imageview\\ImageView.py", line 725, in updateImage\n    image = image.transpose(axorder)\n', "ValueError: axes don't match array\n"]
2022-10-19T16:51:50|ERROR|ThorCamCaptureMeasure|thor_cam_capture Failed to update figure1: axes don't match array. ['Traceback (most recent call last):\n', '  File "C:\\Users\\ZHao\\.conda\\envs\\scopefoundry\\lib\\site-packages\\ScopeFoundry\\measurement.py", line 273, in _on_display_update_timer\n    self.update_display()\n', '  File "C:\\Users\\Public\\quantum_sensing\\quantum_sensing\\fancy_microscope\\thorcam_capture.py", line 362, in update_display\n    self.imview.setImage(image, axes={\'y\':0, \'x\':1}, autoLevels=True)\n', '  File "C:\\Users\\ZHao\\.conda\\envs\\scopefoundry\\lib\\site-packages\\pyqtgraph\\imageview\\ImageView.py", line 322, in setImage\n    self.updateImage(autoHistogramRange=autoHistogramRange)\n', '  File "C:\\Users\\ZHao\\.conda\\envs\\scopefoundry\\lib\\site-packages\\pyqtgraph\\imageview\\ImageView.py", line 725, in updateImage\n    image = image.transpose(axorder)\n', "ValueError: axes don't match array\n"]
2022-10-19T16:51:50|ERROR|ThorCamCaptureMeasure|thor_cam_capture Failed to update figure1: axes don't match array. ['Traceback (most recent call last):\n', '  File "C:\\Users\\ZHao\\.conda\\envs\\scopefoundry\\lib\\site-packages\\ScopeFoundry\\measurement.py", line 273, in _on_display_update_timer\n    self.update_display()\n', '  File "C:\\Users\\Public\\quantum_sensing\\quantum_sensing\\fancy_microscope\\thorcam_capture.py", line 362, in update_display\n    self.imview.setImage(image, axes={\'y\':0, \'x\':1}, autoLevels=True)\n', '  File "C:\\Users\\ZHao\\.conda\\envs\\scopefoundry\\lib\\site-packages\\pyqtgraph\\imageview\\ImageView.py", line 322, in setImage\n    self.updateImage(autoHistogramRange=autoHistogramRange)\n', '  File "C:\\Users\\ZHao\\.conda\\envs\\scopefoundry\\lib\\site-packages\\pyqtgraph\\imageview\\ImageView.py", line 725, in updateImage\n    image = image.transpose(axorder)\n', "ValueError: axes don't match array\n"]
2022-10-19T16:51:51|ERROR|ThorCamCaptureMeasure|thor_cam_capture Failed to update figure1: axes don't match array. ['Traceback (most recent call last):\n', '  File "C:\\Users\\ZHao\\.conda\\envs\\scopefoundry\\lib\\site-packages\\ScopeFoundry\\measurement.py", line 273, in _on_display_update_timer\n    self.update_display()\n', '  File "C:\\Users\\Public\\quantum_sensing\\quantum_sensing\\fancy_microscope\\thorcam_capture.py", line 362, in update_display\n    self.imview.setImage(image, axes={\'y\':0, \'x\':1}, autoLevels=True)\n', '  File "C:\\Users\\ZHao\\.conda\\envs\\scopefoundry\\lib\\site-packages\\pyqtgraph\\imageview\\ImageView.py", line 322, in setImage\n    self.updateImage(autoHistogramRange=autoHistogramRange)\n', '  File "C:\\Users\\ZHao\\.conda\\envs\\scopefoundry\\lib\\site-packages\\pyqtgraph\\imageview\\ImageView.py", line 725, in updateImage\n    image = image.transpose(axorder)\n', "ValueError: axes don't match array\n"]
2022-10-19T16:51:51|ERROR|ThorCamCaptureMeasure|thor_cam_capture Failed to update figure1: axes don't match array. ['Traceback (most recent call last):\n', '  File "C:\\Users\\ZHao\\.conda\\envs\\scopefoundry\\lib\\site-packages\\ScopeFoundry\\measurement.py", line 273, in _on_display_update_timer\n    self.update_display()\n', '  File "C:\\Users\\Public\\quantum_sensing\\quantum_sensing\\fancy_microscope\\thorcam_capture.py", line 362, in update_display\n    self.imview.setImage(image, axes={\'y\':0, \'x\':1}, autoLevels=True)\n', '  File "C:\\Users\\ZHao\\.conda\\envs\\scopefoundry\\lib\\site-packages\\pyqtgraph\\imageview\\ImageView.py", line 322, in setImage\n    self.updateImage(autoHistogramRange=autoHistogramRange)\n', '  File "C:\\Users\\ZHao\\.conda\\envs\\scopefoundry\\lib\\site-packages\\pyqtgraph\\imageview\\ImageView.py", line 725, in updateImage\n    image = image.transpose(axorder)\n', "ValueError: axes don't match array\n"]
2022-10-19T16:51:51|ERROR|ThorCamCaptureMeasure|thor_cam_capture Failed to update figure1: axes don't match array. ['Traceback (most recent call last):\n', '  File "C:\\Users\\ZHao\\.conda\\envs\\scopefoundry\\lib\\site-packages\\ScopeFoundry\\measurement.py", line 273, in _on_display_update_timer\n    self.update_display()\n', '  File "C:\\Users\\Public\\quantum_sensing\\quantum_sensing\\fancy_microscope\\thorcam_capture.py", line 362, in update_display\n    self.imview.setImage(image, axes={\'y\':0, \'x\':1}, autoLevels=True)\n', '  File "C:\\Users\\ZHao\\.conda\\envs\\scopefoundry\\lib\\site-packages\\pyqtgraph\\imageview\\ImageView.py", line 322, in setImage\n    self.updateImage(autoHistogramRange=autoHistogramRange)\n', '  File "C:\\Users\\ZHao\\.conda\\envs\\scopefoundry\\lib\\site-packages\\pyqtgraph\\imageview\\ImageView.py", line 725, in updateImage\n    image = image.transpose(axorder)\n', "ValueError: axes don't match array\n"]
2022-10-19T16:51:51|ERROR|ThorCamCaptureMeasure|thor_cam_capture Failed to update figure1: axes don't match array. ['Traceback (most recent call last):\n', '  File "C:\\Users\\ZHao\\.conda\\envs\\scopefoundry\\lib\\site-packages\\ScopeFoundry\\measurement.py", line 273, in _on_display_update_timer\n    self.update_display()\n', '  File "C:\\Users\\Public\\quantum_sensing\\quantum_sensing\\fancy_microscope\\thorcam_capture.py", line 362, in update_display\n    self.imview.setImage(image, axes={\'y\':0, \'x\':1}, autoLevels=True)\n', '  File "C:\\Users\\ZHao\\.conda\\envs\\scopefoundry\\lib\\site-packages\\pyqtgraph\\imageview\\ImageView.py", line 322, in setImage\n    self.updateImage(autoHistogramRange=autoHistogramRange)\n', '  File "C:\\Users\\ZHao\\.conda\\envs\\scopefoundry\\lib\\site-packages\\pyqtgraph\\imageview\\ImageView.py", line 725, in updateImage\n    image = image.transpose(axorder)\n', "ValueError: axes don't match array\n"]
2022-10-19T16:51:51|ERROR|ThorCamCaptureMeasure|thor_cam_capture Failed to update figure1: axes don't match array. ['Traceback (most recent call last):\n', '  File "C:\\Users\\ZHao\\.conda\\envs\\scopefoundry\\lib\\site-packages\\ScopeFoundry\\measurement.py", line 273, in _on_display_update_timer\n    self.update_display()\n', '  File "C:\\Users\\Public\\quantum_sensing\\quantum_sensing\\fancy_microscope\\thorcam_capture.py", line 362, in update_display\n    self.imview.setImage(image, axes={\'y\':0, \'x\':1}, autoLevels=True)\n', '  File "C:\\Users\\ZHao\\.conda\\envs\\scopefoundry\\lib\\site-packages\\pyqtgraph\\imageview\\ImageView.py", line 322, in setImage\n    self.updateImage(autoHistogramRange=autoHistogramRange)\n', '  File "C:\\Users\\ZHao\\.conda\\envs\\scopefoundry\\lib\\site-packages\\pyqtgraph\\imageview\\ImageView.py", line 725, in updateImage\n    image = image.transpose(axorder)\n', "ValueError: axes don't match array\n"]
2022-10-19T16:51:51|ERROR|ThorCamCaptureMeasure|thor_cam_capture Failed to update figure1: axes don't match array. ['Traceback (most recent call last):\n', '  File "C:\\Users\\ZHao\\.conda\\envs\\scopefoundry\\lib\\site-packages\\ScopeFoundry\\measurement.py", line 273, in _on_display_update_timer\n    self.update_display()\n', '  File "C:\\Users\\Public\\quantum_sensing\\quantum_sensing\\fancy_microscope\\thorcam_capture.py", line 362, in update_display\n    self.imview.setImage(image, axes={\'y\':0, \'x\':1}, autoLevels=True)\n', '  File "C:\\Users\\ZHao\\.conda\\envs\\scopefoundry\\lib\\site-packages\\pyqtgraph\\imageview\\ImageView.py", line 322, in setImage\n    self.updateImage(autoHistogramRange=autoHistogramRange)\n', '  File "C:\\Users\\ZHao\\.conda\\envs\\scopefoundry\\lib\\site-packages\\pyqtgraph\\imageview\\ImageView.py", line 725, in updateImage\n    image = image.transpose(axorder)\n', "ValueError: axes don't match array\n"]
2022-10-19T16:51:51|ERROR|ThorCamCaptureMeasure|thor_cam_capture Failed to update figure1: axes don't match array. ['Traceback (most recent call last):\n', '  File "C:\\Users\\ZHao\\.conda\\envs\\scopefoundry\\lib\\site-packages\\ScopeFoundry\\measurement.py", line 273, in _on_display_update_timer\n    self.update_display()\n', '  File "C:\\Users\\Public\\quantum_sensing\\quantum_sensing\\fancy_microscope\\thorcam_capture.py", line 362, in update_display\n    self.imview.setImage(image, axes={\'y\':0, \'x\':1}, autoLevels=True)\n', '  File "C:\\Users\\ZHao\\.conda\\envs\\scopefoundry\\lib\\site-packages\\pyqtgraph\\imageview\\ImageView.py", line 322, in setImage\n    self.updateImage(autoHistogramRange=autoHistogramRange)\n', '  File "C:\\Users\\ZHao\\.conda\\envs\\scopefoundry\\lib\\site-packages\\pyqtgraph\\imageview\\ImageView.py", line 725, in updateImage\n    image = image.transpose(axorder)\n', "ValueError: axes don't match array\n"]
2022-10-19T16:51:51|ERROR|ThorCamCaptureMeasure|thor_cam_capture Failed to update figure1: axes don't match array. ['Traceback (most recent call last):\n', '  File "C:\\Users\\ZHao\\.conda\\envs\\scopefoundry\\lib\\site-packages\\ScopeFoundry\\measurement.py", line 273, in _on_display_update_timer\n    self.update_display()\n', '  File "C:\\Users\\Public\\quantum_sensing\\quantum_sensing\\fancy_microscope\\thorcam_capture.py", line 362, in update_display\n    self.imview.setImage(image, axes={\'y\':0, \'x\':1}, autoLevels=True)\n', '  File "C:\\Users\\ZHao\\.conda\\envs\\scopefoundry\\lib\\site-packages\\pyqtgraph\\imageview\\ImageView.py", line 322, in setImage\n    self.updateImage(autoHistogramRange=autoHistogramRange)\n', '  File "C:\\Users\\ZHao\\.conda\\envs\\scopefoundry\\lib\\site-packages\\pyqtgraph\\imageview\\ImageView.py", line 725, in updateImage\n    image = image.transpose(axorder)\n', "ValueError: axes don't match array\n"]
2022-10-19T16:51:51|ERROR|ThorCamCaptureMeasure|thor_cam_capture Failed to update figure1: axes don't match array. ['Traceback (most recent call last):\n', '  File "C:\\Users\\ZHao\\.conda\\envs\\scopefoundry\\lib\\site-packages\\ScopeFoundry\\measurement.py", line 273, in _on_display_update_timer\n    self.update_display()\n', '  File "C:\\Users\\Public\\quantum_sensing\\quantum_sensing\\fancy_microscope\\thorcam_capture.py", line 362, in update_display\n    self.imview.setImage(image, axes={\'y\':0, \'x\':1}, autoLevels=True)\n', '  File "C:\\Users\\ZHao\\.conda\\envs\\scopefoundry\\lib\\site-packages\\pyqtgraph\\imageview\\ImageView.py", line 322, in setImage\n    self.updateImage(autoHistogramRange=autoHistogramRange)\n', '  File "C:\\Users\\ZHao\\.conda\\envs\\scopefoundry\\lib\\site-packages\\pyqtgraph\\imageview\\ImageView.py", line 725, in updateImage\n    image = image.transpose(axorder)\n', "ValueError: axes don't match array\n"]
2022-10-19T16:51:52|ERROR|ThorCamCaptureMeasure|thor_cam_capture Failed to update figure1: axes don't match array. ['Traceback (most recent call last):\n', '  File "C:\\Users\\ZHao\\.conda\\envs\\scopefoundry\\lib\\site-packages\\ScopeFoundry\\measurement.py", line 273, in _on_display_update_timer\n    self.update_display()\n', '  File "C:\\Users\\Public\\quantum_sensing\\quantum_sensing\\fancy_microscope\\thorcam_capture.py", line 362, in update_display\n    self.imview.setImage(image, axes={\'y\':0, \'x\':1}, autoLevels=True)\n', '  File "C:\\Users\\ZHao\\.conda\\envs\\scopefoundry\\lib\\site-packages\\pyqtgraph\\imageview\\ImageView.py", line 322, in setImage\n    self.updateImage(autoHistogramRange=autoHistogramRange)\n', '  File "C:\\Users\\ZHao\\.conda\\envs\\scopefoundry\\lib\\site-packages\\pyqtgraph\\imageview\\ImageView.py", line 725, in updateImage\n    image = image.transpose(axorder)\n', "ValueError: axes don't match array\n"]
2022-10-19T16:51:52|ERROR|ThorCamCaptureMeasure|thor_cam_capture Failed to update figure1: axes don't match array. ['Traceback (most recent call last):\n', '  File "C:\\Users\\ZHao\\.conda\\envs\\scopefoundry\\lib\\site-packages\\ScopeFoundry\\measurement.py", line 273, in _on_display_update_timer\n    self.update_display()\n', '  File "C:\\Users\\Public\\quantum_sensing\\quantum_sensing\\fancy_microscope\\thorcam_capture.py", line 362, in update_display\n    self.imview.setImage(image, axes={\'y\':0, \'x\':1}, autoLevels=True)\n', '  File "C:\\Users\\ZHao\\.conda\\envs\\scopefoundry\\lib\\site-packages\\pyqtgraph\\imageview\\ImageView.py", line 322, in setImage\n    self.updateImage(autoHistogramRange=autoHistogramRange)\n', '  File "C:\\Users\\ZHao\\.conda\\envs\\scopefoundry\\lib\\site-packages\\pyqtgraph\\imageview\\ImageView.py", line 725, in updateImage\n    image = image.transpose(axorder)\n', "ValueError: axes don't match array\n"]
2022-10-19T16:51:52|ERROR|ThorCamCaptureMeasure|thor_cam_capture Failed to update figure1: axes don't match array. ['Traceback (most recent call last):\n', '  File "C:\\Users\\ZHao\\.conda\\envs\\scopefoundry\\lib\\site-packages\\ScopeFoundry\\measurement.py", line 273, in _on_display_update_timer\n    self.update_display()\n', '  File "C:\\Users\\Public\\quantum_sensing\\quantum_sensing\\fancy_microscope\\thorcam_capture.py", line 362, in update_display\n    self.imview.setImage(image, axes={\'y\':0, \'x\':1}, autoLevels=True)\n', '  File "C:\\Users\\ZHao\\.conda\\envs\\scopefoundry\\lib\\site-packages\\pyqtgraph\\imageview\\ImageView.py", line 322, in setImage\n    self.updateImage(autoHistogramRange=autoHistogramRange)\n', '  File "C:\\Users\\ZHao\\.conda\\envs\\scopefoundry\\lib\\site-packages\\pyqtgraph\\imageview\\ImageView.py", line 725, in updateImage\n    image = image.transpose(axorder)\n', "ValueError: axes don't match array\n"]
2022-10-19T16:51:52|ERROR|ThorCamCaptureMeasure|thor_cam_capture Failed to update figure1: axes don't match array. ['Traceback (most recent call last):\n', '  File "C:\\Users\\ZHao\\.conda\\envs\\scopefoundry\\lib\\site-packages\\ScopeFoundry\\measurement.py", line 273, in _on_display_update_timer\n    self.update_display()\n', '  File "C:\\Users\\Public\\quantum_sensing\\quantum_sensing\\fancy_microscope\\thorcam_capture.py", line 362, in update_display\n    self.imview.setImage(image, axes={\'y\':0, \'x\':1}, autoLevels=True)\n', '  File "C:\\Users\\ZHao\\.conda\\envs\\scopefoundry\\lib\\site-packages\\pyqtgraph\\imageview\\ImageView.py", line 322, in setImage\n    self.updateImage(autoHistogramRange=autoHistogramRange)\n', '  File "C:\\Users\\ZHao\\.conda\\envs\\scopefoundry\\lib\\site-packages\\pyqtgraph\\imageview\\ImageView.py", line 725, in updateImage\n    image = image.transpose(axorder)\n', "ValueError: axes don't match array\n"]
2022-10-19T16:51:52|ERROR|ThorCamCaptureMeasure|thor_cam_capture Failed to update figure1: axes don't match array. ['Traceback (most recent call last):\n', '  File "C:\\Users\\ZHao\\.conda\\envs\\scopefoundry\\lib\\site-packages\\ScopeFoundry\\measurement.py", line 273, in _on_display_update_timer\n    self.update_display()\n', '  File "C:\\Users\\Public\\quantum_sensing\\quantum_sensing\\fancy_microscope\\thorcam_capture.py", line 362, in update_display\n    self.imview.setImage(image, axes={\'y\':0, \'x\':1}, autoLevels=True)\n', '  File "C:\\Users\\ZHao\\.conda\\envs\\scopefoundry\\lib\\site-packages\\pyqtgraph\\imageview\\ImageView.py", line 322, in setImage\n    self.updateImage(autoHistogramRange=autoHistogramRange)\n', '  File "C:\\Users\\ZHao\\.conda\\envs\\scopefoundry\\lib\\site-packages\\pyqtgraph\\imageview\\ImageView.py", line 725, in updateImage\n    image = image.transpose(axorder)\n', "ValueError: axes don't match array\n"]
2022-10-19T16:51:52|ERROR|ThorCamCaptureMeasure|thor_cam_capture Failed to update figure1: axes don't match array. ['Traceback (most recent call last):\n', '  File "C:\\Users\\ZHao\\.conda\\envs\\scopefoundry\\lib\\site-packages\\ScopeFoundry\\measurement.py", line 273, in _on_display_update_timer\n    self.update_display()\n', '  File "C:\\Users\\Public\\quantum_sensing\\quantum_sensing\\fancy_microscope\\thorcam_capture.py", line 362, in update_display\n    self.imview.setImage(image, axes={\'y\':0, \'x\':1}, autoLevels=True)\n', '  File "C:\\Users\\ZHao\\.conda\\envs\\scopefoundry\\lib\\site-packages\\pyqtgraph\\imageview\\ImageView.py", line 322, in setImage\n    self.updateImage(autoHistogramRange=autoHistogramRange)\n', '  File "C:\\Users\\ZHao\\.conda\\envs\\scopefoundry\\lib\\site-packages\\pyqtgraph\\imageview\\ImageView.py", line 725, in updateImage\n    image = image.transpose(axorder)\n', "ValueError: axes don't match array\n"]
2022-10-19T16:51:52|ERROR|ThorCamCaptureMeasure|thor_cam_capture Failed to update figure1: axes don't match array. ['Traceback (most recent call last):\n', '  File "C:\\Users\\ZHao\\.conda\\envs\\scopefoundry\\lib\\site-packages\\ScopeFoundry\\measurement.py", line 273, in _on_display_update_timer\n    self.update_display()\n', '  File "C:\\Users\\Public\\quantum_sensing\\quantum_sensing\\fancy_microscope\\thorcam_capture.py", line 362, in update_display\n    self.imview.setImage(image, axes={\'y\':0, \'x\':1}, autoLevels=True)\n', '  File "C:\\Users\\ZHao\\.conda\\envs\\scopefoundry\\lib\\site-packages\\pyqtgraph\\imageview\\ImageView.py", line 322, in setImage\n    self.updateImage(autoHistogramRange=autoHistogramRange)\n', '  File "C:\\Users\\ZHao\\.conda\\envs\\scopefoundry\\lib\\site-packages\\pyqtgraph\\imageview\\ImageView.py", line 725, in updateImage\n    image = image.transpose(axorder)\n', "ValueError: axes don't match array\n"]
2022-10-19T16:51:52|ERROR|ThorCamCaptureMeasure|thor_cam_capture Failed to update figure1: axes don't match array. ['Traceback (most recent call last):\n', '  File "C:\\Users\\ZHao\\.conda\\envs\\scopefoundry\\lib\\site-packages\\ScopeFoundry\\measurement.py", line 273, in _on_display_update_timer\n    self.update_display()\n', '  File "C:\\Users\\Public\\quantum_sensing\\quantum_sensing\\fancy_microscope\\thorcam_capture.py", line 362, in update_display\n    self.imview.setImage(image, axes={\'y\':0, \'x\':1}, autoLevels=True)\n', '  File "C:\\Users\\ZHao\\.conda\\envs\\scopefoundry\\lib\\site-packages\\pyqtgraph\\imageview\\ImageView.py", line 322, in setImage\n    self.updateImage(autoHistogramRange=autoHistogramRange)\n', '  File "C:\\Users\\ZHao\\.conda\\envs\\scopefoundry\\lib\\site-packages\\pyqtgraph\\imageview\\ImageView.py", line 725, in updateImage\n    image = image.transpose(axorder)\n', "ValueError: axes don't match array\n"]
2022-10-19T16:51:52|ERROR|ThorCamCaptureMeasure|thor_cam_capture Failed to update figure1: axes don't match array. ['Traceback (most recent call last):\n', '  File "C:\\Users\\ZHao\\.conda\\envs\\scopefoundry\\lib\\site-packages\\ScopeFoundry\\measurement.py", line 273, in _on_display_update_timer\n    self.update_display()\n', '  File "C:\\Users\\Public\\quantum_sensing\\quantum_sensing\\fancy_microscope\\thorcam_capture.py", line 362, in update_display\n    self.imview.setImage(image, axes={\'y\':0, \'x\':1}, autoLevels=True)\n', '  File "C:\\Users\\ZHao\\.conda\\envs\\scopefoundry\\lib\\site-packages\\pyqtgraph\\imageview\\ImageView.py", line 322, in setImage\n    self.updateImage(autoHistogramRange=autoHistogramRange)\n', '  File "C:\\Users\\ZHao\\.conda\\envs\\scopefoundry\\lib\\site-packages\\pyqtgraph\\imageview\\ImageView.py", line 725, in updateImage\n    image = image.transpose(axorder)\n', "ValueError: axes don't match array\n"]
2022-10-19T16:51:53|ERROR|ThorCamCaptureMeasure|thor_cam_capture Failed to update figure1: axes don't match array. ['Traceback (most recent call last):\n', '  File "C:\\Users\\ZHao\\.conda\\envs\\scopefoundry\\lib\\site-packages\\ScopeFoundry\\measurement.py", line 273, in _on_display_update_timer\n    self.update_display()\n', '  File "C:\\Users\\Public\\quantum_sensing\\quantum_sensing\\fancy_microscope\\thorcam_capture.py", line 362, in update_display\n    self.imview.setImage(image, axes={\'y\':0, \'x\':1}, autoLevels=True)\n', '  File "C:\\Users\\ZHao\\.conda\\envs\\scopefoundry\\lib\\site-packages\\pyqtgraph\\imageview\\ImageView.py", line 322, in setImage\n    self.updateImage(autoHistogramRange=autoHistogramRange)\n', '  File "C:\\Users\\ZHao\\.conda\\envs\\scopefoundry\\lib\\site-packages\\pyqtgraph\\imageview\\ImageView.py", line 725, in updateImage\n    image = image.transpose(axorder)\n', "ValueError: axes don't match array\n"]
2022-10-19T16:51:53|ERROR|ThorCamCaptureMeasure|thor_cam_capture Failed to update figure1: axes don't match array. ['Traceback (most recent call last):\n', '  File "C:\\Users\\ZHao\\.conda\\envs\\scopefoundry\\lib\\site-packages\\ScopeFoundry\\measurement.py", line 273, in _on_display_update_timer\n    self.update_display()\n', '  File "C:\\Users\\Public\\quantum_sensing\\quantum_sensing\\fancy_microscope\\thorcam_capture.py", line 362, in update_display\n    self.imview.setImage(image, axes={\'y\':0, \'x\':1}, autoLevels=True)\n', '  File "C:\\Users\\ZHao\\.conda\\envs\\scopefoundry\\lib\\site-packages\\pyqtgraph\\imageview\\ImageView.py", line 322, in setImage\n    self.updateImage(autoHistogramRange=autoHistogramRange)\n', '  File "C:\\Users\\ZHao\\.conda\\envs\\scopefoundry\\lib\\site-packages\\pyqtgraph\\imageview\\ImageView.py", line 725, in updateImage\n    image = image.transpose(axorder)\n', "ValueError: axes don't match array\n"]
2022-10-19T16:51:53|ERROR|ThorCamCaptureMeasure|thor_cam_capture Failed to update figure1: axes don't match array. ['Traceback (most recent call last):\n', '  File "C:\\Users\\ZHao\\.conda\\envs\\scopefoundry\\lib\\site-packages\\ScopeFoundry\\measurement.py", line 273, in _on_display_update_timer\n    self.update_display()\n', '  File "C:\\Users\\Public\\quantum_sensing\\quantum_sensing\\fancy_microscope\\thorcam_capture.py", line 362, in update_display\n    self.imview.setImage(image, axes={\'y\':0, \'x\':1}, autoLevels=True)\n', '  File "C:\\Users\\ZHao\\.conda\\envs\\scopefoundry\\lib\\site-packages\\pyqtgraph\\imageview\\ImageView.py", line 322, in setImage\n    self.updateImage(autoHistogramRange=autoHistogramRange)\n', '  File "C:\\Users\\ZHao\\.conda\\envs\\scopefoundry\\lib\\site-packages\\pyqtgraph\\imageview\\ImageView.py", line 725, in updateImage\n    image = image.transpose(axorder)\n', "ValueError: axes don't match array\n"]
2022-10-19T16:51:53|ERROR|ThorCamCaptureMeasure|thor_cam_capture Failed to update figure1: axes don't match array. ['Traceback (most recent call last):\n', '  File "C:\\Users\\ZHao\\.conda\\envs\\scopefoundry\\lib\\site-packages\\ScopeFoundry\\measurement.py", line 273, in _on_display_update_timer\n    self.update_display()\n', '  File "C:\\Users\\Public\\quantum_sensing\\quantum_sensing\\fancy_microscope\\thorcam_capture.py", line 362, in update_display\n    self.imview.setImage(image, axes={\'y\':0, \'x\':1}, autoLevels=True)\n', '  File "C:\\Users\\ZHao\\.conda\\envs\\scopefoundry\\lib\\site-packages\\pyqtgraph\\imageview\\ImageView.py", line 322, in setImage\n    self.updateImage(autoHistogramRange=autoHistogramRange)\n', '  File "C:\\Users\\ZHao\\.conda\\envs\\scopefoundry\\lib\\site-packages\\pyqtgraph\\imageview\\ImageView.py", line 725, in updateImage\n    image = image.transpose(axorder)\n', "ValueError: axes don't match array\n"]
2022-10-19T16:51:53|ERROR|ThorCamCaptureMeasure|thor_cam_capture Failed to update figure1: axes don't match array. ['Traceback (most recent call last):\n', '  File "C:\\Users\\ZHao\\.conda\\envs\\scopefoundry\\lib\\site-packages\\ScopeFoundry\\measurement.py", line 273, in _on_display_update_timer\n    self.update_display()\n', '  File "C:\\Users\\Public\\quantum_sensing\\quantum_sensing\\fancy_microscope\\thorcam_capture.py", line 362, in update_display\n    self.imview.setImage(image, axes={\'y\':0, \'x\':1}, autoLevels=True)\n', '  File "C:\\Users\\ZHao\\.conda\\envs\\scopefoundry\\lib\\site-packages\\pyqtgraph\\imageview\\ImageView.py", line 322, in setImage\n    self.updateImage(autoHistogramRange=autoHistogramRange)\n', '  File "C:\\Users\\ZHao\\.conda\\envs\\scopefoundry\\lib\\site-packages\\pyqtgraph\\imageview\\ImageView.py", line 725, in updateImage\n    image = image.transpose(axorder)\n', "ValueError: axes don't match array\n"]
2022-10-19T16:51:53|ERROR|ThorCamCaptureMeasure|thor_cam_capture Failed to update figure1: axes don't match array. ['Traceback (most recent call last):\n', '  File "C:\\Users\\ZHao\\.conda\\envs\\scopefoundry\\lib\\site-packages\\ScopeFoundry\\measurement.py", line 273, in _on_display_update_timer\n    self.update_display()\n', '  File "C:\\Users\\Public\\quantum_sensing\\quantum_sensing\\fancy_microscope\\thorcam_capture.py", line 362, in update_display\n    self.imview.setImage(image, axes={\'y\':0, \'x\':1}, autoLevels=True)\n', '  File "C:\\Users\\ZHao\\.conda\\envs\\scopefoundry\\lib\\site-packages\\pyqtgraph\\imageview\\ImageView.py", line 322, in setImage\n    self.updateImage(autoHistogramRange=autoHistogramRange)\n', '  File "C:\\Users\\ZHao\\.conda\\envs\\scopefoundry\\lib\\site-packages\\pyqtgraph\\imageview\\ImageView.py", line 725, in updateImage\n    image = image.transpose(axorder)\n', "ValueError: axes don't match array\n"]
2022-10-19T16:51:53|ERROR|ThorCamCaptureMeasure|thor_cam_capture Failed to update figure1: axes don't match array. ['Traceback (most recent call last):\n', '  File "C:\\Users\\ZHao\\.conda\\envs\\scopefoundry\\lib\\site-packages\\ScopeFoundry\\measurement.py", line 273, in _on_display_update_timer\n    self.update_display()\n', '  File "C:\\Users\\Public\\quantum_sensing\\quantum_sensing\\fancy_microscope\\thorcam_capture.py", line 362, in update_display\n    self.imview.setImage(image, axes={\'y\':0, \'x\':1}, autoLevels=True)\n', '  File "C:\\Users\\ZHao\\.conda\\envs\\scopefoundry\\lib\\site-packages\\pyqtgraph\\imageview\\ImageView.py", line 322, in setImage\n    self.updateImage(autoHistogramRange=autoHistogramRange)\n', '  File "C:\\Users\\ZHao\\.conda\\envs\\scopefoundry\\lib\\site-packages\\pyqtgraph\\imageview\\ImageView.py", line 725, in updateImage\n    image = image.transpose(axorder)\n', "ValueError: axes don't match array\n"]
2022-10-19T16:51:53|ERROR|ThorCamCaptureMeasure|thor_cam_capture Failed to update figure1: axes don't match array. ['Traceback (most recent call last):\n', '  File "C:\\Users\\ZHao\\.conda\\envs\\scopefoundry\\lib\\site-packages\\ScopeFoundry\\measurement.py", line 273, in _on_display_update_timer\n    self.update_display()\n', '  File "C:\\Users\\Public\\quantum_sensing\\quantum_sensing\\fancy_microscope\\thorcam_capture.py", line 362, in update_display\n    self.imview.setImage(image, axes={\'y\':0, \'x\':1}, autoLevels=True)\n', '  File "C:\\Users\\ZHao\\.conda\\envs\\scopefoundry\\lib\\site-packages\\pyqtgraph\\imageview\\ImageView.py", line 322, in setImage\n    self.updateImage(autoHistogramRange=autoHistogramRange)\n', '  File "C:\\Users\\ZHao\\.conda\\envs\\scopefoundry\\lib\\site-packages\\pyqtgraph\\imageview\\ImageView.py", line 725, in updateImage\n    image = image.transpose(axorder)\n', "ValueError: axes don't match array\n"]
2022-10-19T16:51:53|ERROR|ThorCamCaptureMeasure|thor_cam_capture Failed to update figure1: axes don't match array. ['Traceback (most recent call last):\n', '  File "C:\\Users\\ZHao\\.conda\\envs\\scopefoundry\\lib\\site-packages\\ScopeFoundry\\measurement.py", line 273, in _on_display_update_timer\n    self.update_display()\n', '  File "C:\\Users\\Public\\quantum_sensing\\quantum_sensing\\fancy_microscope\\thorcam_capture.py", line 362, in update_display\n    self.imview.setImage(image, axes={\'y\':0, \'x\':1}, autoLevels=True)\n', '  File "C:\\Users\\ZHao\\.conda\\envs\\scopefoundry\\lib\\site-packages\\pyqtgraph\\imageview\\ImageView.py", line 322, in setImage\n    self.updateImage(autoHistogramRange=autoHistogramRange)\n', '  File "C:\\Users\\ZHao\\.conda\\envs\\scopefoundry\\lib\\site-packages\\pyqtgraph\\imageview\\ImageView.py", line 725, in updateImage\n    image = image.transpose(axorder)\n', "ValueError: axes don't match array\n"]
2022-10-19T16:51:54|ERROR|ThorCamCaptureMeasure|thor_cam_capture Failed to update figure1: axes don't match array. ['Traceback (most recent call last):\n', '  File "C:\\Users\\ZHao\\.conda\\envs\\scopefoundry\\lib\\site-packages\\ScopeFoundry\\measurement.py", line 273, in _on_display_update_timer\n    self.update_display()\n', '  File "C:\\Users\\Public\\quantum_sensing\\quantum_sensing\\fancy_microscope\\thorcam_capture.py", line 362, in update_display\n    self.imview.setImage(image, axes={\'y\':0, \'x\':1}, autoLevels=True)\n', '  File "C:\\Users\\ZHao\\.conda\\envs\\scopefoundry\\lib\\site-packages\\pyqtgraph\\imageview\\ImageView.py", line 322, in setImage\n    self.updateImage(autoHistogramRange=autoHistogramRange)\n', '  File "C:\\Users\\ZHao\\.conda\\envs\\scopefoundry\\lib\\site-packages\\pyqtgraph\\imageview\\ImageView.py", line 725, in updateImage\n    image = image.transpose(axorder)\n', "ValueError: axes don't match array\n"]
2022-10-19T16:51:54|ERROR|ThorCamCaptureMeasure|thor_cam_capture Failed to update figure1: axes don't match array. ['Traceback (most recent call last):\n', '  File "C:\\Users\\ZHao\\.conda\\envs\\scopefoundry\\lib\\site-packages\\ScopeFoundry\\measurement.py", line 273, in _on_display_update_timer\n    self.update_display()\n', '  File "C:\\Users\\Public\\quantum_sensing\\quantum_sensing\\fancy_microscope\\thorcam_capture.py", line 362, in update_display\n    self.imview.setImage(image, axes={\'y\':0, \'x\':1}, autoLevels=True)\n', '  File "C:\\Users\\ZHao\\.conda\\envs\\scopefoundry\\lib\\site-packages\\pyqtgraph\\imageview\\ImageView.py", line 322, in setImage\n    self.updateImage(autoHistogramRange=autoHistogramRange)\n', '  File "C:\\Users\\ZHao\\.conda\\envs\\scopefoundry\\lib\\site-packages\\pyqtgraph\\imageview\\ImageView.py", line 725, in updateImage\n    image = image.transpose(axorder)\n', "ValueError: axes don't match array\n"]
2022-10-19T16:51:54|ERROR|ThorCamCaptureMeasure|thor_cam_capture Failed to update figure1: axes don't match array. ['Traceback (most recent call last):\n', '  File "C:\\Users\\ZHao\\.conda\\envs\\scopefoundry\\lib\\site-packages\\ScopeFoundry\\measurement.py", line 273, in _on_display_update_timer\n    self.update_display()\n', '  File "C:\\Users\\Public\\quantum_sensing\\quantum_sensing\\fancy_microscope\\thorcam_capture.py", line 362, in update_display\n    self.imview.setImage(image, axes={\'y\':0, \'x\':1}, autoLevels=True)\n', '  File "C:\\Users\\ZHao\\.conda\\envs\\scopefoundry\\lib\\site-packages\\pyqtgraph\\imageview\\ImageView.py", line 322, in setImage\n    self.updateImage(autoHistogramRange=autoHistogramRange)\n', '  File "C:\\Users\\ZHao\\.conda\\envs\\scopefoundry\\lib\\site-packages\\pyqtgraph\\imageview\\ImageView.py", line 725, in updateImage\n    image = image.transpose(axorder)\n', "ValueError: axes don't match array\n"]
2022-10-19T16:51:54|ERROR|ThorCamCaptureMeasure|thor_cam_capture Failed to update figure1: axes don't match array. ['Traceback (most recent call last):\n', '  File "C:\\Users\\ZHao\\.conda\\envs\\scopefoundry\\lib\\site-packages\\ScopeFoundry\\measurement.py", line 273, in _on_display_update_timer\n    self.update_display()\n', '  File "C:\\Users\\Public\\quantum_sensing\\quantum_sensing\\fancy_microscope\\thorcam_capture.py", line 362, in update_display\n    self.imview.setImage(image, axes={\'y\':0, \'x\':1}, autoLevels=True)\n', '  File "C:\\Users\\ZHao\\.conda\\envs\\scopefoundry\\lib\\site-packages\\pyqtgraph\\imageview\\ImageView.py", line 322, in setImage\n    self.updateImage(autoHistogramRange=autoHistogramRange)\n', '  File "C:\\Users\\ZHao\\.conda\\envs\\scopefoundry\\lib\\site-packages\\pyqtgraph\\imageview\\ImageView.py", line 725, in updateImage\n    image = image.transpose(axorder)\n', "ValueError: axes don't match array\n"]
2022-10-19T16:51:54|ERROR|ThorCamCaptureMeasure|thor_cam_capture Failed to update figure1: axes don't match array. ['Traceback (most recent call last):\n', '  File "C:\\Users\\ZHao\\.conda\\envs\\scopefoundry\\lib\\site-packages\\ScopeFoundry\\measurement.py", line 273, in _on_display_update_timer\n    self.update_display()\n', '  File "C:\\Users\\Public\\quantum_sensing\\quantum_sensing\\fancy_microscope\\thorcam_capture.py", line 362, in update_display\n    self.imview.setImage(image, axes={\'y\':0, \'x\':1}, autoLevels=True)\n', '  File "C:\\Users\\ZHao\\.conda\\envs\\scopefoundry\\lib\\site-packages\\pyqtgraph\\imageview\\ImageView.py", line 322, in setImage\n    self.updateImage(autoHistogramRange=autoHistogramRange)\n', '  File "C:\\Users\\ZHao\\.conda\\envs\\scopefoundry\\lib\\site-packages\\pyqtgraph\\imageview\\ImageView.py", line 725, in updateImage\n    image = image.transpose(axorder)\n', "ValueError: axes don't match array\n"]
2022-10-19T16:51:54|ERROR|ThorCamCaptureMeasure|thor_cam_capture Failed to update figure1: axes don't match array. ['Traceback (most recent call last):\n', '  File "C:\\Users\\ZHao\\.conda\\envs\\scopefoundry\\lib\\site-packages\\ScopeFoundry\\measurement.py", line 273, in _on_display_update_timer\n    self.update_display()\n', '  File "C:\\Users\\Public\\quantum_sensing\\quantum_sensing\\fancy_microscope\\thorcam_capture.py", line 362, in update_display\n    self.imview.setImage(image, axes={\'y\':0, \'x\':1}, autoLevels=True)\n', '  File "C:\\Users\\ZHao\\.conda\\envs\\scopefoundry\\lib\\site-packages\\pyqtgraph\\imageview\\ImageView.py", line 322, in setImage\n    self.updateImage(autoHistogramRange=autoHistogramRange)\n', '  File "C:\\Users\\ZHao\\.conda\\envs\\scopefoundry\\lib\\site-packages\\pyqtgraph\\imageview\\ImageView.py", line 725, in updateImage\n    image = image.transpose(axorder)\n', "ValueError: axes don't match array\n"]
2022-10-19T16:51:54|ERROR|ThorCamCaptureMeasure|thor_cam_capture Failed to update figure1: axes don't match array. ['Traceback (most recent call last):\n', '  File "C:\\Users\\ZHao\\.conda\\envs\\scopefoundry\\lib\\site-packages\\ScopeFoundry\\measurement.py", line 273, in _on_display_update_timer\n    self.update_display()\n', '  File "C:\\Users\\Public\\quantum_sensing\\quantum_sensing\\fancy_microscope\\thorcam_capture.py", line 362, in update_display\n    self.imview.setImage(image, axes={\'y\':0, \'x\':1}, autoLevels=True)\n', '  File "C:\\Users\\ZHao\\.conda\\envs\\scopefoundry\\lib\\site-packages\\pyqtgraph\\imageview\\ImageView.py", line 322, in setImage\n    self.updateImage(autoHistogramRange=autoHistogramRange)\n', '  File "C:\\Users\\ZHao\\.conda\\envs\\scopefoundry\\lib\\site-packages\\pyqtgraph\\imageview\\ImageView.py", line 725, in updateImage\n    image = image.transpose(axorder)\n', "ValueError: axes don't match array\n"]
2022-10-19T16:51:54|ERROR|ThorCamCaptureMeasure|thor_cam_capture Failed to update figure1: axes don't match array. ['Traceback (most recent call last):\n', '  File "C:\\Users\\ZHao\\.conda\\envs\\scopefoundry\\lib\\site-packages\\ScopeFoundry\\measurement.py", line 273, in _on_display_update_timer\n    self.update_display()\n', '  File "C:\\Users\\Public\\quantum_sensing\\quantum_sensing\\fancy_microscope\\thorcam_capture.py", line 362, in update_display\n    self.imview.setImage(image, axes={\'y\':0, \'x\':1}, autoLevels=True)\n', '  File "C:\\Users\\ZHao\\.conda\\envs\\scopefoundry\\lib\\site-packages\\pyqtgraph\\imageview\\ImageView.py", line 322, in setImage\n    self.updateImage(autoHistogramRange=autoHistogramRange)\n', '  File "C:\\Users\\ZHao\\.conda\\envs\\scopefoundry\\lib\\site-packages\\pyqtgraph\\imageview\\ImageView.py", line 725, in updateImage\n    image = image.transpose(axorder)\n', "ValueError: axes don't match array\n"]
2022-10-19T16:51:54|ERROR|ThorCamCaptureMeasure|thor_cam_capture Failed to update figure1: axes don't match array. ['Traceback (most recent call last):\n', '  File "C:\\Users\\ZHao\\.conda\\envs\\scopefoundry\\lib\\site-packages\\ScopeFoundry\\measurement.py", line 273, in _on_display_update_timer\n    self.update_display()\n', '  File "C:\\Users\\Public\\quantum_sensing\\quantum_sensing\\fancy_microscope\\thorcam_capture.py", line 362, in update_display\n    self.imview.setImage(image, axes={\'y\':0, \'x\':1}, autoLevels=True)\n', '  File "C:\\Users\\ZHao\\.conda\\envs\\scopefoundry\\lib\\site-packages\\pyqtgraph\\imageview\\ImageView.py", line 322, in setImage\n    self.updateImage(autoHistogramRange=autoHistogramRange)\n', '  File "C:\\Users\\ZHao\\.conda\\envs\\scopefoundry\\lib\\site-packages\\pyqtgraph\\imageview\\ImageView.py", line 725, in updateImage\n    image = image.transpose(axorder)\n', "ValueError: axes don't match array\n"]
2022-10-19T16:51:55|ERROR|ThorCamCaptureMeasure|thor_cam_capture Failed to update figure1: axes don't match array. ['Traceback (most recent call last):\n', '  File "C:\\Users\\ZHao\\.conda\\envs\\scopefoundry\\lib\\site-packages\\ScopeFoundry\\measurement.py", line 273, in _on_display_update_timer\n    self.update_display()\n', '  File "C:\\Users\\Public\\quantum_sensing\\quantum_sensing\\fancy_microscope\\thorcam_capture.py", line 362, in update_display\n    self.imview.setImage(image, axes={\'y\':0, \'x\':1}, autoLevels=True)\n', '  File "C:\\Users\\ZHao\\.conda\\envs\\scopefoundry\\lib\\site-packages\\pyqtgraph\\imageview\\ImageView.py", line 322, in setImage\n    self.updateImage(autoHistogramRange=autoHistogramRange)\n', '  File "C:\\Users\\ZHao\\.conda\\envs\\scopefoundry\\lib\\site-packages\\pyqtgraph\\imageview\\ImageView.py", line 725, in updateImage\n    image = image.transpose(axorder)\n', "ValueError: axes don't match array\n"]
2022-10-19T16:51:55|ERROR|ThorCamCaptureMeasure|thor_cam_capture Failed to update figure1: axes don't match array. ['Traceback (most recent call last):\n', '  File "C:\\Users\\ZHao\\.conda\\envs\\scopefoundry\\lib\\site-packages\\ScopeFoundry\\measurement.py", line 273, in _on_display_update_timer\n    self.update_display()\n', '  File "C:\\Users\\Public\\quantum_sensing\\quantum_sensing\\fancy_microscope\\thorcam_capture.py", line 362, in update_display\n    self.imview.setImage(image, axes={\'y\':0, \'x\':1}, autoLevels=True)\n', '  File "C:\\Users\\ZHao\\.conda\\envs\\scopefoundry\\lib\\site-packages\\pyqtgraph\\imageview\\ImageView.py", line 322, in setImage\n    self.updateImage(autoHistogramRange=autoHistogramRange)\n', '  File "C:\\Users\\ZHao\\.conda\\envs\\scopefoundry\\lib\\site-packages\\pyqtgraph\\imageview\\ImageView.py", line 725, in updateImage\n    image = image.transpose(axorder)\n', "ValueError: axes don't match array\n"]
2022-10-19T16:51:55|ERROR|ThorCamCaptureMeasure|thor_cam_capture Failed to update figure1: axes don't match array. ['Traceback (most recent call last):\n', '  File "C:\\Users\\ZHao\\.conda\\envs\\scopefoundry\\lib\\site-packages\\ScopeFoundry\\measurement.py", line 273, in _on_display_update_timer\n    self.update_display()\n', '  File "C:\\Users\\Public\\quantum_sensing\\quantum_sensing\\fancy_microscope\\thorcam_capture.py", line 362, in update_display\n    self.imview.setImage(image, axes={\'y\':0, \'x\':1}, autoLevels=True)\n', '  File "C:\\Users\\ZHao\\.conda\\envs\\scopefoundry\\lib\\site-packages\\pyqtgraph\\imageview\\ImageView.py", line 322, in setImage\n    self.updateImage(autoHistogramRange=autoHistogramRange)\n', '  File "C:\\Users\\ZHao\\.conda\\envs\\scopefoundry\\lib\\site-packages\\pyqtgraph\\imageview\\ImageView.py", line 725, in updateImage\n    image = image.transpose(axorder)\n', "ValueError: axes don't match array\n"]
2022-10-19T16:51:55|ERROR|ThorCamCaptureMeasure|thor_cam_capture Failed to update figure1: axes don't match array. ['Traceback (most recent call last):\n', '  File "C:\\Users\\ZHao\\.conda\\envs\\scopefoundry\\lib\\site-packages\\ScopeFoundry\\measurement.py", line 273, in _on_display_update_timer\n    self.update_display()\n', '  File "C:\\Users\\Public\\quantum_sensing\\quantum_sensing\\fancy_microscope\\thorcam_capture.py", line 362, in update_display\n    self.imview.setImage(image, axes={\'y\':0, \'x\':1}, autoLevels=True)\n', '  File "C:\\Users\\ZHao\\.conda\\envs\\scopefoundry\\lib\\site-packages\\pyqtgraph\\imageview\\ImageView.py", line 322, in setImage\n    self.updateImage(autoHistogramRange=autoHistogramRange)\n', '  File "C:\\Users\\ZHao\\.conda\\envs\\scopefoundry\\lib\\site-packages\\pyqtgraph\\imageview\\ImageView.py", line 725, in updateImage\n    image = image.transpose(axorder)\n', "ValueError: axes don't match array\n"]
2022-10-19T16:51:55|ERROR|ThorCamCaptureMeasure|thor_cam_capture Failed to update figure1: axes don't match array. ['Traceback (most recent call last):\n', '  File "C:\\Users\\ZHao\\.conda\\envs\\scopefoundry\\lib\\site-packages\\ScopeFoundry\\measurement.py", line 273, in _on_display_update_timer\n    self.update_display()\n', '  File "C:\\Users\\Public\\quantum_sensing\\quantum_sensing\\fancy_microscope\\thorcam_capture.py", line 362, in update_display\n    self.imview.setImage(image, axes={\'y\':0, \'x\':1}, autoLevels=True)\n', '  File "C:\\Users\\ZHao\\.conda\\envs\\scopefoundry\\lib\\site-packages\\pyqtgraph\\imageview\\ImageView.py", line 322, in setImage\n    self.updateImage(autoHistogramRange=autoHistogramRange)\n', '  File "C:\\Users\\ZHao\\.conda\\envs\\scopefoundry\\lib\\site-packages\\pyqtgraph\\imageview\\ImageView.py", line 725, in updateImage\n    image = image.transpose(axorder)\n', "ValueError: axes don't match array\n"]
2022-10-19T16:51:55|ERROR|ThorCamCaptureMeasure|thor_cam_capture Failed to update figure1: axes don't match array. ['Traceback (most recent call last):\n', '  File "C:\\Users\\ZHao\\.conda\\envs\\scopefoundry\\lib\\site-packages\\ScopeFoundry\\measurement.py", line 273, in _on_display_update_timer\n    self.update_display()\n', '  File "C:\\Users\\Public\\quantum_sensing\\quantum_sensing\\fancy_microscope\\thorcam_capture.py", line 362, in update_display\n    self.imview.setImage(image, axes={\'y\':0, \'x\':1}, autoLevels=True)\n', '  File "C:\\Users\\ZHao\\.conda\\envs\\scopefoundry\\lib\\site-packages\\pyqtgraph\\imageview\\ImageView.py", line 322, in setImage\n    self.updateImage(autoHistogramRange=autoHistogramRange)\n', '  File "C:\\Users\\ZHao\\.conda\\envs\\scopefoundry\\lib\\site-packages\\pyqtgraph\\imageview\\ImageView.py", line 725, in updateImage\n    image = image.transpose(axorder)\n', "ValueError: axes don't match array\n"]
2022-10-19T16:51:55|ERROR|ThorCamCaptureMeasure|thor_cam_capture Failed to update figure1: axes don't match array. ['Traceback (most recent call last):\n', '  File "C:\\Users\\ZHao\\.conda\\envs\\scopefoundry\\lib\\site-packages\\ScopeFoundry\\measurement.py", line 273, in _on_display_update_timer\n    self.update_display()\n', '  File "C:\\Users\\Public\\quantum_sensing\\quantum_sensing\\fancy_microscope\\thorcam_capture.py", line 362, in update_display\n    self.imview.setImage(image, axes={\'y\':0, \'x\':1}, autoLevels=True)\n', '  File "C:\\Users\\ZHao\\.conda\\envs\\scopefoundry\\lib\\site-packages\\pyqtgraph\\imageview\\ImageView.py", line 322, in setImage\n    self.updateImage(autoHistogramRange=autoHistogramRange)\n', '  File "C:\\Users\\ZHao\\.conda\\envs\\scopefoundry\\lib\\site-packages\\pyqtgraph\\imageview\\ImageView.py", line 725, in updateImage\n    image = image.transpose(axorder)\n', "ValueError: axes don't match array\n"]
2022-10-19T16:51:55|ERROR|ThorCamCaptureMeasure|thor_cam_capture Failed to update figure1: axes don't match array. ['Traceback (most recent call last):\n', '  File "C:\\Users\\ZHao\\.conda\\envs\\scopefoundry\\lib\\site-packages\\ScopeFoundry\\measurement.py", line 273, in _on_display_update_timer\n    self.update_display()\n', '  File "C:\\Users\\Public\\quantum_sensing\\quantum_sensing\\fancy_microscope\\thorcam_capture.py", line 362, in update_display\n    self.imview.setImage(image, axes={\'y\':0, \'x\':1}, autoLevels=True)\n', '  File "C:\\Users\\ZHao\\.conda\\envs\\scopefoundry\\lib\\site-packages\\pyqtgraph\\imageview\\ImageView.py", line 322, in setImage\n    self.updateImage(autoHistogramRange=autoHistogramRange)\n', '  File "C:\\Users\\ZHao\\.conda\\envs\\scopefoundry\\lib\\site-packages\\pyqtgraph\\imageview\\ImageView.py", line 725, in updateImage\n    image = image.transpose(axorder)\n', "ValueError: axes don't match array\n"]
2022-10-19T16:51:55|ERROR|ThorCamCaptureMeasure|thor_cam_capture Failed to update figure1: axes don't match array. ['Traceback (most recent call last):\n', '  File "C:\\Users\\ZHao\\.conda\\envs\\scopefoundry\\lib\\site-packages\\ScopeFoundry\\measurement.py", line 273, in _on_display_update_timer\n    self.update_display()\n', '  File "C:\\Users\\Public\\quantum_sensing\\quantum_sensing\\fancy_microscope\\thorcam_capture.py", line 362, in update_display\n    self.imview.setImage(image, axes={\'y\':0, \'x\':1}, autoLevels=True)\n', '  File "C:\\Users\\ZHao\\.conda\\envs\\scopefoundry\\lib\\site-packages\\pyqtgraph\\imageview\\ImageView.py", line 322, in setImage\n    self.updateImage(autoHistogramRange=autoHistogramRange)\n', '  File "C:\\Users\\ZHao\\.conda\\envs\\scopefoundry\\lib\\site-packages\\pyqtgraph\\imageview\\ImageView.py", line 725, in updateImage\n    image = image.transpose(axorder)\n', "ValueError: axes don't match array\n"]
2022-10-19T16:51:56|ERROR|ThorCamCaptureMeasure|thor_cam_capture Failed to update figure1: axes don't match array. ['Traceback (most recent call last):\n', '  File "C:\\Users\\ZHao\\.conda\\envs\\scopefoundry\\lib\\site-packages\\ScopeFoundry\\measurement.py", line 273, in _on_display_update_timer\n    self.update_display()\n', '  File "C:\\Users\\Public\\quantum_sensing\\quantum_sensing\\fancy_microscope\\thorcam_capture.py", line 362, in update_display\n    self.imview.setImage(image, axes={\'y\':0, \'x\':1}, autoLevels=True)\n', '  File "C:\\Users\\ZHao\\.conda\\envs\\scopefoundry\\lib\\site-packages\\pyqtgraph\\imageview\\ImageView.py", line 322, in setImage\n    self.updateImage(autoHistogramRange=autoHistogramRange)\n', '  File "C:\\Users\\ZHao\\.conda\\envs\\scopefoundry\\lib\\site-packages\\pyqtgraph\\imageview\\ImageView.py", line 725, in updateImage\n    image = image.transpose(axorder)\n', "ValueError: axes don't match array\n"]
2022-10-19T16:51:56|CRITICAL|root|Unhandled exception:Traceback (most recent call last):
  File "C:\Users\ZHao\.conda\envs\scopefoundry\lib\site-packages\ScopeFoundry\helper_funcs.py", line 93, in eventFilter
    def eventFilter(self, obj, event):
KeyboardInterrupt

2022-10-19T16:51:56|ERROR|ThorCamCaptureMeasure|thor_cam_capture Failed to update figure1: axes don't match array. ['Traceback (most recent call last):\n', '  File "C:\\Users\\ZHao\\.conda\\envs\\scopefoundry\\lib\\site-packages\\ScopeFoundry\\measurement.py", line 273, in _on_display_update_timer\n    self.update_display()\n', '  File "C:\\Users\\Public\\quantum_sensing\\quantum_sensing\\fancy_microscope\\thorcam_capture.py", line 362, in update_display\n    self.imview.setImage(image, axes={\'y\':0, \'x\':1}, autoLevels=True)\n', '  File "C:\\Users\\ZHao\\.conda\\envs\\scopefoundry\\lib\\site-packages\\pyqtgraph\\imageview\\ImageView.py", line 322, in setImage\n    self.updateImage(autoHistogramRange=autoHistogramRange)\n', '  File "C:\\Users\\ZHao\\.conda\\envs\\scopefoundry\\lib\\site-packages\\pyqtgraph\\imageview\\ImageView.py", line 725, in updateImage\n    image = image.transpose(axorder)\n', "ValueError: axes don't match array\n"]
2022-10-19T16:51:56|ERROR|ThorCamCaptureMeasure|thor_cam_capture Failed to update figure1: axes don't match array. ['Traceback (most recent call last):\n', '  File "C:\\Users\\ZHao\\.conda\\envs\\scopefoundry\\lib\\site-packages\\ScopeFoundry\\measurement.py", line 273, in _on_display_update_timer\n    self.update_display()\n', '  File "C:\\Users\\Public\\quantum_sensing\\quantum_sensing\\fancy_microscope\\thorcam_capture.py", line 362, in update_display\n    self.imview.setImage(image, axes={\'y\':0, \'x\':1}, autoLevels=True)\n', '  File "C:\\Users\\ZHao\\.conda\\envs\\scopefoundry\\lib\\site-packages\\pyqtgraph\\imageview\\ImageView.py", line 322, in setImage\n    self.updateImage(autoHistogramRange=autoHistogramRange)\n', '  File "C:\\Users\\ZHao\\.conda\\envs\\scopefoundry\\lib\\site-packages\\pyqtgraph\\imageview\\ImageView.py", line 725, in updateImage\n    image = image.transpose(axorder)\n', "ValueError: axes don't match array\n"]
2022-10-19T16:51:56|ERROR|ThorCamCaptureMeasure|thor_cam_capture Failed to update figure1: axes don't match array. ['Traceback (most recent call last):\n', '  File "C:\\Users\\ZHao\\.conda\\envs\\scopefoundry\\lib\\site-packages\\ScopeFoundry\\measurement.py", line 273, in _on_display_update_timer\n    self.update_display()\n', '  File "C:\\Users\\Public\\quantum_sensing\\quantum_sensing\\fancy_microscope\\thorcam_capture.py", line 362, in update_display\n    self.imview.setImage(image, axes={\'y\':0, \'x\':1}, autoLevels=True)\n', '  File "C:\\Users\\ZHao\\.conda\\envs\\scopefoundry\\lib\\site-packages\\pyqtgraph\\imageview\\ImageView.py", line 322, in setImage\n    self.updateImage(autoHistogramRange=autoHistogramRange)\n', '  File "C:\\Users\\ZHao\\.conda\\envs\\scopefoundry\\lib\\site-packages\\pyqtgraph\\imageview\\ImageView.py", line 725, in updateImage\n    image = image.transpose(axorder)\n', "ValueError: axes don't match array\n"]
2022-10-19T16:51:56|ERROR|ThorCamCaptureMeasure|thor_cam_capture Failed to update figure1: axes don't match array. ['Traceback (most recent call last):\n', '  File "C:\\Users\\ZHao\\.conda\\envs\\scopefoundry\\lib\\site-packages\\ScopeFoundry\\measurement.py", line 273, in _on_display_update_timer\n    self.update_display()\n', '  File "C:\\Users\\Public\\quantum_sensing\\quantum_sensing\\fancy_microscope\\thorcam_capture.py", line 362, in update_display\n    self.imview.setImage(image, axes={\'y\':0, \'x\':1}, autoLevels=True)\n', '  File "C:\\Users\\ZHao\\.conda\\envs\\scopefoundry\\lib\\site-packages\\pyqtgraph\\imageview\\ImageView.py", line 322, in setImage\n    self.updateImage(autoHistogramRange=autoHistogramRange)\n', '  File "C:\\Users\\ZHao\\.conda\\envs\\scopefoundry\\lib\\site-packages\\pyqtgraph\\imageview\\ImageView.py", line 725, in updateImage\n    image = image.transpose(axorder)\n', "ValueError: axes don't match array\n"]
2022-10-19T16:51:56|ERROR|ThorCamCaptureMeasure|thor_cam_capture Failed to update figure1: axes don't match array. ['Traceback (most recent call last):\n', '  File "C:\\Users\\ZHao\\.conda\\envs\\scopefoundry\\lib\\site-packages\\ScopeFoundry\\measurement.py", line 273, in _on_display_update_timer\n    self.update_display()\n', '  File "C:\\Users\\Public\\quantum_sensing\\quantum_sensing\\fancy_microscope\\thorcam_capture.py", line 362, in update_display\n    self.imview.setImage(image, axes={\'y\':0, \'x\':1}, autoLevels=True)\n', '  File "C:\\Users\\ZHao\\.conda\\envs\\scopefoundry\\lib\\site-packages\\pyqtgraph\\imageview\\ImageView.py", line 322, in setImage\n    self.updateImage(autoHistogramRange=autoHistogramRange)\n', '  File "C:\\Users\\ZHao\\.conda\\envs\\scopefoundry\\lib\\site-packages\\pyqtgraph\\imageview\\ImageView.py", line 725, in updateImage\n    image = image.transpose(axorder)\n', "ValueError: axes don't match array\n"]
2022-10-19T16:51:56|ERROR|ThorCamCaptureMeasure|thor_cam_capture Failed to update figure1: axes don't match array. ['Traceback (most recent call last):\n', '  File "C:\\Users\\ZHao\\.conda\\envs\\scopefoundry\\lib\\site-packages\\ScopeFoundry\\measurement.py", line 273, in _on_display_update_timer\n    self.update_display()\n', '  File "C:\\Users\\Public\\quantum_sensing\\quantum_sensing\\fancy_microscope\\thorcam_capture.py", line 362, in update_display\n    self.imview.setImage(image, axes={\'y\':0, \'x\':1}, autoLevels=True)\n', '  File "C:\\Users\\ZHao\\.conda\\envs\\scopefoundry\\lib\\site-packages\\pyqtgraph\\imageview\\ImageView.py", line 322, in setImage\n    self.updateImage(autoHistogramRange=autoHistogramRange)\n', '  File "C:\\Users\\ZHao\\.conda\\envs\\scopefoundry\\lib\\site-packages\\pyqtgraph\\imageview\\ImageView.py", line 725, in updateImage\n    image = image.transpose(axorder)\n', "ValueError: axes don't match array\n"]
2022-10-19T16:51:56|CRITICAL|root|Unhandled exception:Traceback (most recent call last):
  File "C:\Users\ZHao\.conda\envs\scopefoundry\lib\site-packages\ScopeFoundry\helper_funcs.py", line 93, in eventFilter
    def eventFilter(self, obj, event):
KeyboardInterrupt

2022-10-19T16:51:56|ERROR|ThorCamCaptureMeasure|thor_cam_capture Failed to update figure1: axes don't match array. ['Traceback (most recent call last):\n', '  File "C:\\Users\\ZHao\\.conda\\envs\\scopefoundry\\lib\\site-packages\\ScopeFoundry\\measurement.py", line 273, in _on_display_update_timer\n    self.update_display()\n', '  File "C:\\Users\\Public\\quantum_sensing\\quantum_sensing\\fancy_microscope\\thorcam_capture.py", line 362, in update_display\n    self.imview.setImage(image, axes={\'y\':0, \'x\':1}, autoLevels=True)\n', '  File "C:\\Users\\ZHao\\.conda\\envs\\scopefoundry\\lib\\site-packages\\pyqtgraph\\imageview\\ImageView.py", line 322, in setImage\n    self.updateImage(autoHistogramRange=autoHistogramRange)\n', '  File "C:\\Users\\ZHao\\.conda\\envs\\scopefoundry\\lib\\site-packages\\pyqtgraph\\imageview\\ImageView.py", line 725, in updateImage\n    image = image.transpose(axorder)\n', "ValueError: axes don't match array\n"]
2022-10-19T16:51:56|ERROR|ThorCamCaptureMeasure|thor_cam_capture Failed to update figure1: axes don't match array. ['Traceback (most recent call last):\n', '  File "C:\\Users\\ZHao\\.conda\\envs\\scopefoundry\\lib\\site-packages\\ScopeFoundry\\measurement.py", line 273, in _on_display_update_timer\n    self.update_display()\n', '  File "C:\\Users\\Public\\quantum_sensing\\quantum_sensing\\fancy_microscope\\thorcam_capture.py", line 362, in update_display\n    self.imview.setImage(image, axes={\'y\':0, \'x\':1}, autoLevels=True)\n', '  File "C:\\Users\\ZHao\\.conda\\envs\\scopefoundry\\lib\\site-packages\\pyqtgraph\\imageview\\ImageView.py", line 322, in setImage\n    self.updateImage(autoHistogramRange=autoHistogramRange)\n', '  File "C:\\Users\\ZHao\\.conda\\envs\\scopefoundry\\lib\\site-packages\\pyqtgraph\\imageview\\ImageView.py", line 725, in updateImage\n    image = image.transpose(axorder)\n', "ValueError: axes don't match array\n"]
2022-10-19T16:51:57|CRITICAL|root|Unhandled exception:Traceback (most recent call last):
  File "C:\Users\ZHao\.conda\envs\scopefoundry\lib\site-packages\ScopeFoundry\helper_funcs.py", line 93, in eventFilter
    def eventFilter(self, obj, event):
KeyboardInterrupt

2022-10-19T16:51:57|ERROR|ThorCamCaptureMeasure|thor_cam_capture Failed to update figure1: axes don't match array. ['Traceback (most recent call last):\n', '  File "C:\\Users\\ZHao\\.conda\\envs\\scopefoundry\\lib\\site-packages\\ScopeFoundry\\measurement.py", line 273, in _on_display_update_timer\n    self.update_display()\n', '  File "C:\\Users\\Public\\quantum_sensing\\quantum_sensing\\fancy_microscope\\thorcam_capture.py", line 362, in update_display\n    self.imview.setImage(image, axes={\'y\':0, \'x\':1}, autoLevels=True)\n', '  File "C:\\Users\\ZHao\\.conda\\envs\\scopefoundry\\lib\\site-packages\\pyqtgraph\\imageview\\ImageView.py", line 322, in setImage\n    self.updateImage(autoHistogramRange=autoHistogramRange)\n', '  File "C:\\Users\\ZHao\\.conda\\envs\\scopefoundry\\lib\\site-packages\\pyqtgraph\\imageview\\ImageView.py", line 725, in updateImage\n    image = image.transpose(axorder)\n', "ValueError: axes don't match array\n"]
2022-10-19T16:51:57|ERROR|ThorCamCaptureMeasure|thor_cam_capture Failed to update figure1: axes don't match array. ['Traceback (most recent call last):\n', '  File "C:\\Users\\ZHao\\.conda\\envs\\scopefoundry\\lib\\site-packages\\ScopeFoundry\\measurement.py", line 273, in _on_display_update_timer\n    self.update_display()\n', '  File "C:\\Users\\Public\\quantum_sensing\\quantum_sensing\\fancy_microscope\\thorcam_capture.py", line 362, in update_display\n    self.imview.setImage(image, axes={\'y\':0, \'x\':1}, autoLevels=True)\n', '  File "C:\\Users\\ZHao\\.conda\\envs\\scopefoundry\\lib\\site-packages\\pyqtgraph\\imageview\\ImageView.py", line 322, in setImage\n    self.updateImage(autoHistogramRange=autoHistogramRange)\n', '  File "C:\\Users\\ZHao\\.conda\\envs\\scopefoundry\\lib\\site-packages\\pyqtgraph\\imageview\\ImageView.py", line 725, in updateImage\n    image = image.transpose(axorder)\n', "ValueError: axes don't match array\n"]
2022-10-19T16:51:57|CRITICAL|root|Unhandled exception:Traceback (most recent call last):
  File "C:\Users\ZHao\.conda\envs\scopefoundry\lib\site-packages\ScopeFoundry\helper_funcs.py", line 93, in eventFilter
    def eventFilter(self, obj, event):
KeyboardInterrupt

2022-10-19T16:51:57|ERROR|ThorCamCaptureMeasure|thor_cam_capture Failed to update figure1: axes don't match array. ['Traceback (most recent call last):\n', '  File "C:\\Users\\ZHao\\.conda\\envs\\scopefoundry\\lib\\site-packages\\ScopeFoundry\\measurement.py", line 273, in _on_display_update_timer\n    self.update_display()\n', '  File "C:\\Users\\Public\\quantum_sensing\\quantum_sensing\\fancy_microscope\\thorcam_capture.py", line 362, in update_display\n    self.imview.setImage(image, axes={\'y\':0, \'x\':1}, autoLevels=True)\n', '  File "C:\\Users\\ZHao\\.conda\\envs\\scopefoundry\\lib\\site-packages\\pyqtgraph\\imageview\\ImageView.py", line 322, in setImage\n    self.updateImage(autoHistogramRange=autoHistogramRange)\n', '  File "C:\\Users\\ZHao\\.conda\\envs\\scopefoundry\\lib\\site-packages\\pyqtgraph\\imageview\\ImageView.py", line 725, in updateImage\n    image = image.transpose(axorder)\n', "ValueError: axes don't match array\n"]
2022-10-19T16:51:57|ERROR|ThorCamCaptureMeasure|thor_cam_capture Failed to update figure1: axes don't match array. ['Traceback (most recent call last):\n', '  File "C:\\Users\\ZHao\\.conda\\envs\\scopefoundry\\lib\\site-packages\\ScopeFoundry\\measurement.py", line 273, in _on_display_update_timer\n    self.update_display()\n', '  File "C:\\Users\\Public\\quantum_sensing\\quantum_sensing\\fancy_microscope\\thorcam_capture.py", line 362, in update_display\n    self.imview.setImage(image, axes={\'y\':0, \'x\':1}, autoLevels=True)\n', '  File "C:\\Users\\ZHao\\.conda\\envs\\scopefoundry\\lib\\site-packages\\pyqtgraph\\imageview\\ImageView.py", line 322, in setImage\n    self.updateImage(autoHistogramRange=autoHistogramRange)\n', '  File "C:\\Users\\ZHao\\.conda\\envs\\scopefoundry\\lib\\site-packages\\pyqtgraph\\imageview\\ImageView.py", line 725, in updateImage\n    image = image.transpose(axorder)\n', "ValueError: axes don't match array\n"]
2022-10-19T16:51:57|ERROR|ThorCamCaptureMeasure|thor_cam_capture Failed to update figure1: axes don't match array. ['Traceback (most recent call last):\n', '  File "C:\\Users\\ZHao\\.conda\\envs\\scopefoundry\\lib\\site-packages\\ScopeFoundry\\measurement.py", line 273, in _on_display_update_timer\n    self.update_display()\n', '  File "C:\\Users\\Public\\quantum_sensing\\quantum_sensing\\fancy_microscope\\thorcam_capture.py", line 362, in update_display\n    self.imview.setImage(image, axes={\'y\':0, \'x\':1}, autoLevels=True)\n', '  File "C:\\Users\\ZHao\\.conda\\envs\\scopefoundry\\lib\\site-packages\\pyqtgraph\\imageview\\ImageView.py", line 322, in setImage\n    self.updateImage(autoHistogramRange=autoHistogramRange)\n', '  File "C:\\Users\\ZHao\\.conda\\envs\\scopefoundry\\lib\\site-packages\\pyqtgraph\\imageview\\ImageView.py", line 725, in updateImage\n    image = image.transpose(axorder)\n', "ValueError: axes don't match array\n"]
2022-10-19T16:51:57|ERROR|ThorCamCaptureMeasure|thor_cam_capture Failed to update figure1: axes don't match array. ['Traceback (most recent call last):\n', '  File "C:\\Users\\ZHao\\.conda\\envs\\scopefoundry\\lib\\site-packages\\ScopeFoundry\\measurement.py", line 273, in _on_display_update_timer\n    self.update_display()\n', '  File "C:\\Users\\Public\\quantum_sensing\\quantum_sensing\\fancy_microscope\\thorcam_capture.py", line 362, in update_display\n    self.imview.setImage(image, axes={\'y\':0, \'x\':1}, autoLevels=True)\n', '  File "C:\\Users\\ZHao\\.conda\\envs\\scopefoundry\\lib\\site-packages\\pyqtgraph\\imageview\\ImageView.py", line 322, in setImage\n    self.updateImage(autoHistogramRange=autoHistogramRange)\n', '  File "C:\\Users\\ZHao\\.conda\\envs\\scopefoundry\\lib\\site-packages\\pyqtgraph\\imageview\\ImageView.py", line 725, in updateImage\n    image = image.transpose(axorder)\n', "ValueError: axes don't match array\n"]
2022-10-19T16:51:57|ERROR|ThorCamCaptureMeasure|thor_cam_capture Failed to update figure1: axes don't match array. ['Traceback (most recent call last):\n', '  File "C:\\Users\\ZHao\\.conda\\envs\\scopefoundry\\lib\\site-packages\\ScopeFoundry\\measurement.py", line 273, in _on_display_update_timer\n    self.update_display()\n', '  File "C:\\Users\\Public\\quantum_sensing\\quantum_sensing\\fancy_microscope\\thorcam_capture.py", line 362, in update_display\n    self.imview.setImage(image, axes={\'y\':0, \'x\':1}, autoLevels=True)\n', '  File "C:\\Users\\ZHao\\.conda\\envs\\scopefoundry\\lib\\site-packages\\pyqtgraph\\imageview\\ImageView.py", line 322, in setImage\n    self.updateImage(autoHistogramRange=autoHistogramRange)\n', '  File "C:\\Users\\ZHao\\.conda\\envs\\scopefoundry\\lib\\site-packages\\pyqtgraph\\imageview\\ImageView.py", line 725, in updateImage\n    image = image.transpose(axorder)\n', "ValueError: axes don't match array\n"]
2022-10-19T16:51:57|ERROR|ThorCamCaptureMeasure|thor_cam_capture Failed to update figure1: axes don't match array. ['Traceback (most recent call last):\n', '  File "C:\\Users\\ZHao\\.conda\\envs\\scopefoundry\\lib\\site-packages\\ScopeFoundry\\measurement.py", line 273, in _on_display_update_timer\n    self.update_display()\n', '  File "C:\\Users\\Public\\quantum_sensing\\quantum_sensing\\fancy_microscope\\thorcam_capture.py", line 362, in update_display\n    self.imview.setImage(image, axes={\'y\':0, \'x\':1}, autoLevels=True)\n', '  File "C:\\Users\\ZHao\\.conda\\envs\\scopefoundry\\lib\\site-packages\\pyqtgraph\\imageview\\ImageView.py", line 322, in setImage\n    self.updateImage(autoHistogramRange=autoHistogramRange)\n', '  File "C:\\Users\\ZHao\\.conda\\envs\\scopefoundry\\lib\\site-packages\\pyqtgraph\\imageview\\ImageView.py", line 725, in updateImage\n    image = image.transpose(axorder)\n', "ValueError: axes don't match array\n"]
2022-10-19T16:51:57|ERROR|ThorCamCaptureMeasure|thor_cam_capture Failed to update figure1: axes don't match array. ['Traceback (most recent call last):\n', '  File "C:\\Users\\ZHao\\.conda\\envs\\scopefoundry\\lib\\site-packages\\ScopeFoundry\\measurement.py", line 273, in _on_display_update_timer\n    self.update_display()\n', '  File "C:\\Users\\Public\\quantum_sensing\\quantum_sensing\\fancy_microscope\\thorcam_capture.py", line 362, in update_display\n    self.imview.setImage(image, axes={\'y\':0, \'x\':1}, autoLevels=True)\n', '  File "C:\\Users\\ZHao\\.conda\\envs\\scopefoundry\\lib\\site-packages\\pyqtgraph\\imageview\\ImageView.py", line 322, in setImage\n    self.updateImage(autoHistogramRange=autoHistogramRange)\n', '  File "C:\\Users\\ZHao\\.conda\\envs\\scopefoundry\\lib\\site-packages\\pyqtgraph\\imageview\\ImageView.py", line 725, in updateImage\n    image = image.transpose(axorder)\n', "ValueError: axes don't match array\n"]
2022-10-19T16:51:58|ERROR|ThorCamCaptureMeasure|thor_cam_capture Failed to update figure1: axes don't match array. ['Traceback (most recent call last):\n', '  File "C:\\Users\\ZHao\\.conda\\envs\\scopefoundry\\lib\\site-packages\\ScopeFoundry\\measurement.py", line 273, in _on_display_update_timer\n    self.update_display()\n', '  File "C:\\Users\\Public\\quantum_sensing\\quantum_sensing\\fancy_microscope\\thorcam_capture.py", line 362, in update_display\n    self.imview.setImage(image, axes={\'y\':0, \'x\':1}, autoLevels=True)\n', '  File "C:\\Users\\ZHao\\.conda\\envs\\scopefoundry\\lib\\site-packages\\pyqtgraph\\imageview\\ImageView.py", line 322, in setImage\n    self.updateImage(autoHistogramRange=autoHistogramRange)\n', '  File "C:\\Users\\ZHao\\.conda\\envs\\scopefoundry\\lib\\site-packages\\pyqtgraph\\imageview\\ImageView.py", line 725, in updateImage\n    image = image.transpose(axorder)\n', "ValueError: axes don't match array\n"]
2022-10-19T16:51:58|ERROR|ThorCamCaptureMeasure|thor_cam_capture Failed to update figure1: axes don't match array. ['Traceback (most recent call last):\n', '  File "C:\\Users\\ZHao\\.conda\\envs\\scopefoundry\\lib\\site-packages\\ScopeFoundry\\measurement.py", line 273, in _on_display_update_timer\n    self.update_display()\n', '  File "C:\\Users\\Public\\quantum_sensing\\quantum_sensing\\fancy_microscope\\thorcam_capture.py", line 362, in update_display\n    self.imview.setImage(image, axes={\'y\':0, \'x\':1}, autoLevels=True)\n', '  File "C:\\Users\\ZHao\\.conda\\envs\\scopefoundry\\lib\\site-packages\\pyqtgraph\\imageview\\ImageView.py", line 322, in setImage\n    self.updateImage(autoHistogramRange=autoHistogramRange)\n', '  File "C:\\Users\\ZHao\\.conda\\envs\\scopefoundry\\lib\\site-packages\\pyqtgraph\\imageview\\ImageView.py", line 725, in updateImage\n    image = image.transpose(axorder)\n', "ValueError: axes don't match array\n"]
2022-10-19T16:51:58|ERROR|ThorCamCaptureMeasure|thor_cam_capture Failed to update figure1: axes don't match array. ['Traceback (most recent call last):\n', '  File "C:\\Users\\ZHao\\.conda\\envs\\scopefoundry\\lib\\site-packages\\ScopeFoundry\\measurement.py", line 273, in _on_display_update_timer\n    self.update_display()\n', '  File "C:\\Users\\Public\\quantum_sensing\\quantum_sensing\\fancy_microscope\\thorcam_capture.py", line 362, in update_display\n    self.imview.setImage(image, axes={\'y\':0, \'x\':1}, autoLevels=True)\n', '  File "C:\\Users\\ZHao\\.conda\\envs\\scopefoundry\\lib\\site-packages\\pyqtgraph\\imageview\\ImageView.py", line 322, in setImage\n    self.updateImage(autoHistogramRange=autoHistogramRange)\n', '  File "C:\\Users\\ZHao\\.conda\\envs\\scopefoundry\\lib\\site-packages\\pyqtgraph\\imageview\\ImageView.py", line 725, in updateImage\n    image = image.transpose(axorder)\n', "ValueError: axes don't match array\n"]
2022-10-19T16:51:58|ERROR|ThorCamCaptureMeasure|thor_cam_capture Failed to update figure1: axes don't match array. ['Traceback (most recent call last):\n', '  File "C:\\Users\\ZHao\\.conda\\envs\\scopefoundry\\lib\\site-packages\\ScopeFoundry\\measurement.py", line 273, in _on_display_update_timer\n    self.update_display()\n', '  File "C:\\Users\\Public\\quantum_sensing\\quantum_sensing\\fancy_microscope\\thorcam_capture.py", line 362, in update_display\n    self.imview.setImage(image, axes={\'y\':0, \'x\':1}, autoLevels=True)\n', '  File "C:\\Users\\ZHao\\.conda\\envs\\scopefoundry\\lib\\site-packages\\pyqtgraph\\imageview\\ImageView.py", line 322, in setImage\n    self.updateImage(autoHistogramRange=autoHistogramRange)\n', '  File "C:\\Users\\ZHao\\.conda\\envs\\scopefoundry\\lib\\site-packages\\pyqtgraph\\imageview\\ImageView.py", line 725, in updateImage\n    image = image.transpose(axorder)\n', "ValueError: axes don't match array\n"]
2022-10-19T16:51:58|ERROR|ThorCamCaptureMeasure|thor_cam_capture Failed to update figure1: axes don't match array. ['Traceback (most recent call last):\n', '  File "C:\\Users\\ZHao\\.conda\\envs\\scopefoundry\\lib\\site-packages\\ScopeFoundry\\measurement.py", line 273, in _on_display_update_timer\n    self.update_display()\n', '  File "C:\\Users\\Public\\quantum_sensing\\quantum_sensing\\fancy_microscope\\thorcam_capture.py", line 362, in update_display\n    self.imview.setImage(image, axes={\'y\':0, \'x\':1}, autoLevels=True)\n', '  File "C:\\Users\\ZHao\\.conda\\envs\\scopefoundry\\lib\\site-packages\\pyqtgraph\\imageview\\ImageView.py", line 322, in setImage\n    self.updateImage(autoHistogramRange=autoHistogramRange)\n', '  File "C:\\Users\\ZHao\\.conda\\envs\\scopefoundry\\lib\\site-packages\\pyqtgraph\\imageview\\ImageView.py", line 725, in updateImage\n    image = image.transpose(axorder)\n', "ValueError: axes don't match array\n"]
2022-10-19T16:51:58|ERROR|ThorCamCaptureMeasure|thor_cam_capture Failed to update figure1: axes don't match array. ['Traceback (most recent call last):\n', '  File "C:\\Users\\ZHao\\.conda\\envs\\scopefoundry\\lib\\site-packages\\ScopeFoundry\\measurement.py", line 273, in _on_display_update_timer\n    self.update_display()\n', '  File "C:\\Users\\Public\\quantum_sensing\\quantum_sensing\\fancy_microscope\\thorcam_capture.py", line 362, in update_display\n    self.imview.setImage(image, axes={\'y\':0, \'x\':1}, autoLevels=True)\n', '  File "C:\\Users\\ZHao\\.conda\\envs\\scopefoundry\\lib\\site-packages\\pyqtgraph\\imageview\\ImageView.py", line 322, in setImage\n    self.updateImage(autoHistogramRange=autoHistogramRange)\n', '  File "C:\\Users\\ZHao\\.conda\\envs\\scopefoundry\\lib\\site-packages\\pyqtgraph\\imageview\\ImageView.py", line 725, in updateImage\n    image = image.transpose(axorder)\n', "ValueError: axes don't match array\n"]
2022-10-19T16:51:58|ERROR|ThorCamCaptureMeasure|thor_cam_capture Failed to update figure1: axes don't match array. ['Traceback (most recent call last):\n', '  File "C:\\Users\\ZHao\\.conda\\envs\\scopefoundry\\lib\\site-packages\\ScopeFoundry\\measurement.py", line 273, in _on_display_update_timer\n    self.update_display()\n', '  File "C:\\Users\\Public\\quantum_sensing\\quantum_sensing\\fancy_microscope\\thorcam_capture.py", line 362, in update_display\n    self.imview.setImage(image, axes={\'y\':0, \'x\':1}, autoLevels=True)\n', '  File "C:\\Users\\ZHao\\.conda\\envs\\scopefoundry\\lib\\site-packages\\pyqtgraph\\imageview\\ImageView.py", line 322, in setImage\n    self.updateImage(autoHistogramRange=autoHistogramRange)\n', '  File "C:\\Users\\ZHao\\.conda\\envs\\scopefoundry\\lib\\site-packages\\pyqtgraph\\imageview\\ImageView.py", line 725, in updateImage\n    image = image.transpose(axorder)\n', "ValueError: axes don't match array\n"]
2022-10-19T16:51:58|ERROR|ThorCamCaptureMeasure|thor_cam_capture Failed to update figure1: axes don't match array. ['Traceback (most recent call last):\n', '  File "C:\\Users\\ZHao\\.conda\\envs\\scopefoundry\\lib\\site-packages\\ScopeFoundry\\measurement.py", line 273, in _on_display_update_timer\n    self.update_display()\n', '  File "C:\\Users\\Public\\quantum_sensing\\quantum_sensing\\fancy_microscope\\thorcam_capture.py", line 362, in update_display\n    self.imview.setImage(image, axes={\'y\':0, \'x\':1}, autoLevels=True)\n', '  File "C:\\Users\\ZHao\\.conda\\envs\\scopefoundry\\lib\\site-packages\\pyqtgraph\\imageview\\ImageView.py", line 322, in setImage\n    self.updateImage(autoHistogramRange=autoHistogramRange)\n', '  File "C:\\Users\\ZHao\\.conda\\envs\\scopefoundry\\lib\\site-packages\\pyqtgraph\\imageview\\ImageView.py", line 725, in updateImage\n    image = image.transpose(axorder)\n', "ValueError: axes don't match array\n"]
2022-10-19T16:51:58|ERROR|ThorCamCaptureMeasure|thor_cam_capture Failed to update figure1: axes don't match array. ['Traceback (most recent call last):\n', '  File "C:\\Users\\ZHao\\.conda\\envs\\scopefoundry\\lib\\site-packages\\ScopeFoundry\\measurement.py", line 273, in _on_display_update_timer\n    self.update_display()\n', '  File "C:\\Users\\Public\\quantum_sensing\\quantum_sensing\\fancy_microscope\\thorcam_capture.py", line 362, in update_display\n    self.imview.setImage(image, axes={\'y\':0, \'x\':1}, autoLevels=True)\n', '  File "C:\\Users\\ZHao\\.conda\\envs\\scopefoundry\\lib\\site-packages\\pyqtgraph\\imageview\\ImageView.py", line 322, in setImage\n    self.updateImage(autoHistogramRange=autoHistogramRange)\n', '  File "C:\\Users\\ZHao\\.conda\\envs\\scopefoundry\\lib\\site-packages\\pyqtgraph\\imageview\\ImageView.py", line 725, in updateImage\n    image = image.transpose(axorder)\n', "ValueError: axes don't match array\n"]
2022-10-19T16:51:58|ERROR|ThorCamCaptureMeasure|thor_cam_capture Failed to update figure1: axes don't match array. ['Traceback (most recent call last):\n', '  File "C:\\Users\\ZHao\\.conda\\envs\\scopefoundry\\lib\\site-packages\\ScopeFoundry\\measurement.py", line 273, in _on_display_update_timer\n    self.update_display()\n', '  File "C:\\Users\\Public\\quantum_sensing\\quantum_sensing\\fancy_microscope\\thorcam_capture.py", line 362, in update_display\n    self.imview.setImage(image, axes={\'y\':0, \'x\':1}, autoLevels=True)\n', '  File "C:\\Users\\ZHao\\.conda\\envs\\scopefoundry\\lib\\site-packages\\pyqtgraph\\imageview\\ImageView.py", line 322, in setImage\n    self.updateImage(autoHistogramRange=autoHistogramRange)\n', '  File "C:\\Users\\ZHao\\.conda\\envs\\scopefoundry\\lib\\site-packages\\pyqtgraph\\imageview\\ImageView.py", line 725, in updateImage\n    image = image.transpose(axorder)\n', "ValueError: axes don't match array\n"]
2022-10-19T16:51:59|ERROR|ThorCamCaptureMeasure|thor_cam_capture Failed to update figure1: axes don't match array. ['Traceback (most recent call last):\n', '  File "C:\\Users\\ZHao\\.conda\\envs\\scopefoundry\\lib\\site-packages\\ScopeFoundry\\measurement.py", line 273, in _on_display_update_timer\n    self.update_display()\n', '  File "C:\\Users\\Public\\quantum_sensing\\quantum_sensing\\fancy_microscope\\thorcam_capture.py", line 362, in update_display\n    self.imview.setImage(image, axes={\'y\':0, \'x\':1}, autoLevels=True)\n', '  File "C:\\Users\\ZHao\\.conda\\envs\\scopefoundry\\lib\\site-packages\\pyqtgraph\\imageview\\ImageView.py", line 322, in setImage\n    self.updateImage(autoHistogramRange=autoHistogramRange)\n', '  File "C:\\Users\\ZHao\\.conda\\envs\\scopefoundry\\lib\\site-packages\\pyqtgraph\\imageview\\ImageView.py", line 725, in updateImage\n    image = image.transpose(axorder)\n', "ValueError: axes don't match array\n"]
2022-10-19T16:51:59|ERROR|ThorCamCaptureMeasure|thor_cam_capture Failed to update figure1: axes don't match array. ['Traceback (most recent call last):\n', '  File "C:\\Users\\ZHao\\.conda\\envs\\scopefoundry\\lib\\site-packages\\ScopeFoundry\\measurement.py", line 273, in _on_display_update_timer\n    self.update_display()\n', '  File "C:\\Users\\Public\\quantum_sensing\\quantum_sensing\\fancy_microscope\\thorcam_capture.py", line 362, in update_display\n    self.imview.setImage(image, axes={\'y\':0, \'x\':1}, autoLevels=True)\n', '  File "C:\\Users\\ZHao\\.conda\\envs\\scopefoundry\\lib\\site-packages\\pyqtgraph\\imageview\\ImageView.py", line 322, in setImage\n    self.updateImage(autoHistogramRange=autoHistogramRange)\n', '  File "C:\\Users\\ZHao\\.conda\\envs\\scopefoundry\\lib\\site-packages\\pyqtgraph\\imageview\\ImageView.py", line 725, in updateImage\n    image = image.transpose(axorder)\n', "ValueError: axes don't match array\n"]
2022-10-19T16:51:59|ERROR|ThorCamCaptureMeasure|thor_cam_capture Failed to update figure1: axes don't match array. ['Traceback (most recent call last):\n', '  File "C:\\Users\\ZHao\\.conda\\envs\\scopefoundry\\lib\\site-packages\\ScopeFoundry\\measurement.py", line 273, in _on_display_update_timer\n    self.update_display()\n', '  File "C:\\Users\\Public\\quantum_sensing\\quantum_sensing\\fancy_microscope\\thorcam_capture.py", line 362, in update_display\n    self.imview.setImage(image, axes={\'y\':0, \'x\':1}, autoLevels=True)\n', '  File "C:\\Users\\ZHao\\.conda\\envs\\scopefoundry\\lib\\site-packages\\pyqtgraph\\imageview\\ImageView.py", line 322, in setImage\n    self.updateImage(autoHistogramRange=autoHistogramRange)\n', '  File "C:\\Users\\ZHao\\.conda\\envs\\scopefoundry\\lib\\site-packages\\pyqtgraph\\imageview\\ImageView.py", line 725, in updateImage\n    image = image.transpose(axorder)\n', "ValueError: axes don't match array\n"]
2022-10-19T16:51:59|ERROR|ThorCamCaptureMeasure|thor_cam_capture Failed to update figure1: axes don't match array. ['Traceback (most recent call last):\n', '  File "C:\\Users\\ZHao\\.conda\\envs\\scopefoundry\\lib\\site-packages\\ScopeFoundry\\measurement.py", line 273, in _on_display_update_timer\n    self.update_display()\n', '  File "C:\\Users\\Public\\quantum_sensing\\quantum_sensing\\fancy_microscope\\thorcam_capture.py", line 362, in update_display\n    self.imview.setImage(image, axes={\'y\':0, \'x\':1}, autoLevels=True)\n', '  File "C:\\Users\\ZHao\\.conda\\envs\\scopefoundry\\lib\\site-packages\\pyqtgraph\\imageview\\ImageView.py", line 322, in setImage\n    self.updateImage(autoHistogramRange=autoHistogramRange)\n', '  File "C:\\Users\\ZHao\\.conda\\envs\\scopefoundry\\lib\\site-packages\\pyqtgraph\\imageview\\ImageView.py", line 725, in updateImage\n    image = image.transpose(axorder)\n', "ValueError: axes don't match array\n"]
2022-10-19T16:51:59|ERROR|ThorCamCaptureMeasure|thor_cam_capture Failed to update figure1: axes don't match array. ['Traceback (most recent call last):\n', '  File "C:\\Users\\ZHao\\.conda\\envs\\scopefoundry\\lib\\site-packages\\ScopeFoundry\\measurement.py", line 273, in _on_display_update_timer\n    self.update_display()\n', '  File "C:\\Users\\Public\\quantum_sensing\\quantum_sensing\\fancy_microscope\\thorcam_capture.py", line 362, in update_display\n    self.imview.setImage(image, axes={\'y\':0, \'x\':1}, autoLevels=True)\n', '  File "C:\\Users\\ZHao\\.conda\\envs\\scopefoundry\\lib\\site-packages\\pyqtgraph\\imageview\\ImageView.py", line 322, in setImage\n    self.updateImage(autoHistogramRange=autoHistogramRange)\n', '  File "C:\\Users\\ZHao\\.conda\\envs\\scopefoundry\\lib\\site-packages\\pyqtgraph\\imageview\\ImageView.py", line 725, in updateImage\n    image = image.transpose(axorder)\n', "ValueError: axes don't match array\n"]
2022-10-19T16:51:59|ERROR|ThorCamCaptureMeasure|thor_cam_capture Failed to update figure1: axes don't match array. ['Traceback (most recent call last):\n', '  File "C:\\Users\\ZHao\\.conda\\envs\\scopefoundry\\lib\\site-packages\\ScopeFoundry\\measurement.py", line 273, in _on_display_update_timer\n    self.update_display()\n', '  File "C:\\Users\\Public\\quantum_sensing\\quantum_sensing\\fancy_microscope\\thorcam_capture.py", line 362, in update_display\n    self.imview.setImage(image, axes={\'y\':0, \'x\':1}, autoLevels=True)\n', '  File "C:\\Users\\ZHao\\.conda\\envs\\scopefoundry\\lib\\site-packages\\pyqtgraph\\imageview\\ImageView.py", line 322, in setImage\n    self.updateImage(autoHistogramRange=autoHistogramRange)\n', '  File "C:\\Users\\ZHao\\.conda\\envs\\scopefoundry\\lib\\site-packages\\pyqtgraph\\imageview\\ImageView.py", line 725, in updateImage\n    image = image.transpose(axorder)\n', "ValueError: axes don't match array\n"]
