2022-04-07T13:21:41|CRITICAL|root|Unhandled exception:Traceback (most recent call last):
  File "fancy_microscope.py", line 46, in <module>
    app = FancyMicroscopeApp(sys.argv)
  File "C:\Users\ZHao\.conda\envs\scopefoundry\lib\site-packages\ScopeFoundry\base_app.py", line 332, in __init__
    self.setup()
  File "fancy_microscope.py", line 32, in setup
    self.add_measurement(ThorCamCaptureMeasure(self))
  File "C:\Users\ZHao\.conda\envs\scopefoundry\lib\site-packages\ScopeFoundry\measurement.py", line 93, in __init__
    self.setup()
  File "C:\Users\Public\quantum_sensing\quantum_sensing\fancy_microscope\thorcam_capture.py", line 252, in setup
    frame = camera.get_pending_frame_or_null()
  File "C:\Users\ZHao\.conda\envs\scopefoundry\lib\site-packages\thorlabs_tsi_sdk\tl_camera.py", line 555, in get_pending_frame_or_null
    image_buffer = POINTER(c_ushort)()
KeyboardInterrupt

