2022-02-25T12:24:35|INFO|ThorCamCaptureMeasure|thor_cam_capture start_stop False
2022-02-25T12:24:35|INFO|ThorCamCaptureMeasure|measurement thor_cam_capture interrupt
2022-02-25T12:24:35|INFO|ThorCamTestApp|setting up figures for thor_cam_capture measurement thor_cam_capture
2022-02-25T12:24:39|CRITICAL|root|Unhandled exception:Traceback (most recent call last):
  File "C:\Users\ZHao\.conda\envs\scopefoundry\lib\site-packages\ScopeFoundry\hardware.py", line 204, in enable_connection
    self.connect()
  File "C:\Users\Public\quantum_sensing\quantum_sensing\fancy_microscope\thorcam_hw.py", line 20, in connect
    self.cam.connect()
  File "C:\Users\Public\quantum_sensing\quantum_sensing\fancy_microscope\uc480\__init__.py", line 212, in connect
    self.call("is_InitCamera", ptr(self._camID), None)
  File "C:\Users\Public\quantum_sensing\quantum_sensing\fancy_microscope\uc480\__init__.py", line 116, in call
    assrt(func(*args), function)
  File "C:\Users\Public\quantum_sensing\quantum_sensing\fancy_microscope\uc480\__init__.py", line 66, in assrt
    raise uc480Error(retVal, "Error: uc480 function call failed! Error code = " + str(retVal), fname)
uc480.uc480Error: Error: uc480 function call failed! Error code = 3 in function is_InitCamera

During handling of the above exception, another exception occurred:

Traceback (most recent call last):
  File "C:\Users\ZHao\.conda\envs\scopefoundry\lib\site-packages\ScopeFoundry\hardware.py", line 219, in enable_connection
    raise err
  File "C:\Users\ZHao\.conda\envs\scopefoundry\lib\site-packages\ScopeFoundry\hardware.py", line 212, in enable_connection
    self.disconnect()
  File "C:\Users\Public\quantum_sensing\quantum_sensing\fancy_microscope\thorcam_hw.py", line 49, in disconnect
    self.cam.disconnect()
  File "C:\Users\Public\quantum_sensing\quantum_sensing\fancy_microscope\uc480\__init__.py", line 255, in disconnect
    self.call("is_ExitCamera", self._camID)
  File "C:\Users\Public\quantum_sensing\quantum_sensing\fancy_microscope\uc480\__init__.py", line 116, in call
    assrt(func(*args), function)
  File "C:\Users\Public\quantum_sensing\quantum_sensing\fancy_microscope\uc480\__init__.py", line 66, in assrt
    raise uc480Error(retVal, "Error: uc480 function call failed! Error code = " + str(retVal), fname)
uc480.uc480Error: Error: uc480 function call failed! Error code = 1 in function is_ExitCamera

2022-02-25T12:24:39|CRITICAL|root|Unhandled exception:Traceback (most recent call last):
  File "C:\Users\ZHao\.conda\envs\scopefoundry\lib\site-packages\ScopeFoundry\hardware.py", line 208, in enable_connection
    raise err
  File "C:\Users\ZHao\.conda\envs\scopefoundry\lib\site-packages\ScopeFoundry\hardware.py", line 204, in enable_connection
    self.connect()
  File "C:\Users\Public\quantum_sensing\quantum_sensing\fancy_microscope\thorcam_hw.py", line 20, in connect
    self.cam.connect()
  File "C:\Users\Public\quantum_sensing\quantum_sensing\fancy_microscope\uc480\__init__.py", line 212, in connect
    self.call("is_InitCamera", ptr(self._camID), None)
  File "C:\Users\Public\quantum_sensing\quantum_sensing\fancy_microscope\uc480\__init__.py", line 116, in call
    assrt(func(*args), function)
  File "C:\Users\Public\quantum_sensing\quantum_sensing\fancy_microscope\uc480\__init__.py", line 66, in assrt
    raise uc480Error(retVal, "Error: uc480 function call failed! Error code = " + str(retVal), fname)
uc480.uc480Error: Error: uc480 function call failed! Error code = 3 in function is_InitCamera

