2022-05-20T14:56:35|ERROR|ESRMeasure|ESR_measurement Failed to update figure1: 'ESRMeasure' object has no attribute 'xs'. ['Traceback (most recent call last):\n', '  File "C:\\Users\\ZHao\\.conda\\envs\\scopefoundry\\lib\\site-packages\\ScopeFoundry\\measurement.py", line 273, in _on_display_update_timer\n    self.update_display()\n', '  File "C:\\Users\\Public\\quantum_sensing\\quantum_sensing\\fancy_microscope\\custommeasure2.py", line 290, in update_display\n    self.current_plotline.setData(self.xs, self.ys)\n', "AttributeError: 'ESRMeasure' object has no attribute 'xs'\n"]
2022-05-20T14:56:35|ERROR|ESRMeasure|ESR_measurement Failed to update figure1: 'ESRMeasure' object has no attribute 'xs'. ['Traceback (most recent call last):\n', '  File "C:\\Users\\ZHao\\.conda\\envs\\scopefoundry\\lib\\site-packages\\ScopeFoundry\\measurement.py", line 273, in _on_display_update_timer\n    self.update_display()\n', '  File "C:\\Users\\Public\\quantum_sensing\\quantum_sensing\\fancy_microscope\\custommeasure2.py", line 290, in update_display\n    self.current_plotline.setData(self.xs, self.ys)\n', "AttributeError: 'ESRMeasure' object has no attribute 'xs'\n"]
