2022-10-19T16:59:50|ERROR|ESRMeasure|ESR_measurement Failed to update figure1: 'ESRMeasure' object has no attribute 'average_x'. ['Traceback (most recent call last):\n', '  File "C:\\Users\\ZHao\\.conda\\envs\\scopefoundry\\lib\\site-packages\\ScopeFoundry\\measurement.py", line 273, in _on_display_update_timer\n    self.update_display()\n', '  File "C:\\Users\\Public\\quantum_sensing\\quantum_microscope\\custommeasure2.py", line 297, in update_display\n    self.current_plotline.setData(self.average_x[:self.cutoff], self.average_y[:self.cutoff])\n', "AttributeError: 'ESRMeasure' object has no attribute 'average_x'\n"]
2022-10-19T16:59:50|ERROR|ESRMeasure|ESR_measurement Failed to update figure1: 'ESRMeasure' object has no attribute 'average_x'. ['Traceback (most recent call last):\n', '  File "C:\\Users\\ZHao\\.conda\\envs\\scopefoundry\\lib\\site-packages\\ScopeFoundry\\measurement.py", line 273, in _on_display_update_timer\n    self.update_display()\n', '  File "C:\\Users\\Public\\quantum_sensing\\quantum_microscope\\custommeasure2.py", line 297, in update_display\n    self.current_plotline.setData(self.average_x[:self.cutoff], self.average_y[:self.cutoff])\n', "AttributeError: 'ESRMeasure' object has no attribute 'average_x'\n"]
2022-10-19T16:59:53|CRITICAL|root|Unhandled exception:Traceback (most recent call last):
  File "C:\Users\ZHao\.conda\envs\scopefoundry\lib\site-packages\ScopeFoundry\measurement.py", line 25, in run
    self.measurement._thread_run()
  File "C:\Users\ZHao\.conda\envs\scopefoundry\lib\site-packages\ScopeFoundry\measurement.py", line 179, in _thread_run
    self.run()
  File "C:\Users\Public\quantum_sensing\quantum_microscope\custommeasure2.py", line 257, in run
    DAQ.closeDAQTask(task)
UnboundLocalError: local variable 'task' referenced before assignment

