2023-06-06T10:48:45|CRITICAL|root|Unhandled exception:Traceback (most recent call last):
  File "fancy_microscope.py", line 80, in <module>
    app = FancyMicroscopeApp(sys.argv)
  File "C:\Users\ZHao\.conda\envs\scopefoundry\lib\site-packages\ScopeFoundry\base_app.py", line 332, in __init__
    self.setup()
  File "fancy_microscope.py", line 43, in setup
    self.add_measurement(ThorCamCaptureMeasure(self))
  File "C:\Users\ZHao\.conda\envs\scopefoundry\lib\site-packages\ScopeFoundry\measurement.py", line 93, in __init__
    self.setup()
  File "C:\Users\Public\quantum_sensing\quantum_sensing\fancy_microscope\thorcam_capture.py", line 240, in setup
    self._execute_movePI()
  File "C:\Users\Public\quantum_sensing\quantum_sensing\fancy_microscope\thorcam_capture.py", line 537, in _execute_movePI
    device = initializeController('ROTATIONAL')
  File "C:\Users\Public\quantum_sensing\quantum_sensing\fancy_microscope\movestages.py", line 177, in initializeController
    pidevice.ConnectUSB(serialnum=SERIALNUMBERS[stageType])
  File "C:\Users\Public\quantum_sensing\quantum_sensing\fancy_microscope\pipython\pidevice\gcsdevice.py", line 83, in ConnectUSB
    super(GCSDevice, self).ConnectUSB(serialnum=serialnum)
  File "C:\Users\Public\quantum_sensing\quantum_sensing\fancy_microscope\pipython\pidevice\common\gcsbasedevice.py", line 149, in ConnectUSB
    self.dll.ConnectUSB(serialnum)
  File "C:\Users\Public\quantum_sensing\quantum_sensing\fancy_microscope\pipython\pidevice\interfaces\gcsdll.py", line 437, in ConnectUSB
    raise GCSError(self._error)
pipython.pidevice.gcserror.GCSError: There is no interface or DLL handle with the given ID (-9)

