2022-07-20T16:11:38|ERROR|ESRMeasure|ESR_measurement Failed to update figure1: 'ESRMeasure' object has no attribute 'average_x'. ['Traceback (most recent call last):\n', '  File "C:\\Users\\ZHao\\.conda\\envs\\scopefoundry\\lib\\site-packages\\ScopeFoundry\\measurement.py", line 273, in _on_display_update_timer\n    self.update_display()\n', '  File "C:\\Users\\Public\\quantum_sensing\\quantum_sensing\\fancy_microscope\\custommeasure2.py", line 294, in update_display\n    self.current_plotline.setData(self.average_x[:self.cutoff], self.average_y[:self.cutoff])\n', "AttributeError: 'ESRMeasure' object has no attribute 'average_x'\n"]
2022-07-20T16:11:38|ERROR|ESRMeasure|ESR_measurement Failed to update figure1: 'ESRMeasure' object has no attribute 'average_x'. ['Traceback (most recent call last):\n', '  File "C:\\Users\\ZHao\\.conda\\envs\\scopefoundry\\lib\\site-packages\\ScopeFoundry\\measurement.py", line 273, in _on_display_update_timer\n    self.update_display()\n', '  File "C:\\Users\\Public\\quantum_sensing\\quantum_sensing\\fancy_microscope\\custommeasure2.py", line 294, in update_display\n    self.current_plotline.setData(self.average_x[:self.cutoff], self.average_y[:self.cutoff])\n', "AttributeError: 'ESRMeasure' object has no attribute 'average_x'\n"]
2022-07-20T16:11:38|ERROR|ESRMeasure|ESR_measurement Failed to update figure1: 'ESRMeasure' object has no attribute 'average_x'. ['Traceback (most recent call last):\n', '  File "C:\\Users\\ZHao\\.conda\\envs\\scopefoundry\\lib\\site-packages\\ScopeFoundry\\measurement.py", line 273, in _on_display_update_timer\n    self.update_display()\n', '  File "C:\\Users\\Public\\quantum_sensing\\quantum_sensing\\fancy_microscope\\custommeasure2.py", line 294, in update_display\n    self.current_plotline.setData(self.average_x[:self.cutoff], self.average_y[:self.cutoff])\n', "AttributeError: 'ESRMeasure' object has no attribute 'average_x'\n"]
2022-07-20T16:11:38|ERROR|ESRMeasure|ESR_measurement Failed to update figure1: 'ESRMeasure' object has no attribute 'average_x'. ['Traceback (most recent call last):\n', '  File "C:\\Users\\ZHao\\.conda\\envs\\scopefoundry\\lib\\site-packages\\ScopeFoundry\\measurement.py", line 273, in _on_display_update_timer\n    self.update_display()\n', '  File "C:\\Users\\Public\\quantum_sensing\\quantum_sensing\\fancy_microscope\\custommeasure2.py", line 294, in update_display\n    self.current_plotline.setData(self.average_x[:self.cutoff], self.average_y[:self.cutoff])\n', "AttributeError: 'ESRMeasure' object has no attribute 'average_x'\n"]
2022-07-20T16:11:38|ERROR|ESRMeasure|ESR_measurement Failed to update figure1: 'ESRMeasure' object has no attribute 'average_x'. ['Traceback (most recent call last):\n', '  File "C:\\Users\\ZHao\\.conda\\envs\\scopefoundry\\lib\\site-packages\\ScopeFoundry\\measurement.py", line 273, in _on_display_update_timer\n    self.update_display()\n', '  File "C:\\Users\\Public\\quantum_sensing\\quantum_sensing\\fancy_microscope\\custommeasure2.py", line 294, in update_display\n    self.current_plotline.setData(self.average_x[:self.cutoff], self.average_y[:self.cutoff])\n', "AttributeError: 'ESRMeasure' object has no attribute 'average_x'\n"]
2022-07-20T16:11:38|ERROR|ESRMeasure|ESR_measurement Failed to update figure1: 'ESRMeasure' object has no attribute 'average_x'. ['Traceback (most recent call last):\n', '  File "C:\\Users\\ZHao\\.conda\\envs\\scopefoundry\\lib\\site-packages\\ScopeFoundry\\measurement.py", line 273, in _on_display_update_timer\n    self.update_display()\n', '  File "C:\\Users\\Public\\quantum_sensing\\quantum_sensing\\fancy_microscope\\custommeasure2.py", line 294, in update_display\n    self.current_plotline.setData(self.average_x[:self.cutoff], self.average_y[:self.cutoff])\n', "AttributeError: 'ESRMeasure' object has no attribute 'average_x'\n"]
2022-07-20T16:11:39|ERROR|ESRMeasure|ESR_measurement Failed to update figure1: 'ESRMeasure' object has no attribute 'average_x'. ['Traceback (most recent call last):\n', '  File "C:\\Users\\ZHao\\.conda\\envs\\scopefoundry\\lib\\site-packages\\ScopeFoundry\\measurement.py", line 273, in _on_display_update_timer\n    self.update_display()\n', '  File "C:\\Users\\Public\\quantum_sensing\\quantum_sensing\\fancy_microscope\\custommeasure2.py", line 294, in update_display\n    self.current_plotline.setData(self.average_x[:self.cutoff], self.average_y[:self.cutoff])\n', "AttributeError: 'ESRMeasure' object has no attribute 'average_x'\n"]
2022-07-20T16:11:39|ERROR|ESRMeasure|ESR_measurement Failed to update figure1: 'ESRMeasure' object has no attribute 'average_x'. ['Traceback (most recent call last):\n', '  File "C:\\Users\\ZHao\\.conda\\envs\\scopefoundry\\lib\\site-packages\\ScopeFoundry\\measurement.py", line 273, in _on_display_update_timer\n    self.update_display()\n', '  File "C:\\Users\\Public\\quantum_sensing\\quantum_sensing\\fancy_microscope\\custommeasure2.py", line 294, in update_display\n    self.current_plotline.setData(self.average_x[:self.cutoff], self.average_y[:self.cutoff])\n', "AttributeError: 'ESRMeasure' object has no attribute 'average_x'\n"]
2022-07-20T16:11:39|ERROR|ESRMeasure|ESR_measurement Failed to update figure1: 'ESRMeasure' object has no attribute 'average_x'. ['Traceback (most recent call last):\n', '  File "C:\\Users\\ZHao\\.conda\\envs\\scopefoundry\\lib\\site-packages\\ScopeFoundry\\measurement.py", line 273, in _on_display_update_timer\n    self.update_display()\n', '  File "C:\\Users\\Public\\quantum_sensing\\quantum_sensing\\fancy_microscope\\custommeasure2.py", line 294, in update_display\n    self.current_plotline.setData(self.average_x[:self.cutoff], self.average_y[:self.cutoff])\n', "AttributeError: 'ESRMeasure' object has no attribute 'average_x'\n"]
2022-07-20T16:11:39|ERROR|ESRMeasure|ESR_measurement Failed to update figure1: 'ESRMeasure' object has no attribute 'average_x'. ['Traceback (most recent call last):\n', '  File "C:\\Users\\ZHao\\.conda\\envs\\scopefoundry\\lib\\site-packages\\ScopeFoundry\\measurement.py", line 273, in _on_display_update_timer\n    self.update_display()\n', '  File "C:\\Users\\Public\\quantum_sensing\\quantum_sensing\\fancy_microscope\\custommeasure2.py", line 294, in update_display\n    self.current_plotline.setData(self.average_x[:self.cutoff], self.average_y[:self.cutoff])\n', "AttributeError: 'ESRMeasure' object has no attribute 'average_x'\n"]
2022-07-20T16:11:39|ERROR|ESRMeasure|ESR_measurement Failed to update figure1: 'ESRMeasure' object has no attribute 'average_x'. ['Traceback (most recent call last):\n', '  File "C:\\Users\\ZHao\\.conda\\envs\\scopefoundry\\lib\\site-packages\\ScopeFoundry\\measurement.py", line 273, in _on_display_update_timer\n    self.update_display()\n', '  File "C:\\Users\\Public\\quantum_sensing\\quantum_sensing\\fancy_microscope\\custommeasure2.py", line 294, in update_display\n    self.current_plotline.setData(self.average_x[:self.cutoff], self.average_y[:self.cutoff])\n', "AttributeError: 'ESRMeasure' object has no attribute 'average_x'\n"]
2022-07-20T16:11:39|ERROR|ESRMeasure|ESR_measurement Failed to update figure1: 'ESRMeasure' object has no attribute 'average_x'. ['Traceback (most recent call last):\n', '  File "C:\\Users\\ZHao\\.conda\\envs\\scopefoundry\\lib\\site-packages\\ScopeFoundry\\measurement.py", line 273, in _on_display_update_timer\n    self.update_display()\n', '  File "C:\\Users\\Public\\quantum_sensing\\quantum_sensing\\fancy_microscope\\custommeasure2.py", line 294, in update_display\n    self.current_plotline.setData(self.average_x[:self.cutoff], self.average_y[:self.cutoff])\n', "AttributeError: 'ESRMeasure' object has no attribute 'average_x'\n"]
2022-07-20T16:11:39|ERROR|ESRMeasure|ESR_measurement Failed to update figure1: 'ESRMeasure' object has no attribute 'average_x'. ['Traceback (most recent call last):\n', '  File "C:\\Users\\ZHao\\.conda\\envs\\scopefoundry\\lib\\site-packages\\ScopeFoundry\\measurement.py", line 273, in _on_display_update_timer\n    self.update_display()\n', '  File "C:\\Users\\Public\\quantum_sensing\\quantum_sensing\\fancy_microscope\\custommeasure2.py", line 294, in update_display\n    self.current_plotline.setData(self.average_x[:self.cutoff], self.average_y[:self.cutoff])\n', "AttributeError: 'ESRMeasure' object has no attribute 'average_x'\n"]
2022-07-20T16:11:39|ERROR|ESRMeasure|ESR_measurement Failed to update figure1: 'ESRMeasure' object has no attribute 'average_x'. ['Traceback (most recent call last):\n', '  File "C:\\Users\\ZHao\\.conda\\envs\\scopefoundry\\lib\\site-packages\\ScopeFoundry\\measurement.py", line 273, in _on_display_update_timer\n    self.update_display()\n', '  File "C:\\Users\\Public\\quantum_sensing\\quantum_sensing\\fancy_microscope\\custommeasure2.py", line 294, in update_display\n    self.current_plotline.setData(self.average_x[:self.cutoff], self.average_y[:self.cutoff])\n', "AttributeError: 'ESRMeasure' object has no attribute 'average_x'\n"]
2022-07-20T16:11:39|ERROR|ESRMeasure|ESR_measurement Failed to update figure1: 'ESRMeasure' object has no attribute 'average_x'. ['Traceback (most recent call last):\n', '  File "C:\\Users\\ZHao\\.conda\\envs\\scopefoundry\\lib\\site-packages\\ScopeFoundry\\measurement.py", line 273, in _on_display_update_timer\n    self.update_display()\n', '  File "C:\\Users\\Public\\quantum_sensing\\quantum_sensing\\fancy_microscope\\custommeasure2.py", line 294, in update_display\n    self.current_plotline.setData(self.average_x[:self.cutoff], self.average_y[:self.cutoff])\n', "AttributeError: 'ESRMeasure' object has no attribute 'average_x'\n"]
2022-07-20T16:11:39|ERROR|ESRMeasure|ESR_measurement Failed to update figure1: 'ESRMeasure' object has no attribute 'average_x'. ['Traceback (most recent call last):\n', '  File "C:\\Users\\ZHao\\.conda\\envs\\scopefoundry\\lib\\site-packages\\ScopeFoundry\\measurement.py", line 273, in _on_display_update_timer\n    self.update_display()\n', '  File "C:\\Users\\Public\\quantum_sensing\\quantum_sensing\\fancy_microscope\\custommeasure2.py", line 294, in update_display\n    self.current_plotline.setData(self.average_x[:self.cutoff], self.average_y[:self.cutoff])\n', "AttributeError: 'ESRMeasure' object has no attribute 'average_x'\n"]
2022-07-20T16:11:40|CRITICAL|root|Unhandled exception:Traceback (most recent call last):
  File "C:\Users\Public\quantum_sensing\quantum_sensing\fancy_microscope\DAQ_Analog.py", line 47, in configureDAQ
    readTask.timing.cfg_samp_clk_timing(DAQ_MaxSamplingRate,DAQ_SampleClk,Edge.RISING,AcquisitionType.FINITE, NsampsPerDAQread)
  File "C:\Users\ZHao\.conda\envs\scopefoundry\lib\site-packages\nidaqmx\_task_modules\timing.py", line 3007, in cfg_samp_clk_timing
    check_for_error(error_code)
  File "C:\Users\ZHao\.conda\envs\scopefoundry\lib\site-packages\nidaqmx\errors.py", line 127, in check_for_error
    raise DaqError(error_buffer.value.decode("utf-8"), error_code)
nidaqmx.errors.DaqError: Requested value is not a supported value for this property. The property value may be invalid because it conflicts with another property.
Property: DAQmx_SampClk_Rate
Requested Value:  200.0e6
Maximum Value:  50.0e6
Minimum Value:  22.250739e-309

Task Name: _unnamedTask<0>

Status Code: -200077

During handling of the above exception, another exception occurred:

Traceback (most recent call last):
  File "C:\Users\Public\quantum_sensing\quantum_sensing\fancy_microscope\custommeasure2.py", line 178, in run
    task = DAQ.configureDAQ(self.settings.N_samples.value)
  File "C:\Users\Public\quantum_sensing\quantum_sensing\fancy_microscope\DAQ_Analog.py", line 64, in configureDAQ
    sys.exit()
SystemExit

During handling of the above exception, another exception occurred:

Traceback (most recent call last):
  File "C:\Users\ZHao\.conda\envs\scopefoundry\lib\site-packages\ScopeFoundry\measurement.py", line 25, in run
    self.measurement._thread_run()
  File "C:\Users\ZHao\.conda\envs\scopefoundry\lib\site-packages\ScopeFoundry\measurement.py", line 179, in _thread_run
    self.run()
  File "C:\Users\Public\quantum_sensing\quantum_sensing\fancy_microscope\custommeasure2.py", line 254, in run
    DAQ.closeDAQTask(task)
UnboundLocalError: local variable 'task' referenced before assignment

