2023-05-22T18:16:45|ERROR|ESRMeasure|ESR Failed to update figure1: 'ESRMeasure' object has no attribute 'average_x'. ['Traceback (most recent call last):\n', '  File "C:\\Users\\ZHao\\.conda\\envs\\scopefoundry\\lib\\site-packages\\ScopeFoundry\\measurement.py", line 273, in _on_display_update_timer\n    self.update_display()\n', '  File "C:\\Users\\Public\\quantum_sensing\\quantum_sensing\\fancy_microscope\\ESRMeasure.py", line 348, in update_display\n    self.current_plotline.setData(self.average_x[:self.cutoff], self.average_y[:self.cutoff])\n', "AttributeError: 'ESRMeasure' object has no attribute 'average_x'\n"]
2023-05-22T18:16:45|ERROR|ESRMeasure|ESR Failed to update figure1: 'ESRMeasure' object has no attribute 'average_x'. ['Traceback (most recent call last):\n', '  File "C:\\Users\\ZHao\\.conda\\envs\\scopefoundry\\lib\\site-packages\\ScopeFoundry\\measurement.py", line 273, in _on_display_update_timer\n    self.update_display()\n', '  File "C:\\Users\\Public\\quantum_sensing\\quantum_sensing\\fancy_microscope\\ESRMeasure.py", line 348, in update_display\n    self.current_plotline.setData(self.average_x[:self.cutoff], self.average_y[:self.cutoff])\n', "AttributeError: 'ESRMeasure' object has no attribute 'average_x'\n"]
2023-05-22T18:39:14|CRITICAL|root|Unhandled exception:Traceback (most recent call last):
  File "C:\Users\ZHao\.conda\envs\scopefoundry\lib\site-packages\ScopeFoundry\measurement.py", line 272, in _on_display_update_timer
    try:
KeyboardInterrupt

2023-05-22T18:39:17|CRITICAL|root|Unhandled exception:Traceback (most recent call last):
  File "C:\Users\ZHao\.conda\envs\scopefoundry\lib\site-packages\pyqtgraph\graphicsItems\LabelItem.py", line 129, in sizeHint
    def sizeHint(self, hint, constraint):
KeyboardInterrupt

