2022-10-26T15:57:56|CRITICAL|root|Unhandled exception:Traceback (most recent call last):
  File "fancy_microscope.py", line 48, in <module>
    app = FancyMicroscopeApp(sys.argv)
  File "C:\Users\ZHao\.conda\envs\scopefoundry\lib\site-packages\ScopeFoundry\base_app.py", line 332, in __init__
    self.setup()
  File "fancy_microscope.py", line 34, in setup
    self.add_measurement(ThorCamCaptureMeasure(self))
  File "C:\Users\ZHao\.conda\envs\scopefoundry\lib\site-packages\ScopeFoundry\measurement.py", line 93, in __init__
    self.setup()
  File "C:\Users\Public\quantum_sensing\quantum_sensing\fancy_microscope\thorcam_capture.py", line 186, in setup
    self.ui = load_qt_ui_file(self.ui_filename)
  File "C:\Users\ZHao\.conda\envs\scopefoundry\lib\site-packages\ScopeFoundry\helper_funcs.py", line 64, in load_qt_ui_file
    ui = uic.loadUi(ui_filename)
  File "C:\Users\ZHao\.conda\envs\scopefoundry\lib\site-packages\PyQt5\uic\__init__.py", line 226, in loadUi
    return DynamicUILoader(package).loadUi(uifile, baseinstance, resource_suffix)
  File "C:\Users\ZHao\.conda\envs\scopefoundry\lib\site-packages\PyQt5\uic\Loader\loader.py", line 72, in loadUi
    return self.parse(filename, resource_suffix, basedir)
  File "C:\Users\ZHao\.conda\envs\scopefoundry\lib\site-packages\PyQt5\uic\uiparser.py", line 1013, in parse
    document = parse(filename)
  File "C:\Users\ZHao\.conda\envs\scopefoundry\lib\xml\etree\ElementTree.py", line 1196, in parse
    tree.parse(source, parser)
  File "C:\Users\ZHao\.conda\envs\scopefoundry\lib\xml\etree\ElementTree.py", line 597, in parse
    self._root = parser._parse_whole(source)
  File "<string>", line None
xml.etree.ElementTree.ParseError: mismatched tag: line 152, column 9

